Workbook

Sheet README
B1: PRIVATE CREDIT — WORKED CREDIT ANALYSIS MODEL
B2: Companion workbook to the handbook 'Credit Analysis from First Principles — A Private Credit Handbook'
B3: Fictional case study for training purposes. All names, numbers and events are invented.
B5: THE CASE
B6: Borrower | C6: Meridian Foods Group Ltd — UK mid-market private-label food manufacturer, acquired by a PE sponsor in a 2022 LBO.
B7: Facilities | C7: GBP 175m senior secured unitranche, BULLET maturity Sep-2027, SONIA + 600bps. GBP 15m super-senior RCF, SONIA + 275bps, maturing Mar-2027.
B8: Why this case | C8: It reproduces the classic failure your CRO described: reported EBITDA looks adequate, but the company does not generate enough CASH to repay (or credibly refinance) a large bullet due in two years. The model shows exactly where in the numbers you see it coming.
B10: SHEET GUIDE
B11: PnL | C11: Income statement FY2023A–FY2028F. Note the gap between statutory EBITDA, management 'Adjusted EBITDA', and a lender's view.
B12: BS | C12: Balance sheet. Watch receivables and payables days, goodwill vs tangible net worth, and the cash balance.
B13: CF | C13: Cash flow statement built indirect-method from PnL and BS. This is the sheet that repays your loan — read it first.
B14: Debt | C14: Debt schedule, maturity wall, and the refinancing sources & uses test for the FY2027 bullet.
B15: Ratios | C15: The full ratio toolkit with formulas, thresholds and RAG status. Every cell traces back to the statements.
B16: Stress | C16: Deal-level stress test: mild/severe/reverse scenarios with live operating-leverage transmission (companion to Handbook Part 12).
B17: Red Flags | C17: The 15 red flags present in this credit, each mapped to the exact cell where you can see it.
B18: Credit Memo | C18: A model credit assessment: 5 Cs, ratio verdicts, repayment analysis, downside case, and a recommendation your CRO would sign.
B20: CONVENTIONS
B21: Blue font | C21: Hardcoded input (historical financials as reported / forecast assumptions).
B22: Black font | C22: Live formula — trace it with Cmd+[ (Mac) or Ctrl+[ (Windows).
B23: RAG fills | C23: Green = comfortable, Amber = watch, Red = breach of guide threshold. Thresholds are on the Ratios sheet and are direct-lending market norms, not universal laws — calibrate by sector.
B24: A / F suffix | C24: A = actual (audited), F = forecast (management base case — treat with scepticism; see Red Flag #13).
B26: HOW TO PRACTISE
B27: Step 1 | C27: Read PnL top to bottom. Write down three questions you would put to management before looking at any other sheet.
B28: Step 2 | C28: Read CF. Compute for yourself: after interest, tax and capex, how much cash is left each year to repay 175m in 2027?
B29: Step 3 | C29: Open Debt and check the sources & uses at maturity. This is the single test that would have caught your CRO's example deal.
B30: Step 4 | C30: Only then open Ratios and Red Flags to check what you missed.
B31: Step 5 | C31: Read Credit Memo and compare its recommendation with the one you would have written.
B33: TOP-FIRM FRAMEWORK EXTENSION (added 5 Jul 2026)
B34: Falcon Underwrite | C34: Stages 1–6 of the top-firm framework on Project Falcon: sources & uses, EBITDA re-underwrite bridge (marketed $80m → underwritten $68m), FCCR/ICR/LTV/equity-cushion metrics with PASS/FAIL verdicts. Gold cells are inputs — flex them.
B35: Falcon Downside | C35: Stage 7: downside drivers, trough FCCR, and the three questions — coverage breakeven, liquidity runway, covenant sequencing.
B36: Falcon Recovery | C36: Second repayment leg: recovery waterfall, EBITDA-decline × exit-multiple impairment grid (colour-scaled), expected loss vs spread adequacy.
B37: Framework Scorecard | C37: All 10 stages scored side-by-side: Falcon (approved with conditions) vs Atlas (declined), with the Atlas mini-model and the IC decline record.
B39: Companion PDF: Private_Credit_TopFirm_Underwriting_Framework.pdf (same folder) — sources: Oaktree, Golub NJ IC report, Blue Owl, Blackstone, Ares, Apollo, Jefferies, S&P, KBRA, Proskauer, Cliffwater.

Sheet PnL
A1: Income Statement — Meridian Foods Group Ltd
A2: GBP m, years ending 31 Dec. Blue = as reported / assumption, black = formula.
A4: GBP m unless stated | C4: FY2023A | D4: FY2024A | E4: FY2025A | F4: FY2026F | G4: FY2027F | H4: FY2028F | J4: Analyst commentary
A5: Revenue | C5: 210 | D5: 232 | E5: 248 | F5: 258 | G5: 266 | H5: 274 | J5: Growth decelerating: 10.5% -> 6.9% -> 4.0%. Forecast assumes ~3% — check vs volume/price split and customer wins.
A6: Revenue growth % | D6: =D5/C5-1 | E6: =E5/D5-1 | F6: =F5/E5-1 | G6: =G5/F5-1 | H6: =H5/G5-1
A7: Cost of goods sold | C7: -142.8 | D7: -161.2 | E7: -174.8 | F7: -181.9 | G7: -187.5 | H7: -193.2 | J7: COGS ratio worsening 68.0% -> 69.5% -> 70.5%: input cost inflation not being passed through (weak pricing power).
A8: Gross profit | C8: =C5+C7 | D8: =D5+D7 | E8: =E5+E7 | F8: =F5+F7 | G8: =G5+G7 | H8: =H5+H7
A9: Gross margin % | C9: =C8/C5 | D9: =D8/D5 | E9: =E8/E5 | F9: =F8/F5 | G9: =G8/G5 | H9: =H8/H5
A10: SG&A and distribution (excl. exceptionals) | C10: -35.2 | D10: -36.3 | E10: -38.2 | F10: -39 | G10: -40.2 | H10: -41.4
A11: EBITDA (pre-exceptionals) | C11: =C8+C10 | D11: =D8+D10 | E11: =E8+E10 | F11: =F8+F10 | G11: =G8+G10 | H11: =H8+H10
A12: Exceptional / restructuring costs (cash) | C12: -2 | D12: -3.5 | E12: -4 | F12: -2 | G12: -1 | H12: 0 | J12: 'One-off' costs in 3 consecutive years and still forecast — they are recurring operating costs, not exceptionals. RED FLAG #1.
A13: EBITDA (statutory, post-exceptionals) | C13: =C11+C12 | D13: =D11+D12 | E13: =E11+E12 | F13: =F11+F12 | G13: =G11+G12 | H13: =H11+H12 | J13: The lender's starting point. FY25: 31.0 vs management Adjusted 42.0 — a 35% gap.
A14: EBITDA margin % (statutory) | C14: =C13/C5 | D14: =D13/D5 | E14: =E13/E5 | F14: =F13/F5 | G14: =G13/G5 | H14: =H13/H5
A15: Depreciation & amortisation | C15: -9 | D15: -9.5 | E15: -10 | F15: -10.2 | G15: -10.4 | H15: -10.6
A16: EBIT | C16: =C13+C15 | D16: =D13+D15 | E16: =E13+E15 | F16: =F13+F15 | G16: =G13+G15 | H16: =H13+H15
A17: Net interest expense (cash pay) | C17: -16.2 | D17: -17.6 | E17: -18.7 | F17: -19 | G17: -19.2 | H17: -19.2 | J17: Interest consumes ~60% of statutory EBITDA. FY28F assumes refinancing at TODAY'S margin — optimistic. RED FLAG #10.
A18: Profit before tax | C18: =C16+C17 | D18: =D16+D17 | E18: =E16+E17 | F18: =F16+F17 | G18: =G16+G17 | H18: =H16+H17
A19: Tax | C19: -1.2 | D19: -1 | E19: -0.6 | F19: -1.5 | G19: -1.9 | H19: -2.4
A20: Profit after tax | C20: =C18+C19 | D20: =D18+D19 | E20: =E18+E19 | F20: =F18+F19 | G20: =G18+G19 | H20: =H18+H19 | J20: FY25 PAT of 1.7m on 248m revenue: the equity cushion is being rebuilt at ~1m a year against a 175m bullet.
A22: MANAGEMENT 'ADJUSTED EBITDA' BRIDGE (as presented to lenders)
A23: EBITDA (statutory) | C23: =C13 | D23: =D13 | E23: =E13 | F23: =F13 | G23: =G13 | H23: =H13
A24: Add back: exceptional costs | C24: =-C12 | D24: =-D12 | E24: =-E12 | F24: =-F12 | G24: =-G12 | H24: =-H12
A25: Add back: pro-forma 'run-rate synergies' | C25: 0 | D25: 2 | E25: 3 | F25: 3 | G25: 3 | H25: 3 | J25: Synergies claimed since FY24 but never visible in actual margins. Unbanked synergies are hope, not EBITDA. RED FLAG #2.
A26: Add back: management fees & other | C26: 1 | D26: 1.5 | E26: 2 | F26: 2 | G26: 2 | H26: 2
A27: Management Adjusted EBITDA | C27: =SUM(C23:C26) | D27: =SUM(D23:D26) | E27: =SUM(E23:E26) | F27: =SUM(F23:F26) | G27: =SUM(G23:G26) | H27: =SUM(H23:H26)
A28: Lender-adjusted EBITDA (50% of exceptionals, no synergies) | C28: =C23-0.5*C12+C26 | D28: =D23-0.5*D12+D26 | E28: =E23-0.5*E12+E26 | F28: =F23-0.5*F12+F26 | G28: =G23-0.5*G12+G26 | H28: =H23-0.5*H12+H26 | J28: A defensible middle view: allow half the restructuring (genuinely tapering) and arm's-length fee addbacks; give no credit for synergies.

Sheet BS
A1: Balance Sheet — Meridian Foods Group Ltd
A2: GBP m at 31 Dec. Forecast cash is pulled live from the CF sheet.
A4: GBP m unless stated | C4: FY2023A | D4: FY2024A | E4: FY2025A | F4: FY2026F | G4: FY2027F | H4: FY2028F | J4: Analyst commentary
A5: ASSETS
A6: Cash and equivalents | C6: 12 | D6: 9 | E6: 6.5 | F6: =CF!F24 | G6: =CF!G24 | H6: =CF!H24 | J6: FY26F-FY28F pulled from CF sheet (live formula). Cash down 46% in two years while revenue grew 18%. RED FLAG #6.
A7: Trade receivables | C7: 27.6 | D7: 35.6 | E7: 42.8 | F7: 44.5 | G7: 45.9 | H7: 47.3 | J7: Receivables +55% vs revenue +18% (FY23-25). DSO 48 -> 63 days. Channel stuffing / extended terms / collectability? RED FLAG #4.
A8: Inventory | C8: 21.5 | D8: 25.6 | E8: 28.7 | F8: 29.9 | G8: 30.8 | H8: 31.8 | J8: DIO 55 -> 60 days. Building stock into slowing demand.
A9: Other current assets | C9: 3 | D9: 3 | E9: 3 | F9: 3 | G9: 3 | H9: 3
A10: Total current assets | C10: =SUM(C6:C9) | D10: =SUM(D6:D9) | E10: =SUM(E6:E9) | F10: =SUM(F6:F9) | G10: =SUM(G6:G9) | H10: =SUM(H6:H9)
A11: Property, plant & equipment | C11: 78 | D11: 80.5 | E11: 82.5 | F11: 84.3 | G11: 85.9 | H11: 87.3
A12: Goodwill & acquisition intangibles | C12: 145 | D12: 145 | E12: 145 | F12: 145 | G12: 145 | H12: 145 | J12: 47% of total assets is goodwill from the LBO — zero recovery value for a lender. Tangible net worth is deeply negative. RED FLAG #8.
A13: TOTAL ASSETS | C13: =C10+C11+C12 | D13: =D10+D11+D12 | E13: =E10+E11+E12 | F13: =F10+F11+F12 | G13: =G10+G11+G12 | H13: =H10+H11+H12
A15: LIABILITIES & EQUITY
A16: Trade payables | C16: 20.3 | D16: 25.6 | E16: 31.6 | F16: 32.9 | G16: 33.9 | H16: 34.9 | J16: DPO stretched 52 -> 66 days: the company is funding itself off its suppliers. Unsustainable and it snaps back in distress. RED FLAG #5.
A17: RCF drawn (super-senior) | C17: 0 | D17: 4 | E17: 10 | F17: 12 | G17: 14 | H17: 15 | J17: A 15m working-capital line now structurally drawn and forecast to hit its cap. RCF creep = the liquidity buffer is gone. RED FLAG #7.
A18: Unitranche term debt (bullet Sep-2027) | C18: 175 | D18: 175 | E18: 175 | F18: 175 | G18: 175 | H18: 175 | J18: No amortisation. 100% of principal depends on the FY27 refinancing. See Debt sheet.
A19: Other liabilities (accruals, provisions, deferred tax) | C19: 33.2 | D19: 32.6 | E19: 28.7 | F19: 28.7 | G19: 28.7 | H19: 28.7
A20: Total liabilities | C20: =SUM(C16:C19) | D20: =SUM(D16:D19) | E20: =SUM(E16:E19) | F20: =SUM(F16:F19) | G20: =SUM(G16:G19) | H20: =SUM(H16:H19)
A21: Shareholders' equity | C21: =C13-C20 | D21: =D13-D20 | E21: =E13-E20 | F21: =F13-F20 | G21: =G13-G20 | H21: =H13-H20 | J21: Balancing figure here; verify equity roll: opening equity + PAT = closing (check row below).
A22: TOTAL LIABILITIES & EQUITY | C22: =C20+C21 | D22: =D20+D21 | E22: =E20+E21 | F22: =F20+F21 | G22: =G20+G21 | H22: =H20+H21
A24: Check: equity roll (opening + PAT − closing) = 0 | D24: =C21+PnL!D20-D21 | E24: =D21+PnL!E20-E21 | F24: =E21+PnL!F20-F21 | G24: =F21+PnL!G20-G21 | H24: =G21+PnL!H20-H21 | J24: Should be ~0 for forecast years (historics include minor reserve movements).
A25: Memo: Tangible net worth (equity − goodwill/intangibles) | C25: =C21-C12 | D25: =D21-D12 | E25: =E21-E12 | F25: =F21-F12 | G25: =G21-G12 | H25: =H21-H12 | J25: Negative ~GBP 80m: in a liquidation the ONLY protection is enterprise-value-as-going-concern. Recovery depends on the business being sellable.

Sheet CF
A1: Cash Flow Statement (indirect method) — Meridian Foods Group Ltd
A2: GBP m. Built live from PnL and BS. THIS is the statement that repays debt.
A4: GBP m unless stated | C4: FY2023A | D4: FY2024A | E4: FY2025A | F4: FY2026F | G4: FY2027F | H4: FY2028F | J4: Analyst commentary
A5: OPERATING
A6: EBITDA (statutory) | C6: =PnL!C13 | D6: =PnL!D13 | E6: =PnL!E13 | F6: =PnL!F13 | G6: =PnL!G13 | H6: =PnL!H13
A7: (Increase) in trade receivables | C7: -4.1 | D7: =-(BS!D7-BS!C7) | E7: =-(BS!E7-BS!D7) | F7: =-(BS!F7-BS!E7) | G7: =-(BS!G7-BS!F7) | H7: =-(BS!H7-BS!G7) | J7: Working capital has absorbed ~GBP 18m of cash over FY23-25 — more than one full year of statutory EBITDA after interest.
A8: (Increase) in inventory | C8: -2.9 | D8: =-(BS!D8-BS!C8) | E8: =-(BS!E8-BS!D8) | F8: =-(BS!F8-BS!E8) | G8: =-(BS!G8-BS!F8) | H8: =-(BS!H8-BS!G8)
A9: Increase in trade payables | C9: 2.8 | D9: =BS!D16-BS!C16 | E9: =BS!E16-BS!D16 | F9: =BS!F16-BS!E16 | G9: =BS!G16-BS!F16 | H9: =BS!H16-BS!G16
A10: Movement in other liabilities / provisions | C10: 1.6 | D10: =BS!D19-BS!C19 | E10: =BS!E19-BS!D19 | F10: =BS!F19-BS!E19 | G10: =BS!G19-BS!F19 | H10: =BS!H19-BS!G19
A11: Cash tax paid | C11: =PnL!C19 | D11: =PnL!D19 | E11: =PnL!E19 | F11: =PnL!F19 | G11: =PnL!G19 | H11: =PnL!H19
A12: Net cash from operations (CFO) | C12: =SUM(C6:C11) | D12: =SUM(D6:D11) | E12: =SUM(E6:E11) | F12: =SUM(F6:F11) | G12: =SUM(G6:G11) | H12: =SUM(H6:H11)
A13: Cash conversion (CFO / EBITDA) | C13: =C12/C6 | D13: =D12/D6 | E13: =E12/E6 | F13: =F12/F6 | G13: =G12/G6 | H13: =H12/H6 | J13: Healthy manufacturers convert 85-100%. Meridian's conversion is dragged down by working-capital absorption.
A15: INVESTING
A16: Capital expenditure | C16: -12 | D16: -12 | E16: -12 | F16: -12 | G16: -12 | H16: -12 | J16: Capex > D&A every year (ageing plant). Maintenance capex alone is ~8m — do NOT model capex away in a downside case.
A18: FINANCING
A19: Interest paid | C19: =PnL!C17 | D19: =PnL!D17 | E19: =PnL!E17 | F19: =PnL!F17 | G19: =PnL!G17 | H19: =PnL!H17
A20: RCF drawn / (repaid) | C20: 0 | D20: =BS!D17-BS!C17 | E20: =BS!E17-BS!D17 | F20: =BS!F17-BS!E17 | G20: =BS!G17-BS!F17 | H20: =BS!H17-BS!G17
A21: Term debt drawn / (repaid) | C21: 0 | D21: 0 | E21: 0 | F21: 0 | G21: 0 | H21: 0 | J21: Base case assumes the FY27 bullet is REFINANCED at par (rolled). The Debt sheet tests whether that assumption is credible.
A22: Net cash flow | C22: =C12+C16+C19+C20+C21 | D22: =D12+D16+D19+D20+D21 | E22: =E12+E16+E19+E20+E21 | F22: =F12+F16+F19+F20+F21 | G22: =G12+G16+G19+G20+G21 | H22: =H12+H16+H19+H20+H21
A23: Opening cash | C23: 14 | D23: =C24 | E23: =D24 | F23: =E24 | G23: =F24 | H23: =G24
A24: Closing cash | C24: =C23+C22 | D24: =D23+D22 | E24: =E23+E22 | F24: =F23+F22 | G24: =G23+G22 | H24: =H23+H22 | J24: Ties to BS cash. Forecast BS cash is pulled from this row.
A26: THE NUMBERS THAT MATTER TO A LENDER
A27: Free cash flow pre debt service (CFO − capex) | C27: =C12+C16 | D27: =D12+D16 | E27: =E12+E16 | F27: =F12+F16 | G27: =G12+G16 | H27: =H12+H16
A28: Free cash flow AFTER interest (available for principal) | C28: =C27+C19 | D28: =D27+D19 | E28: =E27+E19 | F28: =F27+F19 | G28: =G27+G19 | H28: =H27+H19 | J28: FY25: NEGATIVE 2.5m. FY26-27F: ~1.0-2.9m a year against a 175m bullet in Sep-2027. This single row is the deal-killer. RED FLAG #3.
A29: Cumulative FCF after interest, FY26F-FY27F | F29: =SUM(D28:F28) | G29: =SUM(D28:G28) | H29: =SUM(D28:H28) | J29: Total organic debt-repayment capacity before the bullet falls due: <4m vs 175m owed = 2% of the principal.

Sheet Debt
A1: Debt Schedule, Maturity Wall & Refinancing Test
A2: GBP m. The test on this sheet is the one that catches 'not enough money to repay the lenders'.
A4: GBP m unless stated | C4: FY2023A | D4: FY2024A | E4: FY2025A | F4: FY2026F | G4: FY2027F | H4: FY2028F | J4: Analyst commentary
A5: FACILITIES
A6: RCF drawn (facility GBP 15m, S+275, matures Mar-2027) | C6: =BS!C17 | D6: =BS!D17 | E6: =BS!E17 | F6: =BS!F17 | G6: =BS!G17 | H6: =BS!H17
A7: Unitranche (S+600, BULLET Sep-2027) | C7: =BS!C18 | D7: =BS!D18 | E7: =BS!E18 | F7: =BS!F18 | G7: =BS!G18 | H7: =BS!H18
A8: Total gross debt | C8: =C6+C7 | D8: =D6+D7 | E8: =E6+E7 | F8: =F6+F7 | G8: =G6+G7 | H8: =H6+H7
A9: Less: cash | C9: =-BS!C6 | D9: =-BS!D6 | E9: =-BS!E6 | F9: =-BS!F6 | G9: =-BS!G6 | H9: =-BS!H6
A10: Net debt | C10: =C8+C9 | D10: =D8+D9 | E10: =E8+E9 | F10: =F8+F9 | G10: =G8+G9 | H10: =H8+H9
A11: Undrawn RCF headroom | C11: =15-C6 | D11: =15-D6 | E11: =15-E6 | F11: =15-F6 | G11: =15-G6 | H11: =15-H6 | J11: Headroom shrinks to ~0 by FY28F. Liquidity = cash + undrawn committed lines; both are evaporating simultaneously.
A13: CONTRACTUAL MATURITIES (principal falling due in each year)
A14: Scheduled amortisation | C14: 0 | D14: 0 | E14: 0 | F14: 0 | G14: 0 | H14: 0 | J14: Bullet structure = zero forced deleveraging. Every pound of the 175m is a FY27 problem.
A15: RCF maturity (Mar-2027) | C15: 0 | D15: 0 | E15: 0 | F15: 0 | G15: 14 | H15: 0
A16: Unitranche bullet (Sep-2027) | C16: 0 | D16: 0 | E16: 0 | F16: 0 | G16: 175 | H16: 0
A17: Total maturities | C17: =SUM(C14:C16) | D17: =SUM(D14:D16) | E17: =SUM(E14:E16) | F17: =SUM(F14:F16) | G17: =SUM(G14:G16) | H17: =SUM(H14:H16) | J17: GBP 189m — 100% of the debt stack — matures within a 6-month window in 2027. A textbook maturity wall. RED FLAG #9.
A19: REFINANCING TEST AT THE FY2027 WALL (do this on every deal with a bullet)
A20: 1. Cash available at maturity (FY27F closing cash) | G20: =CF!G24
A21: 2. Debt to be repaid or refinanced | G21: =G17
A22: 3. Funding gap = refinancing required | G22: =G21-G20 | J22: ~GBP 176m must be raised from new lenders in 2027.
A23: 4. Leverage at refinancing (net debt / statutory EBITDA, FY27F) | G23: =G10/PnL!G13 | J23: ~4.7x statutory at the wall. New lenders will also apply haircuts to addbacks — the refi market sees 5x+, not the sponsor's 4.2x.
A24: 5. Interest cover IF refinanced at +200bps (stress) | G24: =PnL!G13/(-PnL!G17+G8*0.02) | J24: Falls to ~1.6x. The company can only refinance if markets stay open AND pricing stays benign. That is refinancing risk, not credit strength.
A26: VERDICT
A27: Repayment of this loan depends ~2% on the borrower's own cash generation and ~98% on a future refinancing. The credit question is therefore: 'will a rational lender in 2027 refinance 175m against ~37m of statutory EBITDA, negative tangible net worth, deteriorating working capital and a track record of missed synergy delivery?' If you cannot answer YES with evidence, the deal fails first principles.

Sheet Ratios
A1: Ratio Toolkit — every ratio, its formula, threshold and verdict
A2: All cells are live formulas into PnL / BS / CF / Debt. Thresholds are direct-lending guides for a stable mid-market corporate; calibrate by sector and strategy.
A4: Ratio | C4: FY2023A | D4: FY2024A | E4: FY2025A | F4: FY2026F | G4: FY2027F | H4: FY2028F | I4: Guide threshold | J4: What it tells you / why it matters
A5: 1. LEVERAGE — how much debt vs earnings capacity
A6: Gross debt / EBITDA (statutory) | C6: =Debt!C8/PnL!C13 | D6: =Debt!D8/PnL!D13 | E6: =Debt!E8/PnL!E13 | F6: =Debt!F8/PnL!F13 | G6: =Debt!G8/PnL!G13 | H6: =Debt!H8/PnL!H13 | I6: < 4.0x G / 4-5.5x A / > 5.5x R | J6: The headline leverage test on REAL earnings. Meridian: 6.0x statutory — the market only 'sees' 4.4x because it is quoted on management-adjusted EBITDA.
A7: Gross debt / EBITDA (management adjusted) | C7: =Debt!C8/PnL!C27 | D7: =Debt!D8/PnL!D27 | E7: =Debt!E8/PnL!E27 | F7: =Debt!F8/PnL!F27 | G7: =Debt!G8/PnL!G27 | H7: =Debt!H8/PnL!H27 | I7: compare vs statutory | J7: The gap between this row and the one above IS the addback risk: 1.6 turns of leverage live inside adjustments.
A8: Net debt / EBITDA (statutory) | C8: =Debt!C10/PnL!C13 | D8: =Debt!D10/PnL!D13 | E8: =Debt!E10/PnL!E13 | F8: =Debt!F10/PnL!F13 | G8: =Debt!G10/PnL!G13 | H8: =Debt!H10/PnL!H13 | I8: < 3.5x G / 3.5-5x A / > 5x R | J8: Nets off cash — but only net cash that is genuinely free (not trapped in subsidiaries or needed for the working-capital cycle).
A9: Gross debt / (EBITDA − capex) | C9: =Debt!C8/(PnL!C13-12) | D9: =Debt!D8/(PnL!D13-12) | E9: =Debt!E8/(PnL!E13-12) | F9: =Debt!F8/(PnL!F13-12) | G9: =Debt!G8/(PnL!G13-12) | H9: =Debt!H8/(PnL!H13-12) | I9: < 5.5x G / 5.5-7.5x A / > 7.5x R | J9: Capex-adjusted leverage: for capex-heavy businesses this is the honest number. Meridian: ~9.7x — the plant must be fed before lenders are.
A10: 2. COVERAGE — can earnings service the debt as it falls due
A11: EBITDA / cash interest | C11: =PnL!C13/-PnL!C17 | D11: =PnL!D13/-PnL!D17 | E11: =PnL!E13/-PnL!E17 | F11: =PnL!F13/-PnL!F17 | G11: =PnL!G13/-PnL!G17 | H11: =PnL!H13/-PnL!H17 | I11: > 3.0x G / 2-3x A / < 2.0x R | J11: The first-order affordability test. Meridian 1.7x statutory: over half of EBITDA is consumed by interest before tax, capex or people.
A12: (EBITDA − capex) / cash interest | C12: =(PnL!C13-12)/-PnL!C17 | D12: =(PnL!D13-12)/-PnL!D17 | E12: =(PnL!E13-12)/-PnL!E17 | F12: =(PnL!F13-12)/-PnL!F17 | G12: =(PnL!G13-12)/-PnL!G17 | H12: =(PnL!H13-12)/-PnL!H17 | I12: > 2.0x G / 1.3-2x A / < 1.3x R | J12: Interest cover after the reinvestment the business NEEDS. Meridian ~1.0x: every pound of post-capex earnings goes to the lenders' coupon.
A13: DSCR: (EBITDA − capex − tax) / (interest + sched. amort) | C13: =(PnL!C13-12+PnL!C19)/(-PnL!C17+Debt!C14) | D13: =(PnL!D13-12+PnL!D19)/(-PnL!D17+Debt!D14) | E13: =(PnL!E13-12+PnL!E19)/(-PnL!E17+Debt!E14) | F13: =(PnL!F13-12+PnL!F19)/(-PnL!F17+Debt!F14) | G13: =(PnL!G13-12+PnL!G19)/(-PnL!G17+Debt!G14) | H13: =(PnL!H13-12+PnL!H19)/(-PnL!H17+Debt!H14) | I13: > 1.2x G / 1.0-1.2x A / < 1.0x R | J13: THE ratio for 'can they pay us back on schedule'. Meridian: ~1.0x with ZERO amortisation in the denominator — add any principal and it is instantly below 1.0x. This is your CRO's example, in one cell.
A14: Forward DSCR at the wall: FY27 (EBITDA − capex − tax) / (interest + bullet) | G14: =(PnL!G13-12+PnL!G19)/(-PnL!G17+Debt!G17) | I14: must be explained, not excused | J14: Include contractual maturities in debt service and the FY27 DSCR is ~0.1x. Any deal where this number is <1x is a refinancing bet and must be underwritten as one.
A15: Fixed charge cover: (EBITDA − capex) / (interest + leases/rents est. 2.0) | C15: =(PnL!C13-12)/(-PnL!C17+2) | D15: =(PnL!D13-12)/(-PnL!D17+2) | E15: =(PnL!E13-12)/(-PnL!E17+2) | F15: =(PnL!F13-12)/(-PnL!F17+2) | G15: =(PnL!G13-12)/(-PnL!G17+2) | H15: =(PnL!H13-12)/(-PnL!H17+2) | I15: > 1.5x G / 1.1-1.5x A / < 1.1x R | J15: Adds other unavoidable fixed charges (rent, leases). The broadest 'can they keep the lights on and pay us' test.
A16: 3. LIQUIDITY — can they pay what falls due in the next 12 months
A17: Current ratio (current assets / current liabilities) | C17: =BS!C10/(BS!C16+BS!C17+BS!C19) | D17: =BS!D10/(BS!D16+BS!D17+BS!D19) | E17: =BS!E10/(BS!E16+BS!E17+BS!E19) | F17: =BS!F10/(BS!F16+BS!F17+BS!F19) | G17: =BS!G10/(BS!G16+BS!G17+BS!G19) | H17: =BS!H10/(BS!H16+BS!H17+BS!H19) | I17: > 1.5 G / 1.0-1.5 A / < 1.0 R | J17: Crude but fast. Treat drawn RCF as current when it matures <12m or is structurally drawn.
A18: Quick ratio ((cash + receivables) / current liabilities) | C18: =(BS!C6+BS!C7)/(BS!C16+BS!C17+BS!C19) | D18: =(BS!D6+BS!D7)/(BS!D16+BS!D17+BS!D19) | E18: =(BS!E6+BS!E7)/(BS!E16+BS!E17+BS!E19) | F18: =(BS!F6+BS!F7)/(BS!F16+BS!F17+BS!F19) | G18: =(BS!G6+BS!G7)/(BS!G16+BS!G17+BS!G19) | H18: =(BS!H6+BS!H7)/(BS!H16+BS!H17+BS!H19) | I18: > 1.0 G / 0.7-1.0 A / < 0.7 R | J18: Strips inventory (slow to monetise, often overstated in distress).
A19: Total liquidity (cash + undrawn committed RCF) | C19: =BS!C6+Debt!C11 | D19: =BS!D6+Debt!D11 | E19: =BS!E6+Debt!E11 | F19: =BS!F6+Debt!F11 | G19: =BS!G6+Debt!G11 | H19: =BS!H6+Debt!H11 | I19: > 10% of revenue G | J19: The number that determines survival in a bad quarter. Meridian FY25: 11.5m = 4.6% of revenue and falling. RED FLAG #6/#7.
A20: 4. PROFITABILITY & EARNINGS QUALITY
A21: Gross margin | C21: =PnL!C9 | D21: =PnL!D9 | E21: =PnL!E9 | F21: =PnL!F9 | G21: =PnL!G9 | H21: =PnL!H9 | I21: stable/rising G; falling R | J21: Direction matters more than level. Meridian: −250bps in 2 years = no pricing power against input inflation.
A22: EBITDA margin (statutory) | C22: =PnL!C14 | D22: =PnL!D14 | E22: =PnL!E14 | F22: =PnL!F14 | G22: =PnL!G14 | H22: =PnL!H14 | I22: sector-relative | J22: Compare against sector peers, not an absolute rule. 12.5% for private-label food is mid-pack.
A23: Adjusted-to-statutory EBITDA gap (Adj/Stat − 1) | C23: =PnL!C27/PnL!C13-1 | D23: =PnL!D27/PnL!D13-1 | E23: =PnL!E27/PnL!E13-1 | F23: =PnL!F27/PnL!F13-1 | G23: =PnL!G27/PnL!G13-1 | H23: =PnL!H27/PnL!H13-1 | I23: < 10% G / 10-20% A / > 20% R | J23: The single best earnings-quality screen. >20% means you are lending against a spreadsheet, not a company. Meridian: 35%.
A24: Cash conversion (CFO / statutory EBITDA) | D24: =CF!D12/PnL!D13 | E24: =CF!E12/PnL!E13 | F24: =CF!F12/PnL!F13 | G24: =CF!G12/PnL!G13 | H24: =CF!H12/PnL!H13 | I24: > 85% G / 60-85% A / < 60% R | J24: If EBITDA is real, it shows up as cash. Persistent sub-70% conversion means EBITDA overstates cash earnings.
A25: 5. WORKING CAPITAL — where cash hides and where earnings are manufactured
A26: Days sales outstanding (AR / revenue × 365) | C26: =BS!C7/PnL!C5*365 | D26: =BS!D7/PnL!D5*365 | E26: =BS!E7/PnL!E5*365 | F26: =BS!F7/PnL!F5*365 | G26: =BS!G7/PnL!G5*365 | H26: =BS!H7/PnL!H5*365 | I26: stable G / +5d A / +10d R (trend) | J26: Rising DSO = customers paying slower, straining terms to book sales, or doubtful debts building. Meridian: 48 -> 63 days. RED FLAG #4.
A27: Days inventory (Inventory / COGS × 365) | C27: =BS!C8/-PnL!C7*365 | D27: =BS!D8/-PnL!D7*365 | E27: =BS!E8/-PnL!E7*365 | F27: =BS!F8/-PnL!F7*365 | G27: =BS!G8/-PnL!G7*365 | H27: =BS!H8/-PnL!H7*365 | I27: stable G (trend) | J27: Rising DIO into slowing sales = demand problem or obsolete stock not yet written down.
A28: Days payable (AP / COGS × 365) | C28: =BS!C16/-PnL!C7*365 | D28: =BS!D16/-PnL!D7*365 | E28: =BS!E16/-PnL!E7*365 | F28: =BS!F16/-PnL!F7*365 | G28: =BS!G16/-PnL!G7*365 | H28: =BS!H16/-PnL!H7*365 | I28: stable G; sharp rise R | J28: Sharply rising DPO flatters cash flow temporarily — it is borrowing from suppliers, and it reverses violently at the first sign of distress. RED FLAG #5.
A29: Cash conversion cycle (DSO + DIO − DPO) | C29: =(BS!C7/PnL!C5+ (BS!C8+BS!C16*-1)/-PnL!C7)*365 | D29: =(BS!D7/PnL!D5+ (BS!D8+BS!D16*-1)/-PnL!D7)*365 | E29: =(BS!E7/PnL!E5+ (BS!E8+BS!E16*-1)/-PnL!E7)*365 | F29: =(BS!F7/PnL!F5+ (BS!F8+BS!F16*-1)/-PnL!F7)*365 | G29: =(BS!G7/PnL!G5+ (BS!G8+BS!G16*-1)/-PnL!G7)*365 | H29: =(BS!H7/PnL!H5+ (BS!H8+BS!H16*-1)/-PnL!H7)*365 | I29: stable G (trend) | J29: How many days of cash are locked in the trading cycle. Note Meridian holds CCC flat ONLY by stretching payables.
A30: 6. CASH FLOW & REPAYMENT CAPACITY — the section that decides the deal
A31: FCF after interest (GBP m) — cash available for principal | D31: =CF!D28 | E31: =CF!E28 | F31: =CF!F28 | G31: =CF!G28 | H31: =CF!H28 | I31: > 0 and > amortisation | J31: Negative or near-zero with a bullet approaching = your CRO's example. This line, projected forward against the maturity schedule, is the core of repayment analysis.
A32: CFO / total debt | D32: =CF!D12/Debt!D8 | E32: =CF!E12/Debt!E8 | F32: =CF!F12/Debt!F8 | G32: =CF!G12/Debt!G8 | H32: =CF!H12/Debt!H8 | I32: > 20% G / 10-20% A / < 10% R | J32: Implied organic payback: at 12%, the company needs 8+ years of ALL operating cash (no capex, no interest) to repay debt maturing in 2.
A33: Years to repay: net debt / FCF after interest | D33: =IF(CF!D28<=0,"never",Debt!D10/CF!D28) | E33: =IF(CF!E28<=0,"never",Debt!E10/CF!E28) | F33: =IF(CF!F28<=0,"never",Debt!F10/CF!F28) | G33: =IF(CF!G28<=0,"never",Debt!G10/CF!G28) | H33: =IF(CF!H28<=0,"never",Debt!H10/CF!H28) | I33: < tenor G | J33: If this exceeds the remaining tenor, repayment depends on refinancing or sale — underwrite THAT event, not the ratio.
A34: 7. SOLVENCY & STRUCTURE
A35: Tangible net worth (GBP m) | C35: =BS!C25 | D35: =BS!D25 | E35: =BS!E25 | F35: =BS!F25 | G35: =BS!G25 | H35: =BS!H25 | I35: > 0 | J35: Negative TNW = recovery depends entirely on going-concern enterprise value. Your security is a business plan, not assets.
A36: Gearing: gross debt / (debt + equity) | C36: =Debt!C8/(Debt!C8+BS!C21) | D36: =Debt!D8/(Debt!D8+BS!D21) | E36: =Debt!E8/(Debt!E8+BS!E21) | F36: =Debt!F8/(Debt!F8+BS!F21) | G36: =Debt!G8/(Debt!G8+BS!G21) | H36: =Debt!H8/(Debt!H8+BS!H21) | I36: < 60% G / 60-80% A / > 80% R | J36: Book measure of the equity cushion beneath you. Meridian ~75%: thin, and the 'equity' is mostly capitalised goodwill.
A37: Loan-to-value (net debt / est. EV at 7.0x statutory EBITDA) | C37: =Debt!C10/(PnL!C13*7) | D37: =Debt!D10/(PnL!D13*7) | E37: =Debt!E10/(PnL!E13*7) | F37: =Debt!F10/(PnL!F13*7) | G37: =Debt!G10/(PnL!G13*7) | H37: =Debt!H10/(PnL!H13*7) | I37: < 50% G / 50-70% A / > 70% R | J37: Market-value cushion: at a 7x food-sector multiple, lenders are covered only 1.2x. A one-turn multiple contraction largely wipes the cushion. Sensitise the multiple, always.
A39: RAG shading applied to FY2025A (latest audited) column. G/A/R thresholds are guides for senior direct lending to a stable mid-market corporate.

Sheet Stress
A1: Deal-Level Stress Test — Meridian Foods (anchor year FY2026F)
A2: Companion to Handbook Part 12. Blue cells = scenario assumptions (change them and watch the transmission). Note the operating-leverage transmission: EBITDA falls by contribution margin x lost revenue, NOT one-for-one with revenue.
A4: GBP m unless stated | B4: Base (mgmt FY26F) | C4: Mild downside (~1-in-7) | D4: Severe downside (~1-in-25) | F4: Analyst commentary
A5: 1. SCENARIO ASSUMPTIONS (calibrate from sector history, the borrower's own worst year, macro mapping)
A6: Revenue decline vs base case | B6: 0 | C6: 0.05 | D6: 0.15 | F6: Calibration: mild = a normal bad year for the sector; severe = recession + loss of a top-3 customer.
A7: Additional gross-margin erosion (bps) | B7: 0 | C7: -50 | D7: -150 | F7: Input inflation not passed through. Meridian has already lost 250bps in 2 years, so this is not exotic.
A8: DSO deterioration (days) | B8: 0 | C8: 3 | D8: 7 | F8: Customers pay slower in downturns; stress the BALANCE SHEET, not just the P&L.
A9: Capex (management claims 8.0 maintenance floor) | B9: 12 | C9: 11 | D9: 10 | F9: Haircut management's 'we will cut capex' lever: cutting to the bone erodes the enterprise value securing you.
A10: Funding cost increase (bps on gross debt 189) | B10: 0 | C10: 100 | D10: 250 | F10: Floating-rate debt + stressed refi pricing. Severe assumes the FY27 refi prices at +250bps, if it happens at all.
A11: Credible management cost actions (pre-haircut plan x 50%) | B11: 0 | C11: 1 | D11: 2 | F11: Allow only actions that are specific, in management's control, and evidenced. Never let levers offset the whole stress.
A13: 2. TRANSMISSION TO THE P&L (operating leverage: contribution margin ~29.5%)
A14: Revenue | B14: =258*(1-B6) | C14: =258*(1-C6) | D14: =258*(1-D6)
A15: EBITDA (statutory basis) | B15: =35.1-(258-B14)*0.295+B14*B7/10000+B11 | C15: =35.1-(258-C14)*0.295+C14*C7/10000+C11 | D15: =35.1-(258-D14)*0.295+D14*D7/10000+D11 | F15: EBITDA = base 35.1 - lost revenue x 29.5% contribution + margin erosion + cost actions. A 15% revenue fall cuts EBITDA ~36%: THAT is operating leverage.
A16: EBITDA decline vs base | B16: =B15/$B$15-1 | C16: =C15/$B$15-1 | D16: =D15/$B$15-1
A17: Cash interest | B17: =19.0+189*B10/10000 | C17: =19.0+189*C10/10000 | D17: =19.0+189*D10/10000
A18: Cash tax (25% of taxable profit, floored at 0) | B18: =MAX(0.25*(B15-10.2-B17),0) | C18: =MAX(0.25*(C15-10.2-C17),0) | D18: =MAX(0.25*(D15-10.2-D17),0)
A19: Working-capital absorption from DSO slippage | B19: =B14/365*B8 | C19: =C14/365*C8 | D19: =D14/365*D8
A20: Baseline working-capital growth absorption (ties to CF sheet) | B20: 1.6 | C20: 1.6 | D20: 1.6 | F20: The base plan already absorbs ~1.6m of WC from growth (see CF sheet FY26F) - keep it so the base column reconciles to CF.
A21: FCF after interest (available for principal) | B21: =B15-B9-B18-B17-B19-B20 | C21: =C15-C9-C18-C17-C19-C20 | D21: =D15-D9-D18-D17-D19-D20 | F21: Base ties to the CF sheet at ~+1m. Mild burns ~4m a year; severe burns ~17m a year.
A23: 3. WHAT BREAKS, AND WHEN
A24: Interest cover (EBITDA / cash interest) | B24: =B15/B17 | C24: =C15/C17 | D24: =D15/D17 | F24: Severe: below 1.0x - the company cannot pay its coupon from earnings, before any principal.
A25: Gross leverage (189 / EBITDA) | B25: =189/B15 | C25: =189/C15 | D25: =189/D15 | F25: Refi-market ceiling for this credit ~5.5x statutory. The base case is ALREADY 5.4x.
A26: EBITDA headroom to the 5.5x refi ceiling | B26: =B15-189/5.5 | C26: =C15-189/5.5 | D26: =D15-189/5.5 | F26: EBITDA cushion before a 2027 refinancing becomes arithmetically unfundable at market leverage.
A27: Total liquidity at start (cash 6.5 + undrawn RCF 5.0) | B27: =6.5+5 | C27: =6.5+5 | D27: =6.5+5
A28: Months until liquidity exhausted (if FCF negative) | B28: =IF(B21>=0,"n/a",12*B27/-B21) | C28: =IF(C21>=0,"n/a",12*C27/-C21) | D28: =IF(D21>=0,"n/a",12*D27/-D21) | F28: Severe: ~8 months. The company dies of illiquidity in under a year - well before the Sep-2027 bullet even arrives.
A30: 4. REVERSE STRESS TEST - solve for the breaking point (all else held at base)
A31: Revenue decline at which interest cover hits 1.0x | B31: =(35.1-19.0)/0.295/258 | F31: ~21%: the coupon survives a deep recession. The COUPON is not the binding constraint...
A32: Revenue decline at which leverage exceeds the 5.5x refi ceiling | B32: =(35.1-189/5.5)/0.295/258 | F32: ~1%. ...the WALL is. A one-percent revenue miss makes the 2027 refinancing unfundable at market terms. This single cell is the deal's verdict.
A33: Revenue decline exhausting liquidity within 12 months (approx.) | B33: =(35.1-12-19.0-1.6+11.5)/0.295/258 | F33: ~18% (at base capex/tax): liquidity and coupon break at deep-recession levels; the refi ceiling breaks ~17 points of revenue earlier.
A35: READ-ACROSS: a stress test is not a prediction. Its job is to locate the BINDING CONSTRAINT (here: the refinancing ceiling, not the coupon), the TIME TO IMPACT (severe case: ~8 months of liquidity), and the CURE (equity, amortisation, longer tenor) - which is exactly what the restructured terms in the Credit Memo demand. If a stress test does not change the structure you ask for, it was decoration.

Sheet Red Flags
A1: Red Flags Present in This Credit — and Exactly Where to See Them
A2: Every flag below is visible in this workbook from the financial statements alone — no site visit required. This is the discipline: red flags are found in the numbers before they are confirmed in meetings.
A4: # | B4: Red flag | C4: What the data shows (this case) | D4: Where in this workbook | E4: Why it predicts credit loss
A5: 1 | B5: Recurring 'exceptional' costs | C5: Restructuring charges in FY23, FY24 AND FY25 (2.0 / 3.5 / 4.0), still forecast in FY26-27. | D5: PnL row: Exceptional costs | E5: Costs booked as one-off are excluded from covenant EBITDA — leverage and coverage are systematically understated. Recurring exceptionals are simply operating costs.
A6: 2 | B6: Unrealised synergy addbacks | C6: 3.0m of 'run-rate synergies' added back since FY24; actual margins show no trace of them. | D6: PnL: Adjusted EBITDA bridge | E6: Every turn of leverage priced off phantom EBITDA is a turn of real leverage the market will discover at refinancing.
A7: 3 | B7: FCF after interest ≤ 0 with a bullet approaching | C7: FY25 FCF after interest: −2.5m; cumulative FY26-27F: <4m vs a 175m bullet in Sep-2027. | D7: CF: 'FCF after interest' row; Debt: refinancing test | E7: THE failure mode of the CRO's example deal: the borrower cannot repay from its own cash and is 100% dependent on future market conditions.
A8: 4 | B8: Receivables growing faster than revenue | C8: AR +55% vs revenue +18% (FY23-25); DSO 48 -> 63 days. | D8: BS: Trade receivables; Ratios: DSO | E8: Classic signature of channel stuffing, straining terms to book revenue, or uncollectable balances building. Revenue quality is degrading.
A9: 5 | B9: Stretched payables flattering cash flow | C9: DPO 52 -> 66 days adds ~11m of 'free' funding. | D9: BS: Trade payables; Ratios: DPO | E9: Supplier credit is confidence-sensitive: at the first downgrade or late payment, terms tighten and the cash unwinds exactly when it is least affordable.
A10: 6 | B10: Eroding cash despite revenue growth | C10: Cash 12.0 -> 6.5 while revenue +18%. | D10: BS: Cash; CF: Closing cash | E10: Growth that consumes cash is not deleveraging the balance sheet; profitable-on-paper growth can still bankrupt a leveraged company.
A11: 7 | B11: Structural RCF utilisation creep | C11: Working-capital RCF drawn 0 -> 4 -> 10 of 15m; forecast full by FY28. | D11: BS: RCF drawn; Debt: undrawn headroom | E11: The revolver is meant to breathe with the cycle. Permanently drawn = it is funding losses/working capital structurally, and the emergency buffer is already spent.
A12: 8 | B12: Goodwill-heavy balance sheet / negative TNW | C12: Goodwill 145m = 47% of assets; tangible net worth ~ −82m. | D12: BS: memo row; Ratios: TNW | E12: In stress, goodwill is worth zero. Recovery depends entirely on selling the business as a going concern — precisely when buyers evaporate.
A13: 9 | B13: Concentrated maturity wall | C13: 189m — the entire debt stack — matures inside 6 months of 2027. | D13: Debt: maturities block | E13: No sequencing, no early-warning refi. One closed credit-market window = default, regardless of operating performance.
A14: 10 | B14: Forecast assumes benign refinancing | C14: FY28F interest assumes today's margin rolls; no scenario for +200bps or a haircut. | D14: PnL: interest note; Debt: stress test | E14: Base cases that embed the best-case exit hide the tail. Reprice at stress margins and interest cover drops to ~1.6x.
A15: 11 | B15: Margin compression with input inflation | C15: COGS ratio 68.0% -> 70.5%; gross margin −250bps in 2 years. | D15: PnL: COGS / gross margin | E15: No pricing power = earnings quality problem that compounds every year of inflation; forecast margin recovery has no stated mechanism.
... A19: 15 | B19: Cash conversion below 75% | C19: CFO/EBITDA ~72% (FY25) dragged by working-capital absorption. | D19: CF: cash conversion row | E19: EBITDA that does not convert to cash cannot service debt. Persistent low conversion means the covenant metric flatters true capacity.

Sheet Credit Memo
A1: Model Credit Assessment — Meridian Foods Group Ltd
A2: The write-up a credit officer should produce from the preceding sheets. Structure it this way every time: conclusion first, evidence after.
A4: RECOMMENDATION | B4: DECLINE at the proposed structure. The credit is refinance-dependent: organic repayment capacity over the life of the facility is <5% of principal. If the relationship justifies re-engagement, require: (i) leverage reset to ≤4.0x on LENDER-adjusted EBITDA via equity injection or debt paydown; (ii) 5% p.a. cash amortisation plus a 50% excess-cash-flow sweep to force deleveraging before the wall; (iii) maturity extended to 2029+ with the RCF inside the term loan; (iv) quarterly maintenance covenants (net leverage ≤5.0x stepping to 4.0x, interest cover ≥2.0x, minimum liquidity ≥10m) with a tight EBITDA definition capping addbacks at 10%; (v) sponsor equity commitment letter for the refinancing shortfall.
A5: BORROWER & DEAL | B5: Meridian Foods Group Ltd. UK private-label food manufacturer, ~248m revenue, PE-owned since 2022. Requested: hold/refi of 175m unitranche (S+600, bullet Sep-2027) + 15m super-senior RCF (Mar-2027).
A6: 1. CHARACTER (management & sponsor) | B6: Sponsor has taken no dividends (positive) but has missed synergy guidance two years running and presents an Adjusted EBITDA 35% above statutory. Forecasts are hockey-stick shaped ahead of a refinancing need. Credibility assessment: LOW on projections; underwrite the downside case.
A7: 2. CAPACITY (cash flow — decisive factor) | B7: Statutory EBITDA 31.0m; cash interest 18.7m (1.7x cover); capex 12.0m of which ~8m maintenance; FY25 FCF after interest −2.5m. Base-case cumulative FCF FY26-27 <4m against a 189m maturity wall. DSCR ~1.0x with zero amortisation; forward DSCR including the bullet ~0.1x. CAPACITY FAILS: the company does not generate enough money to repay the lenders — repayment rests entirely on a 2027 refinancing.
A8: 3. CAPITAL (cushion beneath us) | B8: Book equity ~63m but goodwill 145m: tangible net worth −82m. LTV ~1.2x covered at a 7x multiple; a one-turn multiple contraction takes lender coverage to ~1.05x. Cushion: THIN and market-dependent.
A9: 4. COLLATERAL (downside recovery) | B9: Security = share pledge + debenture over a business whose value is going-concern EV. Fixed assets 82.5m against 189m of debt; receivables/inventory partially fundable but of falling quality (DSO +15 days). Estimated distressed recovery 50-65% — acceptable only if entry leverage is disciplined, which it is not.
A10: 5. CONDITIONS (sector & docs) | B10: Private-label food: defensive volumes but structurally thin margins and concentrated grocery customers with pricing power over the borrower. Docs are cov-lite with a wide-open EBITDA definition (uncapped addbacks) — the covenant package will not give early control. Rate environment makes the 2027 refi the binding risk.
A11: REPAYMENT SOURCES (rank them, always) | B11: 1st WAY OUT — operating cash flow: FAILS (<5% of principal over tenor). 2nd — refinancing: POSSIBLE but requires benign markets and a lender willing to accept ~5x statutory leverage on deteriorating trends; this is a market bet, not credit strength. 3rd — sponsor support: uncommitted; no equity cure obligation in docs. 4th — enterprise sale/collateral: 50-65% recovery in distress. A deal standing on its 2nd-4th ways out is a workout waiting for a date.
A12: DOWNSIDE CASE (always run one) | B12: Assume: revenue −5%, gross margin −100bps further, DSO +5 days, refi at +200bps. Result: EBITDA ~26m, interest ~21m, cover 1.2x, FCF after interest ~ −8m p.a., RCF exhausted within 12 months, covenant-less until the money is gone. Probability-weighted, this is a Stage-2/watchlist credit AT ORIGINATION.
A13: EARLY-WARNING TRIGGERS TO MONITOR (if held) | B13: Monthly: RCF utilisation >12m; liquidity <8m. Quarterly: DSO +3d vs prior; cash conversion <65%; statutory EBITDA miss >5% vs budget; any new 'exceptional' item; auditor or CFO change; supplier payment terms complaints. 18 months pre-maturity: no signed refi mandate = transfer to watchlist, engage restructuring counsel.
A14: THE ONE-SENTENCE LESSON | B14: Leverage told you this deal was tight; the CASH FLOW STATEMENT told you it could not pay you back; the DEBT SCHEDULE told you exactly when you would find out. Read them in that order on every deal.

Sheet Falcon Underwrite
B2: PROJECT FALCON — TOP-FIRM UNDERWRITE (Stages 1–6)
B3: Companion to 'The Private Credit Underwriting Framework' PDF §15.1. Gold cells = inputs; everything else computes live.
B5: THE DEAL
B6: Borrower | C6: FalconComply — regulatory-compliance software for mid-size insurance carriers. Revenue $200m, 87% recurring, GRR 94% / NRR 106%, top customer 4%.
B7: Transaction | C7: Sponsor LBO at $1,120m = 14.0x MARKETED EBITDA of $80m. Invitation-only process (3 lenders); we are incumbent to another portfolio company.
B8: Ask | C8: $360m unitranche (first-out) + $50m undrawn super-senior revolver, 6-year tenor.
B10: ASSUMPTIONS (flex these)
B11: Input | C11: Value | F11: Input | G11: Value
B12: SOFR | C12: 0.0375 | F12: Capex ($m) | G12: 7
B13: Credit spread | C13: 0.0525 | F13: Cash taxes ($m) | G13: 9
B14: SOFR floor | C14: 0.01 | F14: Sponsor fee ($m) | G14: 1.5
B15: OID (price) | C15: 98 | F15: Opening cash ($m) | G15: 25
B16: Amortisation p.a. | C16: 0.01 | F16: Conservative EV multiple | G16: 11
B17: Term loan ($m) | C17: 360 | F17: Net leverage covenant | G17: 6.65
B19: SOURCES & USES ($m)
B20: Sources | C20: $m | F20: Uses | G20: $m
B21: Unitranche term loan | C21: =C17 | F21: Purchase enterprise value (14.0x × $80m marketed) | G21: 1120
B22: Sponsor equity (plug) | C22: =G21+G22-C21 | F22: Fees & expenses | G22: 30
B23: Total sources | C23: =SUM(C21:C22) | F23: Total uses | G23: =SUM(G21:G22)
B25: STAGE 4 — EBITDA RE-UNDERWRITE (the add-back forensics)
B26: EBITDA bridge ($m) | C26: Claimed | D26: Accepted | E26: Accept % | F26: Disposition (composite top-firm treatment)
B27: Reported LTM EBITDA (QoE-verified) | C27: 62 | D27: 62 | E27: =IF(C27=0,"—",D27/C27) | F27: Anchor — audited/QoE basis
B28: One-time litigation & carve-out costs | C28: 4 | D28: 3 | E28: =IF(C28=0,"—",D28/C28) | F28: $1m is recurring integration spend — rejected
B29: Completed acquisition annualisation | C29: 2 | D29: 2 | E29: =IF(C29=0,"—",D29/C29) | F29: Closed 8 months ago; run-rate verified in QoE
B30: Procurement savings (contracted) | C30: 2 | D30: 1 | E30: =IF(C30=0,"—",D30/C30) | F30: 50% credit — signed but unproven
B31: Headcount programme (announced, unactioned) | C31: 5 | D31: 0 | E31: =IF(C31=0,"—",D31/C31) | F31: Rejected — no credit for unactioned savings
B32: Revenue synergies with sponsor portfolio | C32: 5 | D32: 0 | E32: =IF(C32=0,"—",D32/C32) | F32: Rejected on principle — revenue synergies never credited
B33: MARKETED / UNDERWRITTEN EBITDA | C33: =SUM(C27:C32) | D33: =SUM(D27:D32) | E33: =D33/C33 | F33: Add-backs = 22.5% of marketed (S&P median ~29% — and size of add-backs correlates with default)
B34: Rule: every leverage, coverage and covenant number below is computed on the UNDERWRITTEN column. The marketed column exists only to measure the sponsor's optimism.
B36: STAGES 5–6 — COVERAGE AND VALUE (all on underwritten EBITDA)
B37: Metric | C37: Formula | D37: Value | F37: Top-firm standard | G37: Verdict
B38: Coupon | C38: max(SOFR, floor) + spread | D38: =MAX(C12,C14)+C13 | F38: —
B39: Cash interest ($m) | C39: Term × coupon | D39: =(C17*(MAX(C12,C14)+C13)) | F39: —
B40: Gross leverage | C40: Term / underwritten EBITDA | D40: =C17/D33 | F40: ≤ ~5.5x (software) | G40: =IF(C17/D33<=5.5,"PASS","FAIL")
B41: Net leverage | C41: (Term − cash) / underwritten EBITDA | D41: =(C17-G15)/D33 | F41: ≤ ~5.0x net | G41: =IF((C17-G15)/D33<=5,"PASS","WATCH")
B42: Interest coverage (ICR) | C42: EBITDA / cash interest | D42: =D33/(C17*(MAX(C12,C14)+C13)) | F42: ≥ 2.0x (KBRA market median 1.5x) | G42: =IF(D33/(C17*(MAX(C12,C14)+C13))>=2,"PASS","FAIL")
B43: CFADS ($m) | C43: EBITDA − capex − cash tax − sponsor fee | D43: =(D33-G12-G13-G14) | F43: —
B44: FCCR — the one that matters | C44: CFADS / (interest + amortisation) | D44: =(D33-G12-G13-G14)/((C17*(MAX(C12,C14)+C13))+(C17*C16)) | F44: ≥ 1.3x base case at close | G44: =IF((D33-G12-G13-G14)/((C17*(MAX(C12,C14)+C13))+(C17*C16))>=1.3,"PASS","FAIL")
B45: Equity cushion | C45: Equity / total capitalisation | D45: =C22/C23 | F45: ≥ 50% (market ~60%) | G45: =IF(C22/C23>=0.5,"PASS","FAIL")
B46: Conservative EV ($m) | C46: Underwritten EBITDA × conservative multiple | D46: =(D33*G16) | F46: 2–4 turns below purchase multiple
...

Sheet Falcon Downside
B2: PROJECT FALCON — DOWNSIDE CASE & COVENANT SEQUENCING (Stage 7)
B3: The downside case is a design specification: it must still cover fixed charges, trip the covenant early, and be fundable from liquidity.
B5: DOWNSIDE DRIVERS (composite top-firm calibration)
B6: Driver | C6: Base | D6: Downside | E6: Calibration source | F6: Input
B7: Revenue ($m) | C7: 200 | D7: =C7*(1-F7) | E7: Decline % → input at right. −12% peak-to-trough over 18–24 months; company grew +3% in 2020 — stress beyond history | F7: 0.12
B8: EBITDA margin | C8: 0.34 | D8: 0.295 | E8: −450bps: pricing pressure + cost underabsorption
B9: EBITDA ($m) | C9: ='Falcon Underwrite'!D33 | D9: =D7*D8 | E9: Base = underwritten $68m from the bridge (200 × 34%)
B10: SOFR shift | C10: — | D10: 0.01 | E10: +100bps — the asset class floats (the 2022–23 lesson: coverage halved as SOFR rose)
B12: DOWNSIDE COVERAGE (year-2 trough)
B13: Metric | C13: Base | D13: Downside | E13: Reading
B14: Coupon | C14: =(MAX('Falcon Underwrite'!C12,'Falcon Underwrite'!C14)+'Falcon Underwrite'!C13) | D14: =(MAX('Falcon Underwrite'!C12+D10,'Falcon Underwrite'!C14)+'Falcon Underwrite'!C13)
B15: Cash interest ($m) | C15: ='Falcon Underwrite'!C17*(MAX('Falcon Underwrite'!C12,'Falcon Underwrite'!C14)+'Falcon Underwrite'!C13) | D15: ='Falcon Underwrite'!C17*(MAX('Falcon Underwrite'!C12+D10,'Falcon Underwrite'!C14)+'Falcon Underwrite'!C13)
B16: Capex + cash tax + sponsor fee ($m) | C16: ='Falcon Underwrite'!G12+'Falcon Underwrite'!G13+'Falcon Underwrite'!G14 | D16: =7+5+1.5 | E16: Cash tax falls to $5m at the trough
B17: CFADS ($m) | C17: ='Falcon Underwrite'!D33-C16 | D17: =D9-D16
B18: Fixed charges (interest + 1% amortisation, $m) | C18: =C15+'Falcon Underwrite'!C17*'Falcon Underwrite'!C16 | D18: =D15+'Falcon Underwrite'!C17*'Falcon Underwrite'!C16
B19: FCCR | C19: =C17/C18 | D19: =D17/D18 | E19: =IF(D19>=1,"Covers at the trough — tight by design","Below 1.0x — burning cash at the trough")
B20: Net debt ($m) | C20: ='Falcon Underwrite'!C17-'Falcon Underwrite'!G15 | D20: ='Falcon Underwrite'!C17-10 | E20: Downside: cash partially consumed ($10m left)
B21: Net leverage | C21: =C20/'Falcon Underwrite'!D33 | D21: =D20/D9 | E21: =IF(D21>'Falcon Underwrite'!G17,"BREACHES the "&TEXT('Falcon Underwrite'!G17,"0.00")&"x covenant → lender gets the table early","Inside covenant")
B23: THE THREE QUESTIONS (framework §9.2)
B24: Question | C24: Value | E24: Reading
B25: 1. Coverage breakeven — EBITDA at FCCR = 1.0x ($m) | C25: =C18+C16 | E25: ="A "&TEXT(1-C25/'Falcon Underwrite'!D33,"0%")&" EBITDA decline is the true shock absorber (at base rates)"
B26: 2. Liquidity runway at the trough (quarters) | C26: =MIN(99,IF(D18-D17<=0,99,(50+10)/(D18-D17)*4)) | E26: $50m revolver + $10m cash vs downside burn (fixed charges − CFADS). 99 = effectively unlimited. Standard: ≥ 4–6 quarters
B27: 3. Covenant trip EBITDA ($m) and sequencing | C27: =C20/'Falcon Underwrite'!G17 | E27: ="Trips at −"&TEXT(1-C27/'Falcon Underwrite'!D33,"0%")&" from underwritten EBITDA — BEFORE liquidity exhausts. Sequencing correct: early seat at the table"
B29: Covenant at 6.65x = ~26% EBITDA headroom (inside the 25–35% convention). Push it to 7.5x and the trip point moves to −34% — past the point where negotiating leverage has shifted to the sponsor. The extra headroom IS the workout option, transferred.

Sheet Falcon Recovery
B2: PROJECT FALCON — RECOVERY ANALYSIS (the second repayment leg)
B3: If cash flow fails, what stands between the loan and loss? Fitch 2025 resolved private credit defaults: first lien recovered par in 6 of 8, 70–90% in the other two.
B5: RECOVERY WATERFALL AT THE DOWNSIDE TROUGH
B6: Step | C6: $m / x | E6: Notes
B7: Trough EBITDA (from Downside sheet) | C7: ='Falcon Downside'!D9
B8: Distressed exit multiple | C8: 8.5 | E8: ~40% below the 14x purchase multiple
B9: Distressed enterprise value ($m) | C9: =C7*C8
B10: Claim: term loan + drawn revolver ($25m drawn) | C10: ='Falcon Underwrite'!C17+25
B11: Coverage (EV / claim) | C11: =C9/C10
B12: Implied recovery | C12: =MIN(1,C9/C10) | E12: =IF(C12>=1,"Full recovery expected even at the trough","Impaired — loss = "&TEXT(1-C12,"0%"))
B14: IMPAIRMENT GRID — WHAT MUST JOINTLY GO WRONG (recovery % of claim)
B15: EBITDA decline ↓ / Exit multiple → | C15: 5.5x | D15: 6.5x | E15: 7.5x | F15: 8.5x | G15: 9.5x | H15: 11.0x
B16: 0% (underwritten EBITDA) | C16: =MIN(1,('Falcon Underwrite'!D33*(1-0.0)*5.5)/C10) | D16: =MIN(1,('Falcon Underwrite'!D33*(1-0.0)*6.5)/C10) | E16: =MIN(1,('Falcon Underwrite'!D33*(1-0.0)*7.5)/C10) | F16: =MIN(1,('Falcon Underwrite'!D33*(1-0.0)*8.5)/C10) | G16: =MIN(1,('Falcon Underwrite'!D33*(1-0.0)*9.5)/C10) | H16: =MIN(1,('Falcon Underwrite'!D33*(1-0.0)*11.0)/C10)
B17: −15% EBITDA | C17: =MIN(1,('Falcon Underwrite'!D33*(1-0.15)*5.5)/C10) | D17: =MIN(1,('Falcon Underwrite'!D33*(1-0.15)*6.5)/C10) | E17: =MIN(1,('Falcon Underwrite'!D33*(1-0.15)*7.5)/C10) | F17: =MIN(1,('Falcon Underwrite'!D33*(1-0.15)*8.5)/C10) | G17: =MIN(1,('Falcon Underwrite'!D33*(1-0.15)*9.5)/C10) | H17: =MIN(1,('Falcon Underwrite'!D33*(1-0.15)*11.0)/C10)
B18: −24% EBITDA | C18: =MIN(1,('Falcon Underwrite'!D33*(1-0.24)*5.5)/C10) | D18: =MIN(1,('Falcon Underwrite'!D33*(1-0.24)*6.5)/C10) | E18: =MIN(1,('Falcon Underwrite'!D33*(1-0.24)*7.5)/C10) | F18: =MIN(1,('Falcon Underwrite'!D33*(1-0.24)*8.5)/C10) | G18: =MIN(1,('Falcon Underwrite'!D33*(1-0.24)*9.5)/C10) | H18: =MIN(1,('Falcon Underwrite'!D33*(1-0.24)*11.0)/C10)
B19: −30% EBITDA | C19: =MIN(1,('Falcon Underwrite'!D33*(1-0.3)*5.5)/C10) | D19: =MIN(1,('Falcon Underwrite'!D33*(1-0.3)*6.5)/C10) | E19: =MIN(1,('Falcon Underwrite'!D33*(1-0.3)*7.5)/C10) | F19: =MIN(1,('Falcon Underwrite'!D33*(1-0.3)*8.5)/C10) | G19: =MIN(1,('Falcon Underwrite'!D33*(1-0.3)*9.5)/C10) | H19: =MIN(1,('Falcon Underwrite'!D33*(1-0.3)*11.0)/C10)
B20: −45% EBITDA | C20: =MIN(1,('Falcon Underwrite'!D33*(1-0.45)*5.5)/C10) | D20: =MIN(1,('Falcon Underwrite'!D33*(1-0.45)*6.5)/C10) | E20: =MIN(1,('Falcon Underwrite'!D33*(1-0.45)*7.5)/C10) | F20: =MIN(1,('Falcon Underwrite'!D33*(1-0.45)*8.5)/C10) | G20: =MIN(1,('Falcon Underwrite'!D33*(1-0.45)*9.5)/C10) | H20: =MIN(1,('Falcon Underwrite'!D33*(1-0.45)*11.0)/C10)
B22: First-lien impairment requires BOTH a ~24%+ EBITDA decline AND a distressed multiple ≤ ~6.5x, while $790m of equity absorbs value destruction first. This grid is the quantitative meaning of 'margin of safety from seniority'.
B24: EXPECTED LOSS & SPREAD ADEQUACY (Stage 9 check)
B25: Component | C25: Value | E25: Source / logic
B26: Through-cycle PD [assumption] | C26: 0.025 | E26: Proskauer default index ran 1.8–2.7% through 2025–26
B27: LGD [assumption] | C27: 0.3 | E27: Conservative vs Fitch first-lien experience (0–30% loss)
B28: Expected loss p.a. | C28: =C26*C27 | E28: CDLI long-run realized losses ~1.0% p.a. — sanity anchor
B29: Credit spread | C29: ='Falcon Underwrite'!C13
B30: Spread / EL cover | C30: =C29/C28 | E30: Are we paid for the risk? Spread must clear expected loss several times to fund fees + illiquidity

Sheet Framework Scorecard
B2: THE 10-STAGE TOP-FIRM SCORECARD — FALCON (approved) vs ATLAS (declined)
B3: One row per framework stage. Falcon cells link live to the Falcon sheets; Atlas is the HVAC roll-up from §15.2 of the framework PDF (mini-model below).
B5: SCORECARD
B6: Stage | C6: Test | D6: Standard | E6: Falcon | F6: Verdict | G6: Atlas | H6: Verdict
B7: 1. Sourcing | C7: Deal provenance — who else has seen this? | D7: Invitation-only / incumbent edge | E7: ="3 lenders, incumbent" | F7: ="PASS" | G7: ="14 lenders, incumbents out" | H7: ="FAIL"
B8: 2. Screening | C8: Size, sector, sponsor, structure floors | D8: Inside platform box | E8: ="$68m EBITDA software" | F8: ="PASS" | G8: ="Roll-up, housing-linked" | H8: ="WATCH"
B9: 3. Business quality | C9: Organic growth; recession datapoint | D9: Positive organic; survived 2020 | E9: ="+3% in 2020, 87% recurring" | F9: ="PASS" | G9: ="Same-branch revenue −4%" | H9: ="FAIL"
B10: 4. EBITDA honesty | C10: Add-backs as % of marketed EBITDA | D10: ≤ 20–25% and dispositioned line-by-line | E10: =('Falcon Underwrite'!C33-'Falcon Underwrite'!C27)/'Falcon Underwrite'!C33 | F10: =IF(E10<=0.25,"PASS","FAIL") | G10: =C23 | H10: =IF(G10<=0.25,"PASS","FAIL")
B11: 5. FCCR at close | C11: CFADS / fixed charges, lender numbers | D11: ≥ 1.3x base case | E11: ='Falcon Underwrite'!D44 | F11: =IF(E11>=1.3,"PASS","FAIL") | G11: =C27 | H11: =IF(G11>=1.3,"PASS","FAIL")
B12: 6. LTV / cushion | C12: Debt / conservative EV | D12: ≤ 50% | E12: ='Falcon Underwrite'!D47 | F12: =IF(E12<=0.5,"PASS","FAIL") | G12: =C29 | H12: =IF(G12<=0.5,"PASS","FAIL")
B13: 7. Downside | C13: FCCR at trough; covenant sequencing | D13: ≥ ~1.0x; covenant trips before cash out | E13: ='Falcon Downside'!D19 | F13: =IF(E13>=0.95,"PASS (tight)","FAIL") | G13: ="~0.8x; trips after runway" | H13: ="FAIL"
B14: 8. Documentation | C14: Maintenance covenant, capped EBITDA defn, blockers | D14: All present (Ares: never cov-lite) | E14: ="Full package + blockers" | F14: ="PASS" | G14: ="40% headroom demanded" | H14: ="FAIL"
B15: 9. Pricing | C15: Spread covers expected loss with margin | D15: Spread / EL ≥ ~3x | E15: ='Falcon Recovery'!C30 | F15: =IF(E15>=3,"PASS","WATCH") | G15: ="Not reached" | H15: ="—"
B16: 10. IC decision | C16: Adversarial review outcome | D16: Conditions recorded; decline database fed | E16: ="APPROVED w/ conditions" | F16: ="PASS" | G16: ="DECLINED + rationale" | H16: ="PASS"
B17: Atlas marketed at 5.0x leverage / 2.0x coverage. Four framework numbers converted it to its true shape — ~7x levered, ~1.0x FCCR, ~88% LTV, negative organic growth. That conversion is the entire craft.
B19: ATLAS MINI-MODEL (HVAC services roll-up — the decline)
B20: Item | C20: Value | E20: Note
B21: Reported LTM EBITDA ($m) | C21: 34
B22: Claimed add-backs ($m) | C22: 21 | E22: $9m pro-forma deals <12m owned, $6m unactioned synergies, $4m annualised price rises, $2m one-offs
B23: Add-backs % of marketed EBITDA | C23: =C22/(C21+C22) | E23: 38% — well past the red-flag line (S&P: add-back size predicts default)
B24: Lender-accepted add-backs ($m) | C24: 5
B25: Lender EBITDA ($m) | C25: =C21+C24
B26: Debt ask ($m) | C26: 275 | E26: =TEXT(C26/C25,"0.00")&"x on lender EBITDA vs 5.0x marketed"
B27: FCCR at close | C27: =(C25-6-3-1)/(C26*(0.0375+0.055)+C26*0.01) | E27: CFADS (lender EBITDA − capex 6 − tax 3 − fee 1) / fixed charges at SOFR+550 + 1% amort
B28: Conservative EV at 8.0x ($m) | C28: =C25*8
B29: LTV | C29: =C26/C28 | E29: Second repayment leg fails outright
B31: IC RECORD (decline database entry):
B32: "Roll-up with negative organic growth; 38% add-back load; FCCR ~1.0x on day one; LTV ~88% on lender EV. Revisit at ≤3.5x lender EBITDA with 12 months of integrated performance."
