Workbook

Sheet README
A1: MAT MONITORING WORKBOOK — HOW TO USE
A4: 1. | B4: Go to the strategy tab (coloured by asset class: blue = Private Credit, green = Real Assets, purple = Priv Mkts & HF).
A5: 2. | B5: Paste the ops team data block into the YELLOW grid (STEP 1 zone). Use Paste Special → Values so formatting is preserved. The rows and columns match the ops submission exactly — no re-keying.
A6: 3. | B6: That's it. The RAG layer, the strategy summary, the Dashboard and the Board Charts all populate instantly.
A8: • | B8: OVERRIDES — a risk manager can type G / AG / A / R directly over any auto-RAG cell (e.g. the 'any single Red asset' rule that a % can't capture). Overrides flow through to everything.
A9: • | B9: THRESHOLDS — the pale-green cells (columns O–Q of the RAG zone) hold the trigger levels. Edit them there; formulas pick them up. Blank = level skipped.
A10: • | B10: 'n/a' in a paste cell = MAT not applicable; RAG stays blank and is excluded from all counts.
A11: • | B11: Date MATs (maturities, exit dates) re-grade automatically as time passes (they compare to TODAY()).
B13: RAG scale: G = nothing triggered | AG = triggered, not material — monitor | A = material, plan on track | R = material, no plan / off track — escalate to CRO.

Sheet Dashboard
A1: HSBC ASSET MANAGEMENT | ALTERNATIVES — MATERIAL ACTION TRIGGERS
A2: Board view — all figures update automatically from strategy tabs
A4: MATs ASSESSED | C4: % GREEN | E4: AMBER (A) | G4: RED (R) | H4: STRATEGIES FLAGGED
A5: =SUM(C10:F22) | C5: =SUM(C10:C22)/MAX(1,SUM(C10:F22)) | E5: =SUM(E10:E22) | G5: =SUM(F10:F22) | H5: =SUMPRODUCT(--((E10:E22+F10:F22)>0))
A9: Asset class | B9: Strategy | C9: G | D9: AG | E9: A | F9: R | G9: Total | H9: Status | I9: Funds flagged (A or R)
A10: Private Credit | B10: Direct Lending — UK & EUR Funds | C10: =SUM('DL'!B32:B34) | D10: =SUM('DL'!C32:C34) | E10: =SUM('DL'!D32:D34) | F10: =SUM('DL'!E32:E34) | G10: =SUM(C10:F10) | H10: =IF(F10>0,"RED — escalate",IF(E10>0,"AMBER — action plan",IF(D10>0,"WATCH","GREEN"))) | I10: =TEXTJOIN(", ",TRUE,IF((('DL'!$D$20:$M$29="R")+('DL'!$D$20:$M$29="A"))>0,'DL'!$D$19:$M$19,""))
A11: Private Credit | B11: Infrastructure Debt | C11: =SUM('InfraDebt'!B32:B34) | D11: =SUM('InfraDebt'!C32:C34) | E11: =SUM('InfraDebt'!D32:D34) | F11: =SUM('InfraDebt'!E32:E34) | G11: =SUM(C11:F11) | H11: =IF(F11>0,"RED — escalate",IF(E11>0,"AMBER — action plan",IF(D11>0,"WATCH","GREEN"))) | I11: =TEXTJOIN(", ",TRUE,IF((('InfraDebt'!$D$20:$M$29="R")+('InfraDebt'!$D$20:$M$29="A"))>0,'InfraDebt'!$D$19:$M$19,""))
A12: Private Credit | B12: Revolving Credit Facilities | C12: =SUM('RCF'!B32:B34) | D12: =SUM('RCF'!C32:C34) | E12: =SUM('RCF'!D32:D34) | F12: =SUM('RCF'!E32:E34) | G12: =SUM(C12:F12) | H12: =IF(F12>0,"RED — escalate",IF(E12>0,"AMBER — action plan",IF(D12>0,"WATCH","GREEN"))) | I12: =TEXTJOIN(", ",TRUE,IF((('RCF'!$D$20:$M$29="R")+('RCF'!$D$20:$M$29="A"))>0,'RCF'!$D$19:$M$19,""))
A13: Private Credit | B13: NAV Lending | C13: =SUM('NAV'!B32:B34) | D13: =SUM('NAV'!C32:C34) | E13: =SUM('NAV'!D32:D34) | F13: =SUM('NAV'!E32:E34) | G13: =SUM(C13:F13) | H13: =IF(F13>0,"RED — escalate",IF(E13>0,"AMBER — action plan",IF(D13>0,"WATCH","GREEN"))) | I13: =TEXTJOIN(", ",TRUE,IF((('NAV'!$D$20:$M$29="R")+('NAV'!$D$20:$M$29="A"))>0,'NAV'!$D$19:$M$19,""))
A14: Private Credit | B14: Trade & Working Capital Solutions | C14: =SUM('TWCS'!B32:B34) | D14: =SUM('TWCS'!C32:C34) | E14: =SUM('TWCS'!D32:D34) | F14: =SUM('TWCS'!E32:E34) | G14: =SUM(C14:F14) | H14: =IF(F14>0,"RED — escalate",IF(E14>0,"AMBER — action plan",IF(D14>0,"WATCH","GREEN"))) | I14: =TEXTJOIN(", ",TRUE,IF((('TWCS'!$D$20:$M$29="R")+('TWCS'!$D$20:$M$29="A"))>0,'TWCS'!$D$19:$M$19,""))
A15: Real Assets | B15: HAIL Direct Real Estate | C15: =SUM('HAIL RE'!B32:B34) | D15: =SUM('HAIL RE'!C32:C34) | E15: =SUM('HAIL RE'!D32:D34) | F15: =SUM('HAIL RE'!E32:E34) | G15: =SUM(C15:F15) | H15: =IF(F15>0,"RED — escalate",IF(E15>0,"AMBER — action plan",IF(D15>0,"WATCH","GREEN"))) | I15: =TEXTJOIN(", ",TRUE,IF((('HAIL RE'!$D$20:$M$29="R")+('HAIL RE'!$D$20:$M$29="A"))>0,'HAIL RE'!$D$19:$M$19,""))
A16: Real Assets | B16: HTRE Real Estate (European Fonds) | C16: =SUM('HTRE RE'!B32:B34) | D16: =SUM('HTRE RE'!C32:C34) | E16: =SUM('HTRE RE'!D32:D34) | F16: =SUM('HTRE RE'!E32:E34) | G16: =SUM(C16:F16) | H16: =IF(F16>0,"RED — escalate",IF(E16>0,"AMBER — action plan",IF(D16>0,"WATCH","GREEN"))) | I16: =TEXTJOIN(", ",TRUE,IF((('HTRE RE'!$D$20:$M$29="R")+('HTRE RE'!$D$20:$M$29="A"))>0,'HTRE RE'!$D$19:$M$19,""))
A17: Real Assets | B17: Real Estate Asia | C17: =SUM('RE Asia'!B32:B34) | D17: =SUM('RE Asia'!C32:C34) | E17: =SUM('RE Asia'!D32:D34) | F17: =SUM('RE Asia'!E32:E34) | G17: =SUM(C17:F17) | H17: =IF(F17>0,"RED — escalate",IF(E17>0,"AMBER — action plan",IF(D17>0,"WATCH","GREEN"))) | I17: =TEXTJOIN(", ",TRUE,IF((('RE Asia'!$D$20:$M$29="R")+('RE Asia'!$D$20:$M$29="A"))>0,'RE Asia'!$D$19:$M$19,""))
A18: Real Assets | B18: REIM (Real Estate Investment Mgmt) | C18: =SUM('REIM'!B32:B34) | D18: =SUM('REIM'!C32:C34) | E18: =SUM('REIM'!D32:D34) | F18: =SUM('REIM'!E32:E34) | G18: =SUM(C18:F18) | H18: =IF(F18>0,"RED — escalate",IF(E18>0,"AMBER — action plan",IF(D18>0,"WATCH","GREEN"))) | I18: =TEXTJOIN(", ",TRUE,IF((('REIM'!$D$20:$M$29="R")+('REIM'!$D$20:$M$29="A"))>0,'REIM'!$D$19:$M$19,""))
A19: Real Assets | B19: Energy Transition Infrastructure | C19: =SUM('ETI'!B32:B34) | D19: =SUM('ETI'!C32:C34) | E19: =SUM('ETI'!D32:D34) | F19: =SUM('ETI'!E32:E34) | G19: =SUM(C19:F19) | H19: =IF(F19>0,"RED — escalate",IF(E19>0,"AMBER — action plan",IF(D19>0,"WATCH","GREEN"))) | I19: =TEXTJOIN(", ",TRUE,IF((('ETI'!$D$20:$M$29="R")+('ETI'!$D$20:$M$29="A"))>0,'ETI'!$D$19:$M$19,""))
A20: Priv Mkts & HF | B20: Hedge Funds | C20: =SUM('HF'!B32:B34) | D20: =SUM('HF'!C32:C34) | E20: =SUM('HF'!D32:D34) | F20: =SUM('HF'!E32:E34) | G20: =SUM(C20:F20) | H20: =IF(F20>0,"RED — escalate",IF(E20>0,"AMBER — action plan",IF(D20>0,"WATCH","GREEN"))) | I20: =TEXTJOIN(", ",TRUE,IF((('HF'!$D$20:$M$29="R")+('HF'!$D$20:$M$29="A"))>0,'HF'!$D$19:$M$19,""))
A21: Priv Mkts & HF | B21: Private Markets (Feeders & Syndicates) | C21: =SUM('PrivMkts'!B32:B34) | D21: =SUM('PrivMkts'!C32:C34) | E21: =SUM('PrivMkts'!D32:D34) | F21: =SUM('PrivMkts'!E32:E34) | G21: =SUM(C21:F21) | H21: =IF(F21>0,"RED — escalate",IF(E21>0,"AMBER — action plan",IF(D21>0,"WATCH","GREEN"))) | I21: =TEXTJOIN(", ",TRUE,IF((('PrivMkts'!$D$20:$M$29="R")+('PrivMkts'!$D$20:$M$29="A"))>0,'PrivMkts'!$D$19:$M$19,""))
A22: Priv Mkts & HF | B22: Venture Capital | C22: =SUM('VC'!B32:B34) | D22: =SUM('VC'!C32:C34) | E22: =SUM('VC'!D32:D34) | F22: =SUM('VC'!E32:E34) | G22: =SUM(C22:F22) | H22: =IF(F22>0,"RED — escalate",IF(E22>0,"AMBER — action plan",IF(D22>0,"WATCH","GREEN"))) | I22: =TEXTJOIN(", ",TRUE,IF((('VC'!$D$20:$M$29="R")+('VC'!$D$20:$M$29="A"))>0,'VC'!$D$19:$M$19,""))
B23: TOTAL | C23: =SUM(C10:C22) | D23: =SUM(D10:D22) | E23: =SUM(E10:E22) | F23: =SUM(F10:F22) | G23: =SUM(G10:G22)
A25: RAG DEFINITIONS
A26: G | B26: No MATs triggered — no action required
A27: AG | B27: MATs triggered but not material — enhanced monitoring
A28: A | B28: Triggered and material — action plan in place and on track
A29: R | B29: Triggered and material — no action plan / not on track: escalate to CRO
A31: Note: 'Funds flagged' lists a fund once per triggered MAT. Overrides typed on strategy tabs flow through automatically.

Sheet Board Charts
A1: BOARD RISK VIEW — ESCALATIONS, TREND, CONCENTRATION
A3: # | B3: Strategy (worst first) | C3: Red | D3: Amber | E3: Watch | N3: AC | O3: Strategy | P3: AG | Q3: A | R3: R | S3: score
A4: 1 | B4: =INDEX($O$4:$O$16,MATCH(LARGE($S$4:$S$16,1),$S$4:$S$16,0)) | C4: =INDEX($R$4:$R$16,MATCH(LARGE($S$4:$S$16,1),$S$4:$S$16,0)) | D4: =INDEX($Q$4:$Q$16,MATCH(LARGE($S$4:$S$16,1),$S$4:$S$16,0)) | E4: =INDEX($P$4:$P$16,MATCH(LARGE($S$4:$S$16,1),$S$4:$S$16,0)) | N4: Private Credit | O4: DL | P4: =SUM('DL'!C32:C34) | Q4: =SUM('DL'!D32:D34) | R4: =SUM('DL'!E32:E34) | S4: =R4*10000+Q4*100+P4+ROW()/100000
A5: 2 | B5: =INDEX($O$4:$O$16,MATCH(LARGE($S$4:$S$16,2),$S$4:$S$16,0)) | C5: =INDEX($R$4:$R$16,MATCH(LARGE($S$4:$S$16,2),$S$4:$S$16,0)) | D5: =INDEX($Q$4:$Q$16,MATCH(LARGE($S$4:$S$16,2),$S$4:$S$16,0)) | E5: =INDEX($P$4:$P$16,MATCH(LARGE($S$4:$S$16,2),$S$4:$S$16,0)) | N5: Private Credit | O5: InfraDebt | P5: =SUM('InfraDebt'!C32:C34) | Q5: =SUM('InfraDebt'!D32:D34) | R5: =SUM('InfraDebt'!E32:E34) | S5: =R5*10000+Q5*100+P5+ROW()/100000
A6: 3 | B6: =INDEX($O$4:$O$16,MATCH(LARGE($S$4:$S$16,3),$S$4:$S$16,0)) | C6: =INDEX($R$4:$R$16,MATCH(LARGE($S$4:$S$16,3),$S$4:$S$16,0)) | D6: =INDEX($Q$4:$Q$16,MATCH(LARGE($S$4:$S$16,3),$S$4:$S$16,0)) | E6: =INDEX($P$4:$P$16,MATCH(LARGE($S$4:$S$16,3),$S$4:$S$16,0)) | N6: Private Credit | O6: RCF | P6: =SUM('RCF'!C32:C34) | Q6: =SUM('RCF'!D32:D34) | R6: =SUM('RCF'!E32:E34) | S6: =R6*10000+Q6*100+P6+ROW()/100000
A7: 4 | B7: =INDEX($O$4:$O$16,MATCH(LARGE($S$4:$S$16,4),$S$4:$S$16,0)) | C7: =INDEX($R$4:$R$16,MATCH(LARGE($S$4:$S$16,4),$S$4:$S$16,0)) | D7: =INDEX($Q$4:$Q$16,MATCH(LARGE($S$4:$S$16,4),$S$4:$S$16,0)) | E7: =INDEX($P$4:$P$16,MATCH(LARGE($S$4:$S$16,4),$S$4:$S$16,0)) | N7: Private Credit | O7: NAV | P7: =SUM('NAV'!C32:C34) | Q7: =SUM('NAV'!D32:D34) | R7: =SUM('NAV'!E32:E34) | S7: =R7*10000+Q7*100+P7+ROW()/100000
A8: 5 | B8: =INDEX($O$4:$O$16,MATCH(LARGE($S$4:$S$16,5),$S$4:$S$16,0)) | C8: =INDEX($R$4:$R$16,MATCH(LARGE($S$4:$S$16,5),$S$4:$S$16,0)) | D8: =INDEX($Q$4:$Q$16,MATCH(LARGE($S$4:$S$16,5),$S$4:$S$16,0)) | E8: =INDEX($P$4:$P$16,MATCH(LARGE($S$4:$S$16,5),$S$4:$S$16,0)) | N8: Private Credit | O8: TWCS | P8: =SUM('TWCS'!C32:C34) | Q8: =SUM('TWCS'!D32:D34) | R8: =SUM('TWCS'!E32:E34) | S8: =R8*10000+Q8*100+P8+ROW()/100000
A9: 6 | B9: =INDEX($O$4:$O$16,MATCH(LARGE($S$4:$S$16,6),$S$4:$S$16,0)) | C9: =INDEX($R$4:$R$16,MATCH(LARGE($S$4:$S$16,6),$S$4:$S$16,0)) | D9: =INDEX($Q$4:$Q$16,MATCH(LARGE($S$4:$S$16,6),$S$4:$S$16,0)) | E9: =INDEX($P$4:$P$16,MATCH(LARGE($S$4:$S$16,6),$S$4:$S$16,0)) | N9: Real Assets | O9: HAIL RE | P9: =SUM('HAIL RE'!C32:C34) | Q9: =SUM('HAIL RE'!D32:D34) | R9: =SUM('HAIL RE'!E32:E34) | S9: =R9*10000+Q9*100+P9+ROW()/100000
A10: 7 | B10: =INDEX($O$4:$O$16,MATCH(LARGE($S$4:$S$16,7),$S$4:$S$16,0)) | C10: =INDEX($R$4:$R$16,MATCH(LARGE($S$4:$S$16,7),$S$4:$S$16,0)) | D10: =INDEX($Q$4:$Q$16,MATCH(LARGE($S$4:$S$16,7),$S$4:$S$16,0)) | E10: =INDEX($P$4:$P$16,MATCH(LARGE($S$4:$S$16,7),$S$4:$S$16,0)) | N10: Real Assets | O10: HTRE RE | P10: =SUM('HTRE RE'!C32:C34) | Q10: =SUM('HTRE RE'!D32:D34) | R10: =SUM('HTRE RE'!E32:E34) | S10: =R10*10000+Q10*100+P10+ROW()/100000
A11: 8 | B11: =INDEX($O$4:$O$16,MATCH(LARGE($S$4:$S$16,8),$S$4:$S$16,0)) | C11: =INDEX($R$4:$R$16,MATCH(LARGE($S$4:$S$16,8),$S$4:$S$16,0)) | D11: =INDEX($Q$4:$Q$16,MATCH(LARGE($S$4:$S$16,8),$S$4:$S$16,0)) | E11: =INDEX($P$4:$P$16,MATCH(LARGE($S$4:$S$16,8),$S$4:$S$16,0)) | N11: Real Assets | O11: RE Asia | P11: =SUM('RE Asia'!C32:C34) | Q11: =SUM('RE Asia'!D32:D34) | R11: =SUM('RE Asia'!E32:E34) | S11: =R11*10000+Q11*100+P11+ROW()/100000
A12: 9 | B12: =INDEX($O$4:$O$16,MATCH(LARGE($S$4:$S$16,9),$S$4:$S$16,0)) | C12: =INDEX($R$4:$R$16,MATCH(LARGE($S$4:$S$16,9),$S$4:$S$16,0)) | D12: =INDEX($Q$4:$Q$16,MATCH(LARGE($S$4:$S$16,9),$S$4:$S$16,0)) | E12: =INDEX($P$4:$P$16,MATCH(LARGE($S$4:$S$16,9),$S$4:$S$16,0)) | N12: Real Assets | O12: REIM | P12: =SUM('REIM'!C32:C34) | Q12: =SUM('REIM'!D32:D34) | R12: =SUM('REIM'!E32:E34) | S12: =R12*10000+Q12*100+P12+ROW()/100000
A13: 10 | B13: =INDEX($O$4:$O$16,MATCH(LARGE($S$4:$S$16,10),$S$4:$S$16,0)) | C13: =INDEX($R$4:$R$16,MATCH(LARGE($S$4:$S$16,10),$S$4:$S$16,0)) | D13: =INDEX($Q$4:$Q$16,MATCH(LARGE($S$4:$S$16,10),$S$4:$S$16,0)) | E13: =INDEX($P$4:$P$16,MATCH(LARGE($S$4:$S$16,10),$S$4:$S$16,0)) | N13: Real Assets | O13: ETI | P13: =SUM('ETI'!C32:C34) | Q13: =SUM('ETI'!D32:D34) | R13: =SUM('ETI'!E32:E34) | S13: =R13*10000+Q13*100+P13+ROW()/100000
A14: 11 | B14: =INDEX($O$4:$O$16,MATCH(LARGE($S$4:$S$16,11),$S$4:$S$16,0)) | C14: =INDEX($R$4:$R$16,MATCH(LARGE($S$4:$S$16,11),$S$4:$S$16,0)) | D14: =INDEX($Q$4:$Q$16,MATCH(LARGE($S$4:$S$16,11),$S$4:$S$16,0)) | E14: =INDEX($P$4:$P$16,MATCH(LARGE($S$4:$S$16,11),$S$4:$S$16,0)) | N14: Priv Mkts & HF | O14: HF | P14: =SUM('HF'!C32:C34) | Q14: =SUM('HF'!D32:D34) | R14: =SUM('HF'!E32:E34) | S14: =R14*10000+Q14*100+P14+ROW()/100000
A15: 12 | B15: =INDEX($O$4:$O$16,MATCH(LARGE($S$4:$S$16,12),$S$4:$S$16,0)) | C15: =INDEX($R$4:$R$16,MATCH(LARGE($S$4:$S$16,12),$S$4:$S$16,0)) | D15: =INDEX($Q$4:$Q$16,MATCH(LARGE($S$4:$S$16,12),$S$4:$S$16,0)) | E15: =INDEX($P$4:$P$16,MATCH(LARGE($S$4:$S$16,12),$S$4:$S$16,0)) | N15: Priv Mkts & HF | O15: PrivMkts | P15: =SUM('PrivMkts'!C32:C34) | Q15: =SUM('PrivMkts'!D32:D34) | R15: =SUM('PrivMkts'!E32:E34) | S15: =R15*10000+Q15*100+P15+ROW()/100000
A16: 13 | B16: =INDEX($O$4:$O$16,MATCH(LARGE($S$4:$S$16,13),$S$4:$S$16,0)) | C16: =INDEX($R$4:$R$16,MATCH(LARGE($S$4:$S$16,13),$S$4:$S$16,0)) | D16: =INDEX($Q$4:$Q$16,MATCH(LARGE($S$4:$S$16,13),$S$4:$S$16,0)) | E16: =INDEX($P$4:$P$16,MATCH(LARGE($S$4:$S$16,13),$S$4:$S$16,0)) | N16: Priv Mkts & HF | O16: VC | P16: =SUM('VC'!C32:C34) | Q16: =SUM('VC'!D32:D34) | R16: =SUM('VC'!E32:E34) | S16: =R16*10000+Q16*100+P16+ROW()/100000
A18: =IF(SUM(C4:C16)=0,"No Red MATs across the platform this period.","Focus: "&B4&" carries "&C4&" of "&SUM(C4:C16)&" Red MATs; "&SUMPRODUCT(--((C4:C16+D4:D16)>0))&" of 13 strategies have open exceptions.")
A20: Everything on this tab is formula-driven — no refresh, no macros.
A21: Non-green MATs by asset class | C21: Watch | D21: Amber | E21: Red
A22: Private Credit | C22: =SUMIF($N$4:$N$16,$A22,$P$4:$P$16) | D22: =SUMIF($N$4:$N$16,$A22,$Q$4:$Q$16) | E22: =SUMIF($N$4:$N$16,$A22,$R$4:$R$16)
A23: Real Assets | C23: =SUMIF($N$4:$N$16,$A23,$P$4:$P$16) | D23: =SUMIF($N$4:$N$16,$A23,$Q$4:$Q$16) | E23: =SUMIF($N$4:$N$16,$A23,$R$4:$R$16)
A24: Priv Mkts & HF | C24: =SUMIF($N$4:$N$16,$A24,$P$4:$P$16) | D24: =SUMIF($N$4:$N$16,$A24,$Q$4:$Q$16) | E24: =SUMIF($N$4:$N$16,$A24,$R$4:$R$16)

Sheet History
A1: QUARTERLY SNAPSHOT HISTORY — FEEDS THE TREND CHART
A2: At quarter end: right-click the 'Current (live)' row number → Insert, then Copy the Current row and Paste-Special→Values into the new row; type the quarter label. The trend chart extends itself.
A4: Quarter | B4: G | C4: AG | D4: A | E4: R | F4: % Green | G4: Notes
A5: Q4 2024 | B5: 180 | C5: 18 | D5: 4 | E5: 6 | F5: =B5/SUM(B5:E5) | G5: example — overwrite with your actual history
A6: Q1 2025 | B6: 175 | C6: 22 | D6: 3 | E6: 9 | F6: =B6/SUM(B6:E6) | G6: example — overwrite with your actual history
A7: Q2 2025 | B7: 178 | C7: 20 | D7: 2 | E7: 12 | F7: =B7/SUM(B7:E7) | G7: example — overwrite with your actual history
A8: Current (live) | B8: =SUM(Dashboard!C10:C22) | C8: =SUM(Dashboard!D10:D22) | D8: =SUM(Dashboard!E10:E22) | E8: =SUM(Dashboard!F10:F22) | F8: =B8/SUM(B8:E8) | G8: auto — do not type here

Sheet DL
A1: HSBC AM ALTERNATIVES | DIRECT LENDING — UK & EUR FUNDS
A2: As at: | B2: Q3 2025 | D2: Asset class: Private Credit
A3: STEP 1 — Paste the ops team block into the YELLOW grid below (Paste Special → Values). Do not edit columns A–C.
A5: MAT / Covenant | B5: Unit | C5: Trigger rule | D5: SDLF I | E5: SDLF II | F5: ESDLF | G5: Anglo | H5: Hollywood | I5: INSP | J5: Orchid
A6: Watchlist (% Amber / any Red) | B6: % | C6: >=20% R | any % AG | 0% G | D6: 0.026 | E6: 0 | F6: 0 | G6: 0 | H6: 0 | I6: 0 | J6: 0
A7: Portfolio leverage at origination | B7: x | C7: >=4.5x R | D7: 3.7 | E7: 3.5 | F7: 3.3 | G7: 3.7 | H7: 3.6 | I7: 3.5 | J7: 4.2
A8: Portfolio leverage over time | B8: x | C8: >=5.0x R | D8: 4 | E8: 3.3 | F8: 3.6 | G8: 5.3 | H8: 3.8 | I8: 2.5 | J8: 3.9
A9: Industry concentration | B9: % | C9: >30% R | D9: 0.203 | E9: 0.119 | F9: 0.096 | G9: 0.123 | H9: 0.087 | I9: 0.096 | J9: 0.182
A10: Breach of liquidity MATs | B10: Y/N | C10: Yes = R | D10: No | E10: No | F10: No | G10: No | H10: No | I10: No | J10: No
A11: Any asset downgraded to Weak | B11: Y/N | C11: Yes = R | D11: No | E11: No | F11: No | G11: No | H11: No | I11: No | J11: No
A12: ESG / sustainability breach | B12: Y/N | C12: Yes = R | D12: No | E12: No | F12: No | G12: No | H12: No | I12: No | J12: No
A17: STEP 2 — Nothing to do. RAG below updates instantly. To override a single cell (e.g. 'any Red asset' rule), type G / AG / A / R over the formula. Thresholds are editable in the green cells (O–Q).
A19: MAT / Covenant | B19: Risk type | C19: Rule | D19: =D5 | E19: =E5 | F19: =F5 | G19: =G5 | H19: =H5 | I19: =I5 | J19: =J5 | O19: Thr AG | P19: Thr A | Q19: Thr R
A20: Watchlist (% Amber / any Red) | B20: Market | C20: >=20% R | any % AG | 0% G | D20: =IF(OR(D6="",D6="n/a",D6="N/A"),"",IF(AND($Q20<>"",D6>=$Q20),"R",IF(AND($P20<>"",D6>=$P20),"A",IF(AND($O20<>"",D6>=$O20),"AG","G")))) | E20: =IF(OR(E6="",E6="n/a",E6="N/A"),"",IF(AND($Q20<>"",E6>=$Q20),"R",IF(AND($P20<>"",E6>=$P20),"A",IF(AND($O20<>"",E6>=$O20),"AG","G")))) | F20: =IF(OR(F6="",F6="n/a",F6="N/A"),"",IF(AND($Q20<>"",F6>=$Q20),"R",IF(AND($P20<>"",F6>=$P20),"A",IF(AND($O20<>"",F6>=$O20),"AG","G")))) | G20: =IF(OR(G6="",G6="n/a",G6="N/A"),"",IF(AND($Q20<>"",G6>=$Q20),"R",IF(AND($P20<>"",G6>=$P20),"A",IF(AND($O20<>"",G6>=$O20),"AG","G")))) | H20: =IF(OR(H6="",H6="n/a",H6="N/A"),"",IF(AND($Q20<>"",H6>=$Q20),"R",IF(AND($P20<>"",H6>=$P20),"A",IF(AND($O20<>"",H6>=$O20),"AG","G")))) | I20: =IF(OR(I6="",I6="n/a",I6="N/A"),"",IF(AND($Q20<>"",I6>=$Q20),"R",IF(AND($P20<>"",I6>=$P20),"A",IF(AND($O20<>"",I6>=$O20),"AG","G")))) | J20: =IF(OR(J6="",J6="n/a",J6="N/A"),"",IF(AND($Q20<>"",J6>=$Q20),"R",IF(AND($P20<>"",J6>=$P20),"A",IF(AND($O20<>"",J6>=$O20),"AG","G")))) | O20: 0.01 | Q20: 0.2
A21: Portfolio leverage at origination | B21: Market | C21: >=4.5x R | D21: =IF(OR(D7="",D7="n/a",D7="N/A"),"",IF(AND($Q21<>"",D7>=$Q21),"R",IF(AND($P21<>"",D7>=$P21),"A",IF(AND($O21<>"",D7>=$O21),"AG","G")))) | E21: =IF(OR(E7="",E7="n/a",E7="N/A"),"",IF(AND($Q21<>"",E7>=$Q21),"R",IF(AND($P21<>"",E7>=$P21),"A",IF(AND($O21<>"",E7>=$O21),"AG","G")))) | F21: =IF(OR(F7="",F7="n/a",F7="N/A"),"",IF(AND($Q21<>"",F7>=$Q21),"R",IF(AND($P21<>"",F7>=$P21),"A",IF(AND($O21<>"",F7>=$O21),"AG","G")))) | G21: =IF(OR(G7="",G7="n/a",G7="N/A"),"",IF(AND($Q21<>"",G7>=$Q21),"R",IF(AND($P21<>"",G7>=$P21),"A",IF(AND($O21<>"",G7>=$O21),"AG","G")))) | H21: =IF(OR(H7="",H7="n/a",H7="N/A"),"",IF(AND($Q21<>"",H7>=$Q21),"R",IF(AND($P21<>"",H7>=$P21),"A",IF(AND($O21<>"",H7>=$O21),"AG","G")))) | I21: =IF(OR(I7="",I7="n/a",I7="N/A"),"",IF(AND($Q21<>"",I7>=$Q21),"R",IF(AND($P21<>"",I7>=$P21),"A",IF(AND($O21<>"",I7>=$O21),"AG","G")))) | J21: =IF(OR(J7="",J7="n/a",J7="N/A"),"",IF(AND($Q21<>"",J7>=$Q21),"R",IF(AND($P21<>"",J7>=$P21),"A",IF(AND($O21<>"",J7>=$O21),"AG","G")))) | O21: 4 | P21: 4.25 | Q21: 4.5
A22: Portfolio leverage over time | B22: Market | C22: >=5.0x R | D22: =IF(OR(D8="",D8="n/a",D8="N/A"),"",IF(AND($Q22<>"",D8>=$Q22),"R",IF(AND($P22<>"",D8>=$P22),"A",IF(AND($O22<>"",D8>=$O22),"AG","G")))) | E22: =IF(OR(E8="",E8="n/a",E8="N/A"),"",IF(AND($Q22<>"",E8>=$Q22),"R",IF(AND($P22<>"",E8>=$P22),"A",IF(AND($O22<>"",E8>=$O22),"AG","G")))) | F22: =IF(OR(F8="",F8="n/a",F8="N/A"),"",IF(AND($Q22<>"",F8>=$Q22),"R",IF(AND($P22<>"",F8>=$P22),"A",IF(AND($O22<>"",F8>=$O22),"AG","G")))) | G22: =IF(OR(G8="",G8="n/a",G8="N/A"),"",IF(AND($Q22<>"",G8>=$Q22),"R",IF(AND($P22<>"",G8>=$P22),"A",IF(AND($O22<>"",G8>=$O22),"AG","G")))) | H22: =IF(OR(H8="",H8="n/a",H8="N/A"),"",IF(AND($Q22<>"",H8>=$Q22),"R",IF(AND($P22<>"",H8>=$P22),"A",IF(AND($O22<>"",H8>=$O22),"AG","G")))) | I22: =IF(OR(I8="",I8="n/a",I8="N/A"),"",IF(AND($Q22<>"",I8>=$Q22),"R",IF(AND($P22<>"",I8>=$P22),"A",IF(AND($O22<>"",I8>=$O22),"AG","G")))) | J22: =IF(OR(J8="",J8="n/a",J8="N/A"),"",IF(AND($Q22<>"",J8>=$Q22),"R",IF(AND($P22<>"",J8>=$P22),"A",IF(AND($O22<>"",J8>=$O22),"AG","G")))) | O22: 4.5 | P22: 4.75 | Q22: 5
A23: Industry concentration | B23: Market | C23: >30% R | D23: =IF(OR(D9="",D9="n/a",D9="N/A"),"",IF(AND($Q23<>"",D9>=$Q23),"R",IF(AND($P23<>"",D9>=$P23),"A",IF(AND($O23<>"",D9>=$O23),"AG","G")))) | E23: =IF(OR(E9="",E9="n/a",E9="N/A"),"",IF(AND($Q23<>"",E9>=$Q23),"R",IF(AND($P23<>"",E9>=$P23),"A",IF(AND($O23<>"",E9>=$O23),"AG","G")))) | F23: =IF(OR(F9="",F9="n/a",F9="N/A"),"",IF(AND($Q23<>"",F9>=$Q23),"R",IF(AND($P23<>"",F9>=$P23),"A",IF(AND($O23<>"",F9>=$O23),"AG","G")))) | G23: =IF(OR(G9="",G9="n/a",G9="N/A"),"",IF(AND($Q23<>"",G9>=$Q23),"R",IF(AND($P23<>"",G9>=$P23),"A",IF(AND($O23<>"",G9>=$O23),"AG","G")))) | H23: =IF(OR(H9="",H9="n/a",H9="N/A"),"",IF(AND($Q23<>"",H9>=$Q23),"R",IF(AND($P23<>"",H9>=$P23),"A",IF(AND($O23<>"",H9>=$O23),"AG","G")))) | I23: =IF(OR(I9="",I9="n/a",I9="N/A"),"",IF(AND($Q23<>"",I9>=$Q23),"R",IF(AND($P23<>"",I9>=$P23),"A",IF(AND($O23<>"",I9>=$O23),"AG","G")))) | J23: =IF(OR(J9="",J9="n/a",J9="N/A"),"",IF(AND($Q23<>"",J9>=$Q23),"R",IF(AND($P23<>"",J9>=$P23),"A",IF(AND($O23<>"",J9>=$O23),"AG","G")))) | O23: 0.2 | P23: 0.25 | Q23: 0.3
A24: Breach of liquidity MATs | B24: Liquidity | C24: Yes = R | D24: =IF(OR(D10="",D10="n/a",D10="N/A"),"",IF(D10=$Q24,"R","G")) | E24: =IF(OR(E10="",E10="n/a",E10="N/A"),"",IF(E10=$Q24,"R","G")) | F24: =IF(OR(F10="",F10="n/a",F10="N/A"),"",IF(F10=$Q24,"R","G")) | G24: =IF(OR(G10="",G10="n/a",G10="N/A"),"",IF(G10=$Q24,"R","G")) | H24: =IF(OR(H10="",H10="n/a",H10="N/A"),"",IF(H10=$Q24,"R","G")) | I24: =IF(OR(I10="",I10="n/a",I10="N/A"),"",IF(I10=$Q24,"R","G")) | J24: =IF(OR(J10="",J10="n/a",J10="N/A"),"",IF(J10=$Q24,"R","G")) | Q24: Yes
A25: Any asset downgraded to Weak | B25: Liquidity | C25: Yes = R | D25: =IF(OR(D11="",D11="n/a",D11="N/A"),"",IF(D11=$Q25,"R","G")) | E25: =IF(OR(E11="",E11="n/a",E11="N/A"),"",IF(E11=$Q25,"R","G")) | F25: =IF(OR(F11="",F11="n/a",F11="N/A"),"",IF(F11=$Q25,"R","G")) | G25: =IF(OR(G11="",G11="n/a",G11="N/A"),"",IF(G11=$Q25,"R","G")) | H25: =IF(OR(H11="",H11="n/a",H11="N/A"),"",IF(H11=$Q25,"R","G")) | I25: =IF(OR(I11="",I11="n/a",I11="N/A"),"",IF(I11=$Q25,"R","G")) | J25: =IF(OR(J11="",J11="n/a",J11="N/A"),"",IF(J11=$Q25,"R","G")) | Q25: Yes
A26: ESG / sustainability breach | B26: Sustainability | C26: Yes = R | D26: =IF(OR(D12="",D12="n/a",D12="N/A"),"",IF(D12=$Q26,"R","G")) | E26: =IF(OR(E12="",E12="n/a",E12="N/A"),"",IF(E12=$Q26,"R","G")) | F26: =IF(OR(F12="",F12="n/a",F12="N/A"),"",IF(F12=$Q26,"R","G")) | G26: =IF(OR(G12="",G12="n/a",G12="N/A"),"",IF(G12=$Q26,"R","G")) | H26: =IF(OR(H12="",H12="n/a",H12="N/A"),"",IF(H12=$Q26,"R","G")) | I26: =IF(OR(I12="",I12="n/a",I12="N/A"),"",IF(I12=$Q26,"R","G")) | J26: =IF(OR(J12="",J12="n/a",J12="N/A"),"",IF(J12=$Q26,"R","G")) | Q26: Yes
A31: RAG SUMMARY (auto — feeds Dashboard) | B31: G | C31: AG | D31: A | E31: R
A32: Market | B32: =SUMPRODUCT(($B$20:$B$29="Market")*($D$20:$M$29="G")) | C32: =SUMPRODUCT(($B$20:$B$29="Market")*($D$20:$M$29="AG")) | D32: =SUMPRODUCT(($B$20:$B$29="Market")*($D$20:$M$29="A")) | E32: =SUMPRODUCT(($B$20:$B$29="Market")*($D$20:$M$29="R"))
A33: Liquidity | B33: =SUMPRODUCT(($B$20:$B$29="Liquidity")*($D$20:$M$29="G")) | C33: =SUMPRODUCT(($B$20:$B$29="Liquidity")*($D$20:$M$29="AG")) | D33: =SUMPRODUCT(($B$20:$B$29="Liquidity")*($D$20:$M$29="A")) | E33: =SUMPRODUCT(($B$20:$B$29="Liquidity")*($D$20:$M$29="R"))
A34: Sustainability | B34: =SUMPRODUCT(($B$20:$B$29="Sustainability")*($D$20:$M$29="G")) | C34: =SUMPRODUCT(($B$20:$B$29="Sustainability")*($D$20:$M$29="AG")) | D34: =SUMPRODUCT(($B$20:$B$29="Sustainability")*($D$20:$M$29="A")) | E34: =SUMPRODUCT(($B$20:$B$29="Sustainability")*($D$20:$M$29="R"))

Sheet InfraDebt
A1: HSBC AM ALTERNATIVES | INFRASTRUCTURE DEBT
A2: As at: | B2: Q3 2025 | D2: Asset class: Private Credit
A3: STEP 1 — Paste the ops team block into the YELLOW grid below (Paste Special → Values). Do not edit columns A–C.
A5: MAT / Covenant | B5: Unit | C5: Trigger rule | D5: SGIDF | E5: GIDF | F5: GTIDF | G5: Red Hex | H5: INHK | I5: HSIC | J5: INSP | K5: AIA
A6: Watchlist (% Amber / any Red) | B6: % | C6: >=20% R | any % AG | D6: 0.17 | E6: 0.19 | F6: 0 | G6: 0.16 | H6: 0.02 | I6: 0.11 | J6: 0.07 | K6: 0.33
A7: Guideline breaches (count) | B7: # | C7: >0 = R | D7: 0 | E7: 0 | F7: 0 | G7: 0 | H7: 0 | I7: 0 | J7: 0 | K7: 0
A8: Credit facility >80% for >2wks | B8: Y/N | C8: Yes = R | D8: No | E8: No | F8: No | G8: No | H8: No | I8: No | J8: No | K8: No
A9: FX hedge outside 98–102% >2 days | B9: Y/N | C9: Yes = R | D9: No | E9: No | F9: No | G9: No | H9: No | I9: No | J9: No | K9: No
A10: Liquidity test triggered | B10: Y/N | C10: Yes = R | D10: No | E10: No | F10: No | G10: No | H10: No | I10: No | J10: No | K10: No
A11: Any asset downgraded to Weak | B11: Y/N | C11: Yes = R | D11: No | E11: No | F11: No | G11: No | H11: No | I11: No | J11: No | K11: No
A17: STEP 2 — Nothing to do. RAG below updates instantly. To override a single cell (e.g. 'any Red asset' rule), type G / AG / A / R over the formula. Thresholds are editable in the green cells (O–Q).
A19: MAT / Covenant | B19: Risk type | C19: Rule | D19: =D5 | E19: =E5 | F19: =F5 | G19: =G5 | H19: =H5 | I19: =I5 | J19: =J5 | K19: =K5 | O19: Thr AG | P19: Thr A | Q19: Thr R
A20: Watchlist (% Amber / any Red) | B20: Market | C20: >=20% R | any % AG | D20: =IF(OR(D6="",D6="n/a",D6="N/A"),"",IF(AND($Q20<>"",D6>=$Q20),"R",IF(AND($P20<>"",D6>=$P20),"A",IF(AND($O20<>"",D6>=$O20),"AG","G")))) | E20: =IF(OR(E6="",E6="n/a",E6="N/A"),"",IF(AND($Q20<>"",E6>=$Q20),"R",IF(AND($P20<>"",E6>=$P20),"A",IF(AND($O20<>"",E6>=$O20),"AG","G")))) | F20: =IF(OR(F6="",F6="n/a",F6="N/A"),"",IF(AND($Q20<>"",F6>=$Q20),"R",IF(AND($P20<>"",F6>=$P20),"A",IF(AND($O20<>"",F6>=$O20),"AG","G")))) | G20: =IF(OR(G6="",G6="n/a",G6="N/A"),"",IF(AND($Q20<>"",G6>=$Q20),"R",IF(AND($P20<>"",G6>=$P20),"A",IF(AND($O20<>"",G6>=$O20),"AG","G")))) | H20: =IF(OR(H6="",H6="n/a",H6="N/A"),"",IF(AND($Q20<>"",H6>=$Q20),"R",IF(AND($P20<>"",H6>=$P20),"A",IF(AND($O20<>"",H6>=$O20),"AG","G")))) | I20: =IF(OR(I6="",I6="n/a",I6="N/A"),"",IF(AND($Q20<>"",I6>=$Q20),"R",IF(AND($P20<>"",I6>=$P20),"A",IF(AND($O20<>"",I6>=$O20),"AG","G")))) | J20: =IF(OR(J6="",J6="n/a",J6="N/A"),"",IF(AND($Q20<>"",J6>=$Q20),"R",IF(AND($P20<>"",J6>=$P20),"A",IF(AND($O20<>"",J6>=$O20),"AG","G")))) | K20: =IF(OR(K6="",K6="n/a",K6="N/A"),"",IF(AND($Q20<>"",K6>=$Q20),"R",IF(AND($P20<>"",K6>=$P20),"A",IF(AND($O20<>"",K6>=$O20),"AG","G")))) | O20: 0.01 | Q20: 0.2
A21: Guideline breaches (count) | B21: Market | C21: >0 = R | D21: =IF(OR(D7="",D7="n/a",D7="N/A"),"",IF(AND($Q21<>"",D7>=$Q21),"R",IF(AND($P21<>"",D7>=$P21),"A",IF(AND($O21<>"",D7>=$O21),"AG","G")))) | E21: =IF(OR(E7="",E7="n/a",E7="N/A"),"",IF(AND($Q21<>"",E7>=$Q21),"R",IF(AND($P21<>"",E7>=$P21),"A",IF(AND($O21<>"",E7>=$O21),"AG","G")))) | F21: =IF(OR(F7="",F7="n/a",F7="N/A"),"",IF(AND($Q21<>"",F7>=$Q21),"R",IF(AND($P21<>"",F7>=$P21),"A",IF(AND($O21<>"",F7>=$O21),"AG","G")))) | G21: =IF(OR(G7="",G7="n/a",G7="N/A"),"",IF(AND($Q21<>"",G7>=$Q21),"R",IF(AND($P21<>"",G7>=$P21),"A",IF(AND($O21<>"",G7>=$O21),"AG","G")))) | H21: =IF(OR(H7="",H7="n/a",H7="N/A"),"",IF(AND($Q21<>"",H7>=$Q21),"R",IF(AND($P21<>"",H7>=$P21),"A",IF(AND($O21<>"",H7>=$O21),"AG","G")))) | I21: =IF(OR(I7="",I7="n/a",I7="N/A"),"",IF(AND($Q21<>"",I7>=$Q21),"R",IF(AND($P21<>"",I7>=$P21),"A",IF(AND($O21<>"",I7>=$O21),"AG","G")))) | J21: =IF(OR(J7="",J7="n/a",J7="N/A"),"",IF(AND($Q21<>"",J7>=$Q21),"R",IF(AND($P21<>"",J7>=$P21),"A",IF(AND($O21<>"",J7>=$O21),"AG","G")))) | K21: =IF(OR(K7="",K7="n/a",K7="N/A"),"",IF(AND($Q21<>"",K7>=$Q21),"R",IF(AND($P21<>"",K7>=$P21),"A",IF(AND($O21<>"",K7>=$O21),"AG","G")))) | Q21: 1
A22: Credit facility >80% for >2wks | B22: Market | C22: Yes = R | D22: =IF(OR(D8="",D8="n/a",D8="N/A"),"",IF(D8=$Q22,"R","G")) | E22: =IF(OR(E8="",E8="n/a",E8="N/A"),"",IF(E8=$Q22,"R","G")) | F22: =IF(OR(F8="",F8="n/a",F8="N/A"),"",IF(F8=$Q22,"R","G")) | G22: =IF(OR(G8="",G8="n/a",G8="N/A"),"",IF(G8=$Q22,"R","G")) | H22: =IF(OR(H8="",H8="n/a",H8="N/A"),"",IF(H8=$Q22,"R","G")) | I22: =IF(OR(I8="",I8="n/a",I8="N/A"),"",IF(I8=$Q22,"R","G")) | J22: =IF(OR(J8="",J8="n/a",J8="N/A"),"",IF(J8=$Q22,"R","G")) | K22: =IF(OR(K8="",K8="n/a",K8="N/A"),"",IF(K8=$Q22,"R","G")) | Q22: Yes
A23: FX hedge outside 98–102% >2 days | B23: Market | C23: Yes = R | D23: =IF(OR(D9="",D9="n/a",D9="N/A"),"",IF(D9=$Q23,"R","G")) | E23: =IF(OR(E9="",E9="n/a",E9="N/A"),"",IF(E9=$Q23,"R","G")) | F23: =IF(OR(F9="",F9="n/a",F9="N/A"),"",IF(F9=$Q23,"R","G")) | G23: =IF(OR(G9="",G9="n/a",G9="N/A"),"",IF(G9=$Q23,"R","G")) | H23: =IF(OR(H9="",H9="n/a",H9="N/A"),"",IF(H9=$Q23,"R","G")) | I23: =IF(OR(I9="",I9="n/a",I9="N/A"),"",IF(I9=$Q23,"R","G")) | J23: =IF(OR(J9="",J9="n/a",J9="N/A"),"",IF(J9=$Q23,"R","G")) | K23: =IF(OR(K9="",K9="n/a",K9="N/A"),"",IF(K9=$Q23,"R","G")) | Q23: Yes
A24: Liquidity test triggered | B24: Liquidity | C24: Yes = R | D24: =IF(OR(D10="",D10="n/a",D10="N/A"),"",IF(D10=$Q24,"R","G")) | E24: =IF(OR(E10="",E10="n/a",E10="N/A"),"",IF(E10=$Q24,"R","G")) | F24: =IF(OR(F10="",F10="n/a",F10="N/A"),"",IF(F10=$Q24,"R","G")) | G24: =IF(OR(G10="",G10="n/a",G10="N/A"),"",IF(G10=$Q24,"R","G")) | H24: =IF(OR(H10="",H10="n/a",H10="N/A"),"",IF(H10=$Q24,"R","G")) | I24: =IF(OR(I10="",I10="n/a",I10="N/A"),"",IF(I10=$Q24,"R","G")) | J24: =IF(OR(J10="",J10="n/a",J10="N/A"),"",IF(J10=$Q24,"R","G")) | K24: =IF(OR(K10="",K10="n/a",K10="N/A"),"",IF(K10=$Q24,"R","G")) | Q24: Yes
A25: Any asset downgraded to Weak | B25: Sustainability | C25: Yes = R | D25: =IF(OR(D11="",D11="n/a",D11="N/A"),"",IF(D11=$Q25,"R","G")) | E25: =IF(OR(E11="",E11="n/a",E11="N/A"),"",IF(E11=$Q25,"R","G")) | F25: =IF(OR(F11="",F11="n/a",F11="N/A"),"",IF(F11=$Q25,"R","G")) | G25: =IF(OR(G11="",G11="n/a",G11="N/A"),"",IF(G11=$Q25,"R","G")) | H25: =IF(OR(H11="",H11="n/a",H11="N/A"),"",IF(H11=$Q25,"R","G")) | I25: =IF(OR(I11="",I11="n/a",I11="N/A"),"",IF(I11=$Q25,"R","G")) | J25: =IF(OR(J11="",J11="n/a",J11="N/A"),"",IF(J11=$Q25,"R","G")) | K25: =IF(OR(K11="",K11="n/a",K11="N/A"),"",IF(K11=$Q25,"R","G")) | Q25: Yes
A31: RAG SUMMARY (auto — feeds Dashboard) | B31: G | C31: AG | D31: A | E31: R
A32: Market | B32: =SUMPRODUCT(($B$20:$B$29="Market")*($D$20:$M$29="G")) | C32: =SUMPRODUCT(($B$20:$B$29="Market")*($D$20:$M$29="AG")) | D32: =SUMPRODUCT(($B$20:$B$29="Market")*($D$20:$M$29="A")) | E32: =SUMPRODUCT(($B$20:$B$29="Market")*($D$20:$M$29="R"))
A33: Liquidity | B33: =SUMPRODUCT(($B$20:$B$29="Liquidity")*($D$20:$M$29="G")) | C33: =SUMPRODUCT(($B$20:$B$29="Liquidity")*($D$20:$M$29="AG")) | D33: =SUMPRODUCT(($B$20:$B$29="Liquidity")*($D$20:$M$29="A")) | E33: =SUMPRODUCT(($B$20:$B$29="Liquidity")*($D$20:$M$29="R"))
A34: Sustainability | B34: =SUMPRODUCT(($B$20:$B$29="Sustainability")*($D$20:$M$29="G")) | C34: =SUMPRODUCT(($B$20:$B$29="Sustainability")*($D$20:$M$29="AG")) | D34: =SUMPRODUCT(($B$20:$B$29="Sustainability")*($D$20:$M$29="A")) | E34: =SUMPRODUCT(($B$20:$B$29="Sustainability")*($D$20:$M$29="R"))

Sheet RCF
A1: HSBC AM ALTERNATIVES | REVOLVING CREDIT FACILITIES
A2: As at: | B2: Q3 2025 | D2: Asset class: Private Credit
A3: STEP 1 — Paste the ops team block into the YELLOW grid below (Paste Special → Values). Do not edit columns A–C.
A5: MAT / Covenant | B5: Unit | C5: Trigger rule | D5: RCF | E5: OMERS
A6: Watchlist (% Amber / any Red) | B6: % | C6: >=20% R | any % AG | D6: 0 | E6: 0
A7: Fund borrowings >50% of lines | B7: Y/N | C7: Yes = R | D7: No | E7: No
A8: RCF drawings +10% in 1 week | B8: Y/N | C8: Yes = R | D8: No | E8: No
A9: RCF drawings +35% in 1 month | B9: Y/N | C9: Yes = R | D9: No | E9: No
A10: SLF outstanding maturity | B10: date | C10: <=6 mths R | D10: 46023 | E10: 46296
A11: Unhedged non-EUR exposure >40% | B11: Y/N | C11: Yes = R | D11: No | E11: No
A12: Any asset downgraded to Weak | B12: Y/N | C12: Yes = R | D12: No | E12: No
A17: STEP 2 — Nothing to do. RAG below updates instantly. To override a single cell (e.g. 'any Red asset' rule), type G / AG / A / R over the formula. Thresholds are editable in the green cells (O–Q).
A19: MAT / Covenant | B19: Risk type | C19: Rule | D19: =D5 | E19: =E5 | O19: Thr AG | P19: Thr A | Q19: Thr R
A20: Watchlist (% Amber / any Red) | B20: Market | C20: >=20% R | any % AG | D20: =IF(OR(D6="",D6="n/a",D6="N/A"),"",IF(AND($Q20<>"",D6>=$Q20),"R",IF(AND($P20<>"",D6>=$P20),"A",IF(AND($O20<>"",D6>=$O20),"AG","G")))) | E20: =IF(OR(E6="",E6="n/a",E6="N/A"),"",IF(AND($Q20<>"",E6>=$Q20),"R",IF(AND($P20<>"",E6>=$P20),"A",IF(AND($O20<>"",E6>=$O20),"AG","G")))) | O20: 0.01 | Q20: 0.2
A21: Fund borrowings >50% of lines | B21: Liquidity | C21: Yes = R | D21: =IF(OR(D7="",D7="n/a",D7="N/A"),"",IF(D7=$Q21,"R","G")) | E21: =IF(OR(E7="",E7="n/a",E7="N/A"),"",IF(E7=$Q21,"R","G")) | Q21: Yes
A22: RCF drawings +10% in 1 week | B22: Liquidity | C22: Yes = R | D22: =IF(OR(D8="",D8="n/a",D8="N/A"),"",IF(D8=$Q22,"R","G")) | E22: =IF(OR(E8="",E8="n/a",E8="N/A"),"",IF(E8=$Q22,"R","G")) | Q22: Yes
A23: RCF drawings +35% in 1 month | B23: Liquidity | C23: Yes = R | D23: =IF(OR(D9="",D9="n/a",D9="N/A"),"",IF(D9=$Q23,"R","G")) | E23: =IF(OR(E9="",E9="n/a",E9="N/A"),"",IF(E9=$Q23,"R","G")) | Q23: Yes
A24: SLF outstanding maturity | B24: Liquidity | C24: <=6 mths R | D24: =IF(OR(D10="",D10="n/a",D10="N/A"),"",IF(D10<=EDATE(TODAY(),$Q24),"R",IF(D10<=EDATE(TODAY(),$P24),"A",IF(D10<=EDATE(TODAY(),$O24),"AG","G")))) | E24: =IF(OR(E10="",E10="n/a",E10="N/A"),"",IF(E10<=EDATE(TODAY(),$Q24),"R",IF(E10<=EDATE(TODAY(),$P24),"A",IF(E10<=EDATE(TODAY(),$O24),"AG","G")))) | O24: 12 | P24: 9 | Q24: 6
A25: Unhedged non-EUR exposure >40% | B25: Market | C25: Yes = R | D25: =IF(OR(D11="",D11="n/a",D11="N/A"),"",IF(D11=$Q25,"R","G")) | E25: =IF(OR(E11="",E11="n/a",E11="N/A"),"",IF(E11=$Q25,"R","G")) | Q25: Yes
A26: Any asset downgraded to Weak | B26: Sustainability | C26: Yes = R | D26: =IF(OR(D12="",D12="n/a",D12="N/A"),"",IF(D12=$Q26,"R","G")) | E26: =IF(OR(E12="",E12="n/a",E12="N/A"),"",IF(E12=$Q26,"R","G")) | Q26: Yes
A31: RAG SUMMARY (auto — feeds Dashboard) | B31: G | C31: AG | D31: A | E31: R
A32: Market | B32: =SUMPRODUCT(($B$20:$B$29="Market")*($D$20:$M$29="G")) | C32: =SUMPRODUCT(($B$20:$B$29="Market")*($D$20:$M$29="AG")) | D32: =SUMPRODUCT(($B$20:$B$29="Market")*($D$20:$M$29="A")) | E32: =SUMPRODUCT(($B$20:$B$29="Market")*($D$20:$M$29="R"))
A33: Liquidity | B33: =SUMPRODUCT(($B$20:$B$29="Liquidity")*($D$20:$M$29="G")) | C33: =SUMPRODUCT(($B$20:$B$29="Liquidity")*($D$20:$M$29="AG")) | D33: =SUMPRODUCT(($B$20:$B$29="Liquidity")*($D$20:$M$29="A")) | E33: =SUMPRODUCT(($B$20:$B$29="Liquidity")*($D$20:$M$29="R"))
A34: Sustainability | B34: =SUMPRODUCT(($B$20:$B$29="Sustainability")*($D$20:$M$29="G")) | C34: =SUMPRODUCT(($B$20:$B$29="Sustainability")*($D$20:$M$29="AG")) | D34: =SUMPRODUCT(($B$20:$B$29="Sustainability")*($D$20:$M$29="A")) | E34: =SUMPRODUCT(($B$20:$B$29="Sustainability")*($D$20:$M$29="R"))

Sheet NAV
A1: HSBC AM ALTERNATIVES | NAV LENDING
A2: As at: | B2: Q4 2025 | D2: Asset class: Private Credit
A3: STEP 1 — Paste the ops team block into the YELLOW grid below (Paste Special → Values). Do not edit columns A–C.
A5: MAT / Covenant | B5: Unit | C5: Trigger rule | D5: NAV Fund | E5: AXA
A6: Watchlist (% Amber / any Red) | B6: % | C6: >=20% R | any % AG | D6: 0 | E6: n/a
A7: SLF outstanding maturity | B7: date | C7: <=12 mths R | D7: 46753 | E7: n/a
A8: Unhedged non-EUR exposure >20% | B8: Y/N | C8: Yes = R | D8: No | E8: n/a
A17: STEP 2 — Nothing to do. RAG below updates instantly. To override a single cell (e.g. 'any Red asset' rule), type G / AG / A / R over the formula. Thresholds are editable in the green cells (O–Q).
A19: MAT / Covenant | B19: Risk type | C19: Rule | D19: =D5 | E19: =E5 | O19: Thr AG | P19: Thr A | Q19: Thr R
A20: Watchlist (% Amber / any Red) | B20: Market | C20: >=20% R | any % AG | D20: =IF(OR(D6="",D6="n/a",D6="N/A"),"",IF(AND($Q20<>"",D6>=$Q20),"R",IF(AND($P20<>"",D6>=$P20),"A",IF(AND($O20<>"",D6>=$O20),"AG","G")))) | E20: =IF(OR(E6="",E6="n/a",E6="N/A"),"",IF(AND($Q20<>"",E6>=$Q20),"R",IF(AND($P20<>"",E6>=$P20),"A",IF(AND($O20<>"",E6>=$O20),"AG","G")))) | O20: 0.01 | Q20: 0.2
A21: SLF outstanding maturity | B21: Market | C21: <=12 mths R | D21: =IF(OR(D7="",D7="n/a",D7="N/A"),"",IF(D7<=EDATE(TODAY(),$Q21),"R",IF(D7<=EDATE(TODAY(),$P21),"A",IF(D7<=EDATE(TODAY(),$O21),"AG","G")))) | E21: =IF(OR(E7="",E7="n/a",E7="N/A"),"",IF(E7<=EDATE(TODAY(),$Q21),"R",IF(E7<=EDATE(TODAY(),$P21),"A",IF(E7<=EDATE(TODAY(),$O21),"AG","G")))) | O21: 18 | P21: 15 | Q21: 12
A22: Unhedged non-EUR exposure >20% | B22: Market | C22: Yes = R | D22: =IF(OR(D8="",D8="n/a",D8="N/A"),"",IF(D8=$Q22,"R","G")) | E22: =IF(OR(E8="",E8="n/a",E8="N/A"),"",IF(E8=$Q22,"R","G")) | Q22: Yes
A31: RAG SUMMARY (auto — feeds Dashboard) | B31: G | C31: AG | D31: A | E31: R
A32: Market | B32: =SUMPRODUCT(($B$20:$B$29="Market")*($D$20:$M$29="G")) | C32: =SUMPRODUCT(($B$20:$B$29="Market")*($D$20:$M$29="AG")) | D32: =SUMPRODUCT(($B$20:$B$29="Market")*($D$20:$M$29="A")) | E32: =SUMPRODUCT(($B$20:$B$29="Market")*($D$20:$M$29="R"))
A33: Liquidity | B33: =SUMPRODUCT(($B$20:$B$29="Liquidity")*($D$20:$M$29="G")) | C33: =SUMPRODUCT(($B$20:$B$29="Liquidity")*($D$20:$M$29="AG")) | D33: =SUMPRODUCT(($B$20:$B$29="Liquidity")*($D$20:$M$29="A")) | E33: =SUMPRODUCT(($B$20:$B$29="Liquidity")*($D$20:$M$29="R"))
A34: Sustainability | B34: =SUMPRODUCT(($B$20:$B$29="Sustainability")*($D$20:$M$29="G")) | C34: =SUMPRODUCT(($B$20:$B$29="Sustainability")*($D$20:$M$29="AG")) | D34: =SUMPRODUCT(($B$20:$B$29="Sustainability")*($D$20:$M$29="A")) | E34: =SUMPRODUCT(($B$20:$B$29="Sustainability")*($D$20:$M$29="R"))

Sheet TWCS
A1: HSBC AM ALTERNATIVES | TRADE & WORKING CAPITAL SOLUTIONS
A2: As at: | B2: Q4 2025 | D2: Asset class: Private Credit
A3: STEP 1 — Paste the ops team block into the YELLOW grid below (Paste Special → Values). Do not edit columns A–C.
A5: MAT / Covenant | B5: Unit | C5: Trigger rule | D5: Note Programme | E5: Feeder Fund
A6: Leverage | B6: x | C6: >5.0x R | D6: 2.5 | E6: n/a
A7: Programme utilisation | B7: % | C7: <50% R | D7: 0.64 | E7: n/a
A8: Late payment rate | B8: % | C8: >2% R | D8: 0 | E8: n/a
A9: Avg invoice maturity +2wks | B9: Y/N | C9: Yes = R | D9: No | E9: n/a
A10: Single-name concentration | B10: £m | C10: >£40m R | D10: 38 | E10: n/a
A17: STEP 2 — Nothing to do. RAG below updates instantly. To override a single cell (e.g. 'any Red asset' rule), type G / AG / A / R over the formula. Thresholds are editable in the green cells (O–Q).
A19: MAT / Covenant | B19: Risk type | C19: Rule | D19: =D5 | E19: =E5 | O19: Thr AG | P19: Thr A | Q19: Thr R
A20: Leverage | B20: Market | C20: >5.0x R | D20: =IF(OR(D6="",D6="n/a",D6="N/A"),"",IF(AND($Q20<>"",D6>=$Q20),"R",IF(AND($P20<>"",D6>=$P20),"A",IF(AND($O20<>"",D6>=$O20),"AG","G")))) | E20: =IF(OR(E6="",E6="n/a",E6="N/A"),"",IF(AND($Q20<>"",E6>=$Q20),"R",IF(AND($P20<>"",E6>=$P20),"A",IF(AND($O20<>"",E6>=$O20),"AG","G")))) | O20: 4 | P20: 4.5 | Q20: 5
A21: Programme utilisation | B21: Market | C21: <50% R | D21: =IF(OR(D7="",D7="n/a",D7="N/A"),"",IF(AND($Q21<>"",D7<=$Q21),"R",IF(AND($P21<>"",D7<=$P21),"A",IF(AND($O21<>"",D7<=$O21),"AG","G")))) | E21: =IF(OR(E7="",E7="n/a",E7="N/A"),"",IF(AND($Q21<>"",E7<=$Q21),"R",IF(AND($P21<>"",E7<=$P21),"A",IF(AND($O21<>"",E7<=$O21),"AG","G")))) | Q21: 0.5
A22: Late payment rate | B22: Market | C22: >2% R | D22: =IF(OR(D8="",D8="n/a",D8="N/A"),"",IF(AND($Q22<>"",D8>=$Q22),"R",IF(AND($P22<>"",D8>=$P22),"A",IF(AND($O22<>"",D8>=$O22),"AG","G")))) | E22: =IF(OR(E8="",E8="n/a",E8="N/A"),"",IF(AND($Q22<>"",E8>=$Q22),"R",IF(AND($P22<>"",E8>=$P22),"A",IF(AND($O22<>"",E8>=$O22),"AG","G")))) | O22: 0.01 | P22: 0.015 | Q22: 0.02
A23: Avg invoice maturity +2wks | B23: Market | C23: Yes = R | D23: =IF(OR(D9="",D9="n/a",D9="N/A"),"",IF(D9=$Q23,"R","G")) | E23: =IF(OR(E9="",E9="n/a",E9="N/A"),"",IF(E9=$Q23,"R","G")) | Q23: Yes
A24: Single-name concentration | B24: Market | C24: >£40m R | D24: =IF(OR(D10="",D10="n/a",D10="N/A"),"",IF(AND($Q24<>"",D10>=$Q24),"R",IF(AND($P24<>"",D10>=$P24),"A",IF(AND($O24<>"",D10>=$O24),"AG","G")))) | E24: =IF(OR(E10="",E10="n/a",E10="N/A"),"",IF(AND($Q24<>"",E10>=$Q24),"R",IF(AND($P24<>"",E10>=$P24),"A",IF(AND($O24<>"",E10>=$O24),"AG","G")))) | Q24: 40
A31: RAG SUMMARY (auto — feeds Dashboard) | B31: G | C31: AG | D31: A | E31: R
A32: Market | B32: =SUMPRODUCT(($B$20:$B$29="Market")*($D$20:$M$29="G")) | C32: =SUMPRODUCT(($B$20:$B$29="Market")*($D$20:$M$29="AG")) | D32: =SUMPRODUCT(($B$20:$B$29="Market")*($D$20:$M$29="A")) | E32: =SUMPRODUCT(($B$20:$B$29="Market")*($D$20:$M$29="R"))
A33: Liquidity | B33: =SUMPRODUCT(($B$20:$B$29="Liquidity")*($D$20:$M$29="G")) | C33: =SUMPRODUCT(($B$20:$B$29="Liquidity")*($D$20:$M$29="AG")) | D33: =SUMPRODUCT(($B$20:$B$29="Liquidity")*($D$20:$M$29="A")) | E33: =SUMPRODUCT(($B$20:$B$29="Liquidity")*($D$20:$M$29="R"))
A34: Sustainability | B34: =SUMPRODUCT(($B$20:$B$29="Sustainability")*($D$20:$M$29="G")) | C34: =SUMPRODUCT(($B$20:$B$29="Sustainability")*($D$20:$M$29="AG")) | D34: =SUMPRODUCT(($B$20:$B$29="Sustainability")*($D$20:$M$29="A")) | E34: =SUMPRODUCT(($B$20:$B$29="Sustainability")*($D$20:$M$29="R"))

Sheet HAIL RE
A1: HSBC AM ALTERNATIVES | HAIL DIRECT REAL ESTATE
A2: As at: | B2: Q4 2025 | D2: Asset class: Real Assets
A3: STEP 1 — Paste the ops team block into the YELLOW grid below (Paste Special → Values). Do not edit columns A–C.
A5: MAT / Covenant | B5: Unit | C5: Trigger rule | D5: Downing | E5: Port H | F5: Stand LH | G5: Exch Pl | H5: Geneva | I5: Vienna | J5: Brussels
A6: Target exit date | B6: date | C6: <1 yr R | D6: 45931 | E6: 45627 | F6: 45992 | G6: 45992 | H6: n/a | I6: n/a | J6: n/a
A7: Debt maturity | B7: date | C7: <1 yr R | D7: 46569 | E7: n/a | F7: n/a | G7: 46539 | H7: 46753 | I7: 46388 | J7: n/a
A8: Occupancy | B8: % | C8: <=85% R | D8: 0.975 | E8: 0 | F8: 1 | G8: 0.54 | H8: 1 | I8: 1 | J8: 0.67
A9: LTV headroom vs covenant | B9: % | C9: <10% R | D9: 0.4 | E9: n/a | F9: 0.65 | G9: 0.53 | H9: 0.63 | I9: n/a | J9: n/a
A10: ICR headroom vs covenant | B10: % | C10: <25% R | D10: 2.02 | E10: n/a | F10: 2.27 | G10: 1.57 | H10: n/a | I10: n/a | J10: n/a
A11: Equity multiple | B11: x | C11: <=0.6x R | <=1.0x AG | D11: 1.33 | E11: 0.88 | F11: 0.35 | G11: 0.45 | H11: n/a | I11: n/a | J11: n/a
A12: Total multiple | B12: x | C12: <=0.6x R | <=1.0x AG | D12: 1.63 | E12: 1.39 | F12: 0.97 | G12: 0.78 | H12: n/a | I12: n/a | J12: n/a
A17: STEP 2 — Nothing to do. RAG below updates instantly. To override a single cell (e.g. 'any Red asset' rule), type G / AG / A / R over the formula. Thresholds are editable in the green cells (O–Q).
A19: MAT / Covenant | B19: Risk type | C19: Rule | D19: =D5 | E19: =E5 | F19: =F5 | G19: =G5 | H19: =H5 | I19: =I5 | J19: =J5 | O19: Thr AG | P19: Thr A | Q19: Thr R
A20: Target exit date | B20: Market | C20: <1 yr R | D20: =IF(OR(D6="",D6="n/a",D6="N/A"),"",IF(D6<=EDATE(TODAY(),$Q20),"R",IF(D6<=EDATE(TODAY(),$P20),"A",IF(D6<=EDATE(TODAY(),$O20),"AG","G")))) | E20: =IF(OR(E6="",E6="n/a",E6="N/A"),"",IF(E6<=EDATE(TODAY(),$Q20),"R",IF(E6<=EDATE(TODAY(),$P20),"A",IF(E6<=EDATE(TODAY(),$O20),"AG","G")))) | F20: =IF(OR(F6="",F6="n/a",F6="N/A"),"",IF(F6<=EDATE(TODAY(),$Q20),"R",IF(F6<=EDATE(TODAY(),$P20),"A",IF(F6<=EDATE(TODAY(),$O20),"AG","G")))) | G20: =IF(OR(G6="",G6="n/a",G6="N/A"),"",IF(G6<=EDATE(TODAY(),$Q20),"R",IF(G6<=EDATE(TODAY(),$P20),"A",IF(G6<=EDATE(TODAY(),$O20),"AG","G")))) | H20: =IF(OR(H6="",H6="n/a",H6="N/A"),"",IF(H6<=EDATE(TODAY(),$Q20),"R",IF(H6<=EDATE(TODAY(),$P20),"A",IF(H6<=EDATE(TODAY(),$O20),"AG","G")))) | I20: =IF(OR(I6="",I6="n/a",I6="N/A"),"",IF(I6<=EDATE(TODAY(),$Q20),"R",IF(I6<=EDATE(TODAY(),$P20),"A",IF(I6<=EDATE(TODAY(),$O20),"AG","G")))) | J20: =IF(OR(J6="",J6="n/a",J6="N/A"),"",IF(J6<=EDATE(TODAY(),$Q20),"R",IF(J6<=EDATE(TODAY(),$P20),"A",IF(J6<=EDATE(TODAY(),$O20),"AG","G")))) | O20: 12 | P20: 9 | Q20: 6
A21: Debt maturity | B21: Market | C21: <1 yr R | D21: =IF(OR(D7="",D7="n/a",D7="N/A"),"",IF(D7<=EDATE(TODAY(),$Q21),"R",IF(D7<=EDATE(TODAY(),$P21),"A",IF(D7<=EDATE(TODAY(),$O21),"AG","G")))) | E21: =IF(OR(E7="",E7="n/a",E7="N/A"),"",IF(E7<=EDATE(TODAY(),$Q21),"R",IF(E7<=EDATE(TODAY(),$P21),"A",IF(E7<=EDATE(TODAY(),$O21),"AG","G")))) | F21: =IF(OR(F7="",F7="n/a",F7="N/A"),"",IF(F7<=EDATE(TODAY(),$Q21),"R",IF(F7<=EDATE(TODAY(),$P21),"A",IF(F7<=EDATE(TODAY(),$O21),"AG","G")))) | G21: =IF(OR(G7="",G7="n/a",G7="N/A"),"",IF(G7<=EDATE(TODAY(),$Q21),"R",IF(G7<=EDATE(TODAY(),$P21),"A",IF(G7<=EDATE(TODAY(),$O21),"AG","G")))) | H21: =IF(OR(H7="",H7="n/a",H7="N/A"),"",IF(H7<=EDATE(TODAY(),$Q21),"R",IF(H7<=EDATE(TODAY(),$P21),"A",IF(H7<=EDATE(TODAY(),$O21),"AG","G")))) | I21: =IF(OR(I7="",I7="n/a",I7="N/A"),"",IF(I7<=EDATE(TODAY(),$Q21),"R",IF(I7<=EDATE(TODAY(),$P21),"A",IF(I7<=EDATE(TODAY(),$O21),"AG","G")))) | J21: =IF(OR(J7="",J7="n/a",J7="N/A"),"",IF(J7<=EDATE(TODAY(),$Q21),"R",IF(J7<=EDATE(TODAY(),$P21),"A",IF(J7<=EDATE(TODAY(),$O21),"AG","G")))) | O21: 12 | P21: 9 | Q21: 6
A22: Occupancy | B22: Market | C22: <=85% R | D22: =IF(OR(D8="",D8="n/a",D8="N/A"),"",IF(AND($Q22<>"",D8<=$Q22),"R",IF(AND($P22<>"",D8<=$P22),"A",IF(AND($O22<>"",D8<=$O22),"AG","G")))) | E22: =IF(OR(E8="",E8="n/a",E8="N/A"),"",IF(AND($Q22<>"",E8<=$Q22),"R",IF(AND($P22<>"",E8<=$P22),"A",IF(AND($O22<>"",E8<=$O22),"AG","G")))) | F22: =IF(OR(F8="",F8="n/a",F8="N/A"),"",IF(AND($Q22<>"",F8<=$Q22),"R",IF(AND($P22<>"",F8<=$P22),"A",IF(AND($O22<>"",F8<=$O22),"AG","G")))) | G22: =IF(OR(G8="",G8="n/a",G8="N/A"),"",IF(AND($Q22<>"",G8<=$Q22),"R",IF(AND($P22<>"",G8<=$P22),"A",IF(AND($O22<>"",G8<=$O22),"AG","G")))) | H22: =IF(OR(H8="",H8="n/a",H8="N/A"),"",IF(AND($Q22<>"",H8<=$Q22),"R",IF(AND($P22<>"",H8<=$P22),"A",IF(AND($O22<>"",H8<=$O22),"AG","G")))) | I22: =IF(OR(I8="",I8="n/a",I8="N/A"),"",IF(AND($Q22<>"",I8<=$Q22),"R",IF(AND($P22<>"",I8<=$P22),"A",IF(AND($O22<>"",I8<=$O22),"AG","G")))) | J22: =IF(OR(J8="",J8="n/a",J8="N/A"),"",IF(AND($Q22<>"",J8<=$Q22),"R",IF(AND($P22<>"",J8<=$P22),"A",IF(AND($O22<>"",J8<=$O22),"AG","G")))) | O22: 0.95 | P22: 0.9 | Q22: 0.85
A23: LTV headroom vs covenant | B23: Market | C23: <10% R | D23: =IF(OR(D9="",D9="n/a",D9="N/A"),"",IF(AND($Q23<>"",D9<=$Q23),"R",IF(AND($P23<>"",D9<=$P23),"A",IF(AND($O23<>"",D9<=$O23),"AG","G")))) | E23: =IF(OR(E9="",E9="n/a",E9="N/A"),"",IF(AND($Q23<>"",E9<=$Q23),"R",IF(AND($P23<>"",E9<=$P23),"A",IF(AND($O23<>"",E9<=$O23),"AG","G")))) | F23: =IF(OR(F9="",F9="n/a",F9="N/A"),"",IF(AND($Q23<>"",F9<=$Q23),"R",IF(AND($P23<>"",F9<=$P23),"A",IF(AND($O23<>"",F9<=$O23),"AG","G")))) | G23: =IF(OR(G9="",G9="n/a",G9="N/A"),"",IF(AND($Q23<>"",G9<=$Q23),"R",IF(AND($P23<>"",G9<=$P23),"A",IF(AND($O23<>"",G9<=$O23),"AG","G")))) | H23: =IF(OR(H9="",H9="n/a",H9="N/A"),"",IF(AND($Q23<>"",H9<=$Q23),"R",IF(AND($P23<>"",H9<=$P23),"A",IF(AND($O23<>"",H9<=$O23),"AG","G")))) | I23: =IF(OR(I9="",I9="n/a",I9="N/A"),"",IF(AND($Q23<>"",I9<=$Q23),"R",IF(AND($P23<>"",I9<=$P23),"A",IF(AND($O23<>"",I9<=$O23),"AG","G")))) | J23: =IF(OR(J9="",J9="n/a",J9="N/A"),"",IF(AND($Q23<>"",J9<=$Q23),"R",IF(AND($P23<>"",J9<=$P23),"A",IF(AND($O23<>"",J9<=$O23),"AG","G")))) | O23: 0.2 | Q23: 0.1
A24: ICR headroom vs covenant | B24: Market | C24: <25% R | D24: =IF(OR(D10="",D10="n/a",D10="N/A"),"",IF(AND($Q24<>"",D10<=$Q24),"R",IF(AND($P24<>"",D10<=$P24),"A",IF(AND($O24<>"",D10<=$O24),"AG","G")))) | E24: =IF(OR(E10="",E10="n/a",E10="N/A"),"",IF(AND($Q24<>"",E10<=$Q24),"R",IF(AND($P24<>"",E10<=$P24),"A",IF(AND($O24<>"",E10<=$O24),"AG","G")))) | F24: =IF(OR(F10="",F10="n/a",F10="N/A"),"",IF(AND($Q24<>"",F10<=$Q24),"R",IF(AND($P24<>"",F10<=$P24),"A",IF(AND($O24<>"",F10<=$O24),"AG","G")))) | G24: =IF(OR(G10="",G10="n/a",G10="N/A"),"",IF(AND($Q24<>"",G10<=$Q24),"R",IF(AND($P24<>"",G10<=$P24),"A",IF(AND($O24<>"",G10<=$O24),"AG","G")))) | H24: =IF(OR(H10="",H10="n/a",H10="N/A"),"",IF(AND($Q24<>"",H10<=$Q24),"R",IF(AND($P24<>"",H10<=$P24),"A",IF(AND($O24<>"",H10<=$O24),"AG","G")))) | I24: =IF(OR(I10="",I10="n/a",I10="N/A"),"",IF(AND($Q24<>"",I10<=$Q24),"R",IF(AND($P24<>"",I10<=$P24),"A",IF(AND($O24<>"",I10<=$O24),"AG","G")))) | J24: =IF(OR(J10="",J10="n/a",J10="N/A"),"",IF(AND($Q24<>"",J10<=$Q24),"R",IF(AND($P24<>"",J10<=$P24),"A",IF(AND($O24<>"",J10<=$O24),"AG","G")))) | O24: 0.35 | Q24: 0.25
A25: Equity multiple | B25: Market | C25: <=0.6x R | <=1.0x AG | D25: =IF(OR(D11="",D11="n/a",D11="N/A"),"",IF(AND($Q25<>"",D11<=$Q25),"R",IF(AND($P25<>"",D11<=$P25),"A",IF(AND($O25<>"",D11<=$O25),"AG","G")))) | E25: =IF(OR(E11="",E11="n/a",E11="N/A"),"",IF(AND($Q25<>"",E11<=$Q25),"R",IF(AND($P25<>"",E11<=$P25),"A",IF(AND($O25<>"",E11<=$O25),"AG","G")))) | F25: =IF(OR(F11="",F11="n/a",F11="N/A"),"",IF(AND($Q25<>"",F11<=$Q25),"R",IF(AND($P25<>"",F11<=$P25),"A",IF(AND($O25<>"",F11<=$O25),"AG","G")))) | G25: =IF(OR(G11="",G11="n/a",G11="N/A"),"",IF(AND($Q25<>"",G11<=$Q25),"R",IF(AND($P25<>"",G11<=$P25),"A",IF(AND($O25<>"",G11<=$O25),"AG","G")))) | H25: =IF(OR(H11="",H11="n/a",H11="N/A"),"",IF(AND($Q25<>"",H11<=$Q25),"R",IF(AND($P25<>"",H11<=$P25),"A",IF(AND($O25<>"",H11<=$O25),"AG","G")))) | I25: =IF(OR(I11="",I11="n/a",I11="N/A"),"",IF(AND($Q25<>"",I11<=$Q25),"R",IF(AND($P25<>"",I11<=$P25),"A",IF(AND($O25<>"",I11<=$O25),"AG","G")))) | J25: =IF(OR(J11="",J11="n/a",J11="N/A"),"",IF(AND($Q25<>"",J11<=$Q25),"R",IF(AND($P25<>"",J11<=$P25),"A",IF(AND($O25<>"",J11<=$O25),"AG","G")))) | O25: 1 | Q25: 0.6
A26: Total multiple | B26: Market | C26: <=0.6x R | <=1.0x AG | D26: =IF(OR(D12="",D12="n/a",D12="N/A"),"",IF(AND($Q26<>"",D12<=$Q26),"R",IF(AND($P26<>"",D12<=$P26),"A",IF(AND($O26<>"",D12<=$O26),"AG","G")))) | E26: =IF(OR(E12="",E12="n/a",E12="N/A"),"",IF(AND($Q26<>"",E12<=$Q26),"R",IF(AND($P26<>"",E12<=$P26),"A",IF(AND($O26<>"",E12<=$O26),"AG","G")))) | F26: =IF(OR(F12="",F12="n/a",F12="N/A"),"",IF(AND($Q26<>"",F12<=$Q26),"R",IF(AND($P26<>"",F12<=$P26),"A",IF(AND($O26<>"",F12<=$O26),"AG","G")))) | G26: =IF(OR(G12="",G12="n/a",G12="N/A"),"",IF(AND($Q26<>"",G12<=$Q26),"R",IF(AND($P26<>"",G12<=$P26),"A",IF(AND($O26<>"",G12<=$O26),"AG","G")))) | H26: =IF(OR(H12="",H12="n/a",H12="N/A"),"",IF(AND($Q26<>"",H12<=$Q26),"R",IF(AND($P26<>"",H12<=$P26),"A",IF(AND($O26<>"",H12<=$O26),"AG","G")))) | I26: =IF(OR(I12="",I12="n/a",I12="N/A"),"",IF(AND($Q26<>"",I12<=$Q26),"R",IF(AND($P26<>"",I12<=$P26),"A",IF(AND($O26<>"",I12<=$O26),"AG","G")))) | J26: =IF(OR(J12="",J12="n/a",J12="N/A"),"",IF(AND($Q26<>"",J12<=$Q26),"R",IF(AND($P26<>"",J12<=$P26),"A",IF(AND($O26<>"",J12<=$O26),"AG","G")))) | O26: 1 | Q26: 0.6
A31: RAG SUMMARY (auto — feeds Dashboard) | B31: G | C31: AG | D31: A | E31: R
A32: Market | B32: =SUMPRODUCT(($B$20:$B$29="Market")*($D$20:$M$29="G")) | C32: =SUMPRODUCT(($B$20:$B$29="Market")*($D$20:$M$29="AG")) | D32: =SUMPRODUCT(($B$20:$B$29="Market")*($D$20:$M$29="A")) | E32: =SUMPRODUCT(($B$20:$B$29="Market")*($D$20:$M$29="R"))
A33: Liquidity | B33: =SUMPRODUCT(($B$20:$B$29="Liquidity")*($D$20:$M$29="G")) | C33: =SUMPRODUCT(($B$20:$B$29="Liquidity")*($D$20:$M$29="AG")) | D33: =SUMPRODUCT(($B$20:$B$29="Liquidity")*($D$20:$M$29="A")) | E33: =SUMPRODUCT(($B$20:$B$29="Liquidity")*($D$20:$M$29="R"))
A34: Sustainability | B34: =SUMPRODUCT(($B$20:$B$29="Sustainability")*($D$20:$M$29="G")) | C34: =SUMPRODUCT(($B$20:$B$29="Sustainability")*($D$20:$M$29="AG")) | D34: =SUMPRODUCT(($B$20:$B$29="Sustainability")*($D$20:$M$29="A")) | E34: =SUMPRODUCT(($B$20:$B$29="Sustainability")*($D$20:$M$29="R"))

Sheet HTRE RE
A1: HSBC AM ALTERNATIVES | HTRE REAL ESTATE (EUROPEAN FONDS)
A2: As at: | B2: Q3 2025 | D2: Asset class: Real Assets
A3: STEP 1 — Paste the ops team block into the YELLOW grid below (Paste Special → Values). Do not edit columns A–C.
A5: MAT / Covenant | B5: Unit | C5: Trigger rule | D5: Fonds 3 | E5: Fonds 6 | F5: Fonds 7 | G5: Fonds 8 | H5: Fonds 11 | I5: Fonds 12
A6: Occupancy | B6: % | C6: <90% R | D6: 1 | E6: 0.99 | F6: 0.99 | G6: 0.98 | H6: 1 | I6: 1
A7: Distribution yield | B7: % | C7: <2.9% R | D7: 0.042 | E7: 0.047 | F7: 0.014 | G7: 0.054 | H7: 0.058 | I7: 0.044
A8: LTV | B8: % | C8: >=50% AG | >=75% R | D8: 0.04 | E8: 0.4 | F8: 0.72 | G8: 0.5 | H8: 0.49 | I8: 0.37
A9: Selling option available | B9: Y/N | C9: No = R | D9: Yes | E9: Yes | F9: Yes | G9: Yes | H9: Yes | I9: Yes
A10: Audit clean (no reservation) | B10: Y/N | C10: No = R | D10: Yes | E10: Yes | F10: Yes | G10: Yes | H10: Yes | I10: Yes
A17: STEP 2 — Nothing to do. RAG below updates instantly. To override a single cell (e.g. 'any Red asset' rule), type G / AG / A / R over the formula. Thresholds are editable in the green cells (O–Q).
A19: MAT / Covenant | B19: Risk type | C19: Rule | D19: =D5 | E19: =E5 | F19: =F5 | G19: =G5 | H19: =H5 | I19: =I5 | O19: Thr AG | P19: Thr A | Q19: Thr R
A20: Occupancy | B20: Market | C20: <90% R | D20: =IF(OR(D6="",D6="n/a",D6="N/A"),"",IF(AND($Q20<>"",D6<=$Q20),"R",IF(AND($P20<>"",D6<=$P20),"A",IF(AND($O20<>"",D6<=$O20),"AG","G")))) | E20: =IF(OR(E6="",E6="n/a",E6="N/A"),"",IF(AND($Q20<>"",E6<=$Q20),"R",IF(AND($P20<>"",E6<=$P20),"A",IF(AND($O20<>"",E6<=$O20),"AG","G")))) | F20: =IF(OR(F6="",F6="n/a",F6="N/A"),"",IF(AND($Q20<>"",F6<=$Q20),"R",IF(AND($P20<>"",F6<=$P20),"A",IF(AND($O20<>"",F6<=$O20),"AG","G")))) | G20: =IF(OR(G6="",G6="n/a",G6="N/A"),"",IF(AND($Q20<>"",G6<=$Q20),"R",IF(AND($P20<>"",G6<=$P20),"A",IF(AND($O20<>"",G6<=$O20),"AG","G")))) | H20: =IF(OR(H6="",H6="n/a",H6="N/A"),"",IF(AND($Q20<>"",H6<=$Q20),"R",IF(AND($P20<>"",H6<=$P20),"A",IF(AND($O20<>"",H6<=$O20),"AG","G")))) | I20: =IF(OR(I6="",I6="n/a",I6="N/A"),"",IF(AND($Q20<>"",I6<=$Q20),"R",IF(AND($P20<>"",I6<=$P20),"A",IF(AND($O20<>"",I6<=$O20),"AG","G")))) | O20: 0.96 | P20: 0.93 | Q20: 0.9
A21: Distribution yield | B21: Market | C21: <2.9% R | D21: =IF(OR(D7="",D7="n/a",D7="N/A"),"",IF(AND($Q21<>"",D7<=$Q21),"R",IF(AND($P21<>"",D7<=$P21),"A",IF(AND($O21<>"",D7<=$O21),"AG","G")))) | E21: =IF(OR(E7="",E7="n/a",E7="N/A"),"",IF(AND($Q21<>"",E7<=$Q21),"R",IF(AND($P21<>"",E7<=$P21),"A",IF(AND($O21<>"",E7<=$O21),"AG","G")))) | F21: =IF(OR(F7="",F7="n/a",F7="N/A"),"",IF(AND($Q21<>"",F7<=$Q21),"R",IF(AND($P21<>"",F7<=$P21),"A",IF(AND($O21<>"",F7<=$O21),"AG","G")))) | G21: =IF(OR(G7="",G7="n/a",G7="N/A"),"",IF(AND($Q21<>"",G7<=$Q21),"R",IF(AND($P21<>"",G7<=$P21),"A",IF(AND($O21<>"",G7<=$O21),"AG","G")))) | H21: =IF(OR(H7="",H7="n/a",H7="N/A"),"",IF(AND($Q21<>"",H7<=$Q21),"R",IF(AND($P21<>"",H7<=$P21),"A",IF(AND($O21<>"",H7<=$O21),"AG","G")))) | I21: =IF(OR(I7="",I7="n/a",I7="N/A"),"",IF(AND($Q21<>"",I7<=$Q21),"R",IF(AND($P21<>"",I7<=$P21),"A",IF(AND($O21<>"",I7<=$O21),"AG","G")))) | O21: 0.04 | P21: 0.035 | Q21: 0.029
A22: LTV | B22: Market | C22: >=50% AG | >=75% R | D22: =IF(OR(D8="",D8="n/a",D8="N/A"),"",IF(AND($Q22<>"",D8>=$Q22),"R",IF(AND($P22<>"",D8>=$P22),"A",IF(AND($O22<>"",D8>=$O22),"AG","G")))) | E22: =IF(OR(E8="",E8="n/a",E8="N/A"),"",IF(AND($Q22<>"",E8>=$Q22),"R",IF(AND($P22<>"",E8>=$P22),"A",IF(AND($O22<>"",E8>=$O22),"AG","G")))) | F22: =IF(OR(F8="",F8="n/a",F8="N/A"),"",IF(AND($Q22<>"",F8>=$Q22),"R",IF(AND($P22<>"",F8>=$P22),"A",IF(AND($O22<>"",F8>=$O22),"AG","G")))) | G22: =IF(OR(G8="",G8="n/a",G8="N/A"),"",IF(AND($Q22<>"",G8>=$Q22),"R",IF(AND($P22<>"",G8>=$P22),"A",IF(AND($O22<>"",G8>=$O22),"AG","G")))) | H22: =IF(OR(H8="",H8="n/a",H8="N/A"),"",IF(AND($Q22<>"",H8>=$Q22),"R",IF(AND($P22<>"",H8>=$P22),"A",IF(AND($O22<>"",H8>=$O22),"AG","G")))) | I22: =IF(OR(I8="",I8="n/a",I8="N/A"),"",IF(AND($Q22<>"",I8>=$Q22),"R",IF(AND($P22<>"",I8>=$P22),"A",IF(AND($O22<>"",I8>=$O22),"AG","G")))) | O22: 0.5 | Q22: 0.75
A23: Selling option available | B23: Market | C23: No = R | D23: =IF(OR(D9="",D9="n/a",D9="N/A"),"",IF(D9=$Q23,"R","G")) | E23: =IF(OR(E9="",E9="n/a",E9="N/A"),"",IF(E9=$Q23,"R","G")) | F23: =IF(OR(F9="",F9="n/a",F9="N/A"),"",IF(F9=$Q23,"R","G")) | G23: =IF(OR(G9="",G9="n/a",G9="N/A"),"",IF(G9=$Q23,"R","G")) | H23: =IF(OR(H9="",H9="n/a",H9="N/A"),"",IF(H9=$Q23,"R","G")) | I23: =IF(OR(I9="",I9="n/a",I9="N/A"),"",IF(I9=$Q23,"R","G")) | Q23: No
A24: Audit clean (no reservation) | B24: Market | C24: No = R | D24: =IF(OR(D10="",D10="n/a",D10="N/A"),"",IF(D10=$Q24,"R","G")) | E24: =IF(OR(E10="",E10="n/a",E10="N/A"),"",IF(E10=$Q24,"R","G")) | F24: =IF(OR(F10="",F10="n/a",F10="N/A"),"",IF(F10=$Q24,"R","G")) | G24: =IF(OR(G10="",G10="n/a",G10="N/A"),"",IF(G10=$Q24,"R","G")) | H24: =IF(OR(H10="",H10="n/a",H10="N/A"),"",IF(H10=$Q24,"R","G")) | I24: =IF(OR(I10="",I10="n/a",I10="N/A"),"",IF(I10=$Q24,"R","G")) | Q24: No
A31: RAG SUMMARY (auto — feeds Dashboard) | B31: G | C31: AG | D31: A | E31: R
A32: Market | B32: =SUMPRODUCT(($B$20:$B$29="Market")*($D$20:$M$29="G")) | C32: =SUMPRODUCT(($B$20:$B$29="Market")*($D$20:$M$29="AG")) | D32: =SUMPRODUCT(($B$20:$B$29="Market")*($D$20:$M$29="A")) | E32: =SUMPRODUCT(($B$20:$B$29="Market")*($D$20:$M$29="R"))
A33: Liquidity | B33: =SUMPRODUCT(($B$20:$B$29="Liquidity")*($D$20:$M$29="G")) | C33: =SUMPRODUCT(($B$20:$B$29="Liquidity")*($D$20:$M$29="AG")) | D33: =SUMPRODUCT(($B$20:$B$29="Liquidity")*($D$20:$M$29="A")) | E33: =SUMPRODUCT(($B$20:$B$29="Liquidity")*($D$20:$M$29="R"))
A34: Sustainability | B34: =SUMPRODUCT(($B$20:$B$29="Sustainability")*($D$20:$M$29="G")) | C34: =SUMPRODUCT(($B$20:$B$29="Sustainability")*($D$20:$M$29="AG")) | D34: =SUMPRODUCT(($B$20:$B$29="Sustainability")*($D$20:$M$29="A")) | E34: =SUMPRODUCT(($B$20:$B$29="Sustainability")*($D$20:$M$29="R"))

Sheet RE Asia
A1: HSBC AM ALTERNATIVES | REAL ESTATE ASIA
A2: As at: | B2: Q3 2025 | D2: Asset class: Real Assets
A3: STEP 1 — Paste the ops team block into the YELLOW grid below (Paste Special → Values). Do not edit columns A–C.
A5: MAT / Covenant | B5: Unit | C5: Trigger rule | D5: Asia Portfolio
A6: Occupancy | B6: % | C6: <=85% R | D6: 0.92
A7: LTV | B7: % | C7: >=50% R | D7: 0.45
A8: Counterparty breach | B8: Y/N | C8: Yes = R | D8: No
A9: Sustainability breach | B9: Y/N | C9: Yes = R | D9: No
A17: STEP 2 — Nothing to do. RAG below updates instantly. To override a single cell (e.g. 'any Red asset' rule), type G / AG / A / R over the formula. Thresholds are editable in the green cells (O–Q).
A19: MAT / Covenant | B19: Risk type | C19: Rule | D19: =D5 | O19: Thr AG | P19: Thr A | Q19: Thr R
A20: Occupancy | B20: Market | C20: <=85% R | D20: =IF(OR(D6="",D6="n/a",D6="N/A"),"",IF(AND($Q20<>"",D6<=$Q20),"R",IF(AND($P20<>"",D6<=$P20),"A",IF(AND($O20<>"",D6<=$O20),"AG","G")))) | O20: 0.95 | P20: 0.9 | Q20: 0.85
A21: LTV | B21: Market | C21: >=50% R | D21: =IF(OR(D7="",D7="n/a",D7="N/A"),"",IF(AND($Q21<>"",D7>=$Q21),"R",IF(AND($P21<>"",D7>=$P21),"A",IF(AND($O21<>"",D7>=$O21),"AG","G")))) | O21: 0.4 | P21: 0.45 | Q21: 0.5
A22: Counterparty breach | B22: Market | C22: Yes = R | D22: =IF(OR(D8="",D8="n/a",D8="N/A"),"",IF(D8=$Q22,"R","G")) | Q22: Yes
A23: Sustainability breach | B23: Sustainability | C23: Yes = R | D23: =IF(OR(D9="",D9="n/a",D9="N/A"),"",IF(D9=$Q23,"R","G")) | Q23: Yes
A31: RAG SUMMARY (auto — feeds Dashboard) | B31: G | C31: AG | D31: A | E31: R
A32: Market | B32: =SUMPRODUCT(($B$20:$B$29="Market")*($D$20:$M$29="G")) | C32: =SUMPRODUCT(($B$20:$B$29="Market")*($D$20:$M$29="AG")) | D32: =SUMPRODUCT(($B$20:$B$29="Market")*($D$20:$M$29="A")) | E32: =SUMPRODUCT(($B$20:$B$29="Market")*($D$20:$M$29="R"))
A33: Liquidity | B33: =SUMPRODUCT(($B$20:$B$29="Liquidity")*($D$20:$M$29="G")) | C33: =SUMPRODUCT(($B$20:$B$29="Liquidity")*($D$20:$M$29="AG")) | D33: =SUMPRODUCT(($B$20:$B$29="Liquidity")*($D$20:$M$29="A")) | E33: =SUMPRODUCT(($B$20:$B$29="Liquidity")*($D$20:$M$29="R"))
A34: Sustainability | B34: =SUMPRODUCT(($B$20:$B$29="Sustainability")*($D$20:$M$29="G")) | C34: =SUMPRODUCT(($B$20:$B$29="Sustainability")*($D$20:$M$29="AG")) | D34: =SUMPRODUCT(($B$20:$B$29="Sustainability")*($D$20:$M$29="A")) | E34: =SUMPRODUCT(($B$20:$B$29="Sustainability")*($D$20:$M$29="R"))

Sheet REIM
A1: HSBC AM ALTERNATIVES | REIM (REAL ESTATE INVESTMENT MGMT)
A2: As at: | B2: Q3 2025 | D2: Asset class: Real Assets
A3: STEP 1 — Paste the ops team block into the YELLOW grid below (Paste Special → Values). Do not edit columns A–C.
A5: MAT / Covenant | B5: Unit | C5: Trigger rule | D5: Open End | E5: Closed End
A6: Market risk MAT triggered | B6: Y/N | C6: Yes = R | D6: No | E6: No
A7: Liquidity MAT triggered (open end) | B7: Y/N | C7: Yes = R | D7: No | E7: No
A8: Sustainability breach | B8: Y/N | C8: Yes = R | D8: No | E8: No
