Workbook
Name Spot0: Inputs!$B$5
Name RateUSD: Inputs!$B$6
Name RateEUR: Inputs!$B$7
Name VolFX: Inputs!$B$8
Name Notional: Inputs!$B$11
Name Spread: Inputs!$B$12
Name PerYear: Inputs!$B$13
Name TauStep: Inputs!$B$16
Name AccrRate: Inputs!$B$17
Name MuDrift: Inputs!$B$18
Name FwdFactor: Inputs!$B$19

Sheet Inputs
A1: HRR Deferred Balance — Monte Carlo
A2: One parameterised case per run. Edit the shaded cells, press F9 to resample, then log the result on the Results sheet.
A4: MARKET — edit these
A5: EURUSD spot today | B5: 1.1 | D5: Quoted as USD per EUR. The hedge sells USD forward and buys EUR.
A6: USD interest rate | B6: 0.045 | D6: Used for the forward via covered interest parity.
A7: EUR interest rate | B7: 0.025 | D7: The base currency of the fund.
A8: EURUSD volatility (annualised) | B8: 0.08 | D8: THE VARIABLE TO SWEEP. Long-run realised EURUSD is roughly 8%.
A10: TRADE — edit these
A11: Hedged notional (USD) | B11: 100000000 | D11: Face amount of the foreign-currency asset being hedged.
A12: Dealer spread over EUR | B12: 0.0075 | D12: What the dealer charges on the deferred balance.
A13: Rolls per year | B13: 4 | D13: 4 = quarterly. Changes the step size, not the horizon.
A15: DERIVED — do not edit
A16: Step length tau | B16: =1/PerYear | D16: Years per roll period.
A17: Accrual rate c | B17: =RateEUR+Spread | D17: Rate at which the deferred balance compounds.
A18: Risk-neutral drift mu | B18: =RateUSD-RateEUR | D18: EURUSD drifts at the rate differential under the pricing measure.
A19: Forward factor per step | B19: =(1+RateUSD*TauStep)/(1+RateEUR*TauStep) | D19: F = S x this. Covered interest parity.
A21: SIMULATION SIZE — fixed by the sheet layout
A22: Trials | B22: 2000 | D22: Rows on the Simulation sheet. Sampling error at p99 is material — see Reference.
A23: Steps | B23: 28 | D23: 28 steps at 4 per year = 7 years. Year-ends are read off at steps 4, 8, 12, 16, 20, 24, 28.
A26: HOW TO USE
A27: 1. Set the volatility (and anything else) in the shaded cells above.
A28: 2. Press F9. The workbook is on MANUAL calculation on purpose — 168,000 volatile formulas would otherwise recalculate on every keystroke.
A29: 3. Read the percentiles on the Results sheet.
A30: 4. Copy the Results block and Paste Special → Values into the log on that sheet, then change the volatility and repeat.
A31: 5. Compare against the Reference sheet, which holds the same statistics computed independently in Python at 120,000 paths.
A33: Every number in the simulation is a live Excel formula. Nothing is hard-coded, so the whole chain can be audited cell by cell.

Sheet Method
A1: What the simulation computes
A3: 1 · The spot path | B3: Geometric Brownian motion under the risk-neutral measure: S(t) = S(t-1) x EXP( (mu - 0.5*vol^2)*tau + vol*SQRT(tau)*Z ), Z ~ N(0,1) In Excel: =S_prev * EXP((MuDrift-0.5*VolFX^2)*TauStep + VolFX*SQRT(TauStep)*NORMSINV(RAND())) The drift is the interest rate differential, which is what makes the forward an unbiased predictor of spot.
A4: 2 · The market forward | B4: F(t-1) = S(t-1) x (1 + rUSD*tau) / (1 + rEUR*tau). Computed inline as S_prev*FwdFactor.
A5: 3 · The period loss | B5: The hedge sells USD Notional forward at F(t-1) and settles at S(t): loss = Notional/S(t) - Notional/F(t-1) (positive = the fund owes) A falling EURUSD — a strengthening dollar — produces a loss on the hedge.
A6: 4 · The deferred balance | B6: D(t) = D(t-1) x (1 + c*tau) + period loss. The prior balance accrues at the dealer's rate, and this period's move is added to it. This single line is the entire technique.
A7: 5 · The peak | B7: M(t) = MAX( M(t-1), D(t) ). The running maximum is the size of unsecured credit line the strategy actually needs, which is a larger and more relevant number than the balance at any one date.
A8: 6 · The statistics | B8: PERCENTILE() across the 2,000 trials at each year-end column, expressed as a percentage of hedged notional.
A9: Why percent of notional | B9: It makes the answer portable. Multiply by (hedged notional / NAV) to get the percent-of-NAV figure the fund-level limit is written in — see the manual, section 21, Table 19.
A10: Sampling error | B10: At 2,000 trials only ~20 observations sit above p99, so that column moves visibly between F9 presses. p50 and p95 are stable to a few tenths of a point. The Reference sheet gives 120,000-path values to check against.
A11: Legacy function names | B11: NORMSINV and PERCENTILE are used rather than NORM.S.INV and PERCENTILE.INC. They are identical in behaviour and, being pre-2007 functions, they need no _xlfn. prefix — so the file opens correctly in every version of Excel.

Sheet Simulation
A1: Live simulation — 2,000 trials x 28 quarterly steps. Every cell is a formula. Press F9 to resample.
A2: Three stacked blocks: the spot path, the deferred balance built from it, and the running peak of that balance.
A3: BLOCK A — EURUSD SPOT PATH
A4: S(t) = S(t-1) * EXP((MuDrift - 0.5*VolFX^2)*TauStep + VolFX*SQRT(TauStep)*NORMSINV(RAND()))
A5: Trial | B5: t1 | C5: t2 | D5: t3 | E5: t4 | F5: t5 | G5: t6 | H5: t7 | I5: t8 | J5: t9 | K5: t10 | L5: t11 | M5: t12 | N5: t13 | O5: t14 | P5: t15 | Q5: t16 | R5: t17 | S5: t18 | T5: t19 | U5: t20 | V5: t21 | W5: t22 | X5: t23 | Y5: t24 | Z5: t25 | AA5: t26 | AB5: t27 | AC5: t28
A6: 1 | B6: =Spot0*EXP((MuDrift-0.5*VolFX^2)*TauStep+VolFX*SQRT(TauStep)*NORMSINV(RAND())) | C6: =B6*EXP((MuDrift-0.5*VolFX^2)*TauStep+VolFX*SQRT(TauStep)*NORMSINV(RAND())) | D6: =C6*EXP((MuDrift-0.5*VolFX^2)*TauStep+VolFX*SQRT(TauStep)*NORMSINV(RAND())) | E6: =D6*EXP((MuDrift-0.5*VolFX^2)*TauStep+VolFX*SQRT(TauStep)*NORMSINV(RAND())) | F6: =E6*EXP((MuDrift-0.5*VolFX^2)*TauStep+VolFX*SQRT(TauStep)*NORMSINV(RAND())) | G6: =F6*EXP((MuDrift-0.5*VolFX^2)*TauStep+VolFX*SQRT(TauStep)*NORMSINV(RAND())) | H6: =G6*EXP((MuDrift-0.5*VolFX^2)*TauStep+VolFX*SQRT(TauStep)*NORMSINV(RAND())) | I6: =H6*EXP((MuDrift-0.5*VolFX^2)*TauStep+VolFX*SQRT(TauStep)*NORMSINV(RAND())) | J6: =I6*EXP((MuDrift-0.5*VolFX^2)*TauStep+VolFX*SQRT(TauStep)*NORMSINV(RAND())) | ... AC6: =AB6*EXP((MuDrift-0.5*VolFX^2)*TauStep+VolFX*SQRT(TauStep)*NORMSINV(RAND()))
A7: 2 | B7: =Spot0*EXP((MuDrift-0.5*VolFX^2)*TauStep+VolFX*SQRT(TauStep)*NORMSINV(RAND())) | C7: =B7*EXP((MuDrift-0.5*VolFX^2)*TauStep+VolFX*SQRT(TauStep)*NORMSINV(RAND())) | D7: =C7*EXP((MuDrift-0.5*VolFX^2)*TauStep+VolFX*SQRT(TauStep)*NORMSINV(RAND())) | E7: =D7*EXP((MuDrift-0.5*VolFX^2)*TauStep+VolFX*SQRT(TauStep)*NORMSINV(RAND())) | F7: =E7*EXP((MuDrift-0.5*VolFX^2)*TauStep+VolFX*SQRT(TauStep)*NORMSINV(RAND())) | G7: =F7*EXP((MuDrift-0.5*VolFX^2)*TauStep+VolFX*SQRT(TauStep)*NORMSINV(RAND())) | H7: =G7*EXP((MuDrift-0.5*VolFX^2)*TauStep+VolFX*SQRT(TauStep)*NORMSINV(RAND())) | I7: =H7*EXP((MuDrift-0.5*VolFX^2)*TauStep+VolFX*SQRT(TauStep)*NORMSINV(RAND())) | J7: =I7*EXP((MuDrift-0.5*VolFX^2)*TauStep+VolFX*SQRT(TauStep)*NORMSINV(RAND())) | ... AC7: =AB7*EXP((MuDrift-0.5*VolFX^2)*TauStep+VolFX*SQRT(TauStep)*NORMSINV(RAND()))
A8: 3 | B8: =Spot0*EXP((MuDrift-0.5*VolFX^2)*TauStep+VolFX*SQRT(TauStep)*NORMSINV(RAND())) | C8: =B8*EXP((MuDrift-0.5*VolFX^2)*TauStep+VolFX*SQRT(TauStep)*NORMSINV(RAND())) | D8: =C8*EXP((MuDrift-0.5*VolFX^2)*TauStep+VolFX*SQRT(TauStep)*NORMSINV(RAND())) | E8: =D8*EXP((MuDrift-0.5*VolFX^2)*TauStep+VolFX*SQRT(TauStep)*NORMSINV(RAND())) | F8: =E8*EXP((MuDrift-0.5*VolFX^2)*TauStep+VolFX*SQRT(TauStep)*NORMSINV(RAND())) | G8: =F8*EXP((MuDrift-0.5*VolFX^2)*TauStep+VolFX*SQRT(TauStep)*NORMSINV(RAND())) | H8: =G8*EXP((MuDrift-0.5*VolFX^2)*TauStep+VolFX*SQRT(TauStep)*NORMSINV(RAND())) | I8: =H8*EXP((MuDrift-0.5*VolFX^2)*TauStep+VolFX*SQRT(TauStep)*NORMSINV(RAND())) | J8: =I8*EXP((MuDrift-0.5*VolFX^2)*TauStep+VolFX*SQRT(TauStep)*NORMSINV(RAND())) | ... AC8: =AB8*EXP((MuDrift-0.5*VolFX^2)*TauStep+VolFX*SQRT(TauStep)*NORMSINV(RAND()))
A9: 4 | B9: =Spot0*EXP((MuDrift-0.5*VolFX^2)*TauStep+VolFX*SQRT(TauStep)*NORMSINV(RAND())) | C9: =B9*EXP((MuDrift-0.5*VolFX^2)*TauStep+VolFX*SQRT(TauStep)*NORMSINV(RAND())) | D9: =C9*EXP((MuDrift-0.5*VolFX^2)*TauStep+VolFX*SQRT(TauStep)*NORMSINV(RAND())) | E9: =D9*EXP((MuDrift-0.5*VolFX^2)*TauStep+VolFX*SQRT(TauStep)*NORMSINV(RAND())) | F9: =E9*EXP((MuDrift-0.5*VolFX^2)*TauStep+VolFX*SQRT(TauStep)*NORMSINV(RAND())) | G9: =F9*EXP((MuDrift-0.5*VolFX^2)*TauStep+VolFX*SQRT(TauStep)*NORMSINV(RAND())) | H9: =G9*EXP((MuDrift-0.5*VolFX^2)*TauStep+VolFX*SQRT(TauStep)*NORMSINV(RAND())) | I9: =H9*EXP((MuDrift-0.5*VolFX^2)*TauStep+VolFX*SQRT(TauStep)*NORMSINV(RAND())) | J9: =I9*EXP((MuDrift-0.5*VolFX^2)*TauStep+VolFX*SQRT(TauStep)*NORMSINV(RAND())) | ... AC9: =AB9*EXP((MuDrift-0.5*VolFX^2)*TauStep+VolFX*SQRT(TauStep)*NORMSINV(RAND()))
A10: 5 | B10: =Spot0*EXP((MuDrift-0.5*VolFX^2)*TauStep+VolFX*SQRT(TauStep)*NORMSINV(RAND())) | C10: =B10*EXP((MuDrift-0.5*VolFX^2)*TauStep+VolFX*SQRT(TauStep)*NORMSINV(RAND())) | D10: =C10*EXP((MuDrift-0.5*VolFX^2)*TauStep+VolFX*SQRT(TauStep)*NORMSINV(RAND())) | E10: =D10*EXP((MuDrift-0.5*VolFX^2)*TauStep+VolFX*SQRT(TauStep)*NORMSINV(RAND())) | F10: =E10*EXP((MuDrift-0.5*VolFX^2)*TauStep+VolFX*SQRT(TauStep)*NORMSINV(RAND())) | G10: =F10*EXP((MuDrift-0.5*VolFX^2)*TauStep+VolFX*SQRT(TauStep)*NORMSINV(RAND())) | H10: =G10*EXP((MuDrift-0.5*VolFX^2)*TauStep+VolFX*SQRT(TauStep)*NORMSINV(RAND())) | I10: =H10*EXP((MuDrift-0.5*VolFX^2)*TauStep+VolFX*SQRT(TauStep)*NORMSINV(RAND())) | J10: =I10*EXP((MuDrift-0.5*VolFX^2)*TauStep+VolFX*SQRT(TauStep)*NORMSINV(RAND())) | ... AC10: =AB10*EXP((MuDrift-0.5*VolFX^2)*TauStep+VolFX*SQRT(TauStep)*NORMSINV(RAND()))
A11: 6 | B11: =Spot0*EXP((MuDrift-0.5*VolFX^2)*TauStep+VolFX*SQRT(TauStep)*NORMSINV(RAND())) | C11: =B11*EXP((MuDrift-0.5*VolFX^2)*TauStep+VolFX*SQRT(TauStep)*NORMSINV(RAND())) | D11: =C11*EXP((MuDrift-0.5*VolFX^2)*TauStep+VolFX*SQRT(TauStep)*NORMSINV(RAND())) | E11: =D11*EXP((MuDrift-0.5*VolFX^2)*TauStep+VolFX*SQRT(TauStep)*NORMSINV(RAND())) | F11: =E11*EXP((MuDrift-0.5*VolFX^2)*TauStep+VolFX*SQRT(TauStep)*NORMSINV(RAND())) | G11: =F11*EXP((MuDrift-0.5*VolFX^2)*TauStep+VolFX*SQRT(TauStep)*NORMSINV(RAND())) | H11: =G11*EXP((MuDrift-0.5*VolFX^2)*TauStep+VolFX*SQRT(TauStep)*NORMSINV(RAND())) | I11: =H11*EXP((MuDrift-0.5*VolFX^2)*TauStep+VolFX*SQRT(TauStep)*NORMSINV(RAND())) | J11: =I11*EXP((MuDrift-0.5*VolFX^2)*TauStep+VolFX*SQRT(TauStep)*NORMSINV(RAND())) | ... AC11: =AB11*EXP((MuDrift-0.5*VolFX^2)*TauStep+VolFX*SQRT(TauStep)*NORMSINV(RAND()))
A12: 7 | B12: =Spot0*EXP((MuDrift-0.5*VolFX^2)*TauStep+VolFX*SQRT(TauStep)*NORMSINV(RAND())) | C12: =B12*EXP((MuDrift-0.5*VolFX^2)*TauStep+VolFX*SQRT(TauStep)*NORMSINV(RAND())) | D12: =C12*EXP((MuDrift-0.5*VolFX^2)*TauStep+VolFX*SQRT(TauStep)*NORMSINV(RAND())) | E12: =D12*EXP((MuDrift-0.5*VolFX^2)*TauStep+VolFX*SQRT(TauStep)*NORMSINV(RAND())) | F12: =E12*EXP((MuDrift-0.5*VolFX^2)*TauStep+VolFX*SQRT(TauStep)*NORMSINV(RAND())) | G12: =F12*EXP((MuDrift-0.5*VolFX^2)*TauStep+VolFX*SQRT(TauStep)*NORMSINV(RAND())) | H12: =G12*EXP((MuDrift-0.5*VolFX^2)*TauStep+VolFX*SQRT(TauStep)*NORMSINV(RAND())) | I12: =H12*EXP((MuDrift-0.5*VolFX^2)*TauStep+VolFX*SQRT(TauStep)*NORMSINV(RAND())) | J12: =I12*EXP((MuDrift-0.5*VolFX^2)*TauStep+VolFX*SQRT(TauStep)*NORMSINV(RAND())) | ... AC12: =AB12*EXP((MuDrift-0.5*VolFX^2)*TauStep+VolFX*SQRT(TauStep)*NORMSINV(RAND()))
A13: 8 | B13: =Spot0*EXP((MuDrift-0.5*VolFX^2)*TauStep+VolFX*SQRT(TauStep)*NORMSINV(RAND())) | C13: =B13*EXP((MuDrift-0.5*VolFX^2)*TauStep+VolFX*SQRT(TauStep)*NORMSINV(RAND())) | D13: =C13*EXP((MuDrift-0.5*VolFX^2)*TauStep+VolFX*SQRT(TauStep)*NORMSINV(RAND())) | E13: =D13*EXP((MuDrift-0.5*VolFX^2)*TauStep+VolFX*SQRT(TauStep)*NORMSINV(RAND())) | F13: =E13*EXP((MuDrift-0.5*VolFX^2)*TauStep+VolFX*SQRT(TauStep)*NORMSINV(RAND())) | G13: =F13*EXP((MuDrift-0.5*VolFX^2)*TauStep+VolFX*SQRT(TauStep)*NORMSINV(RAND())) | H13: =G13*EXP((MuDrift-0.5*VolFX^2)*TauStep+VolFX*SQRT(TauStep)*NORMSINV(RAND())) | I13: =H13*EXP((MuDrift-0.5*VolFX^2)*TauStep+VolFX*SQRT(TauStep)*NORMSINV(RAND())) | J13: =I13*EXP((MuDrift-0.5*VolFX^2)*TauStep+VolFX*SQRT(TauStep)*NORMSINV(RAND())) | ... AC13: =AB13*EXP((MuDrift-0.5*VolFX^2)*TauStep+VolFX*SQRT(TauStep)*NORMSINV(RAND()))
A14: 9 | B14: =Spot0*EXP((MuDrift-0.5*VolFX^2)*TauStep+VolFX*SQRT(TauStep)*NORMSINV(RAND())) | C14: =B14*EXP((MuDrift-0.5*VolFX^2)*TauStep+VolFX*SQRT(TauStep)*NORMSINV(RAND())) | D14: =C14*EXP((MuDrift-0.5*VolFX^2)*TauStep+VolFX*SQRT(TauStep)*NORMSINV(RAND())) | E14: =D14*EXP((MuDrift-0.5*VolFX^2)*TauStep+VolFX*SQRT(TauStep)*NORMSINV(RAND())) | F14: =E14*EXP((MuDrift-0.5*VolFX^2)*TauStep+VolFX*SQRT(TauStep)*NORMSINV(RAND())) | G14: =F14*EXP((MuDrift-0.5*VolFX^2)*TauStep+VolFX*SQRT(TauStep)*NORMSINV(RAND())) | H14: =G14*EXP((MuDrift-0.5*VolFX^2)*TauStep+VolFX*SQRT(TauStep)*NORMSINV(RAND())) | I14: =H14*EXP((MuDrift-0.5*VolFX^2)*TauStep+VolFX*SQRT(TauStep)*NORMSINV(RAND())) | J14: =I14*EXP((MuDrift-0.5*VolFX^2)*TauStep+VolFX*SQRT(TauStep)*NORMSINV(RAND())) | ... AC14: =AB14*EXP((MuDrift-0.5*VolFX^2)*TauStep+VolFX*SQRT(TauStep)*NORMSINV(RAND()))
A15: 10 | B15: =Spot0*EXP((MuDrift-0.5*VolFX^2)*TauStep+VolFX*SQRT(TauStep)*NORMSINV(RAND())) | C15: =B15*EXP((MuDrift-0.5*VolFX^2)*TauStep+VolFX*SQRT(TauStep)*NORMSINV(RAND())) | D15: =C15*EXP((MuDrift-0.5*VolFX^2)*TauStep+VolFX*SQRT(TauStep)*NORMSINV(RAND())) | E15: =D15*EXP((MuDrift-0.5*VolFX^2)*TauStep+VolFX*SQRT(TauStep)*NORMSINV(RAND())) | F15: =E15*EXP((MuDrift-0.5*VolFX^2)*TauStep+VolFX*SQRT(TauStep)*NORMSINV(RAND())) | G15: =F15*EXP((MuDrift-0.5*VolFX^2)*TauStep+VolFX*SQRT(TauStep)*NORMSINV(RAND())) | H15: =G15*EXP((MuDrift-0.5*VolFX^2)*TauStep+VolFX*SQRT(TauStep)*NORMSINV(RAND())) | I15: =H15*EXP((MuDrift-0.5*VolFX^2)*TauStep+VolFX*SQRT(TauStep)*NORMSINV(RAND())) | J15: =I15*EXP((MuDrift-0.5*VolFX^2)*TauStep+VolFX*SQRT(TauStep)*NORMSINV(RAND())) | ... AC15: =AB15*EXP((MuDrift-0.5*VolFX^2)*TauStep+VolFX*SQRT(TauStep)*NORMSINV(RAND()))
A16: 11 | B16: =Spot0*EXP((MuDrift-0.5*VolFX^2)*TauStep+VolFX*SQRT(TauStep)*NORMSINV(RAND())) | C16: =B16*EXP((MuDrift-0.5*VolFX^2)*TauStep+VolFX*SQRT(TauStep)*NORMSINV(RAND())) | D16: =C16*EXP((MuDrift-0.5*VolFX^2)*TauStep+VolFX*SQRT(TauStep)*NORMSINV(RAND())) | E16: =D16*EXP((MuDrift-0.5*VolFX^2)*TauStep+VolFX*SQRT(TauStep)*NORMSINV(RAND())) | F16: =E16*EXP((MuDrift-0.5*VolFX^2)*TauStep+VolFX*SQRT(TauStep)*NORMSINV(RAND())) | G16: =F16*EXP((MuDrift-0.5*VolFX^2)*TauStep+VolFX*SQRT(TauStep)*NORMSINV(RAND())) | H16: =G16*EXP((MuDrift-0.5*VolFX^2)*TauStep+VolFX*SQRT(TauStep)*NORMSINV(RAND())) | I16: =H16*EXP((MuDrift-0.5*VolFX^2)*TauStep+VolFX*SQRT(TauStep)*NORMSINV(RAND())) | J16: =I16*EXP((MuDrift-0.5*VolFX^2)*TauStep+VolFX*SQRT(TauStep)*NORMSINV(RAND())) | ... AC16: =AB16*EXP((MuDrift-0.5*VolFX^2)*TauStep+VolFX*SQRT(TauStep)*NORMSINV(RAND()))
A17: 12 | B17: =Spot0*EXP((MuDrift-0.5*VolFX^2)*TauStep+VolFX*SQRT(TauStep)*NORMSINV(RAND())) | C17: =B17*EXP((MuDrift-0.5*VolFX^2)*TauStep+VolFX*SQRT(TauStep)*NORMSINV(RAND())) | D17: =C17*EXP((MuDrift-0.5*VolFX^2)*TauStep+VolFX*SQRT(TauStep)*NORMSINV(RAND())) | E17: =D17*EXP((MuDrift-0.5*VolFX^2)*TauStep+VolFX*SQRT(TauStep)*NORMSINV(RAND())) | F17: =E17*EXP((MuDrift-0.5*VolFX^2)*TauStep+VolFX*SQRT(TauStep)*NORMSINV(RAND())) | G17: =F17*EXP((MuDrift-0.5*VolFX^2)*TauStep+VolFX*SQRT(TauStep)*NORMSINV(RAND())) | H17: =G17*EXP((MuDrift-0.5*VolFX^2)*TauStep+VolFX*SQRT(TauStep)*NORMSINV(RAND())) | I17: =H17*EXP((MuDrift-0.5*VolFX^2)*TauStep+VolFX*SQRT(TauStep)*NORMSINV(RAND())) | J17: =I17*EXP((MuDrift-0.5*VolFX^2)*TauStep+VolFX*SQRT(TauStep)*NORMSINV(RAND())) | ... AC17: =AB17*EXP((MuDrift-0.5*VolFX^2)*TauStep+VolFX*SQRT(TauStep)*NORMSINV(RAND()))
... A2005: 2000 | B2005: =Spot0*EXP((MuDrift-0.5*VolFX^2)*TauStep+VolFX*SQRT(TauStep)*NORMSINV(RAND())) | C2005: =B2005*EXP((MuDrift-0.5*VolFX^2)*TauStep+VolFX*SQRT(TauStep)*NORMSINV(RAND())) | D2005: =C2005*EXP((MuDrift-0.5*VolFX^2)*TauStep+VolFX*SQRT(TauStep)*NORMSINV(RAND())) | E2005: =D2005*EXP((MuDrift-0.5*VolFX^2)*TauStep+VolFX*SQRT(TauStep)*NORMSINV(RAND())) | F2005: =E2005*EXP((MuDrift-0.5*VolFX^2)*TauStep+VolFX*SQRT(TauStep)*NORMSINV(RAND())) | G2005: =F2005*EXP((MuDrift-0.5*VolFX^2)*TauStep+VolFX*SQRT(TauStep)*NORMSINV(RAND())) | H2005: =G2005*EXP((MuDrift-0.5*VolFX^2)*TauStep+VolFX*SQRT(TauStep)*NORMSINV(RAND())) | I2005: =H2005*EXP((MuDrift-0.5*VolFX^2)*TauStep+VolFX*SQRT(TauStep)*NORMSINV(RAND())) | J2005: =I2005*EXP((MuDrift-0.5*VolFX^2)*TauStep+VolFX*SQRT(TauStep)*NORMSINV(RAND())) | ... AC2005: =AB2005*EXP((MuDrift-0.5*VolFX^2)*TauStep+VolFX*SQRT(TauStep)*NORMSINV(RAND()))
A2007: BLOCK B — DEFERRED BALANCE, EUR
A2008: D(t) = D(t-1)*(1+AccrRate*TauStep) + ( Notional/S(t) - Notional/(S(t-1)*FwdFactor) ) | positive = the fund owes the dealer
A2009: Trial | B2009: t1 | C2009: t2 | D2009: t3 | E2009: t4 | F2009: t5 | G2009: t6 | H2009: t7 | I2009: t8 | J2009: t9 | K2009: t10 | L2009: t11 | M2009: t12 | N2009: t13 | O2009: t14 | P2009: t15 | Q2009: t16 | R2009: t17 | S2009: t18 | T2009: t19 | U2009: t20 | V2009: t21 | W2009: t22 | X2009: t23 | Y2009: t24 | Z2009: t25 | AA2009: t26 | AB2009: t27 | AC2009: t28
A2010: 1 | B2010: =0+(Notional/Simulation!B6-Notional/(Spot0*FwdFactor)) | C2010: =B2010*(1+AccrRate*TauStep)+(Notional/Simulation!C6-Notional/(Simulation!B6*FwdFactor)) | D2010: =C2010*(1+AccrRate*TauStep)+(Notional/Simulation!D6-Notional/(Simulation!C6*FwdFactor)) | E2010: =D2010*(1+AccrRate*TauStep)+(Notional/Simulation!E6-Notional/(Simulation!D6*FwdFactor)) | F2010: =E2010*(1+AccrRate*TauStep)+(Notional/Simulation!F6-Notional/(Simulation!E6*FwdFactor)) | G2010: =F2010*(1+AccrRate*TauStep)+(Notional/Simulation!G6-Notional/(Simulation!F6*FwdFactor)) | H2010: =G2010*(1+AccrRate*TauStep)+(Notional/Simulation!H6-Notional/(Simulation!G6*FwdFactor)) | I2010: =H2010*(1+AccrRate*TauStep)+(Notional/Simulation!I6-Notional/(Simulation!H6*FwdFactor)) | J2010: =I2010*(1+AccrRate*TauStep)+(Notional/Simulation!J6-Notional/(Simulation!I6*FwdFactor)) | ... AC2010: =AB2010*(1+AccrRate*TauStep)+(Notional/Simulation!AC6-Notional/(Simulation!AB6*FwdFactor))
A2011: 2 | B2011: =0+(Notional/Simulation!B7-Notional/(Spot0*FwdFactor)) | C2011: =B2011*(1+AccrRate*TauStep)+(Notional/Simulation!C7-Notional/(Simulation!B7*FwdFactor)) | D2011: =C2011*(1+AccrRate*TauStep)+(Notional/Simulation!D7-Notional/(Simulation!C7*FwdFactor)) | E2011: =D2011*(1+AccrRate*TauStep)+(Notional/Simulation!E7-Notional/(Simulation!D7*FwdFactor)) | F2011: =E2011*(1+AccrRate*TauStep)+(Notional/Simulation!F7-Notional/(Simulation!E7*FwdFactor)) | G2011: =F2011*(1+AccrRate*TauStep)+(Notional/Simulation!G7-Notional/(Simulation!F7*FwdFactor)) | H2011: =G2011*(1+AccrRate*TauStep)+(Notional/Simulation!H7-Notional/(Simulation!G7*FwdFactor)) | I2011: =H2011*(1+AccrRate*TauStep)+(Notional/Simulation!I7-Notional/(Simulation!H7*FwdFactor)) | J2011: =I2011*(1+AccrRate*TauStep)+(Notional/Simulation!J7-Notional/(Simulation!I7*FwdFactor)) | ... AC2011: =AB2011*(1+AccrRate*TauStep)+(Notional/Simulation!AC7-Notional/(Simulation!AB7*FwdFactor))
A2012: 3 | B2012: =0+(Notional/Simulation!B8-Notional/(Spot0*FwdFactor)) | C2012: =B2012*(1+AccrRate*TauStep)+(Notional/Simulation!C8-Notional/(Simulation!B8*FwdFactor)) | D2012: =C2012*(1+AccrRate*TauStep)+(Notional/Simulation!D8-Notional/(Simulation!C8*FwdFactor)) | E2012: =D2012*(1+AccrRate*TauStep)+(Notional/Simulation!E8-Notional/(Simulation!D8*FwdFactor)) | F2012: =E2012*(1+AccrRate*TauStep)+(Notional/Simulation!F8-Notional/(Simulation!E8*FwdFactor)) | G2012: =F2012*(1+AccrRate*TauStep)+(Notional/Simulation!G8-Notional/(Simulation!F8*FwdFactor)) | H2012: =G2012*(1+AccrRate*TauStep)+(Notional/Simulation!H8-Notional/(Simulation!G8*FwdFactor)) | I2012: =H2012*(1+AccrRate*TauStep)+(Notional/Simulation!I8-Notional/(Simulation!H8*FwdFactor)) | J2012: =I2012*(1+AccrRate*TauStep)+(Notional/Simulation!J8-Notional/(Simulation!I8*FwdFactor)) | ... AC2012: =AB2012*(1+AccrRate*TauStep)+(Notional/Simulation!AC8-Notional/(Simulation!AB8*FwdFactor))
A2013: 4 | B2013: =0+(Notional/Simulation!B9-Notional/(Spot0*FwdFactor)) | C2013: =B2013*(1+AccrRate*TauStep)+(Notional/Simulation!C9-Notional/(Simulation!B9*FwdFactor)) | D2013: =C2013*(1+AccrRate*TauStep)+(Notional/Simulation!D9-Notional/(Simulation!C9*FwdFactor)) | E2013: =D2013*(1+AccrRate*TauStep)+(Notional/Simulation!E9-Notional/(Simulation!D9*FwdFactor)) | F2013: =E2013*(1+AccrRate*TauStep)+(Notional/Simulation!F9-Notional/(Simulation!E9*FwdFactor)) | G2013: =F2013*(1+AccrRate*TauStep)+(Notional/Simulation!G9-Notional/(Simulation!F9*FwdFactor)) | H2013: =G2013*(1+AccrRate*TauStep)+(Notional/Simulation!H9-Notional/(Simulation!G9*FwdFactor)) | I2013: =H2013*(1+AccrRate*TauStep)+(Notional/Simulation!I9-Notional/(Simulation!H9*FwdFactor)) | J2013: =I2013*(1+AccrRate*TauStep)+(Notional/Simulation!J9-Notional/(Simulation!I9*FwdFactor)) | ... AC2013: =AB2013*(1+AccrRate*TauStep)+(Notional/Simulation!AC9-Notional/(Simulation!AB9*FwdFactor))
A2014: 5 | B2014: =0+(Notional/Simulation!B10-Notional/(Spot0*FwdFactor)) | C2014: =B2014*(1+AccrRate*TauStep)+(Notional/Simulation!C10-Notional/(Simulation!B10*FwdFactor)) | D2014: =C2014*(1+AccrRate*TauStep)+(Notional/Simulation!D10-Notional/(Simulation!C10*FwdFactor)) | E2014: =D2014*(1+AccrRate*TauStep)+(Notional/Simulation!E10-Notional/(Simulation!D10*FwdFactor)) | F2014: =E2014*(1+AccrRate*TauStep)+(Notional/Simulation!F10-Notional/(Simulation!E10*FwdFactor)) | G2014: =F2014*(1+AccrRate*TauStep)+(Notional/Simulation!G10-Notional/(Simulation!F10*FwdFactor)) | H2014: =G2014*(1+AccrRate*TauStep)+(Notional/Simulation!H10-Notional/(Simulation!G10*FwdFactor)) | I2014: =H2014*(1+AccrRate*TauStep)+(Notional/Simulation!I10-Notional/(Simulation!H10*FwdFactor)) | J2014: =I2014*(1+AccrRate*TauStep)+(Notional/Simulation!J10-Notional/(Simulation!I10*FwdFactor)) | ... AC2014: =AB2014*(1+AccrRate*TauStep)+(Notional/Simulation!AC10-Notional/(Simulation!AB10*FwdFactor))
A2015: 6 | B2015: =0+(Notional/Simulation!B11-Notional/(Spot0*FwdFactor)) | C2015: =B2015*(1+AccrRate*TauStep)+(Notional/Simulation!C11-Notional/(Simulation!B11*FwdFactor)) | D2015: =C2015*(1+AccrRate*TauStep)+(Notional/Simulation!D11-Notional/(Simulation!C11*FwdFactor)) | E2015: =D2015*(1+AccrRate*TauStep)+(Notional/Simulation!E11-Notional/(Simulation!D11*FwdFactor)) | F2015: =E2015*(1+AccrRate*TauStep)+(Notional/Simulation!F11-Notional/(Simulation!E11*FwdFactor)) | G2015: =F2015*(1+AccrRate*TauStep)+(Notional/Simulation!G11-Notional/(Simulation!F11*FwdFactor)) | H2015: =G2015*(1+AccrRate*TauStep)+(Notional/Simulation!H11-Notional/(Simulation!G11*FwdFactor)) | I2015: =H2015*(1+AccrRate*TauStep)+(Notional/Simulation!I11-Notional/(Simulation!H11*FwdFactor)) | J2015: =I2015*(1+AccrRate*TauStep)+(Notional/Simulation!J11-Notional/(Simulation!I11*FwdFactor)) | ... AC2015: =AB2015*(1+AccrRate*TauStep)+(Notional/Simulation!AC11-Notional/(Simulation!AB11*FwdFactor))
A2016: 7 | B2016: =0+(Notional/Simulation!B12-Notional/(Spot0*FwdFactor)) | C2016: =B2016*(1+AccrRate*TauStep)+(Notional/Simulation!C12-Notional/(Simulation!B12*FwdFactor)) | D2016: =C2016*(1+AccrRate*TauStep)+(Notional/Simulation!D12-Notional/(Simulation!C12*FwdFactor)) | E2016: =D2016*(1+AccrRate*TauStep)+(Notional/Simulation!E12-Notional/(Simulation!D12*FwdFactor)) | F2016: =E2016*(1+AccrRate*TauStep)+(Notional/Simulation!F12-Notional/(Simulation!E12*FwdFactor)) | G2016: =F2016*(1+AccrRate*TauStep)+(Notional/Simulation!G12-Notional/(Simulation!F12*FwdFactor)) | H2016: =G2016*(1+AccrRate*TauStep)+(Notional/Simulation!H12-Notional/(Simulation!G12*FwdFactor)) | I2016: =H2016*(1+AccrRate*TauStep)+(Notional/Simulation!I12-Notional/(Simulation!H12*FwdFactor)) | J2016: =I2016*(1+AccrRate*TauStep)+(Notional/Simulation!J12-Notional/(Simulation!I12*FwdFactor)) | ... AC2016: =AB2016*(1+AccrRate*TauStep)+(Notional/Simulation!AC12-Notional/(Simulation!AB12*FwdFactor))
A2017: 8 | B2017: =0+(Notional/Simulation!B13-Notional/(Spot0*FwdFactor)) | C2017: =B2017*(1+AccrRate*TauStep)+(Notional/Simulation!C13-Notional/(Simulation!B13*FwdFactor)) | D2017: =C2017*(1+AccrRate*TauStep)+(Notional/Simulation!D13-Notional/(Simulation!C13*FwdFactor)) | E2017: =D2017*(1+AccrRate*TauStep)+(Notional/Simulation!E13-Notional/(Simulation!D13*FwdFactor)) | F2017: =E2017*(1+AccrRate*TauStep)+(Notional/Simulation!F13-Notional/(Simulation!E13*FwdFactor)) | G2017: =F2017*(1+AccrRate*TauStep)+(Notional/Simulation!G13-Notional/(Simulation!F13*FwdFactor)) | H2017: =G2017*(1+AccrRate*TauStep)+(Notional/Simulation!H13-Notional/(Simulation!G13*FwdFactor)) | I2017: =H2017*(1+AccrRate*TauStep)+(Notional/Simulation!I13-Notional/(Simulation!H13*FwdFactor)) | J2017: =I2017*(1+AccrRate*TauStep)+(Notional/Simulation!J13-Notional/(Simulation!I13*FwdFactor)) | ... AC2017: =AB2017*(1+AccrRate*TauStep)+(Notional/Simulation!AC13-Notional/(Simulation!AB13*FwdFactor))
A2018: 9 | B2018: =0+(Notional/Simulation!B14-Notional/(Spot0*FwdFactor)) | C2018: =B2018*(1+AccrRate*TauStep)+(Notional/Simulation!C14-Notional/(Simulation!B14*FwdFactor)) | D2018: =C2018*(1+AccrRate*TauStep)+(Notional/Simulation!D14-Notional/(Simulation!C14*FwdFactor)) | E2018: =D2018*(1+AccrRate*TauStep)+(Notional/Simulation!E14-Notional/(Simulation!D14*FwdFactor)) | F2018: =E2018*(1+AccrRate*TauStep)+(Notional/Simulation!F14-Notional/(Simulation!E14*FwdFactor)) | G2018: =F2018*(1+AccrRate*TauStep)+(Notional/Simulation!G14-Notional/(Simulation!F14*FwdFactor)) | H2018: =G2018*(1+AccrRate*TauStep)+(Notional/Simulation!H14-Notional/(Simulation!G14*FwdFactor)) | I2018: =H2018*(1+AccrRate*TauStep)+(Notional/Simulation!I14-Notional/(Simulation!H14*FwdFactor)) | J2018: =I2018*(1+AccrRate*TauStep)+(Notional/Simulation!J14-Notional/(Simulation!I14*FwdFactor)) | ... AC2018: =AB2018*(1+AccrRate*TauStep)+(Notional/Simulation!AC14-Notional/(Simulation!AB14*FwdFactor))
A2019: 10 | B2019: =0+(Notional/Simulation!B15-Notional/(Spot0*FwdFactor)) | C2019: =B2019*(1+AccrRate*TauStep)+(Notional/Simulation!C15-Notional/(Simulation!B15*FwdFactor)) | D2019: =C2019*(1+AccrRate*TauStep)+(Notional/Simulation!D15-Notional/(Simulation!C15*FwdFactor)) | E2019: =D2019*(1+AccrRate*TauStep)+(Notional/Simulation!E15-Notional/(Simulation!D15*FwdFactor)) | F2019: =E2019*(1+AccrRate*TauStep)+(Notional/Simulation!F15-Notional/(Simulation!E15*FwdFactor)) | G2019: =F2019*(1+AccrRate*TauStep)+(Notional/Simulation!G15-Notional/(Simulation!F15*FwdFactor)) | H2019: =G2019*(1+AccrRate*TauStep)+(Notional/Simulation!H15-Notional/(Simulation!G15*FwdFactor)) | I2019: =H2019*(1+AccrRate*TauStep)+(Notional/Simulation!I15-Notional/(Simulation!H15*FwdFactor)) | J2019: =I2019*(1+AccrRate*TauStep)+(Notional/Simulation!J15-Notional/(Simulation!I15*FwdFactor)) | ... AC2019: =AB2019*(1+AccrRate*TauStep)+(Notional/Simulation!AC15-Notional/(Simulation!AB15*FwdFactor))
A2020: 11 | B2020: =0+(Notional/Simulation!B16-Notional/(Spot0*FwdFactor)) | C2020: =B2020*(1+AccrRate*TauStep)+(Notional/Simulation!C16-Notional/(Simulation!B16*FwdFactor)) | D2020: =C2020*(1+AccrRate*TauStep)+(Notional/Simulation!D16-Notional/(Simulation!C16*FwdFactor)) | E2020: =D2020*(1+AccrRate*TauStep)+(Notional/Simulation!E16-Notional/(Simulation!D16*FwdFactor)) | F2020: =E2020*(1+AccrRate*TauStep)+(Notional/Simulation!F16-Notional/(Simulation!E16*FwdFactor)) | G2020: =F2020*(1+AccrRate*TauStep)+(Notional/Simulation!G16-Notional/(Simulation!F16*FwdFactor)) | H2020: =G2020*(1+AccrRate*TauStep)+(Notional/Simulation!H16-Notional/(Simulation!G16*FwdFactor)) | I2020: =H2020*(1+AccrRate*TauStep)+(Notional/Simulation!I16-Notional/(Simulation!H16*FwdFactor)) | J2020: =I2020*(1+AccrRate*TauStep)+(Notional/Simulation!J16-Notional/(Simulation!I16*FwdFactor)) | ... AC2020: =AB2020*(1+AccrRate*TauStep)+(Notional/Simulation!AC16-Notional/(Simulation!AB16*FwdFactor))
A2021: 12 | B2021: =0+(Notional/Simulation!B17-Notional/(Spot0*FwdFactor)) | C2021: =B2021*(1+AccrRate*TauStep)+(Notional/Simulation!C17-Notional/(Simulation!B17*FwdFactor)) | D2021: =C2021*(1+AccrRate*TauStep)+(Notional/Simulation!D17-Notional/(Simulation!C17*FwdFactor)) | E2021: =D2021*(1+AccrRate*TauStep)+(Notional/Simulation!E17-Notional/(Simulation!D17*FwdFactor)) | F2021: =E2021*(1+AccrRate*TauStep)+(Notional/Simulation!F17-Notional/(Simulation!E17*FwdFactor)) | G2021: =F2021*(1+AccrRate*TauStep)+(Notional/Simulation!G17-Notional/(Simulation!F17*FwdFactor)) | H2021: =G2021*(1+AccrRate*TauStep)+(Notional/Simulation!H17-Notional/(Simulation!G17*FwdFactor)) | I2021: =H2021*(1+AccrRate*TauStep)+(Notional/Simulation!I17-Notional/(Simulation!H17*FwdFactor)) | J2021: =I2021*(1+AccrRate*TauStep)+(Notional/Simulation!J17-Notional/(Simulation!I17*FwdFactor)) | ... AC2021: =AB2021*(1+AccrRate*TauStep)+(Notional/Simulation!AC17-Notional/(Simulation!AB17*FwdFactor))
... A4009: 2000 | B4009: =0+(Notional/Simulation!B2005-Notional/(Spot0*FwdFactor)) | C4009: =B4009*(1+AccrRate*TauStep)+(Notional/Simulation!C2005-Notional/(Simulation!B2005*FwdFactor)) | D4009: =C4009*(1+AccrRate*TauStep)+(Notional/Simulation!D2005-Notional/(Simulation!C2005*FwdFactor)) | E4009: =D4009*(1+AccrRate*TauStep)+(Notional/Simulation!E2005-Notional/(Simulation!D2005*FwdFactor)) | F4009: =E4009*(1+AccrRate*TauStep)+(Notional/Simulation!F2005-Notional/(Simulation!E2005*FwdFactor)) | G4009: =F4009*(1+AccrRate*TauStep)+(Notional/Simulation!G2005-Notional/(Simulation!F2005*FwdFactor)) | H4009: =G4009*(1+AccrRate*TauStep)+(Notional/Simulation!H2005-Notional/(Simulation!G2005*FwdFactor)) | I4009: =H4009*(1+AccrRate*TauStep)+(Notional/Simulation!I2005-Notional/(Simulation!H2005*FwdFactor)) | J4009: =I4009*(1+AccrRate*TauStep)+(Notional/Simulation!J2005-Notional/(Simulation!I2005*FwdFactor)) | ... AC4009: =AB4009*(1+AccrRate*TauStep)+(Notional/Simulation!AC2005-Notional/(Simulation!AB2005*FwdFactor))
A4011: BLOCK C — RUNNING PEAK OF THE DEFERRED BALANCE, EUR
A4012: M(t) = MAX(M(t-1), D(t)) | the peak is the unsecured credit line the strategy actually needs
A4013: Trial | B4013: t1 | C4013: t2 | D4013: t3 | E4013: t4 | F4013: t5 | G4013: t6 | H4013: t7 | I4013: t8 | J4013: t9 | K4013: t10 | L4013: t11 | M4013: t12 | N4013: t13 | O4013: t14 | P4013: t15 | Q4013: t16 | R4013: t17 | S4013: t18 | T4013: t19 | U4013: t20 | V4013: t21 | W4013: t22 | X4013: t23 | Y4013: t24 | Z4013: t25 | AA4013: t26 | AB4013: t27 | AC4013: t28
A4014: 1 | B4014: =MAX(0,B2010) | C4014: =MAX(B4014,C2010) | D4014: =MAX(C4014,D2010) | E4014: =MAX(D4014,E2010) | F4014: =MAX(E4014,F2010) | G4014: =MAX(F4014,G2010) | H4014: =MAX(G4014,H2010) | I4014: =MAX(H4014,I2010) | J4014: =MAX(I4014,J2010) | ... AC4014: =MAX(AB4014,AC2010)
A4015: 2 | B4015: =MAX(0,B2011) | C4015: =MAX(B4015,C2011) | D4015: =MAX(C4015,D2011) | E4015: =MAX(D4015,E2011) | F4015: =MAX(E4015,F2011) | G4015: =MAX(F4015,G2011) | H4015: =MAX(G4015,H2011) | I4015: =MAX(H4015,I2011) | J4015: =MAX(I4015,J2011) | ... AC4015: =MAX(AB4015,AC2011)
A4016: 3 | B4016: =MAX(0,B2012) | C4016: =MAX(B4016,C2012) | D4016: =MAX(C4016,D2012) | E4016: =MAX(D4016,E2012) | F4016: =MAX(E4016,F2012) | G4016: =MAX(F4016,G2012) | H4016: =MAX(G4016,H2012) | I4016: =MAX(H4016,I2012) | J4016: =MAX(I4016,J2012) | ... AC4016: =MAX(AB4016,AC2012)
...

Sheet Results
A1: Results — % of hedged notional
A2: Live off the Simulation sheet. Press F9 on the Inputs sheet to resample. Log a case with Copy → Paste Special → Values below.
A4: A · TERMINAL DEFERRED BALANCE AT EACH YEAR-END
A5: What is owed to the dealer on that date. Read off Block B of the Simulation sheet.
A6: Horizon | B6: Mean | C6: p50 | D6: p75 | E6: p90 | F6: p95 | G6: p99 | H6: P(>10% of notional)
A7: Year 1 | B7: =AVERAGE(Simulation!E2010:E4009)/Notional | C7: =PERCENTILE(Simulation!E2010:E4009,0.50)/Notional | D7: =PERCENTILE(Simulation!E2010:E4009,0.75)/Notional | E7: =PERCENTILE(Simulation!E2010:E4009,0.90)/Notional | F7: =PERCENTILE(Simulation!E2010:E4009,0.95)/Notional | G7: =PERCENTILE(Simulation!E2010:E4009,0.99)/Notional | H7: =COUNTIF(Simulation!E2010:E4009,">"&0.10*Notional)/2000
A8: Year 2 | B8: =AVERAGE(Simulation!I2010:I4009)/Notional | C8: =PERCENTILE(Simulation!I2010:I4009,0.50)/Notional | D8: =PERCENTILE(Simulation!I2010:I4009,0.75)/Notional | E8: =PERCENTILE(Simulation!I2010:I4009,0.90)/Notional | F8: =PERCENTILE(Simulation!I2010:I4009,0.95)/Notional | G8: =PERCENTILE(Simulation!I2010:I4009,0.99)/Notional | H8: =COUNTIF(Simulation!I2010:I4009,">"&0.10*Notional)/2000
A9: Year 3 | B9: =AVERAGE(Simulation!M2010:M4009)/Notional | C9: =PERCENTILE(Simulation!M2010:M4009,0.50)/Notional | D9: =PERCENTILE(Simulation!M2010:M4009,0.75)/Notional | E9: =PERCENTILE(Simulation!M2010:M4009,0.90)/Notional | F9: =PERCENTILE(Simulation!M2010:M4009,0.95)/Notional | G9: =PERCENTILE(Simulation!M2010:M4009,0.99)/Notional | H9: =COUNTIF(Simulation!M2010:M4009,">"&0.10*Notional)/2000
A10: Year 4 | B10: =AVERAGE(Simulation!Q2010:Q4009)/Notional | C10: =PERCENTILE(Simulation!Q2010:Q4009,0.50)/Notional | D10: =PERCENTILE(Simulation!Q2010:Q4009,0.75)/Notional | E10: =PERCENTILE(Simulation!Q2010:Q4009,0.90)/Notional | F10: =PERCENTILE(Simulation!Q2010:Q4009,0.95)/Notional | G10: =PERCENTILE(Simulation!Q2010:Q4009,0.99)/Notional | H10: =COUNTIF(Simulation!Q2010:Q4009,">"&0.10*Notional)/2000
A11: Year 5 | B11: =AVERAGE(Simulation!U2010:U4009)/Notional | C11: =PERCENTILE(Simulation!U2010:U4009,0.50)/Notional | D11: =PERCENTILE(Simulation!U2010:U4009,0.75)/Notional | E11: =PERCENTILE(Simulation!U2010:U4009,0.90)/Notional | F11: =PERCENTILE(Simulation!U2010:U4009,0.95)/Notional | G11: =PERCENTILE(Simulation!U2010:U4009,0.99)/Notional | H11: =COUNTIF(Simulation!U2010:U4009,">"&0.10*Notional)/2000
A12: Year 6 | B12: =AVERAGE(Simulation!Y2010:Y4009)/Notional | C12: =PERCENTILE(Simulation!Y2010:Y4009,0.50)/Notional | D12: =PERCENTILE(Simulation!Y2010:Y4009,0.75)/Notional | E12: =PERCENTILE(Simulation!Y2010:Y4009,0.90)/Notional | F12: =PERCENTILE(Simulation!Y2010:Y4009,0.95)/Notional | G12: =PERCENTILE(Simulation!Y2010:Y4009,0.99)/Notional | H12: =COUNTIF(Simulation!Y2010:Y4009,">"&0.10*Notional)/2000
A13: Year 7 | B13: =AVERAGE(Simulation!AC2010:AC4009)/Notional | C13: =PERCENTILE(Simulation!AC2010:AC4009,0.50)/Notional | D13: =PERCENTILE(Simulation!AC2010:AC4009,0.75)/Notional | E13: =PERCENTILE(Simulation!AC2010:AC4009,0.90)/Notional | F13: =PERCENTILE(Simulation!AC2010:AC4009,0.95)/Notional | G13: =PERCENTILE(Simulation!AC2010:AC4009,0.99)/Notional | H13: =COUNTIF(Simulation!AC2010:AC4009,">"&0.10*Notional)/2000
A15: B · PEAK DEFERRED BALANCE UP TO EACH YEAR-END
A16: The largest the balance ever got along the way — the credit line the strategy actually needs.
A17: Horizon | B17: Mean | C17: p50 | D17: p75 | E17: p90 | F17: p95 | G17: p99 | H17: P(>10% of notional)
A18: Year 1 | B18: =AVERAGE(Simulation!E4014:E6013)/Notional | C18: =PERCENTILE(Simulation!E4014:E6013,0.50)/Notional | D18: =PERCENTILE(Simulation!E4014:E6013,0.75)/Notional | E18: =PERCENTILE(Simulation!E4014:E6013,0.90)/Notional | F18: =PERCENTILE(Simulation!E4014:E6013,0.95)/Notional | G18: =PERCENTILE(Simulation!E4014:E6013,0.99)/Notional | H18: =COUNTIF(Simulation!E4014:E6013,">"&0.10*Notional)/2000
A19: Year 2 | B19: =AVERAGE(Simulation!I4014:I6013)/Notional | C19: =PERCENTILE(Simulation!I4014:I6013,0.50)/Notional | D19: =PERCENTILE(Simulation!I4014:I6013,0.75)/Notional | E19: =PERCENTILE(Simulation!I4014:I6013,0.90)/Notional | F19: =PERCENTILE(Simulation!I4014:I6013,0.95)/Notional | G19: =PERCENTILE(Simulation!I4014:I6013,0.99)/Notional | H19: =COUNTIF(Simulation!I4014:I6013,">"&0.10*Notional)/2000
A20: Year 3 | B20: =AVERAGE(Simulation!M4014:M6013)/Notional | C20: =PERCENTILE(Simulation!M4014:M6013,0.50)/Notional | D20: =PERCENTILE(Simulation!M4014:M6013,0.75)/Notional | E20: =PERCENTILE(Simulation!M4014:M6013,0.90)/Notional | F20: =PERCENTILE(Simulation!M4014:M6013,0.95)/Notional | G20: =PERCENTILE(Simulation!M4014:M6013,0.99)/Notional | H20: =COUNTIF(Simulation!M4014:M6013,">"&0.10*Notional)/2000
A21: Year 4 | B21: =AVERAGE(Simulation!Q4014:Q6013)/Notional | C21: =PERCENTILE(Simulation!Q4014:Q6013,0.50)/Notional | D21: =PERCENTILE(Simulation!Q4014:Q6013,0.75)/Notional | E21: =PERCENTILE(Simulation!Q4014:Q6013,0.90)/Notional | F21: =PERCENTILE(Simulation!Q4014:Q6013,0.95)/Notional | G21: =PERCENTILE(Simulation!Q4014:Q6013,0.99)/Notional | H21: =COUNTIF(Simulation!Q4014:Q6013,">"&0.10*Notional)/2000
A22: Year 5 | B22: =AVERAGE(Simulation!U4014:U6013)/Notional | C22: =PERCENTILE(Simulation!U4014:U6013,0.50)/Notional | D22: =PERCENTILE(Simulation!U4014:U6013,0.75)/Notional | E22: =PERCENTILE(Simulation!U4014:U6013,0.90)/Notional | F22: =PERCENTILE(Simulation!U4014:U6013,0.95)/Notional | G22: =PERCENTILE(Simulation!U4014:U6013,0.99)/Notional | H22: =COUNTIF(Simulation!U4014:U6013,">"&0.10*Notional)/2000
A23: Year 6 | B23: =AVERAGE(Simulation!Y4014:Y6013)/Notional | C23: =PERCENTILE(Simulation!Y4014:Y6013,0.50)/Notional | D23: =PERCENTILE(Simulation!Y4014:Y6013,0.75)/Notional | E23: =PERCENTILE(Simulation!Y4014:Y6013,0.90)/Notional | F23: =PERCENTILE(Simulation!Y4014:Y6013,0.95)/Notional | G23: =PERCENTILE(Simulation!Y4014:Y6013,0.99)/Notional | H23: =COUNTIF(Simulation!Y4014:Y6013,">"&0.10*Notional)/2000
A24: Year 7 | B24: =AVERAGE(Simulation!AC4014:AC6013)/Notional | C24: =PERCENTILE(Simulation!AC4014:AC6013,0.50)/Notional | D24: =PERCENTILE(Simulation!AC4014:AC6013,0.75)/Notional | E24: =PERCENTILE(Simulation!AC4014:AC6013,0.90)/Notional | F24: =PERCENTILE(Simulation!AC4014:AC6013,0.95)/Notional | G24: =PERCENTILE(Simulation!AC4014:AC6013,0.99)/Notional | H24: =COUNTIF(Simulation!AC4014:AC6013,">"&0.10*Notional)/2000
A26: CURRENT CASE
A27: Volatility | B27: =VolFX
A28: Spot | B28: =Spot0
A29: USD rate | B29: =RateUSD
A30: EUR rate | B30: =RateEUR
A31: Dealer spread | B31: =Spread
A32: Rolls per year | B32: =PerYear
A34: CASE LOG — paste values here, one row per run
A35: Copy the peak-balance row you care about, then Paste Special → Values into the next free line.
A36: Vol | B36: Horizon | C36: Mean | D36: p50 | E36: p75 | F36: p90 | G36: p95 | H36: p99 | I36: Notes

Sheet Reference
A1: Reference grid — computed independently in Python at 120,000 paths
A2: Peak deferred balance as % of hedged notional. Use this to check that your Excel run is in the right place.
A3: These are hard-coded values, not formulas — they are the benchmark, deliberately independent of the sheet.
A5: PEAK BALANCE — p95
A6: Volatility | B6: 1-year | C6: 3-year | D6: 5-year | E6: 7-year
A7: 0.06 | B7: 0.10027113 | C7: 0.19318673 | D7: 0.26309893 | E7: 0.3281043
A8: 0.08 | B8: 0.13685323 | C8: 0.26878815 | D8: 0.37088337 | E8: 0.46774189
A9: 0.1 | B9: 0.17518819 | C9: 0.35074711 | D9: 0.49058013 | E9: 0.62585842
A10: 0.12 | B10: 0.2153172 | C10: 0.43947825 | D10: 0.624028 | E10: 0.80589553
A11: 0.15 | B11: 0.27914954 | C11: 0.58757096 | D11: 0.85384025 | E11: 1.1250681
A13: PEAK BALANCE — p99
A14: Volatility | B14: 1-year | C14: 3-year | D14: 5-year | E14: 7-year
A15: 0.06 | B15: 0.13995786 | C15: 0.27090581 | D15: 0.36871557 | E15: 0.45798716
A16: 0.08 | B16: 0.19212396 | C16: 0.38052584 | D16: 0.52627121 | E16: 0.66220836
A17: 0.1 | B17: 0.24725535 | C17: 0.50211153 | D17: 0.70575255 | E17: 0.9016912
A18: 0.12 | B18: 0.30555738 | C18: 0.63701731 | D18: 0.90993301 | E18: 1.1817116
A19: 0.15 | B19: 0.39939664 | C19: 0.86620776 | D19: 1.273109 | E19: 1.6930403
A21: PEAK BALANCE — p50
A22: Volatility | B22: 1-year | C22: 3-year | D22: 5-year | E22: 7-year
A23: 0.06 | B23: 0.022463375 | C23: 0.050870463 | D23: 0.069995056 | E23: 0.08619877
A24: 0.08 | B24: 0.030587454 | C24: 0.069822147 | D24: 0.09707246 | E24: 0.12029922
A25: 0.1 | B25: 0.039020491 | C25: 0.090003026 | D25: 0.12606596 | E25: 0.15742297
A26: 0.12 | B26: 0.047708295 | C26: 0.11120336 | D26: 0.15720114 | E26: 0.19779648
A27: 0.15 | B27: 0.061341015 | C27: 0.14537963 | D27: 0.2083115 | E27: 0.26514289
A29: Base case for the reference grid: spot 1.1000, USD 4.5%, EUR 2.5%, dealer spread 75bp, quarterly rolls.
A30: Generated by build_mc.py from hrr_model.breach_grid(). Regenerate if the model changes.
