Workbook
Name Notional: Inputs!$B$5
Name SpotNow: Inputs!$B$6
Name RateUSD: Inputs!$B$7
Name RateEUR: Inputs!$B$8
Name EurDeployed: Inputs!$B$11

Sheet Inputs
A1: EURUSD scenario analysis — USD 100m hedge
A2: Current spot versus spot at maturity, across tenors. Change anything shaded and every grid recomputes.
A4: POSITION — edit these
A5: Hedged notional (USD) | B5: 100000000 | D5: The fund holds this much USD asset and sells it forward against EUR.
A6: EURUSD spot today | B6: 1.1 | D6: USD per EUR.
A7: USD interest rate | B7: 0.045
A8: EUR interest rate | B8: 0.025 | D8: Fund base currency.
A10: DERIVED
A11: EUR deployed at inception | B11: =Notional/SpotNow | D11: What the USD asset cost the fund in euros.
A12: Rate differential | B12: =(RateUSD-RateEUR)*10000 | D12: The annual cost of hedging, before any FX move.
A15: HOW TO READ THE GRIDS
A16: Grid A — hedge P&L in EUR. This is the CASH that settles, and it swings enormously with spot. It is the exposure.
A17: Grid B — the same thing as a percentage of the hedged notional.
A18: Grid C — the offsetting revaluation of the USD asset in EUR. Equal and opposite to the spot component of grid A.
A19: Grid D — grid A plus grid C, the net economic position.
A21: Grid D is the important one. Read DOWN any column: the number never changes, whatever spot does. That is the whole
A22: 'a fully hedged position leaves only the carry' argument, and it is correct. Now read down the same column of grid A,
A23: where the number moves by tens of millions. The gap between those two behaviours is the gap between net economic cost
A24: and gross unsettled obligation — and a limit has to be written against grid A, not grid D.
A26: Grid E — the cash the fund must find at settlement, which is grid A when grid A is negative and zero otherwise.

Sheet Forward Curve
A1: Forward curve
A2: Built from covered interest parity. Override with traded points where you have them — the override wins.
A4: Tenor | B4: Years | C4: CIP forward | D4: Traded points (optional) | E4: Forward used | F4: Annualised hedge cost
A5: 3M | B5: 0.25 | C5: =SpotNow*(1+RateUSD*B5)/(1+RateEUR*B5) | E5: =IF(D5="",C5,SpotNow+D5/10000) | F5: =(E5/SpotNow)^(1/B5)-1
A6: 6M | B6: 0.5 | C6: =SpotNow*(1+RateUSD*B6)/(1+RateEUR*B6) | E6: =IF(D6="",C6,SpotNow+D6/10000) | F6: =(E6/SpotNow)^(1/B6)-1
A7: 1Y | B7: 1 | C7: =SpotNow*(1+RateUSD*B7)/(1+RateEUR*B7) | E7: =IF(D7="",C7,SpotNow+D7/10000) | F7: =(E7/SpotNow)^(1/B7)-1
A8: 2Y | B8: 2 | C8: =SpotNow*(1+RateUSD*B8)/(1+RateEUR*B8) | E8: =IF(D8="",C8,SpotNow+D8/10000) | F8: =(E8/SpotNow)^(1/B8)-1
A9: 3Y | B9: 3 | C9: =SpotNow*(1+RateUSD*B9)/(1+RateEUR*B9) | E9: =IF(D9="",C9,SpotNow+D9/10000) | F9: =(E9/SpotNow)^(1/B9)-1
A10: 5Y | B10: 5 | C10: =SpotNow*(1+RateUSD*B10)/(1+RateEUR*B10) | E10: =IF(D10="",C10,SpotNow+D10/10000) | F10: =(E10/SpotNow)^(1/B10)-1
A11: 7Y | B11: 7 | C11: =SpotNow*(1+RateUSD*B11)/(1+RateEUR*B11) | E11: =IF(D11="",C11,SpotNow+D11/10000) | F11: =(E11/SpotNow)^(1/B11)-1
A13: The 'forward used' column is what every grid on the next sheet is struck at.

Sheet Scenario Grid
A1: Scenario grids — spot at maturity (rows) x tenor (columns)
A2: USD 100m hedged. Everything links back to Inputs and Forward Curve.
A4: A · HEDGE P&L AT MATURITY, EUR
A5: =Notional/K - Notional/S. This is the cash that settles. Negative means the fund pays.
A6: EURUSD at maturity | B6: 3M | C6: 6M | D6: 1Y | E6: 2Y | F6: 3Y | G6: 5Y | H6: 7Y
A7: 0.85 | B7: =Notional/'Forward Curve'!$E$5-Notional/$A7 | C7: =Notional/'Forward Curve'!$E$6-Notional/$A7 | D7: =Notional/'Forward Curve'!$E$7-Notional/$A7 | E7: =Notional/'Forward Curve'!$E$8-Notional/$A7 | F7: =Notional/'Forward Curve'!$E$9-Notional/$A7 | G7: =Notional/'Forward Curve'!$E$10-Notional/$A7 | H7: =Notional/'Forward Curve'!$E$11-Notional/$A7
A8: 0.9 | B8: =Notional/'Forward Curve'!$E$5-Notional/$A8 | C8: =Notional/'Forward Curve'!$E$6-Notional/$A8 | D8: =Notional/'Forward Curve'!$E$7-Notional/$A8 | E8: =Notional/'Forward Curve'!$E$8-Notional/$A8 | F8: =Notional/'Forward Curve'!$E$9-Notional/$A8 | G8: =Notional/'Forward Curve'!$E$10-Notional/$A8 | H8: =Notional/'Forward Curve'!$E$11-Notional/$A8
A9: 0.95 | B9: =Notional/'Forward Curve'!$E$5-Notional/$A9 | C9: =Notional/'Forward Curve'!$E$6-Notional/$A9 | D9: =Notional/'Forward Curve'!$E$7-Notional/$A9 | E9: =Notional/'Forward Curve'!$E$8-Notional/$A9 | F9: =Notional/'Forward Curve'!$E$9-Notional/$A9 | G9: =Notional/'Forward Curve'!$E$10-Notional/$A9 | H9: =Notional/'Forward Curve'!$E$11-Notional/$A9
A10: 1 | B10: =Notional/'Forward Curve'!$E$5-Notional/$A10 | C10: =Notional/'Forward Curve'!$E$6-Notional/$A10 | D10: =Notional/'Forward Curve'!$E$7-Notional/$A10 | E10: =Notional/'Forward Curve'!$E$8-Notional/$A10 | F10: =Notional/'Forward Curve'!$E$9-Notional/$A10 | G10: =Notional/'Forward Curve'!$E$10-Notional/$A10 | H10: =Notional/'Forward Curve'!$E$11-Notional/$A10
A11: 1.05 | B11: =Notional/'Forward Curve'!$E$5-Notional/$A11 | C11: =Notional/'Forward Curve'!$E$6-Notional/$A11 | D11: =Notional/'Forward Curve'!$E$7-Notional/$A11 | E11: =Notional/'Forward Curve'!$E$8-Notional/$A11 | F11: =Notional/'Forward Curve'!$E$9-Notional/$A11 | G11: =Notional/'Forward Curve'!$E$10-Notional/$A11 | H11: =Notional/'Forward Curve'!$E$11-Notional/$A11
A12: 1.1 | B12: =Notional/'Forward Curve'!$E$5-Notional/$A12 | C12: =Notional/'Forward Curve'!$E$6-Notional/$A12 | D12: =Notional/'Forward Curve'!$E$7-Notional/$A12 | E12: =Notional/'Forward Curve'!$E$8-Notional/$A12 | F12: =Notional/'Forward Curve'!$E$9-Notional/$A12 | G12: =Notional/'Forward Curve'!$E$10-Notional/$A12 | H12: =Notional/'Forward Curve'!$E$11-Notional/$A12
A13: 1.15 | B13: =Notional/'Forward Curve'!$E$5-Notional/$A13 | C13: =Notional/'Forward Curve'!$E$6-Notional/$A13 | D13: =Notional/'Forward Curve'!$E$7-Notional/$A13 | E13: =Notional/'Forward Curve'!$E$8-Notional/$A13 | F13: =Notional/'Forward Curve'!$E$9-Notional/$A13 | G13: =Notional/'Forward Curve'!$E$10-Notional/$A13 | H13: =Notional/'Forward Curve'!$E$11-Notional/$A13
A14: 1.2 | B14: =Notional/'Forward Curve'!$E$5-Notional/$A14 | C14: =Notional/'Forward Curve'!$E$6-Notional/$A14 | D14: =Notional/'Forward Curve'!$E$7-Notional/$A14 | E14: =Notional/'Forward Curve'!$E$8-Notional/$A14 | F14: =Notional/'Forward Curve'!$E$9-Notional/$A14 | G14: =Notional/'Forward Curve'!$E$10-Notional/$A14 | H14: =Notional/'Forward Curve'!$E$11-Notional/$A14
A15: 1.25 | B15: =Notional/'Forward Curve'!$E$5-Notional/$A15 | C15: =Notional/'Forward Curve'!$E$6-Notional/$A15 | D15: =Notional/'Forward Curve'!$E$7-Notional/$A15 | E15: =Notional/'Forward Curve'!$E$8-Notional/$A15 | F15: =Notional/'Forward Curve'!$E$9-Notional/$A15 | G15: =Notional/'Forward Curve'!$E$10-Notional/$A15 | H15: =Notional/'Forward Curve'!$E$11-Notional/$A15
A16: 1.3 | B16: =Notional/'Forward Curve'!$E$5-Notional/$A16 | C16: =Notional/'Forward Curve'!$E$6-Notional/$A16 | D16: =Notional/'Forward Curve'!$E$7-Notional/$A16 | E16: =Notional/'Forward Curve'!$E$8-Notional/$A16 | F16: =Notional/'Forward Curve'!$E$9-Notional/$A16 | G16: =Notional/'Forward Curve'!$E$10-Notional/$A16 | H16: =Notional/'Forward Curve'!$E$11-Notional/$A16
A17: 1.35 | B17: =Notional/'Forward Curve'!$E$5-Notional/$A17 | C17: =Notional/'Forward Curve'!$E$6-Notional/$A17 | D17: =Notional/'Forward Curve'!$E$7-Notional/$A17 | E17: =Notional/'Forward Curve'!$E$8-Notional/$A17 | F17: =Notional/'Forward Curve'!$E$9-Notional/$A17 | G17: =Notional/'Forward Curve'!$E$10-Notional/$A17 | H17: =Notional/'Forward Curve'!$E$11-Notional/$A17
A18: 1.4 | B18: =Notional/'Forward Curve'!$E$5-Notional/$A18 | C18: =Notional/'Forward Curve'!$E$6-Notional/$A18 | D18: =Notional/'Forward Curve'!$E$7-Notional/$A18 | E18: =Notional/'Forward Curve'!$E$8-Notional/$A18 | F18: =Notional/'Forward Curve'!$E$9-Notional/$A18 | G18: =Notional/'Forward Curve'!$E$10-Notional/$A18 | H18: =Notional/'Forward Curve'!$E$11-Notional/$A18
A19: 1.45 | B19: =Notional/'Forward Curve'!$E$5-Notional/$A19 | C19: =Notional/'Forward Curve'!$E$6-Notional/$A19 | D19: =Notional/'Forward Curve'!$E$7-Notional/$A19 | E19: =Notional/'Forward Curve'!$E$8-Notional/$A19 | F19: =Notional/'Forward Curve'!$E$9-Notional/$A19 | G19: =Notional/'Forward Curve'!$E$10-Notional/$A19 | H19: =Notional/'Forward Curve'!$E$11-Notional/$A19
A20: Read down a column: this is the exposure, and it is unbounded.
A22: B · HEDGE P&L AS % OF HEDGED NOTIONAL
A23: The same grid, scaled. This is the unit the per-hedge limit is written in.
A24: EURUSD at maturity | B24: 3M | C24: 6M | D24: 1Y | E24: 2Y | F24: 3Y | G24: 5Y | H24: 7Y
A25: 0.85 | B25: =(Notional/'Forward Curve'!$E$5-Notional/$A25)/EurDeployed | C25: =(Notional/'Forward Curve'!$E$6-Notional/$A25)/EurDeployed | D25: =(Notional/'Forward Curve'!$E$7-Notional/$A25)/EurDeployed | E25: =(Notional/'Forward Curve'!$E$8-Notional/$A25)/EurDeployed | F25: =(Notional/'Forward Curve'!$E$9-Notional/$A25)/EurDeployed | G25: =(Notional/'Forward Curve'!$E$10-Notional/$A25)/EurDeployed | H25: =(Notional/'Forward Curve'!$E$11-Notional/$A25)/EurDeployed
A26: 0.9 | B26: =(Notional/'Forward Curve'!$E$5-Notional/$A26)/EurDeployed | C26: =(Notional/'Forward Curve'!$E$6-Notional/$A26)/EurDeployed | D26: =(Notional/'Forward Curve'!$E$7-Notional/$A26)/EurDeployed | E26: =(Notional/'Forward Curve'!$E$8-Notional/$A26)/EurDeployed | F26: =(Notional/'Forward Curve'!$E$9-Notional/$A26)/EurDeployed | G26: =(Notional/'Forward Curve'!$E$10-Notional/$A26)/EurDeployed | H26: =(Notional/'Forward Curve'!$E$11-Notional/$A26)/EurDeployed
A27: 0.95 | B27: =(Notional/'Forward Curve'!$E$5-Notional/$A27)/EurDeployed | C27: =(Notional/'Forward Curve'!$E$6-Notional/$A27)/EurDeployed | D27: =(Notional/'Forward Curve'!$E$7-Notional/$A27)/EurDeployed | E27: =(Notional/'Forward Curve'!$E$8-Notional/$A27)/EurDeployed | F27: =(Notional/'Forward Curve'!$E$9-Notional/$A27)/EurDeployed | G27: =(Notional/'Forward Curve'!$E$10-Notional/$A27)/EurDeployed | H27: =(Notional/'Forward Curve'!$E$11-Notional/$A27)/EurDeployed
A28: 1 | B28: =(Notional/'Forward Curve'!$E$5-Notional/$A28)/EurDeployed | C28: =(Notional/'Forward Curve'!$E$6-Notional/$A28)/EurDeployed | D28: =(Notional/'Forward Curve'!$E$7-Notional/$A28)/EurDeployed | E28: =(Notional/'Forward Curve'!$E$8-Notional/$A28)/EurDeployed | F28: =(Notional/'Forward Curve'!$E$9-Notional/$A28)/EurDeployed | G28: =(Notional/'Forward Curve'!$E$10-Notional/$A28)/EurDeployed | H28: =(Notional/'Forward Curve'!$E$11-Notional/$A28)/EurDeployed
A29: 1.05 | B29: =(Notional/'Forward Curve'!$E$5-Notional/$A29)/EurDeployed | C29: =(Notional/'Forward Curve'!$E$6-Notional/$A29)/EurDeployed | D29: =(Notional/'Forward Curve'!$E$7-Notional/$A29)/EurDeployed | E29: =(Notional/'Forward Curve'!$E$8-Notional/$A29)/EurDeployed | F29: =(Notional/'Forward Curve'!$E$9-Notional/$A29)/EurDeployed | G29: =(Notional/'Forward Curve'!$E$10-Notional/$A29)/EurDeployed | H29: =(Notional/'Forward Curve'!$E$11-Notional/$A29)/EurDeployed
A30: 1.1 | B30: =(Notional/'Forward Curve'!$E$5-Notional/$A30)/EurDeployed | C30: =(Notional/'Forward Curve'!$E$6-Notional/$A30)/EurDeployed | D30: =(Notional/'Forward Curve'!$E$7-Notional/$A30)/EurDeployed | E30: =(Notional/'Forward Curve'!$E$8-Notional/$A30)/EurDeployed | F30: =(Notional/'Forward Curve'!$E$9-Notional/$A30)/EurDeployed | G30: =(Notional/'Forward Curve'!$E$10-Notional/$A30)/EurDeployed | H30: =(Notional/'Forward Curve'!$E$11-Notional/$A30)/EurDeployed
A31: 1.15 | B31: =(Notional/'Forward Curve'!$E$5-Notional/$A31)/EurDeployed | C31: =(Notional/'Forward Curve'!$E$6-Notional/$A31)/EurDeployed | D31: =(Notional/'Forward Curve'!$E$7-Notional/$A31)/EurDeployed | E31: =(Notional/'Forward Curve'!$E$8-Notional/$A31)/EurDeployed | F31: =(Notional/'Forward Curve'!$E$9-Notional/$A31)/EurDeployed | G31: =(Notional/'Forward Curve'!$E$10-Notional/$A31)/EurDeployed | H31: =(Notional/'Forward Curve'!$E$11-Notional/$A31)/EurDeployed
A32: 1.2 | B32: =(Notional/'Forward Curve'!$E$5-Notional/$A32)/EurDeployed | C32: =(Notional/'Forward Curve'!$E$6-Notional/$A32)/EurDeployed | D32: =(Notional/'Forward Curve'!$E$7-Notional/$A32)/EurDeployed | E32: =(Notional/'Forward Curve'!$E$8-Notional/$A32)/EurDeployed | F32: =(Notional/'Forward Curve'!$E$9-Notional/$A32)/EurDeployed | G32: =(Notional/'Forward Curve'!$E$10-Notional/$A32)/EurDeployed | H32: =(Notional/'Forward Curve'!$E$11-Notional/$A32)/EurDeployed
A33: 1.25 | B33: =(Notional/'Forward Curve'!$E$5-Notional/$A33)/EurDeployed | C33: =(Notional/'Forward Curve'!$E$6-Notional/$A33)/EurDeployed | D33: =(Notional/'Forward Curve'!$E$7-Notional/$A33)/EurDeployed | E33: =(Notional/'Forward Curve'!$E$8-Notional/$A33)/EurDeployed | F33: =(Notional/'Forward Curve'!$E$9-Notional/$A33)/EurDeployed | G33: =(Notional/'Forward Curve'!$E$10-Notional/$A33)/EurDeployed | H33: =(Notional/'Forward Curve'!$E$11-Notional/$A33)/EurDeployed
A34: 1.3 | B34: =(Notional/'Forward Curve'!$E$5-Notional/$A34)/EurDeployed | C34: =(Notional/'Forward Curve'!$E$6-Notional/$A34)/EurDeployed | D34: =(Notional/'Forward Curve'!$E$7-Notional/$A34)/EurDeployed | E34: =(Notional/'Forward Curve'!$E$8-Notional/$A34)/EurDeployed | F34: =(Notional/'Forward Curve'!$E$9-Notional/$A34)/EurDeployed | G34: =(Notional/'Forward Curve'!$E$10-Notional/$A34)/EurDeployed | H34: =(Notional/'Forward Curve'!$E$11-Notional/$A34)/EurDeployed
A35: 1.35 | B35: =(Notional/'Forward Curve'!$E$5-Notional/$A35)/EurDeployed | C35: =(Notional/'Forward Curve'!$E$6-Notional/$A35)/EurDeployed | D35: =(Notional/'Forward Curve'!$E$7-Notional/$A35)/EurDeployed | E35: =(Notional/'Forward Curve'!$E$8-Notional/$A35)/EurDeployed | F35: =(Notional/'Forward Curve'!$E$9-Notional/$A35)/EurDeployed | G35: =(Notional/'Forward Curve'!$E$10-Notional/$A35)/EurDeployed | H35: =(Notional/'Forward Curve'!$E$11-Notional/$A35)/EurDeployed
A36: 1.4 | B36: =(Notional/'Forward Curve'!$E$5-Notional/$A36)/EurDeployed | C36: =(Notional/'Forward Curve'!$E$6-Notional/$A36)/EurDeployed | D36: =(Notional/'Forward Curve'!$E$7-Notional/$A36)/EurDeployed | E36: =(Notional/'Forward Curve'!$E$8-Notional/$A36)/EurDeployed | F36: =(Notional/'Forward Curve'!$E$9-Notional/$A36)/EurDeployed | G36: =(Notional/'Forward Curve'!$E$10-Notional/$A36)/EurDeployed | H36: =(Notional/'Forward Curve'!$E$11-Notional/$A36)/EurDeployed
A37: 1.45 | B37: =(Notional/'Forward Curve'!$E$5-Notional/$A37)/EurDeployed | C37: =(Notional/'Forward Curve'!$E$6-Notional/$A37)/EurDeployed | D37: =(Notional/'Forward Curve'!$E$7-Notional/$A37)/EurDeployed | E37: =(Notional/'Forward Curve'!$E$8-Notional/$A37)/EurDeployed | F37: =(Notional/'Forward Curve'!$E$9-Notional/$A37)/EurDeployed | G37: =(Notional/'Forward Curve'!$E$10-Notional/$A37)/EurDeployed | H37: =(Notional/'Forward Curve'!$E$11-Notional/$A37)/EurDeployed
A39: C · USD ASSET REVALUATION IN EUR
A40: =Notional/S - Notional/SpotNow. The offsetting gain or loss on the asset, which is unrealised and illiquid.
A41: EURUSD at maturity | B41: 3M | C41: 6M | D41: 1Y | E41: 2Y | F41: 3Y | G41: 5Y | H41: 7Y
A42: 0.85 | B42: =Notional/$A42-EurDeployed | C42: =Notional/$A42-EurDeployed | D42: =Notional/$A42-EurDeployed | E42: =Notional/$A42-EurDeployed | F42: =Notional/$A42-EurDeployed | G42: =Notional/$A42-EurDeployed | H42: =Notional/$A42-EurDeployed
A43: 0.9 | B43: =Notional/$A43-EurDeployed | C43: =Notional/$A43-EurDeployed | D43: =Notional/$A43-EurDeployed | E43: =Notional/$A43-EurDeployed | F43: =Notional/$A43-EurDeployed | G43: =Notional/$A43-EurDeployed | H43: =Notional/$A43-EurDeployed
...

Sheet Method
A1: Method
A3: The position | B3: A EUR-denominated fund holds a USD asset and sells USD forward against EUR to hedge it. Contract: sell USD N at rate K (EURUSD, USD per EUR). The fund receives EUR N/K at maturity.
A4: Hedge P&L | B4: At maturity spot S the delivered USD N is worth EUR N/S, so hedge P&L in EUR = N/K - N/S Negative when S < K, i.e. a strengthening dollar costs the hedge money.
A5: Asset revaluation | B5: The USD asset was worth EUR N/SpotNow at inception and EUR N/S at maturity, so asset revaluation = N/S - N/SpotNow
A6: Why grid D is flat | B6: Add them: (N/K - N/S) + (N/S - N/SpotNow) = N/K - N/SpotNow. The S terms cancel algebraically. The net depends only on the strike and the starting spot — never on where spot ends up. That is what a working hedge looks like, and it is why 'all that remains is the carry' is a correct statement about ECONOMICS.
A7: Why that is not a limit | B7: Grid A and grid D differ by grid C, which is the unrealised gain locked inside the asset. The dealer nets only what is inside the netting set; the asset is not in it. Settlement is in cash on grid A, not on grid D.
A8: Forward curve | B8: F = SpotNow x (1 + rUSD*T) / (1 + rEUR*T), simple interest, or the traded points where supplied. Override with traded points wherever you have them — the CIP forward ignores cross-currency basis.
A9: Scenario range | B9: 0.85 to 1.45 covers the realised EURUSD range of the last decade and then some: 1.39 in 2014, 0.96 in 2022.
A10: Source | B10: Built by build_scenario.py alongside HRR_FX_Framework.pdf. See manual sections 3, 7 and 19.
