Workbook

Sheet ReadMe
A1: Kaushik's KAC3 Factor Model — 10-Stock Universe, 3-Stock Portfolio
A3: PURPOSE
A4: A factor model is estimated once from a broad UNIVERSE of stocks (here, 10). That estimation
A5: produces two reusable outputs: (1) a factor covariance matrix, and (2) a specific-risk series
A6: for every stock in the universe. Any PORTFOLIO drawn from that universe — here, 3 stocks out
A7: of the 10 — can then have its risk computed by combining its own holdings' exposures with the
A8: universe-level factor covariance matrix. You never re-estimate the model per portfolio.
A10: TABS (in order)
A11: 1. Returns Dummy weekly returns, 10-stock universe, 3 years (156 weeks). INPUT.
A12: 2. Exposures Each universe stock's Market/Value/Momentum exposure + regression
A13: machinery: X'X, (X'X)^-1, P = X(X'X)^-1 (pure factor-portfolio weights).
A14: 3. CSR_FactorReturns Weekly cross-sectional regression across all 10 stocks: f_t = r_t' P.
... A52: where X_h = exposures of the HELD stocks only, F = universe factor covariance matrix.

Sheet Returns
A1: Date | B1: STK_A | C1: STK_B | D1: STK_C | E1: STK_D | F1: STK_E | G1: STK_F | H1: STK_G | I1: STK_H | J1: STK_I | K1: STK_J
A2: 44932 | B2: -0.016818 | C2: -0.067912 | D2: -0.046266 | E2: -0.051299 | F2: -0.053507 | G2: 0.005198 | H2: 0.004828 | I2: -0.055552 | J2: -0.041319 | K2: -0.078766
A3: =A2+7 -> 44939 | B3: -0.031246 | C3: -0.016621 | D3: -0.024494 | E3: -0.022123 | F3: -0.045531 | G3: -0.039814 | H3: -0.003658 | I3: 0.061567 | J3: 0.060647 | K3: -0.017235
A4: =A3+7 -> 44946 | B4: -0.02211 | C4: -0.000106 | D4: -0.024771 | E4: -0.019181 | F4: -0.006117 | G4: -0.050139 | H4: 0.029234 | I4: 0.01515 | J4: 0.016411 | K4: -0.004126
A5: =A4+7 -> 44953 | B5: -0.01702 | C5: -0.02079 | D5: -0.008345 | E5: -0.014201 | F5: 0.004046 | G5: -0.00081 | H5: -0.043955 | I5: 0.005131 | J5: -0.050721 | K5: -0.022849
A6: =A5+7 -> 44960 | B6: -0.013865 | C6: -0.05723 | D6: -0.011023 | E6: -0.031169 | F6: -0.020184 | G6: -0.01808 | H6: -0.052036 | I6: -0.063284 | J6: -0.061099 | K6: -0.05827
A7: =A6+7 -> 44967 | B7: -0.023885 | C7: -0.051219 | D7: -0.022108 | E7: -0.036889 | F7: -0.035555 | G7: -0.0515 | H7: -0.01245 | I7: -0.083098 | J7: -0.021188 | K7: -0.029609
A8: =A7+7 -> 44974 | B8: 0.010525 | C8: 0.018862 | D8: -0.030648 | E8: -0.040681 | F8: -0.001302 | G8: -0.006651 | H8: -0.008158 | I8: -0.035426 | J8: -0.016315 | K8: 0.00579
A9: =A8+7 -> 44981 | B9: 0.009579 | C9: -0.010657 | D9: -0.073127 | E9: -0.009254 | F9: -0.023503 | G9: -0.097186 | H9: -0.018812 | I9: -0.084329 | J9: -0.081482 | K9: -0.051622
A10: =A9+7 -> 44988 | B10: 0.030967 | C10: -0.006497 | D10: 0.006238 | E10: 0.02709 | F10: 0.027443 | G10: -0.013344 | H10: -0.00723 | I10: -0.041214 | J10: -0.029203 | K10: 0.007575
A11: =A10+7 -> 44995 | B11: 0.021653 | C11: 0.021203 | D11: 0.044189 | E11: -0.00957 | F11: 0.006213 | G11: 0.014772 | H11: 0.046101 | I11: 0.090448 | J11: 0.035827 | K11: 0.004379
A12: =A11+7 -> 45002 | B12: 0.015812 | C12: -0.01859 | D12: -0.049439 | E12: 0.020221 | F12: 0.006936 | G12: 0.022608 | H12: -0.050542 | I12: -0.018033 | J12: -0.017181 | K12: -0.021913
A13: =A12+7 -> 45009 | B13: -0.082296 | C13: -0.035952 | D13: 0.007432 | E13: -0.009647 | F13: -0.034346 | G13: -0.020354 | H13: 0.000261 | I13: -0.150464 | J13: -0.022747 | K13: -0.001106
A14: =A13+7 -> 45016 | B14: 0.024963 | C14: 0.054706 | D14: 0.049607 | E14: 0.024364 | F14: 0.015852 | G14: 0.014805 | H14: 0.02278 | I14: 0.04265 | J14: 0.072113 | K14: 0.091285
... A157: =A156+7 -> 46017 | B157: -0.079161 | C157: -0.024843 | D157: -0.034989 | E157: -0.039034 | F157: -0.053602 | G157: -0.062387 | H157: 0.002354 | I157: -0.046206 | J157: 0.025605 | K157: -0.07948
A159: Ann. Mean Return | B159: =AVERAGE(B2:B157)*52 -> -0.037985 | C159: =AVERAGE(C2:C157)*52 -> -0.41456933 | D159: =AVERAGE(D2:D157)*52 -> -0.23551933 | E159: =AVERAGE(E2:E157)*52 -> -0.026959333 | F159: =AVERAGE(F2:F157)*52 -> -0.237349 | G159: =AVERAGE(G2:G157)*52 -> -0.35732633 | H159: =AVERAGE(H2:H157)*52 -> -0.061311 | I159: =AVERAGE(I2:I157)*52 -> -0.39918233 | ... K159: =AVERAGE(K2:K157)*52 -> -0.32357233
A160: Ann. Volatility | B160: =_xlfn.STDEV.S(B2:B157)*SQRT(52) -> 0.27164579 | C160: =_xlfn.STDEV.S(C2:C157)*SQRT(52) -> 0.24085866 | D160: =_xlfn.STDEV.S(D2:D157)*SQRT(52) -> 0.28306558 | E160: =_xlfn.STDEV.S(E2:E157)*SQRT(52) -> 0.22032805 | F160: =_xlfn.STDEV.S(F2:F157)*SQRT(52) -> 0.2186354 | G160: =_xlfn.STDEV.S(G2:G157)*SQRT(52) -> 0.30490388 | H160: =_xlfn.STDEV.S(H2:H157)*SQRT(52) -> 0.26812042 | I160: =_xlfn.STDEV.S(I2:I157)*SQRT(52) -> 0.38257868 | ... K160: =_xlfn.STDEV.S(K2:K157)*SQRT(52) -> 0.27880681

Sheet Exposures
A1: Stock | B1: Market | C1: Value | D1: Momentum
A2: STK_A | B2: 1 | C2: 0.32 | D2: 1.09
A3: STK_B | B3: 1 | C3: 0.78 | D3: 0.93
A4: STK_C | B4: 1 | C4: -0.11 | D4: 0.63
A5: STK_D | B5: 1 | C5: -1.07 | D5: -0.59
A6: STK_E | B6: 1 | C6: -0.39 | D6: 0.47
A7: STK_F | B7: 1 | C7: -1.22 | D7: 1.33
A8: STK_G | B8: 1 | C8: 0.41 | D8: -1.08
A9: STK_H | B9: 1 | C9: 2.39 | D9: -0.03
A10: STK_I | B10: 1 | C10: -0.45 | D10: -1.74
A11: STK_J | B11: 1 | C11: -0.65 | D11: -1.01
A13: Regression machinery
A14: X = the 10x3 exposure table above (B2:D11).
A16: X'X (3x3)
B17: Market | C17: Value | D17: Momentum
B18: {=MMULT(TRANSPOSE(B2:D11),B2:D11)} -> 10 | C18: 0.01 | D18: 4.4408921e-16
B19: 0.01 | C19: 10.0135 | D19: 0.7553
B20: 4.4408921e-16 | C20: 0.7553 | D20: 10.0028
A22: (X'X)^-1 (3x3)
B23: Market | C23: Value | D23: Momentum
B24: {=MINVERSE(B18:D20)} -> 0.1000001 | C24: -0.00010043732 | D24: 7.5839075e-06
B25: -0.00010043732 | C25: 0.10043732 | D25: -0.0075839075
B26: 7.5839075e-06 | C26: -0.0075839075 | D26: 0.10054466
A28: P = X . (X'X)^-1 [pure factor-portfolio weights: rows=stocks, cols=Market/Value/Momentum]
A29: Column k of P is the set of universe stock weights whose portfolio return equals f_k every week: exposure 1 to factor k, exposure 0 to the other two. The weekly regression in CSR_FactorReturns uses this directly: f_t = r_t' P.
B31: Market | C31: Value | D31: Momentum
A32: STK_A | B32: {=MMULT(B2:D11,B24:D26)} -> 0.099976227 | C32: 0.023773047 | D32: 0.10717441
A33: STK_B | B33: 0.099928812 | C33: 0.07118764 | D33: 0.08759867
A34: STK_C | B34: 0.10001593 | C34: -0.015926405 | D34: 0.06418495
A35: STK_D | B35: 0.10010309 | C35: -0.10309387 | D35: -0.051198985
A36: STK_E | B36: 0.10004284 | C36: -0.04283543 | D36: 0.050221298
A37: STK_F | B37: 0.10013272 | C37: -0.13272057 | D37: 0.14298435
A38: STK_G | B38: 0.099950731 | C38: 0.049269485 | D38: -0.11169005
A39: STK_H | B39: 0.099759828 | C39: 0.24017228 | D39: -0.021134295
A40: STK_I | B40: 0.1000321 | C40: -0.032101233 | D40: -0.17152737
A41: STK_J | B41: 0.10005772 | C41: -0.05772495 | D41: -0.096612983

Sheet CSR_FactorReturns
A1: Date | B1: f_Market | C1: f_Value | D1: f_Momentum | F1: Fitted_A | G1: Fitted_B | H1: Fitted_C | I1: Fitted_D | J1: Fitted_E | K1: Fitted_F | L1: Fitted_G | M1: Fitted_H | N1: Fitted_I | O1: Fitted_J | Q1: Resid_A | R1: Resid_B | S1: Resid_C | T1: Resid_D | U1: Resid_E | V1: Resid_F | W1: Resid_G | X1: Resid_H | Y1: Resid_I | Z1: Resid_J
A2: =Returns!A2 -> 44932 | B2: {=MMULT(Returns!B2:K2,Exposures!$B$32:$D$41)} -> -0.040136462 | C2: -0.0048377562 | D2: 0.0052934276 | F2: =SUMPRODUCT($B2:$D2,Exposures!$B$2:$D$2) -> -0.035914708 | G2: =SUMPRODUCT($B2:$D2,Exposures!$B$3:$D$3) -> -0.038987024 | H2: =SUMPRODUCT($B2:$D2,Exposures!$B$4:$D$4) -> -0.03626945 | I2: =SUMPRODUCT($B2:$D2,Exposures!$B$5:$D$5) -> -0.038083185 | J2: =SUMPRODUCT($B2:$D2,Exposures!$B$6:$D$6) -> -0.035761826 | K2: =SUMPRODUCT($B2:$D2,Exposures!$B$7:$D$7) -> -0.027194141 | L2: =SUMPRODUCT($B2:$D2,Exposures!$B$8:$D$8) -> -0.047836844 | M2: =SUMPRODUCT($B2:$D2,Exposures!$B$9:$D$9) -> -0.051857502 | N2: =SUMPRODUCT($B2:$D2,Exposures!$B$10:$D$10) -> -0.047170036 | O2: =SUMPRODUCT($B2:$D2,Exposures!$B$11:$D$11) -> -0.042338283 | Q2: =Returns!B2-F2 -> 0.019096708 | R2: =Returns!C2-G2 -> -0.028924976 | S2: =Returns!D2-H2 -> -0.0099965503 | T2: =Returns!E2-I2 -> -0.013215815 | U2: =Returns!F2-J2 -> -0.017745174 | V2: =Returns!G2-K2 -> 0.032392141 | W2: =Returns!H2-L2 -> 0.052664844 | X2: =Returns!I2-M2 -> -0.0036944977 | ... Z2: =Returns!K2-O2 -> -0.036427717
A3: =Returns!A3 -> 44939 | B3: {=MMULT(Returns!B3:K3,Exposures!$B$32:$D$41)} -> -0.0078724338 | C3: 0.021633806 | D3: -0.022853733 | F3: =SUMPRODUCT($B3:$D3,Exposures!$B$2:$D$2) -> -0.025860185 | G3: =SUMPRODUCT($B3:$D3,Exposures!$B$3:$D$3) -> -0.012252037 | H3: =SUMPRODUCT($B3:$D3,Exposures!$B$4:$D$4) -> -0.024650005 | I3: =SUMPRODUCT($B3:$D3,Exposures!$B$5:$D$5) -> -0.017536904 | J3: =SUMPRODUCT($B3:$D3,Exposures!$B$6:$D$6) -> -0.027050873 | K3: =SUMPRODUCT($B3:$D3,Exposures!$B$7:$D$7) -> -0.064661143 | L3: =SUMPRODUCT($B3:$D3,Exposures!$B$8:$D$8) -> 0.025679459 | M3: =SUMPRODUCT($B3:$D3,Exposures!$B$9:$D$9) -> 0.044517975 | N3: =SUMPRODUCT($B3:$D3,Exposures!$B$10:$D$10) -> 0.022157849 | O3: =SUMPRODUCT($B3:$D3,Exposures!$B$11:$D$11) -> 0.0011478628 | Q3: =Returns!B3-F3 -> -0.0053858149 | R3: =Returns!C3-G3 -> -0.0043689631 | S3: =Returns!D3-H3 -> 0.0001560045 | T3: =Returns!E3-I3 -> -0.0045860962 | U3: =Returns!F3-J3 -> -0.018480127 | V3: =Returns!G3-K3 -> 0.024847143 | W3: =Returns!H3-L3 -> -0.029337459 | X3: =Returns!I3-M3 -> 0.017049025 | ... Z3: =Returns!K3-O3 -> -0.018382863
A4: =Returns!A4 -> 44946 | B4: {=MMULT(Returns!B4:K4,Exposures!$B$32:$D$41)} -> -0.0065890456 | C4: 0.013545603 | D4: -0.016464727 | F4: =SUMPRODUCT($B4:$D4,Exposures!$B$2:$D$2) -> -0.020201005 | G4: =SUMPRODUCT($B4:$D4,Exposures!$B$3:$D$3) -> -0.011335671 | H4: =SUMPRODUCT($B4:$D4,Exposures!$B$4:$D$4) -> -0.01845184 | I4: =SUMPRODUCT($B4:$D4,Exposures!$B$5:$D$5) -> -0.011368652 | J4: =SUMPRODUCT($B4:$D4,Exposures!$B$6:$D$6) -> -0.019610253 | K4: =SUMPRODUCT($B4:$D4,Exposures!$B$7:$D$7) -> -0.045012769 | L4: =SUMPRODUCT($B4:$D4,Exposures!$B$8:$D$8) -> 0.016746557 | M4: =SUMPRODUCT($B4:$D4,Exposures!$B$9:$D$9) -> 0.026278888 | N4: =SUMPRODUCT($B4:$D4,Exposures!$B$10:$D$10) -> 0.015964058 | O4: =SUMPRODUCT($B4:$D4,Exposures!$B$11:$D$11) -> 0.0012356868 | Q4: =Returns!B4-F4 -> -0.0019089947 | R4: =Returns!C4-G4 -> 0.011229671 | S4: =Returns!D4-H4 -> -0.0063191598 | T4: =Returns!E4-I4 -> -0.0078123479 | U4: =Returns!F4-J4 -> 0.013493253 | V4: =Returns!G4-K4 -> -0.005126231 | W4: =Returns!H4-L4 -> 0.012487443 | X4: =Returns!I4-M4 -> -0.011128888 | ... Z4: =Returns!K4-O4 -> -0.0053616868
A5: =Returns!A5 -> 44953 | B5: {=MMULT(Returns!B5:K5,Exposures!$B$32:$D$41)} -> -0.01695306 | C5: 0.0016603729 | D5: 0.012341992 | F5: =SUMPRODUCT($B5:$D5,Exposures!$B$2:$D$2) -> -0.0029689695 | G5: =SUMPRODUCT($B5:$D5,Exposures!$B$3:$D$3) -> -0.0041799167 | H5: =SUMPRODUCT($B5:$D5,Exposures!$B$4:$D$4) -> -0.0093602463 | I5: =SUMPRODUCT($B5:$D5,Exposures!$B$5:$D$5) -> -0.026011435 | J5: =SUMPRODUCT($B5:$D5,Exposures!$B$6:$D$6) -> -0.011799869 | K5: =SUMPRODUCT($B5:$D5,Exposures!$B$7:$D$7) -> -0.0025638656 | L5: =SUMPRODUCT($B5:$D5,Exposures!$B$8:$D$8) -> -0.029601659 | M5: =SUMPRODUCT($B5:$D5,Exposures!$B$9:$D$9) -> -0.013355029 | N5: =SUMPRODUCT($B5:$D5,Exposures!$B$10:$D$10) -> -0.039175295 | O5: =SUMPRODUCT($B5:$D5,Exposures!$B$11:$D$11) -> -0.030497715 | Q5: =Returns!B5-F5 -> -0.014051031 | R5: =Returns!C5-G5 -> -0.016610083 | S5: =Returns!D5-H5 -> 0.0010152463 | T5: =Returns!E5-I5 -> 0.011810435 | U5: =Returns!F5-J5 -> 0.015845869 | V5: =Returns!G5-K5 -> 0.0017538656 | W5: =Returns!H5-L5 -> -0.014353341 | X5: =Returns!I5-M5 -> 0.018486029 | ... Z5: =Returns!K5-O5 -> 0.0076487149
A6: =Returns!A6 -> 44960 | B6: {=MMULT(Returns!B6:K6,Exposures!$B$32:$D$41)} -> -0.038613812 | C6: -0.010188478 | D6: 0.014049397 | F6: =SUMPRODUCT($B6:$D6,Exposures!$B$2:$D$2) -> -0.026560282 | G6: =SUMPRODUCT($B6:$D6,Exposures!$B$3:$D$3) -> -0.033494885 | H6: =SUMPRODUCT($B6:$D6,Exposures!$B$4:$D$4) -> -0.028641959 | I6: =SUMPRODUCT($B6:$D6,Exposures!$B$5:$D$5) -> -0.036001285 | J6: =SUMPRODUCT($B6:$D6,Exposures!$B$6:$D$6) -> -0.028037089 | K6: =SUMPRODUCT($B6:$D6,Exposures!$B$7:$D$7) -> -0.0074981709 | L6: =SUMPRODUCT($B6:$D6,Exposures!$B$8:$D$8) -> -0.057964436 | M6: =SUMPRODUCT($B6:$D6,Exposures!$B$9:$D$9) -> -0.063385755 | N6: =SUMPRODUCT($B6:$D6,Exposures!$B$10:$D$10) -> -0.058474947 | O6: =SUMPRODUCT($B6:$D6,Exposures!$B$11:$D$11) -> -0.046181192 | Q6: =Returns!B6-F6 -> 0.012695282 | R6: =Returns!C6-G6 -> -0.023735115 | S6: =Returns!D6-H6 -> 0.017618959 | T6: =Returns!E6-I6 -> 0.0048322846 | U6: =Returns!F6-J6 -> 0.0078530887 | V6: =Returns!G6-K6 -> -0.010581829 | W6: =Returns!H6-L6 -> 0.005928436 | X6: =Returns!I6-M6 -> 0.00010175511 | ... Z6: =Returns!K6-O6 -> -0.012088808
A7: =Returns!A7 -> 44967 | B7: {=MMULT(Returns!B7:K7,Exposures!$B$32:$D$41)} -> -0.036740217 | C7: -0.0098826277 | D7: -0.0060845165 | F7: =SUMPRODUCT($B7:$D7,Exposures!$B$2:$D$2) -> -0.046534781 | G7: =SUMPRODUCT($B7:$D7,Exposures!$B$3:$D$3) -> -0.050107267 | H7: =SUMPRODUCT($B7:$D7,Exposures!$B$4:$D$4) -> -0.039486374 | I7: =SUMPRODUCT($B7:$D7,Exposures!$B$5:$D$5) -> -0.022575941 | J7: =SUMPRODUCT($B7:$D7,Exposures!$B$6:$D$6) -> -0.035745715 | K7: =SUMPRODUCT($B7:$D7,Exposures!$B$7:$D$7) -> -0.032775818 | L7: =SUMPRODUCT($B7:$D7,Exposures!$B$8:$D$8) -> -0.034220817 | M7: =SUMPRODUCT($B7:$D7,Exposures!$B$9:$D$9) -> -0.060177162 | N7: =SUMPRODUCT($B7:$D7,Exposures!$B$10:$D$10) -> -0.021705976 | O7: =SUMPRODUCT($B7:$D7,Exposures!$B$11:$D$11) -> -0.024171148 | Q7: =Returns!B7-F7 -> 0.022649781 | R7: =Returns!C7-G7 -> -0.0011117327 | S7: =Returns!D7-H7 -> 0.017378374 | T7: =Returns!E7-I7 -> -0.014313059 | U7: =Returns!F7-J7 -> 0.00019071531 | V7: =Returns!G7-K7 -> -0.018724182 | W7: =Returns!H7-L7 -> 0.021770817 | X7: =Returns!I7-M7 -> -0.022920838 | ... Z7: =Returns!K7-O7 -> -0.0054378523
A8: =Returns!A8 -> 44974 | B8: {=MMULT(Returns!B8:K8,Exposures!$B$32:$D$41)} -> -0.010398893 | C8: -0.0015072567 | D8: 0.0057785561 | F8: =SUMPRODUCT($B8:$D8,Exposures!$B$2:$D$2) -> -0.0045825887 | G8: =SUMPRODUCT($B8:$D8,Exposures!$B$3:$D$3) -> -0.0062004958 | H8: =SUMPRODUCT($B8:$D8,Exposures!$B$4:$D$4) -> -0.0065926042 | I8: =SUMPRODUCT($B8:$D8,Exposures!$B$5:$D$5) -> -0.012195476 | J8: =SUMPRODUCT($B8:$D8,Exposures!$B$6:$D$6) -> -0.0070951413 | K8: =SUMPRODUCT($B8:$D8,Exposures!$B$7:$D$7) -> -0.00087456001 | L8: =SUMPRODUCT($B8:$D8,Exposures!$B$8:$D$8) -> -0.017257709 | M8: =SUMPRODUCT($B8:$D8,Exposures!$B$9:$D$9) -> -0.014174593 | N8: =SUMPRODUCT($B8:$D8,Exposures!$B$10:$D$10) -> -0.019775315 | O8: =SUMPRODUCT($B8:$D8,Exposures!$B$11:$D$11) -> -0.015255518 | Q8: =Returns!B8-F8 -> 0.015107589 | R8: =Returns!C8-G8 -> 0.025062496 | S8: =Returns!D8-H8 -> -0.024055396 | T8: =Returns!E8-I8 -> -0.028485524 | U8: =Returns!F8-J8 -> 0.0057931413 | V8: =Returns!G8-K8 -> -0.00577644 | W8: =Returns!H8-L8 -> 0.0090997086 | X8: =Returns!I8-M8 -> -0.021251407 | ... Z8: =Returns!K8-O8 -> 0.021045518
A9: =Returns!A9 -> 44981 | B9: {=MMULT(Returns!B9:K9,Exposures!$B$32:$D$41)} -> -0.044039208 | C9: -9.169736e-05 | D9: 0.0036438946 | F9: =SUMPRODUCT($B9:$D9,Exposures!$B$2:$D$2) -> -0.040096706 | G9: =SUMPRODUCT($B9:$D9,Exposures!$B$3:$D$3) -> -0.04072191 | H9: =SUMPRODUCT($B9:$D9,Exposures!$B$4:$D$4) -> -0.041733468 | I9: =SUMPRODUCT($B9:$D9,Exposures!$B$5:$D$5) -> -0.04609099 | J9: =SUMPRODUCT($B9:$D9,Exposures!$B$6:$D$6) -> -0.042290816 | K9: =SUMPRODUCT($B9:$D9,Exposures!$B$7:$D$7) -> -0.039080958 | L9: =SUMPRODUCT($B9:$D9,Exposures!$B$8:$D$8) -> -0.04801221 | M9: =SUMPRODUCT($B9:$D9,Exposures!$B$9:$D$9) -> -0.044367682 | N9: =SUMPRODUCT($B9:$D9,Exposures!$B$10:$D$10) -> -0.050338321 | O9: =SUMPRODUCT($B9:$D9,Exposures!$B$11:$D$11) -> -0.047659939 | Q9: =Returns!B9-F9 -> 0.049675706 | R9: =Returns!C9-G9 -> 0.03006491 | S9: =Returns!D9-H9 -> -0.031393532 | T9: =Returns!E9-I9 -> 0.03683699 | U9: =Returns!F9-J9 -> 0.018787816 | V9: =Returns!G9-K9 -> -0.058105042 | W9: =Returns!H9-L9 -> 0.02920021 | X9: =Returns!I9-M9 -> -0.039961318 | ... Z9: =Returns!K9-O9 -> -0.0039620614
A10: =Returns!A10 -> 44988 | B10: {=MMULT(Returns!B10:K10,Exposures!$B$32:$D$41)} -> 0.00019427749 | C10: -0.01177749 | D10: 0.0071892049 | F10: =SUMPRODUCT($B10:$D10,Exposures!$B$2:$D$2) -> 0.0042617139 | G10: =SUMPRODUCT($B10:$D10,Exposures!$B$3:$D$3) -> -0.0023062044 | H10: =SUMPRODUCT($B10:$D10,Exposures!$B$4:$D$4) -> 0.0060190005 | I10: =SUMPRODUCT($B10:$D10,Exposures!$B$5:$D$5) -> 0.0085545613 | J10: =SUMPRODUCT($B10:$D10,Exposures!$B$6:$D$6) -> 0.008166425 | K10: =SUMPRODUCT($B10:$D10,Exposures!$B$7:$D$7) -> 0.024124458 | L10: =SUMPRODUCT($B10:$D10,Exposures!$B$8:$D$8) -> -0.012398835 | M10: =SUMPRODUCT($B10:$D10,Exposures!$B$9:$D$9) -> -0.0281696 | N10: =SUMPRODUCT($B10:$D10,Exposures!$B$10:$D$10) -> -0.0070150683 | O10: =SUMPRODUCT($B10:$D10,Exposures!$B$11:$D$11) -> 0.00058854928 | Q10: =Returns!B10-F10 -> 0.026705286 | R10: =Returns!C10-G10 -> -0.0041907956 | S10: =Returns!D10-H10 -> 0.00021899951 | T10: =Returns!E10-I10 -> 0.018535439 | U10: =Returns!F10-J10 -> 0.019276575 | V10: =Returns!G10-K10 -> -0.037468458 | W10: =Returns!H10-L10 -> 0.0051688348 | X10: =Returns!I10-M10 -> -0.0130444 | ... Z10: =Returns!K10-O10 -> 0.0069864507
A11: =Returns!A11 -> 44995 | B11: {=MMULT(Returns!B11:K11,Exposures!$B$32:$D$41)} -> 0.027498828 | C11: 0.022671908 | D11: -0.003700522 | F11: =SUMPRODUCT($B11:$D11,Exposures!$B$2:$D$2) -> 0.030720269 | G11: =SUMPRODUCT($B11:$D11,Exposures!$B$3:$D$3) -> 0.04174143 | H11: =SUMPRODUCT($B11:$D11,Exposures!$B$4:$D$4) -> 0.022673589 | I11: =SUMPRODUCT($B11:$D11,Exposures!$B$5:$D$5) -> 0.005423195 | J11: =SUMPRODUCT($B11:$D11,Exposures!$B$6:$D$6) -> 0.016917539 | K11: =SUMPRODUCT($B11:$D11,Exposures!$B$7:$D$7) -> -0.0050825934 | L11: =SUMPRODUCT($B11:$D11,Exposures!$B$8:$D$8) -> 0.040790874 | M11: =SUMPRODUCT($B11:$D11,Exposures!$B$9:$D$9) -> 0.081795703 | N11: =SUMPRODUCT($B11:$D11,Exposures!$B$10:$D$10) -> 0.023735378 | O11: =SUMPRODUCT($B11:$D11,Exposures!$B$11:$D$11) -> 0.016499615 | Q11: =Returns!B11-F11 -> -0.0090672695 | R11: =Returns!C11-G11 -> -0.02053843 | S11: =Returns!D11-H11 -> 0.021515411 | T11: =Returns!E11-I11 -> -0.014993195 | U11: =Returns!F11-J11 -> -0.010704539 | V11: =Returns!G11-K11 -> 0.019854593 | W11: =Returns!H11-L11 -> 0.005310126 | X11: =Returns!I11-M11 -> 0.0086522973 | ... Z11: =Returns!K11-O11 -> -0.012120615
A12: =Returns!A12 -> 45002 | B12: {=MMULT(Returns!B12:K12,Exposures!$B$32:$D$41)} -> -0.011001553 | C12: -0.010547154 | D12: 0.010528819 | F12: =SUMPRODUCT($B12:$D12,Exposures!$B$2:$D$2) -> -0.0029002301 | G12: =SUMPRODUCT($B12:$D12,Exposures!$B$3:$D$3) -> -0.0094365321 | H12: =SUMPRODUCT($B12:$D12,Exposures!$B$4:$D$4) -> -0.0032082102 | I12: =SUMPRODUCT($B12:$D12,Exposures!$B$5:$D$5) -> -0.0059281005 | J12: =SUMPRODUCT($B12:$D12,Exposures!$B$6:$D$6) -> -0.0019396179 | K12: =SUMPRODUCT($B12:$D12,Exposures!$B$7:$D$7) -> 0.015869304 | L12: =SUMPRODUCT($B12:$D12,Exposures!$B$8:$D$8) -> -0.02669701 | M12: =SUMPRODUCT($B12:$D12,Exposures!$B$9:$D$9) -> -0.036525117 | N12: =SUMPRODUCT($B12:$D12,Exposures!$B$10:$D$10) -> -0.024575478 | O12: =SUMPRODUCT($B12:$D12,Exposures!$B$11:$D$11) -> -0.014780009 | Q12: =Returns!B12-F12 -> 0.01871223 | R12: =Returns!C12-G12 -> -0.0091534679 | S12: =Returns!D12-H12 -> -0.04623079 | T12: =Returns!E12-I12 -> 0.026149101 | U12: =Returns!F12-J12 -> 0.0088756179 | V12: =Returns!G12-K12 -> 0.0067386958 | W12: =Returns!H12-L12 -> -0.02384499 | X12: =Returns!I12-M12 -> 0.018492117 | ... Z12: =Returns!K12-O12 -> -0.0071329909
A13: =Returns!A13 -> 45009 | B13: {=MMULT(Returns!B13:K13,Exposures!$B$32:$D$41)} -> -0.034887103 | C13: -0.034797335 | D13: -0.0084742515 | F13: =SUMPRODUCT($B13:$D13,Exposures!$B$2:$D$2) -> -0.055259184 | G13: =SUMPRODUCT($B13:$D13,Exposures!$B$3:$D$3) -> -0.069910078 | H13: =SUMPRODUCT($B13:$D13,Exposures!$B$4:$D$4) -> -0.036398174 | I13: =SUMPRODUCT($B13:$D13,Exposures!$B$5:$D$5) -> 0.0073458545 | J13: =SUMPRODUCT($B13:$D13,Exposures!$B$6:$D$6) -> -0.02529904 | K13: =SUMPRODUCT($B13:$D13,Exposures!$B$7:$D$7) -> -0.0037051081 | L13: =SUMPRODUCT($B13:$D13,Exposures!$B$8:$D$8) -> -0.040001819 | M13: =SUMPRODUCT($B13:$D13,Exposures!$B$9:$D$9) -> -0.11779851 | N13: =SUMPRODUCT($B13:$D13,Exposures!$B$10:$D$10) -> -0.0044831042 | O13: =SUMPRODUCT($B13:$D13,Exposures!$B$11:$D$11) -> -0.0037098407 | Q13: =Returns!B13-F13 -> -0.027036816 | R13: =Returns!C13-G13 -> 0.033958078 | S13: =Returns!D13-H13 -> 0.043830174 | T13: =Returns!E13-I13 -> -0.016992854 | U13: =Returns!F13-J13 -> -0.0090469599 | V13: =Returns!G13-K13 -> -0.016648892 | W13: =Returns!H13-L13 -> 0.040262819 | X13: =Returns!I13-M13 -> -0.032665494 | ... Z13: =Returns!K13-O13 -> 0.0026038407
... A157: =Returns!A157 -> 46017 | B157: {=MMULT(Returns!B157:K157,Exposures!$B$32:$D$41)} -> -0.039178592 | C157: 0.004291712 | D157: -0.018519386 | F157: =SUMPRODUCT($B157:$D157,Exposures!$B$2:$D$2) -> -0.057991374 | G157: =SUMPRODUCT($B157:$D157,Exposures!$B$3:$D$3) -> -0.053054085 | H157: =SUMPRODUCT($B157:$D157,Exposures!$B$4:$D$4) -> -0.051317893 | I157: =SUMPRODUCT($B157:$D157,Exposures!$B$5:$D$5) -> -0.032844286 | J157: =SUMPRODUCT($B157:$D157,Exposures!$B$6:$D$6) -> -0.049556471 | K157: =SUMPRODUCT($B157:$D157,Exposures!$B$7:$D$7) -> -0.069045263 | L157: =SUMPRODUCT($B157:$D157,Exposures!$B$8:$D$8) -> -0.017418053 | M157: =SUMPRODUCT($B157:$D157,Exposures!$B$9:$D$9) -> -0.028365819 | N157: =SUMPRODUCT($B157:$D157,Exposures!$B$10:$D$10) -> -0.0088861312 | O157: =SUMPRODUCT($B157:$D157,Exposures!$B$11:$D$11) -> -0.023263625 | Q157: =Returns!B157-F157 -> -0.021169626 | R157: =Returns!C157-G157 -> 0.028211085 | S157: =Returns!D157-H157 -> 0.016328893 | T157: =Returns!E157-I157 -> -0.006189714 | U157: =Returns!F157-J157 -> -0.0040455294 | V157: =Returns!G157-K157 -> 0.0066582631 | W157: =Returns!H157-L157 -> 0.019772053 | X157: =Returns!I157-M157 -> -0.017840181 | ... Z157: =Returns!K157-O157 -> -0.056216375

Sheet FactorCovariance
A1: Weekly Factor Covariance Matrix
B2: Market | C2: Value | D2: Momentum
A3: Market | B3: =_xlfn.COVARIANCE.S(CSR_FactorReturns!$B$2:$B$157,CSR_FactorReturns!$B$2:$B$157) -> 0.00054731675 | C3: =_xlfn.COVARIANCE.S(CSR_FactorReturns!$B$2:$B$157,CSR_FactorReturns!$C$2:$C$157) -> 2.7162732e-05 | D3: =_xlfn.COVARIANCE.S(CSR_FactorReturns!$B$2:$B$157,CSR_FactorReturns!$D$2:$D$157) -> -1.4110986e-05
A4: Value | B4: =_xlfn.COVARIANCE.S(CSR_FactorReturns!$C$2:$C$157,CSR_FactorReturns!$B$2:$B$157) -> 2.7162732e-05 | C4: =_xlfn.COVARIANCE.S(CSR_FactorReturns!$C$2:$C$157,CSR_FactorReturns!$C$2:$C$157) -> 0.00022457246 | D4: =_xlfn.COVARIANCE.S(CSR_FactorReturns!$C$2:$C$157,CSR_FactorReturns!$D$2:$D$157) -> -3.7604795e-05
A5: Momentum | B5: =_xlfn.COVARIANCE.S(CSR_FactorReturns!$D$2:$D$157,CSR_FactorReturns!$B$2:$B$157) -> -1.4110986e-05 | C5: =_xlfn.COVARIANCE.S(CSR_FactorReturns!$D$2:$D$157,CSR_FactorReturns!$C$2:$C$157) -> -3.7604795e-05 | D5: =_xlfn.COVARIANCE.S(CSR_FactorReturns!$D$2:$D$157,CSR_FactorReturns!$D$2:$D$157) -> 0.0002334485
A8: Annualized Factor Covariance Matrix (x 52, iid weekly assumption)
B9: Market | C9: Value | D9: Momentum
A10: Market | B10: =B3*52 -> 0.028460471 | C10: =C3*52 -> 0.0014124621 | D10: =D3*52 -> -0.00073377126
A11: Value | B11: =B4*52 -> 0.0014124621 | C11: =C4*52 -> 0.011677768 | D11: =D4*52 -> -0.0019554493
A12: Momentum | B12: =B5*52 -> -0.00073377126 | C12: =C5*52 -> -0.0019554493 | D12: =D5*52 -> 0.012139322
A14: Annualized Factor Volatility
B15: Market | C15: Value | D15: Momentum
B16: =SQRT(B10) -> 0.16870231 | C16: =SQRT(C11) -> 0.10806372 | D16: =SQRT(D12) -> 0.11017859
A18: Factor Correlation Matrix
B19: Market | C19: Value | D19: Momentum
A20: Market | B20: =CORREL(CSR_FactorReturns!$B$2:$B$157,CSR_FactorReturns!$B$2:$B$157) -> 1 | C20: =CORREL(CSR_FactorReturns!$B$2:$B$157,CSR_FactorReturns!$C$2:$C$157) -> 0.07747754 | D20: =CORREL(CSR_FactorReturns!$B$2:$B$157,CSR_FactorReturns!$D$2:$D$157) -> -0.039476845
A21: Value | B21: =CORREL(CSR_FactorReturns!$C$2:$C$157,CSR_FactorReturns!$B$2:$B$157) -> 0.07747754 | C21: =CORREL(CSR_FactorReturns!$C$2:$C$157,CSR_FactorReturns!$C$2:$C$157) -> 1 | D21: =CORREL(CSR_FactorReturns!$C$2:$C$157,CSR_FactorReturns!$D$2:$D$157) -> -0.1642364
A22: Momentum | B22: =CORREL(CSR_FactorReturns!$D$2:$D$157,CSR_FactorReturns!$B$2:$B$157) -> -0.039476845 | C22: =CORREL(CSR_FactorReturns!$D$2:$D$157,CSR_FactorReturns!$C$2:$C$157) -> -0.1642364 | D22: =CORREL(CSR_FactorReturns!$D$2:$D$157,CSR_FactorReturns!$D$2:$D$157) -> 1

Sheet PortfolioRisk
A1: Portfolio Holdings (3 of the 10-stock estimation universe)
A2: Exposures below are LOOKED UP from the Exposures tab (INDEX/MATCH) — you never retype a held stock's factor profile, you just point at the universe table.
A4: Stock | B4: Weight | C4: Market | D4: Value | E4: Momentum
A5: STK_C | B5: 0.45 | C5: =INDEX(Exposures!$B$2:$B$11,MATCH($A5,Exposures!$A$2:$A$11,0)) -> 1 | D5: =INDEX(Exposures!$C$2:$C$11,MATCH($A5,Exposures!$A$2:$A$11,0)) -> -0.11 | E5: =INDEX(Exposures!$D$2:$D$11,MATCH($A5,Exposures!$A$2:$A$11,0)) -> 0.63
A6: STK_F | B6: 0.35 | C6: =INDEX(Exposures!$B$2:$B$11,MATCH($A6,Exposures!$A$2:$A$11,0)) -> 1 | D6: =INDEX(Exposures!$C$2:$C$11,MATCH($A6,Exposures!$A$2:$A$11,0)) -> -1.22 | E6: =INDEX(Exposures!$D$2:$D$11,MATCH($A6,Exposures!$A$2:$A$11,0)) -> 1.33
A7: STK_I | B7: 0.2 | C7: =INDEX(Exposures!$B$2:$B$11,MATCH($A7,Exposures!$A$2:$A$11,0)) -> 1 | D7: =INDEX(Exposures!$C$2:$C$11,MATCH($A7,Exposures!$A$2:$A$11,0)) -> -0.45 | E7: =INDEX(Exposures!$D$2:$D$11,MATCH($A7,Exposures!$A$2:$A$11,0)) -> -1.74
A9: Check (should = 100%) | B9: =SUM(B5:B7) -> 1
A11: Portfolio Factor Exposure (weighted holdings) | H11: Factor Contribution to Risk (Euler decomposition)
D12: Market | E12: Value | F12: Momentum | H12: Factor | I12: Marginal Contrib. | J12: Contribution to Variance
D13: =SUMPRODUCT($B$5:$B$7,C$5:C$7) -> 1 | E13: =SUMPRODUCT($B$5:$B$7,D$5:D$7) -> -0.5665 | F13: =SUMPRODUCT($B$5:$B$7,E$5:E$7) -> 0.401 | H13: Market | I13: {=MMULT(FactorCovariance!$B$10:$D$12,TRANSPOSE(D13:F13))} -> 0.027366069 | J13: =D13*I13 -> 0.027366069
H14: Value | I14: -0.0059871288 | J14: =E13*I14 -> 0.0033917084
A15: Factor Risk (annualized variance, X_p' F X_p) | H15: Momentum | I15: 0.0052418589 | J15: =F13*I15 -> 0.0021019854
A16: Factor variance = | B16: {=MMULT(MMULT(D13:F13,FactorCovariance!$B$10:$D$12),TRANSPOSE(D13:F13))} -> 0.032859763 | H16: Sum (check vs Factor variance) | J16: =SUM(J13:J15) -> 0.032859763
A18: Specific Risk (per held stock, from CSR residual variance)
A19: Each stock's residual column in CSR_FactorReturns is found dynamically via MATCH on the header row ("Resid_<letter>"), keyed off the stock code typed in the Holdings table above — change a holding and this re-points automatically.
A20: Stock | B20: Ann. Specific Variance
A21: =A5 -> STK_C | B21: =_xlfn.VAR.S(INDEX(CSR_FactorReturns!$Q$2:$Z$157,0,MATCH("Resid_"&RIGHT(A21,1),CSR_FactorReturns!$Q$1:$Z$1,0)))*52 -> 0.041054427
A22: =A6 -> STK_F | B22: =_xlfn.VAR.S(INDEX(CSR_FactorReturns!$Q$2:$Z$157,0,MATCH("Resid_"&RIGHT(A22,1),CSR_FactorReturns!$Q$1:$Z$1,0)))*52 -> 0.029749612
A23: =A7 -> STK_I | B23: =_xlfn.VAR.S(INDEX(CSR_FactorReturns!$Q$2:$Z$157,0,MATCH("Resid_"&RIGHT(A23,1),CSR_FactorReturns!$Q$1:$Z$1,0)))*52 -> 0.031600535
A25: Portfolio specific variance (assumes zero residual cross-correlation) | B25: =SUMPRODUCT(B5:B7^2,B21:B23) -> 0.01322187
A27: Total Portfolio Risk
A28: Total variance (factor + specific) | B28: =B16+B25 -> 0.046081633
A29: Total annualized volatility | B29: =SQRT(B28) -> 0.21466633
A31: Risk decomposition
A32: Factor risk % of total variance | B32: =B16/B28 -> 0.71307722
A33: Specific risk % of total variance | B33: =B25/B28 -> 0.28692278

Sheet KAC3_Refinements
A1: KAC3 Refinements — Applying the Methodology Notes to This Model
A3: This tab layers four concrete refinements from my Kaushik_KAC3_Risk_Model_Methodology_Notes.pdf onto
A4: the original 10-stock / 3-factor cross-sectional regression example. Each section reads from the
A5: existing Returns / Exposures / CSR_FactorReturns / FactorCovariance tabs without modifying them.
A7: (A) Inverse-Residual-Variance Regression Weighting
A8: Traditional practice weights the cross-sectional regression by sqrt(market cap). The weighting that
A9: minimizes the noise of the factor-return estimate is inverse residual variance instead. Below: each
A10: universe stock's OLS specific variance (from the original regression's residuals), the implied WLS
A11: weight, and a re-estimated pure-factor-portfolio matrix used to compute WLS factor returns.
A13: Stock | B13: OLS Ann. Specific Var | C13: WLS Weight (=1/Var) | H13: X scaled by WLS weight (helper)
A14: STK_A | B14: =_xlfn.VAR.S(CSR_FactorReturns!Q2:Q157)*52 -> 0.028717601 | C14: =1/B14 -> 34.82185 | H14: {=Exposures!$B2:$D2*$C14} -> 34.82185 | I14: 11.142992 | J14: 37.955817
A15: STK_B | B15: =_xlfn.VAR.S(CSR_FactorReturns!R2:R157)*52 -> 0.028119684 | C15: =1/B15 -> 35.562277 | H15: {=Exposures!$B3:$D3*$C15} -> 35.562277 | I15: 27.738576 | J15: 33.072918
A16: STK_C | B16: =_xlfn.VAR.S(CSR_FactorReturns!S2:S157)*52 -> 0.041054427 | C16: =1/B16 -> 24.357909 | H16: {=Exposures!$B4:$D4*$C16} -> 24.357909 | I16: -2.67937 | J16: 15.345483
A17: STK_D | B17: =_xlfn.VAR.S(CSR_FactorReturns!T2:T157)*52 -> 0.026658821 | C17: =1/B17 -> 37.511037 | H17: {=Exposures!$B5:$D5*$C17} -> 37.511037 | I17: -40.136809 | J17: -22.131512
A18: STK_E | B18: =_xlfn.VAR.S(CSR_FactorReturns!U2:U157)*52 -> 0.022124368 | C18: =1/B18 -> 45.199031 | H18: {=Exposures!$B6:$D6*$C18} -> 45.199031 | I18: -17.627622 | J18: 21.243544
A19: STK_F | B19: =_xlfn.VAR.S(CSR_FactorReturns!V2:V157)*52 -> 0.029749612 | C19: =1/B19 -> 33.613884 | H19: {=Exposures!$B7:$D7*$C19} -> 33.613884 | I19: -41.008939 | J19: 44.706466
A20: STK_G | B20: =_xlfn.VAR.S(CSR_FactorReturns!W2:W157)*52 -> 0.03194561 | C20: =1/B20 -> 31.303205 | H20: {=Exposures!$B8:$D8*$C20} -> 31.303205 | I20: 12.834314 | J20: -33.807462
A21: STK_H | B21: =_xlfn.VAR.S(CSR_FactorReturns!X2:X157)*52 -> 0.017829636 | C21: =1/B21 -> 56.086394 | H21: {=Exposures!$B9:$D9*$C21} -> 56.086394 | I21: 134.04648 | J21: -1.6825918
A22: STK_I | B22: =_xlfn.VAR.S(CSR_FactorReturns!Y2:Y157)*52 -> 0.031600535 | C22: =1/B22 -> 31.645034 | H22: {=Exposures!$B10:$D10*$C22} -> 31.645034 | I22: -14.240265 | J22: -55.062359
A23: STK_J | B23: =_xlfn.VAR.S(CSR_FactorReturns!Z2:Z157)*52 -> 0.031553287 | C23: =1/B23 -> 31.692419 | H23: {=Exposures!$B11:$D11*$C23} -> 31.692419 | I23: -20.600072 | J23: -32.009343
D25: X'VX (3x3)
D26: Market | E26: Value | F26: Momentum
D27: {=MMULT(TRANSPOSE(Exposures!$B$2:$D$11),H14:J23)} -> 361.79304 | E27: 49.469287 | F27: 7.6309602
D28: 49.469287 | E28: 470.77997 | F28: 24.810261
D29: 7.6309602 | E29: 24.810261 | F29: 328.99944
D31: (X'VX)^-1 (3x3)
D32: Market | E32: Value | F32: Momentum
D33: {=MINVERSE(D27:F29)} -> 0.0028049089 | E33: -0.00029247196 | F33: -4.3002634e-05
D34: -0.00029247196 | E34: 0.0021631064 | F34: -0.00015633885
D35: -4.3002634e-05 | E35: -0.00015633885 | F35: 0.003052306
A37: P_WLS = X_scaled . (X'VX)^-1 [10x3 pure factor-portfolio weights, WLS version]
B38: Market | C38: Value | D38: Momentum
A39: STK_A | B39: {=MMULT(H14:J23,D33:F35)} -> 0.092780906 | C39: 0.0079850946 | D39: 0.11261325
A40: STK_B | B40: 0.09021397 | C40: 0.044429942 | D40: 0.095082775
A41: STK_C | B41: 0.068445461 | C41: -0.015318863 | D41: 0.046210544
A42: STK_D | B42: 0.11790565 | C42: -0.094331103 | D42: -0.062890276
A43: STK_E | B43: 0.13102122 | C43: -0.054671063 | D43: 0.065654002
A44: STK_F | B44: 0.10435535 | C44: -0.10552718 | D44: 0.14142362
A45: STK_G | B45: 0.085502774 | C45: 0.023892098 | D45: -0.10654334
A46: STK_H | B46: 0.11818475 | C46: 0.27381617 | D46: -0.028504321
...
