Workbook

Sheet 0. README
A1: Management Case + Sensitivity Template — How To Use This Workbook
A4: WHAT THIS IS
A5: A fully generic, reusable credit-analysis template: one Management (base) Case tab, four Sensitivity tabs (Downside, Severe Downside, Reverse Stress, Upside), a live Sensitivity Summary, and a single Assumptions tab that every case pulls from. The row structure, headings and order are IDENTICAL across all five case tabs — only the Assumptions inputs and each tab's own 'flex' cells differ. There is no deal-specific data anywhere in this file — every numeric input defaults to zero and is coloured yellow/blue for you to fill in.
A7: STEP 1 — SET UP PERIODS & SEGMENTS (Assumptions tab, Section 0)
A8: Rename the 12 period labels to your deal's actual fiscal years (e.g. FY24A...FY31F) — this propagates to every tab automatically. Rename up to 6 revenue segments (or leave the unused ones as 'Segment N' with 0% growth and 0 revenue if your deal has fewer lines of business).
A10: STEP 2 — FILL IN HISTORICALS (Assumptions tab, Section 1, columns B–E)
A11: Actuals for the last 2–3 fiscal years plus a stub period to deal close. These are identical across every case tab (the past doesn't change under a sensitivity), so they only live here.
A13: STEP 3 — FILL IN YOUR MANAGEMENT CASE (Assumptions tab, Section 2, columns F–M)
A14: Revenue growth by segment, target gross margin, cost ratios, D&A, capex ratios, tax rate and any acquisition-related cash flows. This is your base case — it flows straight into the '1. Management Case' tab, which has all its flex cells at zero.
A16: STEP 4 — FILL IN DEBT & COVENANT TERMS (Assumptions tab, Section 3)
A17: Base rate, credit margin, RCF/acquisition-facility limits, term loan opening balance and amortisation profile, opening cash, and the actual covenant levels in your facility agreement.
A19: STEP 5 — CALIBRATE THE SENSITIVITY TABS
... A33: • 'Other income' flows into EBITDA, consistent with a standard P&L presentation.

Sheet Assumptions
A1: Assumptions — fill in the yellow cells; everything else in this workbook is a formula
A2: Section 0 sets your period labels and segment names once — they flow through to every tab. Section 1 is historical actuals (same across every case). Section 2 is your management-case forecast drivers. Section 3 is debt/rate/covenant terms.
A4: 0. SETUP — PERIOD LABELS & SEGMENT NAMES (edit once here, every tab picks these up)
A5: Period labels (rename to your deal's actual fiscal years)
B6: FY-2A | C6: FY-1A | D6: FY0A | E6: Stub / At Close | F6: FY1F | G6: FY2F | H6: FY3F | I6: FY4F | J6: FY5F | K6: FY6F | L6: FY7F | M6: FY8F
A8: Segment names (rename any/all of the up-to-6 revenue segments; leave a row's growth at 0% and revenue blank if you use fewer than 6)
A9: Segment 1 name -> | C9: Segment 1
A10: Segment 2 name -> | C10: Segment 2
A11: Segment 3 name -> | C11: Segment 3
A12: Segment 4 name -> | C12: Segment 4
A13: Segment 5 name -> | C13: Segment 5
A14: Segment 6 name -> | C14: Segment 6
A16: 1. HISTORICAL & STUB ACTUALS (£m, columns B–E only — identical across every case tab)
A17: Revenue by segment
A18: ="Revenue — "&Assumptions!$C$9 | B18: 0 | C18: 0 | D18: 0 | E18: 0
A19: ="Revenue — "&Assumptions!$C$10 | B19: 0 | C19: 0 | D19: 0 | E19: 0
A20: ="Revenue — "&Assumptions!$C$11 | B20: 0 | C20: 0 | D20: 0 | E20: 0
A21: ="Revenue — "&Assumptions!$C$12 | B21: 0 | C21: 0 | D21: 0 | E21: 0
A22: ="Revenue — "&Assumptions!$C$13 | B22: 0 | C22: 0 | D22: 0 | E22: 0
A23: ="Revenue — "&Assumptions!$C$14 | B23: 0 | C23: 0 | D23: 0 | E23: 0
A25: Gross margin % (historical)
B26: 0 | C26: 0 | D26: 0 | E26: 0
A28: Other income (£m)
B29: 0 | C29: 0 | D29: 0 | E29: 0
A31: Staff costs (£m, negative = cost)
B32: 0 | C32: 0 | D32: 0 | E32: 0
A34: Other operating expenses (£m, negative = cost)
B35: 0 | C35: 0 | D35: 0 | E35: 0
A37: Depreciation & amortisation (£m, negative)
B38: 0 | C38: 0 | D38: 0 | E38: 0
A40: Non-recurring / QoE adjustments (£m)
B41: 0 | C41: 0 | D41: 0 | E41: 0
A43: Δ Net working capital (£m, outflow negative)
B44: 0 | C44: 0 | D44: 0 | E44: 0
A46: Maintenance capex (£m, negative)
B47: 0 | C47: 0 | D47: 0 | E47: 0
A49: Growth capex (£m, negative)
B50: 0 | C50: 0 | D50: 0 | E50: 0
A52: Exceptional & other cash items (£m)
B53: 0 | C53: 0 | D53: 0 | E53: 0
...

Sheet 1. Management Case
A1: 1. Management Case
A2: Base / management case. Flex cells all zero by default — this tab IS the anchor the sensitivities flex off. Fill in the Assumptions tab; every number here is a formula, nothing is typed directly into this tab.
A4: SENSITIVITY FLEX ASSUMPTIONS (this tab only — tweak these, everything below recalculates)
A5: Revenue growth adjustment (ppt, added to every segment, every forecast period) | C5: 0
A6: Gross margin compression (ppt, subtracted from target margin) | C6: 0
A7: Cost inflation add-on (ppt of revenue, on 'Other operating expenses') | C7: 0
A8: Capex increase (%, multiplicative uplift to capex ratios) | C8: 0
A9: Working-capital drag increase (%, multiplicative uplift to NWC outflow) | C9: 0
A10: Interest rate shock (bps, added to all-in cost of debt) | C10: 0
A12: £m | Period | B12: =Assumptions!B$6 | C12: =Assumptions!C$6 | D12: =Assumptions!D$6 | E12: =Assumptions!E$6 | F12: =Assumptions!F$6 | G12: =Assumptions!G$6 | H12: =Assumptions!H$6 | I12: =Assumptions!I$6 | ... M12: =Assumptions!M$6
A14: REVENUE
A15: =Assumptions!$C$9 | B15: =Assumptions!B18 | C15: =Assumptions!C18 | D15: =Assumptions!D18 | E15: =Assumptions!E18 | F15: =E15*(1+Assumptions!F68+$C$5) | G15: =F15*(1+Assumptions!G68+$C$5) | H15: =G15*(1+Assumptions!H68+$C$5) | I15: =H15*(1+Assumptions!I68+$C$5) | J15: =I15*(1+Assumptions!J68+$C$5) | K15: =J15*(1+Assumptions!K68+$C$5) | L15: =K15*(1+Assumptions!L68+$C$5) | M15: =L15*(1+Assumptions!M68+$C$5)
A16: =Assumptions!$C$10 | B16: =Assumptions!B19 | C16: =Assumptions!C19 | D16: =Assumptions!D19 | E16: =Assumptions!E19 | F16: =E16*(1+Assumptions!F69+$C$5) | G16: =F16*(1+Assumptions!G69+$C$5) | H16: =G16*(1+Assumptions!H69+$C$5) | I16: =H16*(1+Assumptions!I69+$C$5) | J16: =I16*(1+Assumptions!J69+$C$5) | K16: =J16*(1+Assumptions!K69+$C$5) | L16: =K16*(1+Assumptions!L69+$C$5) | M16: =L16*(1+Assumptions!M69+$C$5)
A17: =Assumptions!$C$11 | B17: =Assumptions!B20 | C17: =Assumptions!C20 | D17: =Assumptions!D20 | E17: =Assumptions!E20 | F17: =E17*(1+Assumptions!F70+$C$5) | G17: =F17*(1+Assumptions!G70+$C$5) | H17: =G17*(1+Assumptions!H70+$C$5) | I17: =H17*(1+Assumptions!I70+$C$5) | J17: =I17*(1+Assumptions!J70+$C$5) | K17: =J17*(1+Assumptions!K70+$C$5) | L17: =K17*(1+Assumptions!L70+$C$5) | M17: =L17*(1+Assumptions!M70+$C$5)
A18: =Assumptions!$C$12 | B18: =Assumptions!B21 | C18: =Assumptions!C21 | D18: =Assumptions!D21 | E18: =Assumptions!E21 | F18: =E18*(1+Assumptions!F71+$C$5) | G18: =F18*(1+Assumptions!G71+$C$5) | H18: =G18*(1+Assumptions!H71+$C$5) | I18: =H18*(1+Assumptions!I71+$C$5) | J18: =I18*(1+Assumptions!J71+$C$5) | K18: =J18*(1+Assumptions!K71+$C$5) | L18: =K18*(1+Assumptions!L71+$C$5) | M18: =L18*(1+Assumptions!M71+$C$5)
A19: =Assumptions!$C$13 | B19: =Assumptions!B22 | C19: =Assumptions!C22 | D19: =Assumptions!D22 | E19: =Assumptions!E22 | F19: =E19*(1+Assumptions!F72+$C$5) | G19: =F19*(1+Assumptions!G72+$C$5) | H19: =G19*(1+Assumptions!H72+$C$5) | I19: =H19*(1+Assumptions!I72+$C$5) | J19: =I19*(1+Assumptions!J72+$C$5) | K19: =J19*(1+Assumptions!K72+$C$5) | L19: =K19*(1+Assumptions!L72+$C$5) | M19: =L19*(1+Assumptions!M72+$C$5)
A20: =Assumptions!$C$14 | B20: =Assumptions!B23 | C20: =Assumptions!C23 | D20: =Assumptions!D23 | E20: =Assumptions!E23 | F20: =E20*(1+Assumptions!F73+$C$5) | G20: =F20*(1+Assumptions!G73+$C$5) | H20: =G20*(1+Assumptions!H73+$C$5) | I20: =H20*(1+Assumptions!I73+$C$5) | J20: =I20*(1+Assumptions!J73+$C$5) | K20: =J20*(1+Assumptions!K73+$C$5) | L20: =K20*(1+Assumptions!L73+$C$5) | M20: =L20*(1+Assumptions!M73+$C$5)
A21: Total Revenue | B21: =B15+B16+B17+B18+B19+B20 | C21: =C15+C16+C17+C18+C19+C20 | D21: =D15+D16+D17+D18+D19+D20 | E21: =E15+E16+E17+E18+E19+E20 | F21: =F15+F16+F17+F18+F19+F20 | G21: =G15+G16+G17+G18+G19+G20 | H21: =H15+H16+H17+H18+H19+H20 | I21: =I15+I16+I17+I18+I19+I20 | ... M21: =M15+M16+M17+M18+M19+M20
A22: % growth | C22: =C21/B21-1 | D22: =D21/C21-1 | E22: =E21/D21-1 | F22: =F21/E21-1 | G22: =G21/F21-1 | H22: =H21/G21-1 | I22: =I21/H21-1 | J22: =J21/I21-1 | ... M22: =M21/L21-1
A24: COST OF SALES & GROSS PROFIT
A25: Cost of sales / COGS | B25: =-B21*(1-Assumptions!B26) | C25: =-C21*(1-Assumptions!C26) | D25: =-D21*(1-Assumptions!D26) | E25: =-E21*(1-Assumptions!E26) | F25: =-F21*(1-(Assumptions!F76-$C$6)) | G25: =-G21*(1-(Assumptions!G76-$C$6)) | H25: =-H21*(1-(Assumptions!H76-$C$6)) | I25: =-I21*(1-(Assumptions!I76-$C$6)) | J25: =-J21*(1-(Assumptions!J76-$C$6)) | K25: =-K21*(1-(Assumptions!K76-$C$6)) | L25: =-L21*(1-(Assumptions!L76-$C$6)) | M25: =-M21*(1-(Assumptions!M76-$C$6))
A26: Gross Profit | B26: =B21+B25 | C26: =C21+C25 | D26: =D21+D25 | E26: =E21+E25 | F26: =F21+F25 | G26: =G21+G25 | H26: =H21+H25 | I26: =I21+I25 | ... M26: =M21+M25
A27: Gross margin % | B27: =B26/B21 | C27: =C26/C21 | D27: =D26/D21 | E27: =E26/E21 | F27: =F26/F21 | G27: =G26/G21 | H27: =H26/H21 | I27: =I26/I21 | ... M27: =M26/M21
A29: OPERATING EXPENSES
A30: Other income | B30: =Assumptions!B29 | C30: =Assumptions!C29 | D30: =Assumptions!D29 | E30: =Assumptions!E29 | F30: =Assumptions!F79 | G30: =Assumptions!G79 | H30: =Assumptions!H79 | I30: =Assumptions!I79 | J30: =Assumptions!J79 | K30: =Assumptions!K79 | L30: =Assumptions!L79 | M30: =Assumptions!M79
A31: Staff costs | B31: =Assumptions!B32 | C31: =Assumptions!C32 | D31: =Assumptions!D32 | E31: =Assumptions!E32 | F31: =-F21*Assumptions!F82 | G31: =-G21*Assumptions!G82 | H31: =-H21*Assumptions!H82 | I31: =-I21*Assumptions!I82 | J31: =-J21*Assumptions!J82 | K31: =-K21*Assumptions!K82 | L31: =-L21*Assumptions!L82 | M31: =-M21*Assumptions!M82
A32: Other operating expenses | B32: =Assumptions!B35 | C32: =Assumptions!C35 | D32: =Assumptions!D35 | E32: =Assumptions!E35 | F32: =-F21*(Assumptions!F85+$C$7) | G32: =-G21*(Assumptions!G85+$C$7) | H32: =-H21*(Assumptions!H85+$C$7) | I32: =-I21*(Assumptions!I85+$C$7) | J32: =-J21*(Assumptions!J85+$C$7) | K32: =-K21*(Assumptions!K85+$C$7) | L32: =-L21*(Assumptions!L85+$C$7) | M32: =-M21*(Assumptions!M85+$C$7)
A33: Total Operating Expenses | B33: =B31+B32 | C33: =C31+C32 | D33: =D31+D32 | E33: =E31+E32 | F33: =F31+F32 | G33: =G31+G32 | H33: =H31+H32 | I33: =I31+I32 | ... M33: =M31+M32
A34: Operating expenses — % of sales | B34: =-B33/B21 | C34: =-C33/C21 | D34: =-D33/D21 | E34: =-E33/E21 | F34: =-F33/F21 | G34: =-G33/G21 | H34: =-H33/H21 | I34: =-I33/I21 | ... M34: =-M33/M21
A36: EBITDA, D&A & EBIT
A37: EBITDA | B37: =B26+B30+B33 | C37: =C26+C30+C33 | D37: =D26+D30+D33 | E37: =E26+E30+E33 | F37: =F26+F30+F33 | G37: =G26+G30+G33 | H37: =H26+H30+H33 | I37: =I26+I30+I33 | ... M37: =M26+M30+M33
A38: EBITDA margin % | B38: =B37/B21 | C38: =C37/C21 | D38: =D37/D21 | E38: =E37/E21 | F38: =F37/F21 | G38: =G37/G21 | H38: =H37/H21 | I38: =I37/I21 | ... M38: =M37/M21
A39: Depreciation & amortisation | B39: =Assumptions!B38 | C39: =Assumptions!C38 | D39: =Assumptions!D38 | E39: =Assumptions!E38 | F39: =-F21*Assumptions!F88 | G39: =-G21*Assumptions!G88 | H39: =-H21*Assumptions!H88 | I39: =-I21*Assumptions!I88 | J39: =-J21*Assumptions!J88 | K39: =-K21*Assumptions!K88 | L39: =-L21*Assumptions!L88 | M39: =-M21*Assumptions!M88
A40: EBIT | B40: =B37+B39 | C40: =C37+C39 | D40: =D37+D39 | E40: =E37+E39 | F40: =F37+F39 | G40: =G37+G39 | H40: =H37+H39 | I40: =I37+I39 | ... M40: =M37+M39
A41: Non-recurring / QoE adjustments | B41: =Assumptions!B41 | C41: =Assumptions!C41 | D41: =Assumptions!D41 | E41: =Assumptions!E41 | F41: =Assumptions!F91 | G41: =Assumptions!G91 | H41: =Assumptions!H91 | I41: =Assumptions!I91 | J41: =Assumptions!J91 | K41: =Assumptions!K91 | L41: =Assumptions!L91 | M41: =Assumptions!M91
A42: Adjusted EBITDA | B42: =B37+B41 | C42: =C37+C41 | D42: =D37+D41 | E42: =E37+E41 | F42: =F37+F41 | G42: =G37+G41 | H42: =H37+H41 | I42: =I37+I41 | ... M42: =M37+M41
A43: Adjusted EBITDA margin % | B43: =B42/B21 | C43: =C42/C21 | D43: =D42/D21 | E43: =E42/E21 | F43: =F42/F21 | G43: =G42/G21 | H43: =H42/H21 | I43: =I42/I21 | ... M43: =M42/M21
A45: Δ Net working capital | B45: =Assumptions!B44 | C45: =Assumptions!C44 | D45: =Assumptions!D44 | E45: =Assumptions!E44 | F45: =Assumptions!F94*(1+$C$9) | G45: =Assumptions!G94*(1+$C$9) | H45: =Assumptions!H94*(1+$C$9) | I45: =Assumptions!I94*(1+$C$9) | J45: =Assumptions!J94*(1+$C$9) | K45: =Assumptions!K94*(1+$C$9) | L45: =Assumptions!L94*(1+$C$9) | M45: =Assumptions!M94*(1+$C$9)
A46: Operating Cash Flow | B46: =B42+B45 | C46: =C42+C45 | D46: =D42+D45 | E46: =E42+E45 | F46: =F42+F45 | G46: =G42+G45 | H46: =H42+H45 | I46: =I42+I45 | ... M46: =M42+M45
A47: OCF : Adjusted EBITDA % | B47: =B46/B42 | C47: =C46/C42 | D47: =D46/D42 | E47: =E46/E42 | F47: =F46/F42 | G47: =G46/G42 | H47: =H46/H42 | I47: =I46/I42 | ... M47: =M46/M42
...

Sheet 2. Downside Case
A1: 2. Downside Case
A2: Mild downside — illustrative starting calibration, recalibrate to your deal: -3ppt revenue growth, 100bps gross-margin compression, cost inflation not recovered, working-capital drag +20%, 100bps rate shock.
A4: SENSITIVITY FLEX ASSUMPTIONS (this tab only — tweak these, everything below recalculates)
A5: Revenue growth adjustment (ppt, added to every segment, every forecast period) | C5: -0.03
A6: Gross margin compression (ppt, subtracted from target margin) | C6: 0.01
A7: Cost inflation add-on (ppt of revenue, on 'Other operating expenses') | C7: 0.005
A8: Capex increase (%, multiplicative uplift to capex ratios) | C8: 0.15
A9: Working-capital drag increase (%, multiplicative uplift to NWC outflow) | C9: 0.2
A10: Interest rate shock (bps, added to all-in cost of debt) | C10: 100
A12: £m | Period | B12: =Assumptions!B$6 | C12: =Assumptions!C$6 | D12: =Assumptions!D$6 | E12: =Assumptions!E$6 | F12: =Assumptions!F$6 | G12: =Assumptions!G$6 | H12: =Assumptions!H$6 | I12: =Assumptions!I$6 | ... M12: =Assumptions!M$6
A14: REVENUE
A15: =Assumptions!$C$9 | B15: =Assumptions!B18 | C15: =Assumptions!C18 | D15: =Assumptions!D18 | E15: =Assumptions!E18 | F15: =E15*(1+Assumptions!F68+$C$5) | G15: =F15*(1+Assumptions!G68+$C$5) | H15: =G15*(1+Assumptions!H68+$C$5) | I15: =H15*(1+Assumptions!I68+$C$5) | J15: =I15*(1+Assumptions!J68+$C$5) | K15: =J15*(1+Assumptions!K68+$C$5) | L15: =K15*(1+Assumptions!L68+$C$5) | M15: =L15*(1+Assumptions!M68+$C$5)
A16: =Assumptions!$C$10 | B16: =Assumptions!B19 | C16: =Assumptions!C19 | D16: =Assumptions!D19 | E16: =Assumptions!E19 | F16: =E16*(1+Assumptions!F69+$C$5) | G16: =F16*(1+Assumptions!G69+$C$5) | H16: =G16*(1+Assumptions!H69+$C$5) | I16: =H16*(1+Assumptions!I69+$C$5) | J16: =I16*(1+Assumptions!J69+$C$5) | K16: =J16*(1+Assumptions!K69+$C$5) | L16: =K16*(1+Assumptions!L69+$C$5) | M16: =L16*(1+Assumptions!M69+$C$5)
A17: =Assumptions!$C$11 | B17: =Assumptions!B20 | C17: =Assumptions!C20 | D17: =Assumptions!D20 | E17: =Assumptions!E20 | F17: =E17*(1+Assumptions!F70+$C$5) | G17: =F17*(1+Assumptions!G70+$C$5) | H17: =G17*(1+Assumptions!H70+$C$5) | I17: =H17*(1+Assumptions!I70+$C$5) | J17: =I17*(1+Assumptions!J70+$C$5) | K17: =J17*(1+Assumptions!K70+$C$5) | L17: =K17*(1+Assumptions!L70+$C$5) | M17: =L17*(1+Assumptions!M70+$C$5)
A18: =Assumptions!$C$12 | B18: =Assumptions!B21 | C18: =Assumptions!C21 | D18: =Assumptions!D21 | E18: =Assumptions!E21 | F18: =E18*(1+Assumptions!F71+$C$5) | G18: =F18*(1+Assumptions!G71+$C$5) | H18: =G18*(1+Assumptions!H71+$C$5) | I18: =H18*(1+Assumptions!I71+$C$5) | J18: =I18*(1+Assumptions!J71+$C$5) | K18: =J18*(1+Assumptions!K71+$C$5) | L18: =K18*(1+Assumptions!L71+$C$5) | M18: =L18*(1+Assumptions!M71+$C$5)
A19: =Assumptions!$C$13 | B19: =Assumptions!B22 | C19: =Assumptions!C22 | D19: =Assumptions!D22 | E19: =Assumptions!E22 | F19: =E19*(1+Assumptions!F72+$C$5) | G19: =F19*(1+Assumptions!G72+$C$5) | H19: =G19*(1+Assumptions!H72+$C$5) | I19: =H19*(1+Assumptions!I72+$C$5) | J19: =I19*(1+Assumptions!J72+$C$5) | K19: =J19*(1+Assumptions!K72+$C$5) | L19: =K19*(1+Assumptions!L72+$C$5) | M19: =L19*(1+Assumptions!M72+$C$5)
A20: =Assumptions!$C$14 | B20: =Assumptions!B23 | C20: =Assumptions!C23 | D20: =Assumptions!D23 | E20: =Assumptions!E23 | F20: =E20*(1+Assumptions!F73+$C$5) | G20: =F20*(1+Assumptions!G73+$C$5) | H20: =G20*(1+Assumptions!H73+$C$5) | I20: =H20*(1+Assumptions!I73+$C$5) | J20: =I20*(1+Assumptions!J73+$C$5) | K20: =J20*(1+Assumptions!K73+$C$5) | L20: =K20*(1+Assumptions!L73+$C$5) | M20: =L20*(1+Assumptions!M73+$C$5)
A21: Total Revenue | B21: =B15+B16+B17+B18+B19+B20 | C21: =C15+C16+C17+C18+C19+C20 | D21: =D15+D16+D17+D18+D19+D20 | E21: =E15+E16+E17+E18+E19+E20 | F21: =F15+F16+F17+F18+F19+F20 | G21: =G15+G16+G17+G18+G19+G20 | H21: =H15+H16+H17+H18+H19+H20 | I21: =I15+I16+I17+I18+I19+I20 | ... M21: =M15+M16+M17+M18+M19+M20
A22: % growth | C22: =C21/B21-1 | D22: =D21/C21-1 | E22: =E21/D21-1 | F22: =F21/E21-1 | G22: =G21/F21-1 | H22: =H21/G21-1 | I22: =I21/H21-1 | J22: =J21/I21-1 | ... M22: =M21/L21-1
A24: COST OF SALES & GROSS PROFIT
A25: Cost of sales / COGS | B25: =-B21*(1-Assumptions!B26) | C25: =-C21*(1-Assumptions!C26) | D25: =-D21*(1-Assumptions!D26) | E25: =-E21*(1-Assumptions!E26) | F25: =-F21*(1-(Assumptions!F76-$C$6)) | G25: =-G21*(1-(Assumptions!G76-$C$6)) | H25: =-H21*(1-(Assumptions!H76-$C$6)) | I25: =-I21*(1-(Assumptions!I76-$C$6)) | J25: =-J21*(1-(Assumptions!J76-$C$6)) | K25: =-K21*(1-(Assumptions!K76-$C$6)) | L25: =-L21*(1-(Assumptions!L76-$C$6)) | M25: =-M21*(1-(Assumptions!M76-$C$6))
A26: Gross Profit | B26: =B21+B25 | C26: =C21+C25 | D26: =D21+D25 | E26: =E21+E25 | F26: =F21+F25 | G26: =G21+G25 | H26: =H21+H25 | I26: =I21+I25 | ... M26: =M21+M25
A27: Gross margin % | B27: =B26/B21 | C27: =C26/C21 | D27: =D26/D21 | E27: =E26/E21 | F27: =F26/F21 | G27: =G26/G21 | H27: =H26/H21 | I27: =I26/I21 | ... M27: =M26/M21
A29: OPERATING EXPENSES
A30: Other income | B30: =Assumptions!B29 | C30: =Assumptions!C29 | D30: =Assumptions!D29 | E30: =Assumptions!E29 | F30: =Assumptions!F79 | G30: =Assumptions!G79 | H30: =Assumptions!H79 | I30: =Assumptions!I79 | J30: =Assumptions!J79 | K30: =Assumptions!K79 | L30: =Assumptions!L79 | M30: =Assumptions!M79
A31: Staff costs | B31: =Assumptions!B32 | C31: =Assumptions!C32 | D31: =Assumptions!D32 | E31: =Assumptions!E32 | F31: =-F21*Assumptions!F82 | G31: =-G21*Assumptions!G82 | H31: =-H21*Assumptions!H82 | I31: =-I21*Assumptions!I82 | J31: =-J21*Assumptions!J82 | K31: =-K21*Assumptions!K82 | L31: =-L21*Assumptions!L82 | M31: =-M21*Assumptions!M82
A32: Other operating expenses | B32: =Assumptions!B35 | C32: =Assumptions!C35 | D32: =Assumptions!D35 | E32: =Assumptions!E35 | F32: =-F21*(Assumptions!F85+$C$7) | G32: =-G21*(Assumptions!G85+$C$7) | H32: =-H21*(Assumptions!H85+$C$7) | I32: =-I21*(Assumptions!I85+$C$7) | J32: =-J21*(Assumptions!J85+$C$7) | K32: =-K21*(Assumptions!K85+$C$7) | L32: =-L21*(Assumptions!L85+$C$7) | M32: =-M21*(Assumptions!M85+$C$7)
A33: Total Operating Expenses | B33: =B31+B32 | C33: =C31+C32 | D33: =D31+D32 | E33: =E31+E32 | F33: =F31+F32 | G33: =G31+G32 | H33: =H31+H32 | I33: =I31+I32 | ... M33: =M31+M32
A34: Operating expenses — % of sales | B34: =-B33/B21 | C34: =-C33/C21 | D34: =-D33/D21 | E34: =-E33/E21 | F34: =-F33/F21 | G34: =-G33/G21 | H34: =-H33/H21 | I34: =-I33/I21 | ... M34: =-M33/M21
A36: EBITDA, D&A & EBIT
A37: EBITDA | B37: =B26+B30+B33 | C37: =C26+C30+C33 | D37: =D26+D30+D33 | E37: =E26+E30+E33 | F37: =F26+F30+F33 | G37: =G26+G30+G33 | H37: =H26+H30+H33 | I37: =I26+I30+I33 | ... M37: =M26+M30+M33
A38: EBITDA margin % | B38: =B37/B21 | C38: =C37/C21 | D38: =D37/D21 | E38: =E37/E21 | F38: =F37/F21 | G38: =G37/G21 | H38: =H37/H21 | I38: =I37/I21 | ... M38: =M37/M21
A39: Depreciation & amortisation | B39: =Assumptions!B38 | C39: =Assumptions!C38 | D39: =Assumptions!D38 | E39: =Assumptions!E38 | F39: =-F21*Assumptions!F88 | G39: =-G21*Assumptions!G88 | H39: =-H21*Assumptions!H88 | I39: =-I21*Assumptions!I88 | J39: =-J21*Assumptions!J88 | K39: =-K21*Assumptions!K88 | L39: =-L21*Assumptions!L88 | M39: =-M21*Assumptions!M88
A40: EBIT | B40: =B37+B39 | C40: =C37+C39 | D40: =D37+D39 | E40: =E37+E39 | F40: =F37+F39 | G40: =G37+G39 | H40: =H37+H39 | I40: =I37+I39 | ... M40: =M37+M39
A41: Non-recurring / QoE adjustments | B41: =Assumptions!B41 | C41: =Assumptions!C41 | D41: =Assumptions!D41 | E41: =Assumptions!E41 | F41: =Assumptions!F91 | G41: =Assumptions!G91 | H41: =Assumptions!H91 | I41: =Assumptions!I91 | J41: =Assumptions!J91 | K41: =Assumptions!K91 | L41: =Assumptions!L91 | M41: =Assumptions!M91
A42: Adjusted EBITDA | B42: =B37+B41 | C42: =C37+C41 | D42: =D37+D41 | E42: =E37+E41 | F42: =F37+F41 | G42: =G37+G41 | H42: =H37+H41 | I42: =I37+I41 | ... M42: =M37+M41
A43: Adjusted EBITDA margin % | B43: =B42/B21 | C43: =C42/C21 | D43: =D42/D21 | E43: =E42/E21 | F43: =F42/F21 | G43: =G42/G21 | H43: =H42/H21 | I43: =I42/I21 | ... M43: =M42/M21
A45: Δ Net working capital | B45: =Assumptions!B44 | C45: =Assumptions!C44 | D45: =Assumptions!D44 | E45: =Assumptions!E44 | F45: =Assumptions!F94*(1+$C$9) | G45: =Assumptions!G94*(1+$C$9) | H45: =Assumptions!H94*(1+$C$9) | I45: =Assumptions!I94*(1+$C$9) | J45: =Assumptions!J94*(1+$C$9) | K45: =Assumptions!K94*(1+$C$9) | L45: =Assumptions!L94*(1+$C$9) | M45: =Assumptions!M94*(1+$C$9)
A46: Operating Cash Flow | B46: =B42+B45 | C46: =C42+C45 | D46: =D42+D45 | E46: =E42+E45 | F46: =F42+F45 | G46: =G42+G45 | H46: =H42+H45 | I46: =I42+I45 | ... M46: =M42+M45
A47: OCF : Adjusted EBITDA % | B47: =B46/B42 | C47: =C46/C42 | D47: =D46/D42 | E47: =E46/E42 | F47: =F46/F42 | G47: =G46/G42 | H47: =H46/H42 | I47: =I46/I42 | ... M47: =M46/M42
...

Sheet 3. Severe Downside Case
A1: 3. Severe Downside Case
A2: Severe downside — illustrative starting calibration, recalibrate to your deal: -7ppt revenue growth, 250bps margin compression, working-capital drag +40%, 250bps rate shock.
A4: SENSITIVITY FLEX ASSUMPTIONS (this tab only — tweak these, everything below recalculates)
A5: Revenue growth adjustment (ppt, added to every segment, every forecast period) | C5: -0.07
A6: Gross margin compression (ppt, subtracted from target margin) | C6: 0.025
A7: Cost inflation add-on (ppt of revenue, on 'Other operating expenses') | C7: 0.012
A8: Capex increase (%, multiplicative uplift to capex ratios) | C8: 0.25
A9: Working-capital drag increase (%, multiplicative uplift to NWC outflow) | C9: 0.4
A10: Interest rate shock (bps, added to all-in cost of debt) | C10: 250
A12: £m | Period | B12: =Assumptions!B$6 | C12: =Assumptions!C$6 | D12: =Assumptions!D$6 | E12: =Assumptions!E$6 | F12: =Assumptions!F$6 | G12: =Assumptions!G$6 | H12: =Assumptions!H$6 | I12: =Assumptions!I$6 | ... M12: =Assumptions!M$6
A14: REVENUE
A15: =Assumptions!$C$9 | B15: =Assumptions!B18 | C15: =Assumptions!C18 | D15: =Assumptions!D18 | E15: =Assumptions!E18 | F15: =E15*(1+Assumptions!F68+$C$5) | G15: =F15*(1+Assumptions!G68+$C$5) | H15: =G15*(1+Assumptions!H68+$C$5) | I15: =H15*(1+Assumptions!I68+$C$5) | J15: =I15*(1+Assumptions!J68+$C$5) | K15: =J15*(1+Assumptions!K68+$C$5) | L15: =K15*(1+Assumptions!L68+$C$5) | M15: =L15*(1+Assumptions!M68+$C$5)
A16: =Assumptions!$C$10 | B16: =Assumptions!B19 | C16: =Assumptions!C19 | D16: =Assumptions!D19 | E16: =Assumptions!E19 | F16: =E16*(1+Assumptions!F69+$C$5) | G16: =F16*(1+Assumptions!G69+$C$5) | H16: =G16*(1+Assumptions!H69+$C$5) | I16: =H16*(1+Assumptions!I69+$C$5) | J16: =I16*(1+Assumptions!J69+$C$5) | K16: =J16*(1+Assumptions!K69+$C$5) | L16: =K16*(1+Assumptions!L69+$C$5) | M16: =L16*(1+Assumptions!M69+$C$5)
A17: =Assumptions!$C$11 | B17: =Assumptions!B20 | C17: =Assumptions!C20 | D17: =Assumptions!D20 | E17: =Assumptions!E20 | F17: =E17*(1+Assumptions!F70+$C$5) | G17: =F17*(1+Assumptions!G70+$C$5) | H17: =G17*(1+Assumptions!H70+$C$5) | I17: =H17*(1+Assumptions!I70+$C$5) | J17: =I17*(1+Assumptions!J70+$C$5) | K17: =J17*(1+Assumptions!K70+$C$5) | L17: =K17*(1+Assumptions!L70+$C$5) | M17: =L17*(1+Assumptions!M70+$C$5)
A18: =Assumptions!$C$12 | B18: =Assumptions!B21 | C18: =Assumptions!C21 | D18: =Assumptions!D21 | E18: =Assumptions!E21 | F18: =E18*(1+Assumptions!F71+$C$5) | G18: =F18*(1+Assumptions!G71+$C$5) | H18: =G18*(1+Assumptions!H71+$C$5) | I18: =H18*(1+Assumptions!I71+$C$5) | J18: =I18*(1+Assumptions!J71+$C$5) | K18: =J18*(1+Assumptions!K71+$C$5) | L18: =K18*(1+Assumptions!L71+$C$5) | M18: =L18*(1+Assumptions!M71+$C$5)
A19: =Assumptions!$C$13 | B19: =Assumptions!B22 | C19: =Assumptions!C22 | D19: =Assumptions!D22 | E19: =Assumptions!E22 | F19: =E19*(1+Assumptions!F72+$C$5) | G19: =F19*(1+Assumptions!G72+$C$5) | H19: =G19*(1+Assumptions!H72+$C$5) | I19: =H19*(1+Assumptions!I72+$C$5) | J19: =I19*(1+Assumptions!J72+$C$5) | K19: =J19*(1+Assumptions!K72+$C$5) | L19: =K19*(1+Assumptions!L72+$C$5) | M19: =L19*(1+Assumptions!M72+$C$5)
A20: =Assumptions!$C$14 | B20: =Assumptions!B23 | C20: =Assumptions!C23 | D20: =Assumptions!D23 | E20: =Assumptions!E23 | F20: =E20*(1+Assumptions!F73+$C$5) | G20: =F20*(1+Assumptions!G73+$C$5) | H20: =G20*(1+Assumptions!H73+$C$5) | I20: =H20*(1+Assumptions!I73+$C$5) | J20: =I20*(1+Assumptions!J73+$C$5) | K20: =J20*(1+Assumptions!K73+$C$5) | L20: =K20*(1+Assumptions!L73+$C$5) | M20: =L20*(1+Assumptions!M73+$C$5)
A21: Total Revenue | B21: =B15+B16+B17+B18+B19+B20 | C21: =C15+C16+C17+C18+C19+C20 | D21: =D15+D16+D17+D18+D19+D20 | E21: =E15+E16+E17+E18+E19+E20 | F21: =F15+F16+F17+F18+F19+F20 | G21: =G15+G16+G17+G18+G19+G20 | H21: =H15+H16+H17+H18+H19+H20 | I21: =I15+I16+I17+I18+I19+I20 | ... M21: =M15+M16+M17+M18+M19+M20
A22: % growth | C22: =C21/B21-1 | D22: =D21/C21-1 | E22: =E21/D21-1 | F22: =F21/E21-1 | G22: =G21/F21-1 | H22: =H21/G21-1 | I22: =I21/H21-1 | J22: =J21/I21-1 | ... M22: =M21/L21-1
A24: COST OF SALES & GROSS PROFIT
A25: Cost of sales / COGS | B25: =-B21*(1-Assumptions!B26) | C25: =-C21*(1-Assumptions!C26) | D25: =-D21*(1-Assumptions!D26) | E25: =-E21*(1-Assumptions!E26) | F25: =-F21*(1-(Assumptions!F76-$C$6)) | G25: =-G21*(1-(Assumptions!G76-$C$6)) | H25: =-H21*(1-(Assumptions!H76-$C$6)) | I25: =-I21*(1-(Assumptions!I76-$C$6)) | J25: =-J21*(1-(Assumptions!J76-$C$6)) | K25: =-K21*(1-(Assumptions!K76-$C$6)) | L25: =-L21*(1-(Assumptions!L76-$C$6)) | M25: =-M21*(1-(Assumptions!M76-$C$6))
A26: Gross Profit | B26: =B21+B25 | C26: =C21+C25 | D26: =D21+D25 | E26: =E21+E25 | F26: =F21+F25 | G26: =G21+G25 | H26: =H21+H25 | I26: =I21+I25 | ... M26: =M21+M25
A27: Gross margin % | B27: =B26/B21 | C27: =C26/C21 | D27: =D26/D21 | E27: =E26/E21 | F27: =F26/F21 | G27: =G26/G21 | H27: =H26/H21 | I27: =I26/I21 | ... M27: =M26/M21
A29: OPERATING EXPENSES
A30: Other income | B30: =Assumptions!B29 | C30: =Assumptions!C29 | D30: =Assumptions!D29 | E30: =Assumptions!E29 | F30: =Assumptions!F79 | G30: =Assumptions!G79 | H30: =Assumptions!H79 | I30: =Assumptions!I79 | J30: =Assumptions!J79 | K30: =Assumptions!K79 | L30: =Assumptions!L79 | M30: =Assumptions!M79
A31: Staff costs | B31: =Assumptions!B32 | C31: =Assumptions!C32 | D31: =Assumptions!D32 | E31: =Assumptions!E32 | F31: =-F21*Assumptions!F82 | G31: =-G21*Assumptions!G82 | H31: =-H21*Assumptions!H82 | I31: =-I21*Assumptions!I82 | J31: =-J21*Assumptions!J82 | K31: =-K21*Assumptions!K82 | L31: =-L21*Assumptions!L82 | M31: =-M21*Assumptions!M82
A32: Other operating expenses | B32: =Assumptions!B35 | C32: =Assumptions!C35 | D32: =Assumptions!D35 | E32: =Assumptions!E35 | F32: =-F21*(Assumptions!F85+$C$7) | G32: =-G21*(Assumptions!G85+$C$7) | H32: =-H21*(Assumptions!H85+$C$7) | I32: =-I21*(Assumptions!I85+$C$7) | J32: =-J21*(Assumptions!J85+$C$7) | K32: =-K21*(Assumptions!K85+$C$7) | L32: =-L21*(Assumptions!L85+$C$7) | M32: =-M21*(Assumptions!M85+$C$7)
A33: Total Operating Expenses | B33: =B31+B32 | C33: =C31+C32 | D33: =D31+D32 | E33: =E31+E32 | F33: =F31+F32 | G33: =G31+G32 | H33: =H31+H32 | I33: =I31+I32 | ... M33: =M31+M32
A34: Operating expenses — % of sales | B34: =-B33/B21 | C34: =-C33/C21 | D34: =-D33/D21 | E34: =-E33/E21 | F34: =-F33/F21 | G34: =-G33/G21 | H34: =-H33/H21 | I34: =-I33/I21 | ... M34: =-M33/M21
A36: EBITDA, D&A & EBIT
A37: EBITDA | B37: =B26+B30+B33 | C37: =C26+C30+C33 | D37: =D26+D30+D33 | E37: =E26+E30+E33 | F37: =F26+F30+F33 | G37: =G26+G30+G33 | H37: =H26+H30+H33 | I37: =I26+I30+I33 | ... M37: =M26+M30+M33
A38: EBITDA margin % | B38: =B37/B21 | C38: =C37/C21 | D38: =D37/D21 | E38: =E37/E21 | F38: =F37/F21 | G38: =G37/G21 | H38: =H37/H21 | I38: =I37/I21 | ... M38: =M37/M21
A39: Depreciation & amortisation | B39: =Assumptions!B38 | C39: =Assumptions!C38 | D39: =Assumptions!D38 | E39: =Assumptions!E38 | F39: =-F21*Assumptions!F88 | G39: =-G21*Assumptions!G88 | H39: =-H21*Assumptions!H88 | I39: =-I21*Assumptions!I88 | J39: =-J21*Assumptions!J88 | K39: =-K21*Assumptions!K88 | L39: =-L21*Assumptions!L88 | M39: =-M21*Assumptions!M88
A40: EBIT | B40: =B37+B39 | C40: =C37+C39 | D40: =D37+D39 | E40: =E37+E39 | F40: =F37+F39 | G40: =G37+G39 | H40: =H37+H39 | I40: =I37+I39 | ... M40: =M37+M39
A41: Non-recurring / QoE adjustments | B41: =Assumptions!B41 | C41: =Assumptions!C41 | D41: =Assumptions!D41 | E41: =Assumptions!E41 | F41: =Assumptions!F91 | G41: =Assumptions!G91 | H41: =Assumptions!H91 | I41: =Assumptions!I91 | J41: =Assumptions!J91 | K41: =Assumptions!K91 | L41: =Assumptions!L91 | M41: =Assumptions!M91
A42: Adjusted EBITDA | B42: =B37+B41 | C42: =C37+C41 | D42: =D37+D41 | E42: =E37+E41 | F42: =F37+F41 | G42: =G37+G41 | H42: =H37+H41 | I42: =I37+I41 | ... M42: =M37+M41
A43: Adjusted EBITDA margin % | B43: =B42/B21 | C43: =C42/C21 | D43: =D42/D21 | E43: =E42/E21 | F43: =F42/F21 | G43: =G42/G21 | H43: =H42/H21 | I43: =I42/I21 | ... M43: =M42/M21
A45: Δ Net working capital | B45: =Assumptions!B44 | C45: =Assumptions!C44 | D45: =Assumptions!D44 | E45: =Assumptions!E44 | F45: =Assumptions!F94*(1+$C$9) | G45: =Assumptions!G94*(1+$C$9) | H45: =Assumptions!H94*(1+$C$9) | I45: =Assumptions!I94*(1+$C$9) | J45: =Assumptions!J94*(1+$C$9) | K45: =Assumptions!K94*(1+$C$9) | L45: =Assumptions!L94*(1+$C$9) | M45: =Assumptions!M94*(1+$C$9)
A46: Operating Cash Flow | B46: =B42+B45 | C46: =C42+C45 | D46: =D42+D45 | E46: =E42+E45 | F46: =F42+F45 | G46: =G42+G45 | H46: =H42+H45 | I46: =I42+I45 | ... M46: =M42+M45
A47: OCF : Adjusted EBITDA % | B47: =B46/B42 | C47: =C46/C42 | D47: =D46/D42 | E47: =E46/E42 | F47: =F46/F42 | G47: =G46/G42 | H47: =H46/H42 | I47: =I46/I42 | ... M47: =M46/M42
...

Sheet 4. Reverse Stress
A1: 4. Reverse Stress
A2: Other flexes held at an illustrative stress level. Use Data > What-If Analysis > Goal Seek — set the Covenant Test Result / DSCR headroom cell to 0 by changing the revenue-growth-adjustment cell (C5) — to solve for the exact revenue decline that first breaches a covenant.
A4: SENSITIVITY FLEX ASSUMPTIONS (this tab only — tweak these, everything below recalculates)
A5: Revenue growth adjustment (ppt, added to every segment, every forecast period) | C5: -0.05
A6: Gross margin compression (ppt, subtracted from target margin) | C6: 0.015
A7: Cost inflation add-on (ppt of revenue, on 'Other operating expenses') | C7: 0.008
A8: Capex increase (%, multiplicative uplift to capex ratios) | C8: 0.2
A9: Working-capital drag increase (%, multiplicative uplift to NWC outflow) | C9: 0.3
A10: Interest rate shock (bps, added to all-in cost of debt) | C10: 150
A12: £m | Period | B12: =Assumptions!B$6 | C12: =Assumptions!C$6 | D12: =Assumptions!D$6 | E12: =Assumptions!E$6 | F12: =Assumptions!F$6 | G12: =Assumptions!G$6 | H12: =Assumptions!H$6 | I12: =Assumptions!I$6 | ... M12: =Assumptions!M$6
A14: REVENUE
A15: =Assumptions!$C$9 | B15: =Assumptions!B18 | C15: =Assumptions!C18 | D15: =Assumptions!D18 | E15: =Assumptions!E18 | F15: =E15*(1+Assumptions!F68+$C$5) | G15: =F15*(1+Assumptions!G68+$C$5) | H15: =G15*(1+Assumptions!H68+$C$5) | I15: =H15*(1+Assumptions!I68+$C$5) | J15: =I15*(1+Assumptions!J68+$C$5) | K15: =J15*(1+Assumptions!K68+$C$5) | L15: =K15*(1+Assumptions!L68+$C$5) | M15: =L15*(1+Assumptions!M68+$C$5)
A16: =Assumptions!$C$10 | B16: =Assumptions!B19 | C16: =Assumptions!C19 | D16: =Assumptions!D19 | E16: =Assumptions!E19 | F16: =E16*(1+Assumptions!F69+$C$5) | G16: =F16*(1+Assumptions!G69+$C$5) | H16: =G16*(1+Assumptions!H69+$C$5) | I16: =H16*(1+Assumptions!I69+$C$5) | J16: =I16*(1+Assumptions!J69+$C$5) | K16: =J16*(1+Assumptions!K69+$C$5) | L16: =K16*(1+Assumptions!L69+$C$5) | M16: =L16*(1+Assumptions!M69+$C$5)
A17: =Assumptions!$C$11 | B17: =Assumptions!B20 | C17: =Assumptions!C20 | D17: =Assumptions!D20 | E17: =Assumptions!E20 | F17: =E17*(1+Assumptions!F70+$C$5) | G17: =F17*(1+Assumptions!G70+$C$5) | H17: =G17*(1+Assumptions!H70+$C$5) | I17: =H17*(1+Assumptions!I70+$C$5) | J17: =I17*(1+Assumptions!J70+$C$5) | K17: =J17*(1+Assumptions!K70+$C$5) | L17: =K17*(1+Assumptions!L70+$C$5) | M17: =L17*(1+Assumptions!M70+$C$5)
A18: =Assumptions!$C$12 | B18: =Assumptions!B21 | C18: =Assumptions!C21 | D18: =Assumptions!D21 | E18: =Assumptions!E21 | F18: =E18*(1+Assumptions!F71+$C$5) | G18: =F18*(1+Assumptions!G71+$C$5) | H18: =G18*(1+Assumptions!H71+$C$5) | I18: =H18*(1+Assumptions!I71+$C$5) | J18: =I18*(1+Assumptions!J71+$C$5) | K18: =J18*(1+Assumptions!K71+$C$5) | L18: =K18*(1+Assumptions!L71+$C$5) | M18: =L18*(1+Assumptions!M71+$C$5)
A19: =Assumptions!$C$13 | B19: =Assumptions!B22 | C19: =Assumptions!C22 | D19: =Assumptions!D22 | E19: =Assumptions!E22 | F19: =E19*(1+Assumptions!F72+$C$5) | G19: =F19*(1+Assumptions!G72+$C$5) | H19: =G19*(1+Assumptions!H72+$C$5) | I19: =H19*(1+Assumptions!I72+$C$5) | J19: =I19*(1+Assumptions!J72+$C$5) | K19: =J19*(1+Assumptions!K72+$C$5) | L19: =K19*(1+Assumptions!L72+$C$5) | M19: =L19*(1+Assumptions!M72+$C$5)
A20: =Assumptions!$C$14 | B20: =Assumptions!B23 | C20: =Assumptions!C23 | D20: =Assumptions!D23 | E20: =Assumptions!E23 | F20: =E20*(1+Assumptions!F73+$C$5) | G20: =F20*(1+Assumptions!G73+$C$5) | H20: =G20*(1+Assumptions!H73+$C$5) | I20: =H20*(1+Assumptions!I73+$C$5) | J20: =I20*(1+Assumptions!J73+$C$5) | K20: =J20*(1+Assumptions!K73+$C$5) | L20: =K20*(1+Assumptions!L73+$C$5) | M20: =L20*(1+Assumptions!M73+$C$5)
A21: Total Revenue | B21: =B15+B16+B17+B18+B19+B20 | C21: =C15+C16+C17+C18+C19+C20 | D21: =D15+D16+D17+D18+D19+D20 | E21: =E15+E16+E17+E18+E19+E20 | F21: =F15+F16+F17+F18+F19+F20 | G21: =G15+G16+G17+G18+G19+G20 | H21: =H15+H16+H17+H18+H19+H20 | I21: =I15+I16+I17+I18+I19+I20 | ... M21: =M15+M16+M17+M18+M19+M20
A22: % growth | C22: =C21/B21-1 | D22: =D21/C21-1 | E22: =E21/D21-1 | F22: =F21/E21-1 | G22: =G21/F21-1 | H22: =H21/G21-1 | I22: =I21/H21-1 | J22: =J21/I21-1 | ... M22: =M21/L21-1
A24: COST OF SALES & GROSS PROFIT
A25: Cost of sales / COGS | B25: =-B21*(1-Assumptions!B26) | C25: =-C21*(1-Assumptions!C26) | D25: =-D21*(1-Assumptions!D26) | E25: =-E21*(1-Assumptions!E26) | F25: =-F21*(1-(Assumptions!F76-$C$6)) | G25: =-G21*(1-(Assumptions!G76-$C$6)) | H25: =-H21*(1-(Assumptions!H76-$C$6)) | I25: =-I21*(1-(Assumptions!I76-$C$6)) | J25: =-J21*(1-(Assumptions!J76-$C$6)) | K25: =-K21*(1-(Assumptions!K76-$C$6)) | L25: =-L21*(1-(Assumptions!L76-$C$6)) | M25: =-M21*(1-(Assumptions!M76-$C$6))
A26: Gross Profit | B26: =B21+B25 | C26: =C21+C25 | D26: =D21+D25 | E26: =E21+E25 | F26: =F21+F25 | G26: =G21+G25 | H26: =H21+H25 | I26: =I21+I25 | ... M26: =M21+M25
A27: Gross margin % | B27: =B26/B21 | C27: =C26/C21 | D27: =D26/D21 | E27: =E26/E21 | F27: =F26/F21 | G27: =G26/G21 | H27: =H26/H21 | I27: =I26/I21 | ... M27: =M26/M21
A29: OPERATING EXPENSES
A30: Other income | B30: =Assumptions!B29 | C30: =Assumptions!C29 | D30: =Assumptions!D29 | E30: =Assumptions!E29 | F30: =Assumptions!F79 | G30: =Assumptions!G79 | H30: =Assumptions!H79 | I30: =Assumptions!I79 | J30: =Assumptions!J79 | K30: =Assumptions!K79 | L30: =Assumptions!L79 | M30: =Assumptions!M79
A31: Staff costs | B31: =Assumptions!B32 | C31: =Assumptions!C32 | D31: =Assumptions!D32 | E31: =Assumptions!E32 | F31: =-F21*Assumptions!F82 | G31: =-G21*Assumptions!G82 | H31: =-H21*Assumptions!H82 | I31: =-I21*Assumptions!I82 | J31: =-J21*Assumptions!J82 | K31: =-K21*Assumptions!K82 | L31: =-L21*Assumptions!L82 | M31: =-M21*Assumptions!M82
A32: Other operating expenses | B32: =Assumptions!B35 | C32: =Assumptions!C35 | D32: =Assumptions!D35 | E32: =Assumptions!E35 | F32: =-F21*(Assumptions!F85+$C$7) | G32: =-G21*(Assumptions!G85+$C$7) | H32: =-H21*(Assumptions!H85+$C$7) | I32: =-I21*(Assumptions!I85+$C$7) | J32: =-J21*(Assumptions!J85+$C$7) | K32: =-K21*(Assumptions!K85+$C$7) | L32: =-L21*(Assumptions!L85+$C$7) | M32: =-M21*(Assumptions!M85+$C$7)
A33: Total Operating Expenses | B33: =B31+B32 | C33: =C31+C32 | D33: =D31+D32 | E33: =E31+E32 | F33: =F31+F32 | G33: =G31+G32 | H33: =H31+H32 | I33: =I31+I32 | ... M33: =M31+M32
A34: Operating expenses — % of sales | B34: =-B33/B21 | C34: =-C33/C21 | D34: =-D33/D21 | E34: =-E33/E21 | F34: =-F33/F21 | G34: =-G33/G21 | H34: =-H33/H21 | I34: =-I33/I21 | ... M34: =-M33/M21
A36: EBITDA, D&A & EBIT
A37: EBITDA | B37: =B26+B30+B33 | C37: =C26+C30+C33 | D37: =D26+D30+D33 | E37: =E26+E30+E33 | F37: =F26+F30+F33 | G37: =G26+G30+G33 | H37: =H26+H30+H33 | I37: =I26+I30+I33 | ... M37: =M26+M30+M33
A38: EBITDA margin % | B38: =B37/B21 | C38: =C37/C21 | D38: =D37/D21 | E38: =E37/E21 | F38: =F37/F21 | G38: =G37/G21 | H38: =H37/H21 | I38: =I37/I21 | ... M38: =M37/M21
A39: Depreciation & amortisation | B39: =Assumptions!B38 | C39: =Assumptions!C38 | D39: =Assumptions!D38 | E39: =Assumptions!E38 | F39: =-F21*Assumptions!F88 | G39: =-G21*Assumptions!G88 | H39: =-H21*Assumptions!H88 | I39: =-I21*Assumptions!I88 | J39: =-J21*Assumptions!J88 | K39: =-K21*Assumptions!K88 | L39: =-L21*Assumptions!L88 | M39: =-M21*Assumptions!M88
A40: EBIT | B40: =B37+B39 | C40: =C37+C39 | D40: =D37+D39 | E40: =E37+E39 | F40: =F37+F39 | G40: =G37+G39 | H40: =H37+H39 | I40: =I37+I39 | ... M40: =M37+M39
A41: Non-recurring / QoE adjustments | B41: =Assumptions!B41 | C41: =Assumptions!C41 | D41: =Assumptions!D41 | E41: =Assumptions!E41 | F41: =Assumptions!F91 | G41: =Assumptions!G91 | H41: =Assumptions!H91 | I41: =Assumptions!I91 | J41: =Assumptions!J91 | K41: =Assumptions!K91 | L41: =Assumptions!L91 | M41: =Assumptions!M91
A42: Adjusted EBITDA | B42: =B37+B41 | C42: =C37+C41 | D42: =D37+D41 | E42: =E37+E41 | F42: =F37+F41 | G42: =G37+G41 | H42: =H37+H41 | I42: =I37+I41 | ... M42: =M37+M41
A43: Adjusted EBITDA margin % | B43: =B42/B21 | C43: =C42/C21 | D43: =D42/D21 | E43: =E42/E21 | F43: =F42/F21 | G43: =G42/G21 | H43: =H42/H21 | I43: =I42/I21 | ... M43: =M42/M21
A45: Δ Net working capital | B45: =Assumptions!B44 | C45: =Assumptions!C44 | D45: =Assumptions!D44 | E45: =Assumptions!E44 | F45: =Assumptions!F94*(1+$C$9) | G45: =Assumptions!G94*(1+$C$9) | H45: =Assumptions!H94*(1+$C$9) | I45: =Assumptions!I94*(1+$C$9) | J45: =Assumptions!J94*(1+$C$9) | K45: =Assumptions!K94*(1+$C$9) | L45: =Assumptions!L94*(1+$C$9) | M45: =Assumptions!M94*(1+$C$9)
A46: Operating Cash Flow | B46: =B42+B45 | C46: =C42+C45 | D46: =D42+D45 | E46: =E42+E45 | F46: =F42+F45 | G46: =G42+G45 | H46: =H42+H45 | I46: =I42+I45 | ... M46: =M42+M45
A47: OCF : Adjusted EBITDA % | B47: =B46/B42 | C47: =C46/C42 | D47: =D46/D42 | E47: =E46/E42 | F47: =F46/F42 | G47: =G46/G42 | H47: =H46/H42 | I47: =I46/I42 | ... M47: =M46/M42
...

Sheet 5. Upside Case
A1: 5. Upside Case
A2: Upside — illustrative starting calibration: +2ppt revenue growth, operating leverage adds margin, rates ease.
A4: SENSITIVITY FLEX ASSUMPTIONS (this tab only — tweak these, everything below recalculates)
A5: Revenue growth adjustment (ppt, added to every segment, every forecast period) | C5: 0.02
A6: Gross margin compression (ppt, subtracted from target margin) | C6: -0.005
A7: Cost inflation add-on (ppt of revenue, on 'Other operating expenses') | C7: -0.003
A8: Capex increase (%, multiplicative uplift to capex ratios) | C8: -0.05
A9: Working-capital drag increase (%, multiplicative uplift to NWC outflow) | C9: -0.1
A10: Interest rate shock (bps, added to all-in cost of debt) | C10: -25
A12: £m | Period | B12: =Assumptions!B$6 | C12: =Assumptions!C$6 | D12: =Assumptions!D$6 | E12: =Assumptions!E$6 | F12: =Assumptions!F$6 | G12: =Assumptions!G$6 | H12: =Assumptions!H$6 | I12: =Assumptions!I$6 | ... M12: =Assumptions!M$6
A14: REVENUE
A15: =Assumptions!$C$9 | B15: =Assumptions!B18 | C15: =Assumptions!C18 | D15: =Assumptions!D18 | E15: =Assumptions!E18 | F15: =E15*(1+Assumptions!F68+$C$5) | G15: =F15*(1+Assumptions!G68+$C$5) | H15: =G15*(1+Assumptions!H68+$C$5) | I15: =H15*(1+Assumptions!I68+$C$5) | J15: =I15*(1+Assumptions!J68+$C$5) | K15: =J15*(1+Assumptions!K68+$C$5) | L15: =K15*(1+Assumptions!L68+$C$5) | M15: =L15*(1+Assumptions!M68+$C$5)
A16: =Assumptions!$C$10 | B16: =Assumptions!B19 | C16: =Assumptions!C19 | D16: =Assumptions!D19 | E16: =Assumptions!E19 | F16: =E16*(1+Assumptions!F69+$C$5) | G16: =F16*(1+Assumptions!G69+$C$5) | H16: =G16*(1+Assumptions!H69+$C$5) | I16: =H16*(1+Assumptions!I69+$C$5) | J16: =I16*(1+Assumptions!J69+$C$5) | K16: =J16*(1+Assumptions!K69+$C$5) | L16: =K16*(1+Assumptions!L69+$C$5) | M16: =L16*(1+Assumptions!M69+$C$5)
A17: =Assumptions!$C$11 | B17: =Assumptions!B20 | C17: =Assumptions!C20 | D17: =Assumptions!D20 | E17: =Assumptions!E20 | F17: =E17*(1+Assumptions!F70+$C$5) | G17: =F17*(1+Assumptions!G70+$C$5) | H17: =G17*(1+Assumptions!H70+$C$5) | I17: =H17*(1+Assumptions!I70+$C$5) | J17: =I17*(1+Assumptions!J70+$C$5) | K17: =J17*(1+Assumptions!K70+$C$5) | L17: =K17*(1+Assumptions!L70+$C$5) | M17: =L17*(1+Assumptions!M70+$C$5)
A18: =Assumptions!$C$12 | B18: =Assumptions!B21 | C18: =Assumptions!C21 | D18: =Assumptions!D21 | E18: =Assumptions!E21 | F18: =E18*(1+Assumptions!F71+$C$5) | G18: =F18*(1+Assumptions!G71+$C$5) | H18: =G18*(1+Assumptions!H71+$C$5) | I18: =H18*(1+Assumptions!I71+$C$5) | J18: =I18*(1+Assumptions!J71+$C$5) | K18: =J18*(1+Assumptions!K71+$C$5) | L18: =K18*(1+Assumptions!L71+$C$5) | M18: =L18*(1+Assumptions!M71+$C$5)
A19: =Assumptions!$C$13 | B19: =Assumptions!B22 | C19: =Assumptions!C22 | D19: =Assumptions!D22 | E19: =Assumptions!E22 | F19: =E19*(1+Assumptions!F72+$C$5) | G19: =F19*(1+Assumptions!G72+$C$5) | H19: =G19*(1+Assumptions!H72+$C$5) | I19: =H19*(1+Assumptions!I72+$C$5) | J19: =I19*(1+Assumptions!J72+$C$5) | K19: =J19*(1+Assumptions!K72+$C$5) | L19: =K19*(1+Assumptions!L72+$C$5) | M19: =L19*(1+Assumptions!M72+$C$5)
A20: =Assumptions!$C$14 | B20: =Assumptions!B23 | C20: =Assumptions!C23 | D20: =Assumptions!D23 | E20: =Assumptions!E23 | F20: =E20*(1+Assumptions!F73+$C$5) | G20: =F20*(1+Assumptions!G73+$C$5) | H20: =G20*(1+Assumptions!H73+$C$5) | I20: =H20*(1+Assumptions!I73+$C$5) | J20: =I20*(1+Assumptions!J73+$C$5) | K20: =J20*(1+Assumptions!K73+$C$5) | L20: =K20*(1+Assumptions!L73+$C$5) | M20: =L20*(1+Assumptions!M73+$C$5)
A21: Total Revenue | B21: =B15+B16+B17+B18+B19+B20 | C21: =C15+C16+C17+C18+C19+C20 | D21: =D15+D16+D17+D18+D19+D20 | E21: =E15+E16+E17+E18+E19+E20 | F21: =F15+F16+F17+F18+F19+F20 | G21: =G15+G16+G17+G18+G19+G20 | H21: =H15+H16+H17+H18+H19+H20 | I21: =I15+I16+I17+I18+I19+I20 | ... M21: =M15+M16+M17+M18+M19+M20
A22: % growth | C22: =C21/B21-1 | D22: =D21/C21-1 | E22: =E21/D21-1 | F22: =F21/E21-1 | G22: =G21/F21-1 | H22: =H21/G21-1 | I22: =I21/H21-1 | J22: =J21/I21-1 | ... M22: =M21/L21-1
A24: COST OF SALES & GROSS PROFIT
A25: Cost of sales / COGS | B25: =-B21*(1-Assumptions!B26) | C25: =-C21*(1-Assumptions!C26) | D25: =-D21*(1-Assumptions!D26) | E25: =-E21*(1-Assumptions!E26) | F25: =-F21*(1-(Assumptions!F76-$C$6)) | G25: =-G21*(1-(Assumptions!G76-$C$6)) | H25: =-H21*(1-(Assumptions!H76-$C$6)) | I25: =-I21*(1-(Assumptions!I76-$C$6)) | J25: =-J21*(1-(Assumptions!J76-$C$6)) | K25: =-K21*(1-(Assumptions!K76-$C$6)) | L25: =-L21*(1-(Assumptions!L76-$C$6)) | M25: =-M21*(1-(Assumptions!M76-$C$6))
A26: Gross Profit | B26: =B21+B25 | C26: =C21+C25 | D26: =D21+D25 | E26: =E21+E25 | F26: =F21+F25 | G26: =G21+G25 | H26: =H21+H25 | I26: =I21+I25 | ... M26: =M21+M25
A27: Gross margin % | B27: =B26/B21 | C27: =C26/C21 | D27: =D26/D21 | E27: =E26/E21 | F27: =F26/F21 | G27: =G26/G21 | H27: =H26/H21 | I27: =I26/I21 | ... M27: =M26/M21
A29: OPERATING EXPENSES
A30: Other income | B30: =Assumptions!B29 | C30: =Assumptions!C29 | D30: =Assumptions!D29 | E30: =Assumptions!E29 | F30: =Assumptions!F79 | G30: =Assumptions!G79 | H30: =Assumptions!H79 | I30: =Assumptions!I79 | J30: =Assumptions!J79 | K30: =Assumptions!K79 | L30: =Assumptions!L79 | M30: =Assumptions!M79
A31: Staff costs | B31: =Assumptions!B32 | C31: =Assumptions!C32 | D31: =Assumptions!D32 | E31: =Assumptions!E32 | F31: =-F21*Assumptions!F82 | G31: =-G21*Assumptions!G82 | H31: =-H21*Assumptions!H82 | I31: =-I21*Assumptions!I82 | J31: =-J21*Assumptions!J82 | K31: =-K21*Assumptions!K82 | L31: =-L21*Assumptions!L82 | M31: =-M21*Assumptions!M82
A32: Other operating expenses | B32: =Assumptions!B35 | C32: =Assumptions!C35 | D32: =Assumptions!D35 | E32: =Assumptions!E35 | F32: =-F21*(Assumptions!F85+$C$7) | G32: =-G21*(Assumptions!G85+$C$7) | H32: =-H21*(Assumptions!H85+$C$7) | I32: =-I21*(Assumptions!I85+$C$7) | J32: =-J21*(Assumptions!J85+$C$7) | K32: =-K21*(Assumptions!K85+$C$7) | L32: =-L21*(Assumptions!L85+$C$7) | M32: =-M21*(Assumptions!M85+$C$7)
A33: Total Operating Expenses | B33: =B31+B32 | C33: =C31+C32 | D33: =D31+D32 | E33: =E31+E32 | F33: =F31+F32 | G33: =G31+G32 | H33: =H31+H32 | I33: =I31+I32 | ... M33: =M31+M32
A34: Operating expenses — % of sales | B34: =-B33/B21 | C34: =-C33/C21 | D34: =-D33/D21 | E34: =-E33/E21 | F34: =-F33/F21 | G34: =-G33/G21 | H34: =-H33/H21 | I34: =-I33/I21 | ... M34: =-M33/M21
A36: EBITDA, D&A & EBIT
A37: EBITDA | B37: =B26+B30+B33 | C37: =C26+C30+C33 | D37: =D26+D30+D33 | E37: =E26+E30+E33 | F37: =F26+F30+F33 | G37: =G26+G30+G33 | H37: =H26+H30+H33 | I37: =I26+I30+I33 | ... M37: =M26+M30+M33
A38: EBITDA margin % | B38: =B37/B21 | C38: =C37/C21 | D38: =D37/D21 | E38: =E37/E21 | F38: =F37/F21 | G38: =G37/G21 | H38: =H37/H21 | I38: =I37/I21 | ... M38: =M37/M21
A39: Depreciation & amortisation | B39: =Assumptions!B38 | C39: =Assumptions!C38 | D39: =Assumptions!D38 | E39: =Assumptions!E38 | F39: =-F21*Assumptions!F88 | G39: =-G21*Assumptions!G88 | H39: =-H21*Assumptions!H88 | I39: =-I21*Assumptions!I88 | J39: =-J21*Assumptions!J88 | K39: =-K21*Assumptions!K88 | L39: =-L21*Assumptions!L88 | M39: =-M21*Assumptions!M88
A40: EBIT | B40: =B37+B39 | C40: =C37+C39 | D40: =D37+D39 | E40: =E37+E39 | F40: =F37+F39 | G40: =G37+G39 | H40: =H37+H39 | I40: =I37+I39 | ... M40: =M37+M39
A41: Non-recurring / QoE adjustments | B41: =Assumptions!B41 | C41: =Assumptions!C41 | D41: =Assumptions!D41 | E41: =Assumptions!E41 | F41: =Assumptions!F91 | G41: =Assumptions!G91 | H41: =Assumptions!H91 | I41: =Assumptions!I91 | J41: =Assumptions!J91 | K41: =Assumptions!K91 | L41: =Assumptions!L91 | M41: =Assumptions!M91
A42: Adjusted EBITDA | B42: =B37+B41 | C42: =C37+C41 | D42: =D37+D41 | E42: =E37+E41 | F42: =F37+F41 | G42: =G37+G41 | H42: =H37+H41 | I42: =I37+I41 | ... M42: =M37+M41
A43: Adjusted EBITDA margin % | B43: =B42/B21 | C43: =C42/C21 | D43: =D42/D21 | E43: =E42/E21 | F43: =F42/F21 | G43: =G42/G21 | H43: =H42/H21 | I43: =I42/I21 | ... M43: =M42/M21
A45: Δ Net working capital | B45: =Assumptions!B44 | C45: =Assumptions!C44 | D45: =Assumptions!D44 | E45: =Assumptions!E44 | F45: =Assumptions!F94*(1+$C$9) | G45: =Assumptions!G94*(1+$C$9) | H45: =Assumptions!H94*(1+$C$9) | I45: =Assumptions!I94*(1+$C$9) | J45: =Assumptions!J94*(1+$C$9) | K45: =Assumptions!K94*(1+$C$9) | L45: =Assumptions!L94*(1+$C$9) | M45: =Assumptions!M94*(1+$C$9)
A46: Operating Cash Flow | B46: =B42+B45 | C46: =C42+C45 | D46: =D42+D45 | E46: =E42+E45 | F46: =F42+F45 | G46: =G42+G45 | H46: =H42+H45 | I46: =I42+I45 | ... M46: =M42+M45
A47: OCF : Adjusted EBITDA % | B47: =B46/B42 | C47: =C46/C42 | D47: =D46/D42 | E47: =E46/E42 | F47: =F46/F42 | G47: =G46/G42 | H47: =H46/H42 | I47: =I46/I42 | ... M47: =M46/M42
...

Sheet 6. Sensitivity Summary
A1: Sensitivity Summary — Key Credit Metrics Across Cases
A2: Every cell below is a live link into the case tabs — tweak a flex assumption on any case tab and this page updates.
A4: Metric | B4: 1. Management Case | C4: 2. Downside Case | D4: 3. Severe Downside Case | E4: 4. Reverse Stress | F4: 5. Upside Case
A6: Total Revenue, final forecast period (£m) | B6: ='1. Management Case'!M21 | C6: ='2. Downside Case'!M21 | D6: ='3. Severe Downside Case'!M21 | E6: ='4. Reverse Stress'!M21 | F6: ='5. Upside Case'!M21
A7: Adjusted EBITDA, final forecast period (£m) | B7: ='1. Management Case'!M42 | C7: ='2. Downside Case'!M42 | D7: ='3. Severe Downside Case'!M42 | E7: ='4. Reverse Stress'!M42 | F7: ='5. Upside Case'!M42
A8: Adjusted EBITDA margin, final forecast period (%) | B8: ='1. Management Case'!M42/'1. Management Case'!M21 | C8: ='2. Downside Case'!M42/'2. Downside Case'!M21 | D8: ='3. Severe Downside Case'!M42/'3. Severe Downside Case'!M21 | E8: ='4. Reverse Stress'!M42/'4. Reverse Stress'!M21 | F8: ='5. Upside Case'!M42/'5. Upside Case'!M21
A10: Net Leverage — FY1F (x) | B10: ='1. Management Case'!F90 | C10: ='2. Downside Case'!F90 | D10: ='3. Severe Downside Case'!F90 | E10: ='4. Reverse Stress'!F90 | F10: ='5. Upside Case'!F90
A11: Net Leverage — mid-forecast (x) | B11: ='1. Management Case'!I90 | C11: ='2. Downside Case'!I90 | D11: ='3. Severe Downside Case'!I90 | E11: ='4. Reverse Stress'!I90 | F11: ='5. Upside Case'!I90
A12: Net Leverage — final forecast period (x) | B12: ='1. Management Case'!M90 | C12: ='2. Downside Case'!M90 | D12: ='3. Severe Downside Case'!M90 | E12: ='4. Reverse Stress'!M90 | F12: ='5. Upside Case'!M90
A14: Minimum DSCR across the forecast (x) | B14: =MIN('1. Management Case'!F92:M92) | C14: =MIN('2. Downside Case'!F92:M92) | D14: =MIN('3. Severe Downside Case'!F92:M92) | E14: =MIN('4. Reverse Stress'!F92:M92) | F14: =MIN('5. Upside Case'!F92:M92)
A15: Minimum Interest Cover across the forecast (x) | B15: =MIN('1. Management Case'!F91:M91) | C15: =MIN('2. Downside Case'!F91:M91) | D15: =MIN('3. Severe Downside Case'!F91:M91) | E15: =MIN('4. Reverse Stress'!F91:M91) | F15: =MIN('5. Upside Case'!F91:M91)
A16: Worst leverage headroom across the forecast (x) | B16: =MIN('1. Management Case'!F96:M96) | C16: =MIN('2. Downside Case'!F96:M96) | D16: =MIN('3. Severe Downside Case'!F96:M96) | E16: =MIN('4. Reverse Stress'!F96:M96) | F16: =MIN('5. Upside Case'!F96:M96)
A17: Lowest undrawn RCF across the forecast (£m) | B17: =MIN('1. Management Case'!F85:M85) | C17: =MIN('2. Downside Case'!F85:M85) | D17: =MIN('3. Severe Downside Case'!F85:M85) | E17: =MIN('4. Reverse Stress'!F85:M85) | F17: =MIN('5. Upside Case'!F85:M85)
A19: Any covenant breach across the forecast? | B19: =IF(COUNTIF('1. Management Case'!F99:M99,"FAIL")>0,"BREACH","Clean") | C19: =IF(COUNTIF('2. Downside Case'!F99:M99,"FAIL")>0,"BREACH","Clean") | D19: =IF(COUNTIF('3. Severe Downside Case'!F99:M99,"FAIL")>0,"BREACH","Clean") | E19: =IF(COUNTIF('4. Reverse Stress'!F99:M99,"FAIL")>0,"BREACH","Clean") | F19: =IF(COUNTIF('5. Upside Case'!F99:M99,"FAIL")>0,"BREACH","Clean")
