Workbook

Sheet ReadMe
A1: BoE Private Markets SWES — APT Factor Shock File (v2, formula-transparent)
A3: Source: BoE Private Markets SWES Variable Paths annex. Generated 2026-07-10. Methodology: SWES_PrivateCredit_Framework.pdf Sections 5.3 & 7.
A5: FIVE CUMULATIVE RUNS — each is one instantaneous APT scenario applied to the SAME jump-off portfolio:
A6: Run 1 (end-Y1) ... Run 5 (end-Y5). Each run carries the ENTIRE journey from jump-off to that year-end.
A7: Never apply an annual change to an already-shocked base: the end-Y2 scenario REPLACES the end-Y1 scenario, it does not stack on it.
A8: Year-on-year incremental P&L (if templates require) = result(Run n) − result(Run n−1), plus coupon carry computed outside APT.
A9: Run 2 (end-Y2) is the peak / max-drawdown point for the credit book: spreads peak end-Y2 across the annex.
A11: ALL CUMULATIVE CELLS ARE LIVE FORMULAS, chained year by year for auditability:
A12: % change variables : cum(n) = (1+cum(n−1)) × (1+annual(n)) − 1 e.g. FTSE end-Y2 = (1−0.31)×(1−0.06)−1 = −35.1%
A13: bp change variables: cum(n) = cum(n−1) + annual(n) e.g. GBP HY end-Y2 = 390+400 = +790bp
A14: level variables : Run 1 = end-Y1 level, interpolated as (avgY1+avgY2)/2 on monotone paths, or Y1 avg where Y1 is the
A15: path extreme (IF formula visible in cell — e.g. VIX, gilt yields). Runs 2–5 = Y2..Y5 annual averages.
... A27: CHECK FIRST: participant guidance-pack conventions (jump-off date, FX, static vs action-adjusted balance sheet) override defaults here.

Sheet 1_Change_Shocks
A1: Group | B1: Variable | C1: Unit of shock | D1: APT factor family | E1: Use | F1: Y1 annual | G1: Y2 annual | H1: Y3 annual | I1: Y4 annual | J1: Y5 annual | K1: Run 1 cum end-Y1 | L1: Run 2 cum end-Y2 (PEAK) | M1: Run 3 cum end-Y3 | N1: Run 4 cum end-Y4 | O1: Run 5 cum end-Y5
A2: UK macro | B2: UK real GDP | C2: % (compounded) | D2: n/a — macro | E2: Engine 2 input | F2: -0.02 | G2: -0.02 | H2: 0.007 | I2: 0.007 | J2: 0.007 | K2: =F2 | L2: =(1+K2)*(1+G2)-1 | M2: =(1+L2)*(1+H2)-1 | N2: =(1+M2)*(1+I2)-1 | O2: =(1+N2)*(1+J2)-1
A3: UK macro | B3: UK nominal GDP | C3: % (compounded) | D3: n/a — macro | E3: Engine 2 input | F3: -0.015 | G3: -0.015 | H3: 0.015 | I3: 0.03 | J3: 0.035 | K3: =F3 | L3: =(1+K3)*(1+G3)-1 | M3: =(1+L3)*(1+H3)-1 | N3: =(1+M3)*(1+I3)-1 | O3: =(1+N3)*(1+J3)-1
A4: UK macro | B4: UK house prices | C4: % (compounded) | D4: n/a — macro | E4: Engine 2 input | F4: -0.05 | G4: -0.12 | H4: -0.11 | I4: 0.02 | J4: 0.07 | K4: =F4 | L4: =(1+K4)*(1+G4)-1 | M4: =(1+L4)*(1+H4)-1 | N4: =(1+M4)*(1+I4)-1 | O4: =(1+N4)*(1+J4)-1
A5: UK macro | B5: UK commercial real estate prices | C5: % (compounded) | D5: n/a — macro | E5: Engine 2 input | F5: -0.13 | G5: -0.21 | H5: -0.01 | I5: 0.07 | J5: 0.07 | K5: =F5 | L5: =(1+K5)*(1+G5)-1 | M5: =(1+L5)*(1+H5)-1 | N5: =(1+M5)*(1+I5)-1 | O5: =(1+N5)*(1+J5)-1
A6: UK macro | B6: UK CPI | C6: % (compounded) | D6: n/a — macro | E6: Engine 2 input | F6: 0.07 | G6: 0.045 | H6: 0.027 | I6: 0.023 | J6: 0.02 | K6: =F6 | L6: =(1+K6)*(1+G6)-1 | M6: =(1+L6)*(1+H6)-1 | N6: =(1+M6)*(1+I6)-1 | O6: =(1+N6)*(1+J6)-1
A7: US macro | B7: US real GDP | C7: % (compounded) | D7: n/a — macro | E7: Engine 2 input | F7: -0.015 | G7: -0.015 | H7: 0.007 | I7: 0.007 | J7: 0.007 | K7: =F7 | L7: =(1+K7)*(1+G7)-1 | M7: =(1+L7)*(1+H7)-1 | N7: =(1+M7)*(1+I7)-1 | O7: =(1+N7)*(1+J7)-1
A8: US macro | B8: US house prices | C8: % (compounded) | D8: n/a — macro | E8: Engine 2 input | F8: -0.04 | G8: -0.1 | H8: -0.11 | I8: 0.01 | J8: 0.1 | K8: =F8 | L8: =(1+K8)*(1+G8)-1 | M8: =(1+L8)*(1+H8)-1 | N8: =(1+M8)*(1+I8)-1 | O8: =(1+N8)*(1+J8)-1
A9: US macro | B9: US commercial real estate prices | C9: % (compounded) | D9: n/a — macro | E9: Engine 2 input | F9: -0.16 | G9: -0.25 | H9: -0.06 | I9: 0.14 | J9: 0.14 | K9: =F9 | L9: =(1+K9)*(1+G9)-1 | M9: =(1+L9)*(1+H9)-1 | N9: =(1+M9)*(1+I9)-1 | O9: =(1+N9)*(1+J9)-1
A10: US macro | B10: US PCE price index | C10: % (compounded) | D10: n/a — macro | E10: Engine 2 input | F10: 0.052 | G10: 0.038 | H10: 0.027 | I10: 0.023 | J10: 0.02 | K10: =F10 | L10: =(1+K10)*(1+G10)-1 | M10: =(1+L10)*(1+H10)-1 | N10: =(1+M10)*(1+I10)-1 | O10: =(1+N10)*(1+J10)-1
A11: Euro area macro | B11: Euro area real GDP | C11: % (compounded) | D11: n/a — macro | E11: Engine 2 input | F11: -0.015 | G11: -0.015 | H11: 0.006 | I11: 0.006 | J11: 0.006 | K11: =F11 | L11: =(1+K11)*(1+G11)-1 | M11: =(1+L11)*(1+H11)-1 | N11: =(1+M11)*(1+I11)-1 | O11: =(1+N11)*(1+J11)-1
A12: Euro area macro | B12: Euro area house prices | C12: % (compounded) | D12: n/a — macro | E12: Engine 2 input | F12: -0.02 | G12: -0.08 | H12: -0.09 | I12: 0 | J12: 0.07 | K12: =F12 | L12: =(1+K12)*(1+G12)-1 | M12: =(1+L12)*(1+H12)-1 | N12: =(1+M12)*(1+I12)-1 | O12: =(1+N12)*(1+J12)-1
A13: Euro area macro | B13: Euro area commercial real estate prices | C13: % (compounded) | D13: n/a — macro | E13: Engine 2 input | F13: -0.14 | G13: -0.23 | H13: -0.06 | I13: 0.11 | J13: 0.11 | K13: =F13 | L13: =(1+K13)*(1+G13)-1 | M13: =(1+L13)*(1+H13)-1 | N13: =(1+M13)*(1+I13)-1 | O13: =(1+N13)*(1+J13)-1
A14: Euro area macro | B14: Euro area HICP | C14: % (compounded) | D14: n/a — macro | E14: Engine 2 input | F14: 0.06 | G14: 0.042 | H14: 0.027 | I14: 0.023 | J14: 0.02 | K14: =F14 | L14: =(1+K14)*(1+G14)-1 | M14: =(1+L14)*(1+H14)-1 | N14: =(1+M14)*(1+I14)-1 | O14: =(1+N14)*(1+J14)-1
A15: Corporate bond spreads | B15: Sterling IG corporate bond spread | C15: bp (summed) | D15: Credit spread factor — GBP by rating | E15: APT factor | F15: 120 | G15: 110 | H15: -50 | I15: -50 | J15: -50 | K15: =F15 | L15: =K15+G15 | M15: =L15+H15 | N15: =M15+I15 | O15: =N15+J15
A16: Corporate bond spreads | B16: Sterling AAA corporate bond spread | C16: bp (summed) | D16: Credit spread factor — GBP by rating | E16: APT factor | F16: 50 | G16: 40 | H16: -20 | I16: -20 | J16: -20 | K16: =F16 | L16: =K16+G16 | M16: =L16+H16 | N16: =M16+I16 | O16: =N16+J16
A17: Corporate bond spreads | B17: Sterling AA corporate bond spread | C17: bp (summed) | D17: Credit spread factor — GBP by rating | E17: APT factor | F17: 100 | G17: 70 | H17: -40 | I17: -40 | J17: -40 | K17: =F17 | L17: =K17+G17 | M17: =L17+H17 | N17: =M17+I17 | O17: =N17+J17
A18: Corporate bond spreads | B18: Sterling A corporate bond spread | C18: bp (summed) | D18: Credit spread factor — GBP by rating | E18: APT factor | F18: 140 | G18: 110 | H18: -60 | I18: -60 | J18: -60 | K18: =F18 | L18: =K18+G18 | M18: =L18+H18 | N18: =M18+I18 | O18: =N18+J18
A19: Corporate bond spreads | B19: Sterling BBB corporate bond spread | C19: bp (summed) | D19: Credit spread factor — GBP by rating | E19: APT factor | F19: 180 | G19: 150 | H19: -70 | I19: -70 | J19: -70 | K19: =F19 | L19: =K19+G19 | M19: =L19+H19 | N19: =M19+I19 | O19: =N19+J19
A20: Corporate bond spreads | B20: Sterling HY corporate bond spread | C20: bp (summed) | D20: Credit spread factor — GBP by rating | E20: APT factor | F20: 390 | G20: 400 | H20: -200 | I20: -200 | J20: -200 | K20: =F20 | L20: =K20+G20 | M20: =L20+H20 | N20: =M20+I20 | O20: =N20+J20
A21: Corporate bond spreads | B21: Sterling BB corporate bond spread | C21: bp (summed) | D21: Credit spread factor — GBP by rating | E21: APT factor | F21: 370 | G21: 310 | H21: -160 | I21: -160 | J21: -160 | K21: =F21 | L21: =K21+G21 | M21: =L21+H21 | N21: =M21+I21 | O21: =N21+J21
A22: Corporate bond spreads | B22: Sterling B corporate bond spread | C22: bp (summed) | D22: Credit spread factor — GBP by rating | E22: APT factor | F22: 440 | G22: 420 | H22: -210 | I22: -210 | J22: -210 | K22: =F22 | L22: =K22+G22 | M22: =L22+H22 | N22: =M22+I22 | O22: =N22+J22
A23: Corporate bond spreads | B23: Sterling CCC corporate bond spread | C23: bp (summed) | D23: Credit spread factor — GBP by rating | E23: APT factor | F23: 380 | G23: 380 | H23: -360 | I23: -360 | J23: -360 | K23: =F23 | L23: =K23+G23 | M23: =L23+H23 | N23: =M23+I23 | O23: =N23+J23
A24: Corporate bond spreads | B24: US dollar IG corporate bond spread | C24: bp (summed) | D24: Credit spread factor — USD by rating | E24: APT factor | F24: 130 | G24: 110 | H24: -50 | I24: -50 | J24: -50 | K24: =F24 | L24: =K24+G24 | M24: =L24+H24 | N24: =M24+I24 | O24: =N24+J24
A25: Corporate bond spreads | B25: US dollar AAA corporate bond spread | C25: bp (summed) | D25: Credit spread factor — USD by rating | E25: APT factor | F25: 50 | G25: 40 | H25: -20 | I25: -20 | J25: -20 | K25: =F25 | L25: =K25+G25 | M25: =L25+H25 | N25: =M25+I25 | O25: =N25+J25
A26: Corporate bond spreads | B26: US dollar AA corporate bond spread | C26: bp (summed) | D26: Credit spread factor — USD by rating | E26: APT factor | F26: 100 | G26: 70 | H26: -40 | I26: -40 | J26: -40 | K26: =F26 | L26: =K26+G26 | M26: =L26+H26 | N26: =M26+I26 | O26: =N26+J26
... A32: Corporate bond spreads | B32: US dollar CCC corporate bond spread | C32: bp (summed) | D32: Credit spread factor — USD by rating | E32: APT factor | F32: 600 | G32: 720 | H32: -360 | I32: -360 | J32: -360 | K32: =F32 | L32: =K32+G32 | M32: =L32+H32 | N32: =M32+I32 | O32: =N32+J32
A33: Sector revenues | B33: UK average revenue - Aggregate | C33: % (compounded) | D33: n/a — borrower fundamentals | E33: Engine 2 input | F33: -0.05 | G33: -0.05 | H33: 0.04 | I33: 0.05 | J33: 0.06 | K33: =F33 | L33: =(1+K33)*(1+G33)-1 | M33: =(1+L33)*(1+H33)-1 | N33: =(1+M33)*(1+I33)-1 | O33: =(1+N33)*(1+J33)-1
A34: Sector revenues | B34: UK average revenue - Consumer Discretionary | C34: % (compounded) | D34: n/a — borrower fundamentals | E34: Engine 2 input | F34: -0.1 | G34: -0.11 | H34: 0.11 | I34: 0.1 | J34: 0.08 | K34: =F34 | L34: =(1+K34)*(1+G34)-1 | M34: =(1+L34)*(1+H34)-1 | N34: =(1+M34)*(1+I34)-1 | O34: =(1+N34)*(1+J34)-1
A35: Sector revenues | B35: UK average revenue - Consumer Staples | C35: % (compounded) | D35: n/a — borrower fundamentals | E35: Engine 2 input | F35: -0.05 | G35: -0.05 | H35: 0.04 | I35: 0.05 | J35: 0.04 | K35: =F35 | L35: =(1+K35)*(1+G35)-1 | M35: =(1+L35)*(1+H35)-1 | N35: =(1+M35)*(1+I35)-1 | O35: =(1+N35)*(1+J35)-1
A36: Sector revenues | B36: UK average revenue - Energy | C36: % (compounded) | D36: n/a — borrower fundamentals | E36: Engine 2 input | F36: 0.08 | G36: 0.07 | H36: -0.02 | I36: -0.01 | J36: -0.02 | K36: =F36 | L36: =(1+K36)*(1+G36)-1 | M36: =(1+L36)*(1+H36)-1 | N36: =(1+M36)*(1+I36)-1 | O36: =(1+N36)*(1+J36)-1
A37: Sector revenues | B37: UK average revenue - Financial Services | C37: % (compounded) | D37: n/a — borrower fundamentals | E37: Engine 2 input | F37: -0.1 | G37: -0.11 | H37: 0.05 | I37: 0.06 | J37: 0.05 | K37: =F37 | L37: =(1+K37)*(1+G37)-1 | M37: =(1+L37)*(1+H37)-1 | N37: =(1+M37)*(1+I37)-1 | O37: =(1+N37)*(1+J37)-1
A38: Sector revenues | B38: UK average revenue - Health Care | C38: % (compounded) | D38: n/a — borrower fundamentals | E38: Engine 2 input | F38: -0.05 | G38: -0.05 | H38: 0.04 | I38: 0.05 | J38: 0.04 | K38: =F38 | L38: =(1+K38)*(1+G38)-1 | M38: =(1+L38)*(1+H38)-1 | N38: =(1+M38)*(1+I38)-1 | O38: =(1+N38)*(1+J38)-1
A39: Sector revenues | B39: UK average revenue - Industrial | C39: % (compounded) | D39: n/a — borrower fundamentals | E39: Engine 2 input | F39: -0.1 | G39: -0.11 | H39: 0.11 | I39: 0.1 | J39: 0.08 | K39: =F39 | L39: =(1+K39)*(1+G39)-1 | M39: =(1+L39)*(1+H39)-1 | N39: =(1+M39)*(1+I39)-1 | O39: =(1+N39)*(1+J39)-1
A40: Sector revenues | B40: UK average revenue - Materials | C40: % (compounded) | D40: n/a — borrower fundamentals | E40: Engine 2 input | F40: -0.05 | G40: -0.05 | H40: 0.04 | I40: 0.05 | J40: 0.04 | K40: =F40 | L40: =(1+K40)*(1+G40)-1 | M40: =(1+L40)*(1+H40)-1 | N40: =(1+M40)*(1+I40)-1 | O40: =(1+N40)*(1+J40)-1
A41: Sector revenues | B41: UK average revenue - Real Estate | C41: % (compounded) | D41: n/a — borrower fundamentals | E41: Engine 2 input | F41: -0.1 | G41: -0.11 | H41: 0.11 | I41: 0.1 | J41: 0.08 | K41: =F41 | L41: =(1+K41)*(1+G41)-1 | M41: =(1+L41)*(1+H41)-1 | N41: =(1+M41)*(1+I41)-1 | O41: =(1+N41)*(1+J41)-1
A42: Sector revenues | B42: UK average revenue - Technology | C42: % (compounded) | D42: n/a — borrower fundamentals | E42: Engine 2 input | F42: -0.1 | G42: -0.11 | H42: 0.05 | I42: 0.06 | J42: 0.05 | K42: =F42 | L42: =(1+K42)*(1+G42)-1 | M42: =(1+L42)*(1+H42)-1 | N42: =(1+M42)*(1+I42)-1 | O42: =(1+N42)*(1+J42)-1
A43: Sector revenues | B43: UK average revenue - Telecom | C43: % (compounded) | D43: n/a — borrower fundamentals | E43: Engine 2 input | F43: -0.05 | G43: -0.05 | H43: 0.04 | I43: 0.05 | J43: 0.04 | K43: =F43 | L43: =(1+K43)*(1+G43)-1 | M43: =(1+L43)*(1+H43)-1 | N43: =(1+M43)*(1+I43)-1 | O43: =(1+N43)*(1+J43)-1
A44: Sector revenues | B44: UK average revenue - Utilities | C44: % (compounded) | D44: n/a — borrower fundamentals | E44: Engine 2 input | F44: 0.02 | G44: 0.03 | H44: -0.01 | I44: 0 | J44: -0.01 | K44: =F44 | L44: =(1+K44)*(1+G44)-1 | M44: =(1+L44)*(1+H44)-1 | N44: =(1+M44)*(1+I44)-1 | O44: =(1+N44)*(1+J44)-1
... A109: Leveraged loan indices (LLIs) | B109: Morningstar European BB Ratings Loan price index | C109: % (compounded) | D109: Loan price index | E109: Cross-check vs FRN revaluation | F109: -0.23 | G109: -0.06 | H109: 0.1 | I109: 0.1 | J109: 0.1 | K109: =F109 | L109: =(1+K109)*(1+G109)-1 | M109: =(1+L109)*(1+H109)-1 | N109: =(1+M109)*(1+I109)-1 | O109: =(1+N109)*(1+J109)-1
...

Sheet 2_Rate_Levels
A1: Group | B1: Variable | C1: Unit | D1: APT factor family | E1: Use | F1: Y1 avg | G1: Y2 avg | H1: Y3 avg | I1: Y4 avg | J1: Y5 avg | K1: Run 1 level end-Y1 (interp.) | L1: Run 2 level (Y2 avg, PEAK) | M1: Run 3 level (Y3 avg) | N1: Run 4 level (Y4 avg) | O1: Run 5 level (Y5 avg) | P1: JUMP-OFF level (ENTER) | Q1: Run 1 shock | R1: Run 2 shock | S1: Run 3 shock | T1: Run 4 shock | U1: Run 5 shock
A2: UK macro | B2: UK unemployment rate | C2: % | D2: n/a — macro | E2: Engine 2 input | F2: 0.052 | G2: 0.064 | H2: 0.075 | I2: 0.072 | J2: 0.069 | K2: =IF(AND(F2>G2,F2>=MAX(F2:J2)),F2,(F2+G2)/2) | L2: =G2 | M2: =H2 | N2: =I2 | O2: =J2 | Q2: =IF($P2="","",K2-$P2) | R2: =IF($P2="","",L2-$P2) | S2: =IF($P2="","",M2-$P2) | T2: =IF($P2="","",N2-$P2) | U2: =IF($P2="","",O2-$P2)
A3: UK macro | B3: Bank Rate | C3: % | D3: Policy rate (captured via SONIA/SOFR/Euribor o/n) | E3: Reference only | F3: 0.06 | G3: 0.07 | H3: 0.06 | I3: 0.05 | J3: 0.04 | K3: =IF(AND(F3>G3,F3>=MAX(F3:J3)),F3,(F3+G3)/2) | L3: =G3 | M3: =H3 | N3: =I3 | O3: =J3 | Q3: =IF($P3="","",K3-$P3) | R3: =IF($P3="","",L3-$P3) | S3: =IF($P3="","",M3-$P3) | T3: =IF($P3="","",N3-$P3) | U3: =IF($P3="","",O3-$P3)
A4: US macro | B4: US unemployment rate | C4: % | D4: n/a — macro | E4: Engine 2 input | F4: 0.048 | G4: 0.067 | H4: 0.08 | I4: 0.074 | J4: 0.068 | K4: =IF(AND(F4>G4,F4>=MAX(F4:J4)),F4,(F4+G4)/2) | L4: =G4 | M4: =H4 | N4: =I4 | O4: =J4 | Q4: =IF($P4="","",K4-$P4) | R4: =IF($P4="","",L4-$P4) | S4: =IF($P4="","",M4-$P4) | T4: =IF($P4="","",N4-$P4) | U4: =IF($P4="","",O4-$P4)
A5: US macro | B5: US policy rate | C5: % | D5: Policy rate (captured via SONIA/SOFR/Euribor o/n) | E5: Reference only | F5: 0.06 | G5: 0.07 | H5: 0.06 | I5: 0.05 | J5: 0.04 | K5: =IF(AND(F5>G5,F5>=MAX(F5:J5)),F5,(F5+G5)/2) | L5: =G5 | M5: =H5 | N5: =I5 | O5: =J5 | Q5: =IF($P5="","",K5-$P5) | R5: =IF($P5="","",L5-$P5) | S5: =IF($P5="","",M5-$P5) | T5: =IF($P5="","",N5-$P5) | U5: =IF($P5="","",O5-$P5)
A6: Euro area macro | B6: Euro area unemployment rate | C6: % | D6: n/a — macro | E6: Engine 2 input | F6: 0.069 | G6: 0.086 | H6: 0.1 | I6: 0.095 | J6: 0.091 | K6: =IF(AND(F6>G6,F6>=MAX(F6:J6)),F6,(F6+G6)/2) | L6: =G6 | M6: =H6 | N6: =I6 | O6: =J6 | Q6: =IF($P6="","",K6-$P6) | R6: =IF($P6="","",L6-$P6) | S6: =IF($P6="","",M6-$P6) | T6: =IF($P6="","",N6-$P6) | U6: =IF($P6="","",O6-$P6)
A7: Euro area macro | B7: ECB policy rate | C7: % | D7: Policy rate (captured via SONIA/SOFR/Euribor o/n) | E7: Reference only | F7: 0.04 | G7: 0.05 | H7: 0.04 | I7: 0.03 | J7: 0.02 | K7: =IF(AND(F7>G7,F7>=MAX(F7:J7)),F7,(F7+G7)/2) | L7: =G7 | M7: =H7 | N7: =I7 | O7: =J7 | Q7: =IF($P7="","",K7-$P7) | R7: =IF($P7="","",L7-$P7) | S7: =IF($P7="","",M7-$P7) | T7: =IF($P7="","",N7-$P7) | U7: =IF($P7="","",O7-$P7)
A8: Commodity prices | B8: Brent crude oil price | C8: US dollars per barrel | D8: Commodity factor (Brent) | E8: APT factor | F8: 125 | G8: 155 | H8: 140 | I8: 125 | J8: 110 | K8: =IF(AND(F8>G8,F8>=MAX(F8:J8)),F8,(F8+G8)/2) | L8: =G8 | M8: =H8 | N8: =I8 | O8: =J8 | Q8: =IF($P8="","",K8-$P8) | R8: =IF($P8="","",L8-$P8) | S8: =IF($P8="","",M8-$P8) | T8: =IF($P8="","",N8-$P8) | U8: =IF($P8="","",O8-$P8)
A9: Equity prices | B9: CBOE Volatility Index | C9: Units | D9: Volatility factor (VIX) | E9: APT factor | F9: 40 | G9: 25 | H9: 25 | I9: 25 | J9: 20 | K9: =IF(AND(F9>G9,F9>=MAX(F9:J9)),F9,(F9+G9)/2) | L9: =G9 | M9: =H9 | N9: =I9 | O9: =J9 | Q9: =IF($P9="","",K9-$P9) | R9: =IF($P9="","",L9-$P9) | S9: =IF($P9="","",M9-$P9) | T9: =IF($P9="","",N9-$P9) | U9: =IF($P9="","",O9-$P9)
A10: UK government bond yields | B10: 3m government bond yield | C10: % | D10: Government curve node — GBP | E10: APT factor | F10: 0.061 | G10: 0.071 | H10: 0.061 | I10: 0.05 | J10: 0.04 | K10: =IF(AND(F10>G10,F10>=MAX(F10:J10)),F10,(F10+G10)/2) | L10: =G10 | M10: =H10 | N10: =I10 | O10: =J10 | Q10: =IF($P10="","",K10-$P10) | R10: =IF($P10="","",L10-$P10) | S10: =IF($P10="","",M10-$P10) | T10: =IF($P10="","",N10-$P10) | U10: =IF($P10="","",O10-$P10)
A11: UK government bond yields | B11: 1y government bond yield | C11: % | D11: Government curve node — GBP | E11: APT factor | F11: 0.065 | G11: 0.072 | H11: 0.062 | I11: 0.051 | J11: 0.041 | K11: =IF(AND(F11>G11,F11>=MAX(F11:J11)),F11,(F11+G11)/2) | L11: =G11 | M11: =H11 | N11: =I11 | O11: =J11 | Q11: =IF($P11="","",K11-$P11) | R11: =IF($P11="","",L11-$P11) | S11: =IF($P11="","",M11-$P11) | T11: =IF($P11="","",N11-$P11) | U11: =IF($P11="","",O11-$P11)
A12: UK government bond yields | B12: 2y government bond yield | C12: % | D12: Government curve node — GBP | E12: APT factor | F12: 0.07 | G12: 0.069 | H12: 0.058 | I12: 0.047 | J12: 0.036 | K12: =IF(AND(F12>G12,F12>=MAX(F12:J12)),F12,(F12+G12)/2) | L12: =G12 | M12: =H12 | N12: =I12 | O12: =J12 | Q12: =IF($P12="","",K12-$P12) | R12: =IF($P12="","",L12-$P12) | S12: =IF($P12="","",M12-$P12) | T12: =IF($P12="","",N12-$P12) | U12: =IF($P12="","",O12-$P12)
A13: UK government bond yields | B13: 3y government bond yield | C13: % | D13: Government curve node — GBP | E13: APT factor | F13: 0.07 | G13: 0.066 | H13: 0.055 | I13: 0.043 | J13: 0.035 | K13: =IF(AND(F13>G13,F13>=MAX(F13:J13)),F13,(F13+G13)/2) | L13: =G13 | M13: =H13 | N13: =I13 | O13: =J13 | Q13: =IF($P13="","",K13-$P13) | R13: =IF($P13="","",L13-$P13) | S13: =IF($P13="","",M13-$P13) | T13: =IF($P13="","",N13-$P13) | U13: =IF($P13="","",O13-$P13)
... A75: Euribor | B75: 20y swap rate | C75: % | D75: Swap curve node — Euribor | E75: APT factor | F75: 0.037 | G75: 0.035 | H75: 0.028 | I75: 0.022 | J75: 0.016 | K75: =IF(AND(F75>G75,F75>=MAX(F75:J75)),F75,(F75+G75)/2) | L75: =G75 | M75: =H75 | N75: =I75 | O75: =J75 | Q75: =IF($P75="","",K75-$P75) | R75: =IF($P75="","",L75-$P75) | S75: =IF($P75="","",M75-$P75) | T75: =IF($P75="","",N75-$P75) | U75: =IF($P75="","",O75-$P75)

Sheet 3_Derived_PC
A1: Bucket-B expansion: private credit discount-margin shocks = beta × LSTA US Leveraged Loan nominal spread path (live link to Sheet 1)
A2: Anchor: 1_Change_Shocks row 110 (Morningstar LSTA US Leveraged Loan nominal spread). Betas in yellow are WORKING ASSUMPTIONS pending CDLI/Lincoln/KBRA calibration (framework Section 7.1). Engine 2 migration add-ons apply per name ON TOP.
A4: Derived variable | B4: Beta (edit) | C4: Run 1 DM shock (bp) | D4: Run 2 DM shock — PEAK (bp) | E4: Run 3 DM shock (bp) | F4: Run 4 DM shock (bp) | G4: Run 5 DM shock (bp)
A5: Private credit DM — senior middle-market direct lending | B5: 0.75 | C5: =$B5*'1_Change_Shocks'!K110 | D5: =$B5*'1_Change_Shocks'!L110 | E5: =$B5*'1_Change_Shocks'!M110 | F5: =$B5*'1_Change_Shocks'!N110 | G5: =$B5*'1_Change_Shocks'!O110
A6: Private credit DM — unitranche | B6: 0.85 | C6: =$B6*'1_Change_Shocks'!K110 | D6: =$B6*'1_Change_Shocks'!L110 | E6: =$B6*'1_Change_Shocks'!M110 | F6: =$B6*'1_Change_Shocks'!N110 | G6: =$B6*'1_Change_Shocks'!O110
A7: Private credit DM — junior / mezzanine | B7: 1 | C7: =$B7*'1_Change_Shocks'!K110 | D7: =$B7*'1_Change_Shocks'!L110 | E7: =$B7*'1_Change_Shocks'!M110 | F7: =$B7*'1_Change_Shocks'!N110 | G7: =$B7*'1_Change_Shocks'!O110
A8: Sensitivity: senior DM, low beta | B8: 0.6 | C8: =$B8*'1_Change_Shocks'!K110 | D8: =$B8*'1_Change_Shocks'!L110 | E8: =$B8*'1_Change_Shocks'!M110 | F8: =$B8*'1_Change_Shocks'!N110 | G8: =$B8*'1_Change_Shocks'!O110
A9: Sensitivity: senior DM, high beta (PC = BSL) | B9: 1 | C9: =$B9*'1_Change_Shocks'!K110 | D9: =$B9*'1_Change_Shocks'!L110 | E9: =$B9*'1_Change_Shocks'!M110 | F9: =$B9*'1_Change_Shocks'!N110 | G9: =$B9*'1_Change_Shocks'!O110
