Workbook

Sheet 0_ReadMe
A1: UK REVENUE & EV/EBITDA SHOCK PROPAGATION — BETA vs REAL-DATA, SIDE BY SIDE
A2: GICS Level 1 (Sector) -> Level 4 (Sub-Industry), UK only, both metrics, both methods compared
A5: SCOPE
A6: This workbook is UK-only (US removed) and covers both PRA SWES metrics: Revenue and EV/EBITDA multiple.
A7: For each of 163 GICS sub-industries, both a Damodaran-beta-based estimate AND a real-Bloomberg-data-based
A8: estimate are computed side by side, with the divergence between them shown explicitly. Companion to
A9: GICS_Shock_Propagation_L1_to_L4.xlsx (the original, broader US+UK build) and
A10: UK_EVEBITDA_Methodology_Change.pdf (the first-principles rationale for the real-data substitution).
A12: A BUG FIXED FROM THE PREVIOUS FILE
A13: The prior workbook showed #VALUE! errors in the live cascade once opened in real Excel, despite passing
A14: every structural check I could run without a live Excel engine. Most likely cause: a chain of formulas
A15: referencing formulas across sheets (a helper column computed by INDEX/MATCH, itself fed into a SUMPRODUCT
... A54: 7_Output clean flat table for lookup against a loan tape's GICS sub-industry code

Sheet 1_GICS_Structure
A1: Reference sheet, unchanged from GICS_Shock_Propagation_L1_to_L4.xlsx. All 163 GICS sub-industries, crosswalked to a Damodaran industry. Weight defaults to 1 (equal-weight).
A2: Sector Code | B2: Sector | C2: IG Code | D2: Industry Group | E2: Industry Code | F2: Industry | G2: Sub-Ind Code | H2: Sub-Industry | I2: Damodaran Industry (crosswalk) | J2: Weight
A3: 10 | B3: Energy | C3: 1010 | D3: Energy | E3: 101010 | F3: Energy Equipment & Services | G3: 10101010 | H3: Oil & Gas Drilling | I3: Oilfield Svcs/Equip. | J3: 1
A4: 10 | B4: Energy | C4: 1010 | D4: Energy | E4: 101010 | F4: Energy Equipment & Services | G4: 10101020 | H4: Oil & Gas Equipment & Services | I4: Oilfield Svcs/Equip. | J4: 1
A5: 10 | B5: Energy | C5: 1010 | D5: Energy | E5: 101020 | F5: Oil, Gas & Consumable Fuels | G5: 10102010 | H5: Integrated Oil & Gas | I5: Oil/Gas (Integrated) | J5: 1
A6: 10 | B6: Energy | C6: 1010 | D6: Energy | E6: 101020 | F6: Oil, Gas & Consumable Fuels | G6: 10102020 | H6: Oil & Gas Exploration & Production | I6: Oil/Gas (Production and Exploration) | J6: 1
A7: 10 | B7: Energy | C7: 1010 | D7: Energy | E7: 101020 | F7: Oil, Gas & Consumable Fuels | G7: 10102030 | H7: Oil & Gas Refining & Marketing | I7: Oil/Gas Distribution | J7: 1
A8: 10 | B8: Energy | C8: 1010 | D8: Energy | E8: 101020 | F8: Oil, Gas & Consumable Fuels | G8: 10102040 | H8: Oil & Gas Storage & Transportation | I8: Oil/Gas Distribution | J8: 1
A9: 10 | B9: Energy | C9: 1010 | D9: Energy | E9: 101020 | F9: Oil, Gas & Consumable Fuels | G9: 10102050 | H9: Coal & Consumable Fuels | I9: Coal & Related Energy | J9: 1
A10: 15 | B10: Materials | C10: 1510 | D10: Materials | E10: 151010 | F10: Chemicals | G10: 15101010 | H10: Commodity Chemicals | I10: Chemical (Basic) | J10: 1
A11: 15 | B11: Materials | C11: 1510 | D11: Materials | E11: 151010 | F11: Chemicals | G11: 15101020 | H11: Diversified Chemicals | I11: Chemical (Diversified) | J11: 1
A12: 15 | B12: Materials | C12: 1510 | D12: Materials | E12: 151010 | F12: Chemicals | G12: 15101030 | H12: Fertilizers & Agricultural Chemicals | I12: Chemical (Basic) | J12: 1
A13: 15 | B13: Materials | C13: 1510 | D13: Materials | E13: 151010 | F13: Chemicals | G13: 15101040 | H13: Industrial Gases | I13: Chemical (Specialty) | J13: 1
A14: 15 | B14: Materials | C14: 1510 | D14: Materials | E14: 151010 | F14: Chemicals | G14: 15101050 | H14: Specialty Chemicals | I14: Chemical (Specialty) | J14: 1
... A165: 60 | B165: Real Estate | C165: 6020 | D165: Real Estate Management & Development | E165: 602010 | F165: Real Estate Management & Development | G165: 60201040 | H165: Real Estate Services | I165: Real Estate (Operations & Services) | J165: 1

Sheet 2_Damodaran_Betas
A1: Reference sheet, unchanged. Damodaran industry betas (NYU Stern, updated 5 Jan 2026, US companies), credibility-shrunk toward the ex-financials market mean.
A2: Industry Name | B2: Number of firms | C2: Raw Beta | D2: Unlevered Beta (corrected for cash) | E2: Credibility n/(n+10) | F2: Shrunk Beta (used in cascade)
A3: Advertising | B3: 52 | C3: 1.2105 | D3: 1.008 | E3: =B3/(B3+10) | F3: =E3*D3+(1-E3)*$F$100
A4: Aerospace/Defense | B4: 79 | C4: 0.9455 | D4: 0.8694 | E4: =B4/(B4+10) | F4: =E4*D4+(1-E4)*$F$100
A5: Air Transport | B5: 23 | C5: 1.1855 | D5: 0.7579 | E5: =B5/(B5+10) | F5: =E5*D5+(1-E5)*$F$100
A6: Apparel | B6: 35 | C6: 0.9359 | D6: 0.7946 | E6: =B6/(B6+10) | F6: =E6*D6+(1-E6)*$F$100
A7: Auto & Truck | B7: 33 | C7: 1.4565 | D7: 1.3082 | E7: =B7/(B7+10) | F7: =E7*D7+(1-E7)*$F$100
A8: Auto Parts | B8: 35 | C8: 1.3394 | D8: 1.1283 | E8: =B8/(B8+10) | F8: =E8*D8+(1-E8)*$F$100
A9: Bank (Money Center) | B9: 15 | C9: 0.761 | D9: 0.4439 | E9: =B9/(B9+10) | F9: =E9*D9+(1-E9)*$F$100
A10: Banks (Regional) | B10: 568 | C10: 0.3985 | D10: 0.3744 | E10: =B10/(B10+10) | F10: =E10*D10+(1-E10)*$F$100
A11: Beverage (Alcoholic) | B11: 14 | C11: 0.8125 | D11: 0.628 | E11: =B11/(B11+10) | F11: =E11*D11+(1-E11)*$F$100
A12: Beverage (Soft) | B12: 27 | C12: 0.6415 | D12: 0.5755 | E12: =B12/(B12+10) | F12: =E12*D12+(1-E12)*$F$100
A13: Broadcasting | B13: 24 | C13: 0.4708 | D13: 0.3153 | E13: =B13/(B13+10) | F13: =E13*D13+(1-E13)*$F$100
A14: Brokerage & Investment Banking | B14: 32 | C14: 1.1715 | D14: 0.6794 | E14: =B14/(B14+10) | F14: =E14*D14+(1-E14)*$F$100
... A97: Total Market (without financials) | B97: 4822 | C97: 0.9913 | D97: 0.901 | E97: =B97/(B97+10) | F97: =E97*D97+(1-E97)*$F$100
A99: Reference:
A100: Total Market unlevered beta (ex-financials) — shrinkage target | F100: 0.901

Sheet 3_UK_Bloomberg_Data
A1: REAL DATA, VALUES ONLY (no formulas in this sheet — see 0_ReadMe for why). Bloomberg EQS<GO>, UK Refined/Investable Universe (1,298 companies), GICS Sub-Industry level, two independent exports (EV/EBITDA and Revenue) cross-validated against each other: 139/139 names and market caps matched exactly. Read 8 Aug 2026.
A3: Sub-Ind Code | B3: Sub-Industry | C3: N Cos | D3: Sector Code | E3: Market Cap (GBP) | F3: Revenue T12M (GBP) | G3: Current EV/EBITDA | H3: BF EV/EBITDA | I3: Multiple Used (outlier-corrected) | J3: Note
A4: 10101010 | B4: Oil & Gas Drilling | C4: 1 | D4: 10 | E4: 2270000000 | F4: 554970000 | G4: 3.74 | H4: 3.3 | I4: 3.74
A5: 10101020 | B5: Oil & Gas Equipment & Services | C5: 7 | D5: 10 | E5: 18050000000 | F5: 2690000000 | G5: 8.22 | H5: 6.7 | I5: 8.22
A6: 10102010 | B6: Integrated Oil & Gas | C6: 2 | D6: 10 | E6: 131690000000 | F6: 256880000000 | G6: 3.39 | H6: 3.6 | I6: 3.39
A7: 10102020 | B7: Oil & Gas Exploration & Production | C7: 48 | D7: 10 | E7: 288850000 | F7: 217770000 | G7: 3.17 | H7: 2.1 | I7: 3.17
A8: 10102030 | B8: Oil & Gas Refining & Marketing | C8: 1 | D8: 10 | E8: 22750000 | F8: 87000
A9: 10102040 | B9: Oil & Gas Storage & Transportation | C9: 3 | D9: 10 | E9: 6580000000 | F9: 901710000 | G9: 3.94 | H9: 4.2 | I9: 3.94
A10: 10102050 | B10: Coal & Consumable Fuels | C10: 8 | D10: 10 | E10: 210400000 | G10: 9.47 | H10: 16 | I10: 9.47 | J10: Revenue shows 0.00 in source — treated as no-data
A11: 15101010 | B11: Commodity Chemicals | C11: 2 | D11: 15 | E11: 266070000 | F11: 246000000 | G11: 5.64 | H11: 5.5 | I11: 5.64
A12: 15101030 | B12: Fertilizers & Agricultural Chemicals | C12: 3 | D12: 15 | E12: 20780000 | F12: 21070000
A13: 15101040 | B13: Industrial Gases | C13: 2 | D13: 15 | E13: 44030000 | J13: Revenue shows 0.00 in source — treated as no-data
A14: 15101050 | B14: Specialty Chemicals | C14: 13 | D14: 15 | E14: 876550000 | F14: 1590000000 | G14: 8.87 | H14: 15.9 | I14: 8.87
A15: 15102010 | B15: Construction Materials | C15: 6 | D15: 15 | E15: 655910000 | F15: 699210000 | G15: 6.57 | H15: 6.1 | I15: 6.57
A16: 15103010 | B16: Metal, Glass & Plastic Containers | C16: 1 | D16: 15 | E16: 5110000 | F16: 33260000
A17: 15103020 | B17: Paper & Plastic Packaging Products & Materials | C17: 1 | D17: 15 | E17: 20940000 | F17: 56210000 | G17: 3.38 | H17: 3.2 | I17: 3.38
A18: 15104020 | B18: Diversified Metals & Mining | C18: 47 | D18: 15 | E18: 3860000000 | F18: 1930000000 | G18: 5.94 | H18: 5 | I18: 5.94
A19: 15104025 | B19: Copper | C19: 3 | D19: 15 | E19: 98500000 | F19: 76620000 | G19: 1.5 | H19: 1.3 | I19: 1.5
A20: 15104030 | B20: Gold | C20: 14 | D20: 15 | E20: 1430000000 | F20: 410600000 | G20: 4.23 | H20: 3.2 | I20: 4.23
A21: 15104040 | B21: Precious Metals & Minerals | C21: 6 | D21: 15 | E21: 32640000 | F21: 20970000
A22: 15104050 | B22: Steel | C22: 6 | D22: 15 | E22: 509320000 | F22: 229700000 | G22: 10.16 | H22: 10 | I22: 10.16
A23: 15105010 | B23: Forest Products | C23: 1 | D23: 15 | E23: 170210000 | F23: 153280000 | G23: 9.59 | H23: 8.7 | I23: 9.59
A24: 15105020 | B24: Paper Products | C24: 2 | D24: 15 | E24: 2060000000 | F24: 3920000000 | G24: 6.56 | H24: 6 | I24: 6.56
A25: 20101010 | B25: Aerospace & Defense | C25: 14 | D25: 20 | E25: 15250000000 | F25: 4670000000 | G25: 13.03 | H25: 11.4 | I25: 13.03
A26: 20102010 | B26: Building Products | C26: 9 | D26: 20 | E26: 358510000 | F26: 250880000 | G26: 7.16 | H26: 6.5 | I26: 7.16
A27: 20103010 | B27: Construction & Engineering | C27: 14 | D27: 20 | E27: 850040000 | F27: 1920000000 | G27: 6.91 | H27: 5.9 | I27: 6.91
A28: 20104010 | B28: Electrical Components & Equipment | C28: 16 | D28: 20 | E28: 2040000000 | F28: 480480000 | G28: 213.01 | H28: 9.8 | I28: 9.8 | J28: Current EV/EBITDA (213.01x) is a near-zero-EBITDA artifact — using BF instead
A29: 20104020 | B29: Heavy Electrical Equipment | C29: 4 | D29: 20 | E29: 2180000000 | F29: 229090000 | G29: 38.05 | H29: 32.3 | I29: 38.05
A30: 20105010 | B30: Industrial Conglomerates | C30: 2 | D30: 20 | E30: 3980000000 | F30: 1130000000 | G30: 12.91 | H30: 12.9 | I30: 12.91
A31: 20106015 | B31: Agricultural & Farm Machinery | C31: 1 | D31: 20 | E31: 13500000000 | F31: 18180000000 | G31: 27.38 | H31: 23.7 | I31: 27.38
A32: 20106020 | B32: Industrial Machinery & Supplies & Components | C32: 17 | D32: 20 | E32: 2440000000 | F32: 966980000 | G32: 10.77 | H32: 10.1 | I32: 10.77
A33: 20107010 | B33: Trading Companies & Distributors | C33: 18 | D33: 20 | E33: 1790000000 | F33: 1710000000 | G33: 7.57 | H33: 7.2 | I33: 7.57
A34: 20201010 | B34: Commercial Printing | C34: 1 | D34: 20 | E34: 62410000 | F34: 22260000
A35: 20201050 | B35: Environmental & Facilities Services | C35: 6 | D35: 20 | E35: 2410000000 | F35: 2970000000 | G35: 8.34 | H35: 7.9 | I35: 8.34
A36: 20201070 | B36: Diversified Support Services | C36: 10 | D36: 20 | E36: 221420000 | F36: 272250000 | G36: 5.61 | H36: 5.5 | I36: 5.61
A37: 20201080 | B37: Security & Alarm Services | C37: 1 | D37: 20 | E37: 9930000000 | F37: 13500000000 | G37: 8.49 | H37: 8 | I37: 8.49
A38: 20202010 | B38: Human Resource & Employment Services | C38: 10 | D38: 20 | E38: 225530000 | F38: 1210000000 | G38: 9.43 | H38: 6.1 | I38: 9.43
A39: 20202020 | B39: Research & Consulting Services | C39: 25 | D39: 20 | E39: 2380000000 | F39: 760740000 | G39: 7.31 | H39: 6.7 | I39: 7.31
A40: 20202030 | B40: Data Processing & Outsourced Services | C40: 1 | D40: 20 | E40: 318990000 | F40: 279910000 | G40: 6.59 | H40: 5.1 | I40: 6.59
A41: 20301010 | B41: Air Freight & Logistics | C41: 1 | D41: 20 | E41: 731310000 | F41: 137040000 | G41: 6.05 | H41: 5.7 | I41: 6.05
...

Sheet 4_UK_L1_Input
A1: STEP 4 — PASTE ZONE. PRA SWES Level-1 (GICS Sector) UK shocks, Year 1, from the BoE annex.
A3: Sector Code | B3: GICS Sector | C3: UK Revenue Shock % | D3: UK EV/EBITDA Shock %
A4: 10 | B4: Energy | C4: 0.08 | D4: 0
A5: 15 | B5: Materials | C5: -0.05 | D5: -0.28
A6: 20 | B6: Industrials | C6: -0.1 | D6: -0.32
A7: 25 | B7: Consumer Discretionary | C7: -0.1 | D7: -0.25
A8: 30 | B8: Consumer Staples | C8: -0.05 | D8: -0.25
A9: 35 | B9: Health Care | C9: -0.05 | D9: -0.25
A10: 40 | B10: Financials | C10: -0.1 | D10: -0.32
A11: 45 | B11: Information Technology | C11: -0.1 | D11: -0.36
A12: 50 | B12: Communication Services | C12: -0.05 | D12: -0.26
A13: 55 | B13: Utilities | C13: 0.02 | D13: -0.01
A14: 60 | B14: Real Estate | C14: -0.1 | D14: -0.36

Sheet 5_Cascade_Engine
A1: STEP 5 — 163 sub-industries. Columns F-O: the ORIGINAL Damodaran-beta cascade, equal-weighted (unchanged method). Columns P-AD: the REAL-DATA cascade — Revenue keeps the beta DIFFERENTIATOR but reweights by real UK revenue; EV/EBITDA uses the real multiple as the differentiator outright, falling back to the beta estimate only where no UK listing exists. Columns AE-AF: the divergence between the two.
A2: Sub-Ind Code | B2: Sub-Industry | C2: Sector Code | D2: IG Code | E2: Ind Code | F2: Shrunk Beta L4 | G2: Weight (=1) | H2: AvgBeta L3 (eq-wt) | I2: AvgBeta L2 (eq-wt) | J2: AvgBeta L1 (eq-wt) | K2: RelBeta L2 | L2: RelBeta L3 | M2: RelBeta L4 | N2: [BETA] Rev Shock L4 | O2: [BETA] EV/EBITDA Shock L4 | P2: Real UK Revenue | Q2: Real UK Market Cap | R2: Real UK Multiple Used | S2: AvgBeta L3 (real-rev-wt) | T2: AvgBeta L2 (real-rev-wt) | U2: AvgBeta L1 (real-rev-wt) | V2: RelBeta L2 (real-rev-wt) | W2: RelBeta L3 (real-rev-wt) | X2: RelBeta L4 (real-rev-wt) | Y2: [REAL] Rev Shock L4 | Z2: Rev Source | AA2: Real Sector Wtd-Avg Multiple | AB2: RelMultiple (real) | AC2: [REAL] EV/EBITDA Shock L4 | AD2: EV/EBITDA Source | AE2: Rev Divergence | AF2: EV/EBITDA Divergence
A3: 10101010 | B3: Oil & Gas Drilling | C3: 10 | D3: 1010 | E3: 101010 | F3: 0.797703 | G3: 1 | H3: =SUMPRODUCT(($E$3:$E$165=E3)*$G$3:$G$165*$F$3:$F$165)/SUMPRODUCT(($E$3:$E$165=E3)*$G$3:$G$165) | I3: =SUMPRODUCT(($D$3:$D$165=D3)*$G$3:$G$165*$F$3:$F$165)/SUMPRODUCT(($D$3:$D$165=D3)*$G$3:$G$165) | J3: =SUMPRODUCT(($C$3:$C$165=C3)*$G$3:$G$165*$F$3:$F$165)/SUMPRODUCT(($C$3:$C$165=C3)*$G$3:$G$165) | K3: =I3/J3 | L3: =H3/I3 | M3: =F3/H3 | N3: =INDEX('4_UK_L1_Input'!$C$4:$C$14,MATCH($C3,'4_UK_L1_Input'!$A$4:$A$14,0))*K3*L3*M3 | O3: =INDEX('4_UK_L1_Input'!$D$4:$D$14,MATCH($C3,'4_UK_L1_Input'!$A$4:$A$14,0))*K3*L3*M3 | P3: 554970000 | Q3: 2270000000 | R3: 3.74 | S3: =IFERROR(SUMPRODUCT(($E$3:$E$165=E3)*ISNUMBER($P$3:$P$165)*$P$3:$P$165*$F$3:$F$165)/SUMPRODUCT(($E$3:$E$165=E3)*ISNUMBER($P$3:$P$165)*$P$3:$P$165),"") | T3: =IFERROR(SUMPRODUCT(($D$3:$D$165=D3)*ISNUMBER($P$3:$P$165)*$P$3:$P$165*$F$3:$F$165)/SUMPRODUCT(($D$3:$D$165=D3)*ISNUMBER($P$3:$P$165)*$P$3:$P$165),"") | U3: =IFERROR(SUMPRODUCT(($C$3:$C$165=C3)*ISNUMBER($P$3:$P$165)*$P$3:$P$165*$F$3:$F$165)/SUMPRODUCT(($C$3:$C$165=C3)*ISNUMBER($P$3:$P$165)*$P$3:$P$165),"") | V3: =IF(OR(T3="",U3=""),"",T3/U3) | W3: =IF(OR(S3="",T3=""),"",S3/T3) | X3: =IF(S3="","",F3/S3) | Y3: =IF(V3="",N3,INDEX('4_UK_L1_Input'!$C$4:$C$14,MATCH($C3,'4_UK_L1_Input'!$A$4:$A$14,0))*V3*W3*X3) | Z3: =IF(V3="","BETA FALLBACK","REAL (Bloomberg UK)") | AA3: =IFERROR(SUMPRODUCT(($C$3:$C$165=C3)*ISNUMBER($R$3:$R$165)*$Q$3:$Q$165*IF(ISNUMBER($R$3:$R$165),$R$3:$R$165,0))/SUMPRODUCT(($C$3:$C$165=C3)*ISNUMBER($R$3:$R$165)*$Q$3:$Q$165),"") | AB3: =IF(OR(R3="",AA3=""),"",R3/AA3) | AC3: =IF(AB3="",O3,INDEX('4_UK_L1_Input'!$D$4:$D$14,MATCH($C3,'4_UK_L1_Input'!$A$4:$A$14,0))*AB3) | AD3: =IF(AB3="","BETA FALLBACK","REAL (Bloomberg UK)") | AE3: =Y3-N3 | AF3: =AC3-O3
A4: 10101020 | B4: Oil & Gas Equipment & Services | C4: 10 | D4: 1010 | E4: 101010 | F4: 0.797703 | G4: 1 | H4: =SUMPRODUCT(($E$3:$E$165=E4)*$G$3:$G$165*$F$3:$F$165)/SUMPRODUCT(($E$3:$E$165=E4)*$G$3:$G$165) | I4: =SUMPRODUCT(($D$3:$D$165=D4)*$G$3:$G$165*$F$3:$F$165)/SUMPRODUCT(($D$3:$D$165=D4)*$G$3:$G$165) | J4: =SUMPRODUCT(($C$3:$C$165=C4)*$G$3:$G$165*$F$3:$F$165)/SUMPRODUCT(($C$3:$C$165=C4)*$G$3:$G$165) | K4: =I4/J4 | L4: =H4/I4 | M4: =F4/H4 | N4: =INDEX('4_UK_L1_Input'!$C$4:$C$14,MATCH($C4,'4_UK_L1_Input'!$A$4:$A$14,0))*K4*L4*M4 | O4: =INDEX('4_UK_L1_Input'!$D$4:$D$14,MATCH($C4,'4_UK_L1_Input'!$A$4:$A$14,0))*K4*L4*M4 | P4: 2690000000 | Q4: 18050000000 | R4: 8.22 | S4: =IFERROR(SUMPRODUCT(($E$3:$E$165=E4)*ISNUMBER($P$3:$P$165)*$P$3:$P$165*$F$3:$F$165)/SUMPRODUCT(($E$3:$E$165=E4)*ISNUMBER($P$3:$P$165)*$P$3:$P$165),"") | T4: =IFERROR(SUMPRODUCT(($D$3:$D$165=D4)*ISNUMBER($P$3:$P$165)*$P$3:$P$165*$F$3:$F$165)/SUMPRODUCT(($D$3:$D$165=D4)*ISNUMBER($P$3:$P$165)*$P$3:$P$165),"") | U4: =IFERROR(SUMPRODUCT(($C$3:$C$165=C4)*ISNUMBER($P$3:$P$165)*$P$3:$P$165*$F$3:$F$165)/SUMPRODUCT(($C$3:$C$165=C4)*ISNUMBER($P$3:$P$165)*$P$3:$P$165),"") | V4: =IF(OR(T4="",U4=""),"",T4/U4) | W4: =IF(OR(S4="",T4=""),"",S4/T4) | X4: =IF(S4="","",F4/S4) | Y4: =IF(V4="",N4,INDEX('4_UK_L1_Input'!$C$4:$C$14,MATCH($C4,'4_UK_L1_Input'!$A$4:$A$14,0))*V4*W4*X4) | Z4: =IF(V4="","BETA FALLBACK","REAL (Bloomberg UK)") | AA4: =IFERROR(SUMPRODUCT(($C$3:$C$165=C4)*ISNUMBER($R$3:$R$165)*$Q$3:$Q$165*IF(ISNUMBER($R$3:$R$165),$R$3:$R$165,0))/SUMPRODUCT(($C$3:$C$165=C4)*ISNUMBER($R$3:$R$165)*$Q$3:$Q$165),"") | AB4: =IF(OR(R4="",AA4=""),"",R4/AA4) | AC4: =IF(AB4="",O4,INDEX('4_UK_L1_Input'!$D$4:$D$14,MATCH($C4,'4_UK_L1_Input'!$A$4:$A$14,0))*AB4) | AD4: =IF(AB4="","BETA FALLBACK","REAL (Bloomberg UK)") | AE4: =Y4-N4 | AF4: =AC4-O4
A5: 10102010 | B5: Integrated Oil & Gas | C5: 10 | D5: 1010 | E5: 101020 | F5: 0.722978 | G5: 1 | H5: =SUMPRODUCT(($E$3:$E$165=E5)*$G$3:$G$165*$F$3:$F$165)/SUMPRODUCT(($E$3:$E$165=E5)*$G$3:$G$165) | I5: =SUMPRODUCT(($D$3:$D$165=D5)*$G$3:$G$165*$F$3:$F$165)/SUMPRODUCT(($D$3:$D$165=D5)*$G$3:$G$165) | J5: =SUMPRODUCT(($C$3:$C$165=C5)*$G$3:$G$165*$F$3:$F$165)/SUMPRODUCT(($C$3:$C$165=C5)*$G$3:$G$165) | K5: =I5/J5 | L5: =H5/I5 | M5: =F5/H5 | N5: =INDEX('4_UK_L1_Input'!$C$4:$C$14,MATCH($C5,'4_UK_L1_Input'!$A$4:$A$14,0))*K5*L5*M5 | O5: =INDEX('4_UK_L1_Input'!$D$4:$D$14,MATCH($C5,'4_UK_L1_Input'!$A$4:$A$14,0))*K5*L5*M5 | P5: 256880000000 | Q5: 131690000000 | R5: 3.39 | S5: =IFERROR(SUMPRODUCT(($E$3:$E$165=E5)*ISNUMBER($P$3:$P$165)*$P$3:$P$165*$F$3:$F$165)/SUMPRODUCT(($E$3:$E$165=E5)*ISNUMBER($P$3:$P$165)*$P$3:$P$165),"") | T5: =IFERROR(SUMPRODUCT(($D$3:$D$165=D5)*ISNUMBER($P$3:$P$165)*$P$3:$P$165*$F$3:$F$165)/SUMPRODUCT(($D$3:$D$165=D5)*ISNUMBER($P$3:$P$165)*$P$3:$P$165),"") | U5: =IFERROR(SUMPRODUCT(($C$3:$C$165=C5)*ISNUMBER($P$3:$P$165)*$P$3:$P$165*$F$3:$F$165)/SUMPRODUCT(($C$3:$C$165=C5)*ISNUMBER($P$3:$P$165)*$P$3:$P$165),"") | V5: =IF(OR(T5="",U5=""),"",T5/U5) | W5: =IF(OR(S5="",T5=""),"",S5/T5) | X5: =IF(S5="","",F5/S5) | Y5: =IF(V5="",N5,INDEX('4_UK_L1_Input'!$C$4:$C$14,MATCH($C5,'4_UK_L1_Input'!$A$4:$A$14,0))*V5*W5*X5) | Z5: =IF(V5="","BETA FALLBACK","REAL (Bloomberg UK)") | AA5: =IFERROR(SUMPRODUCT(($C$3:$C$165=C5)*ISNUMBER($R$3:$R$165)*$Q$3:$Q$165*IF(ISNUMBER($R$3:$R$165),$R$3:$R$165,0))/SUMPRODUCT(($C$3:$C$165=C5)*ISNUMBER($R$3:$R$165)*$Q$3:$Q$165),"") | AB5: =IF(OR(R5="",AA5=""),"",R5/AA5) | AC5: =IF(AB5="",O5,INDEX('4_UK_L1_Input'!$D$4:$D$14,MATCH($C5,'4_UK_L1_Input'!$A$4:$A$14,0))*AB5) | AD5: =IF(AB5="","BETA FALLBACK","REAL (Bloomberg UK)") | AE5: =Y5-N5 | AF5: =AC5-O5
A6: 10102020 | B6: Oil & Gas Exploration & Production | C6: 10 | D6: 1010 | E6: 101020 | F6: 0.599753 | G6: 1 | H6: =SUMPRODUCT(($E$3:$E$165=E6)*$G$3:$G$165*$F$3:$F$165)/SUMPRODUCT(($E$3:$E$165=E6)*$G$3:$G$165) | I6: =SUMPRODUCT(($D$3:$D$165=D6)*$G$3:$G$165*$F$3:$F$165)/SUMPRODUCT(($D$3:$D$165=D6)*$G$3:$G$165) | J6: =SUMPRODUCT(($C$3:$C$165=C6)*$G$3:$G$165*$F$3:$F$165)/SUMPRODUCT(($C$3:$C$165=C6)*$G$3:$G$165) | K6: =I6/J6 | L6: =H6/I6 | M6: =F6/H6 | N6: =INDEX('4_UK_L1_Input'!$C$4:$C$14,MATCH($C6,'4_UK_L1_Input'!$A$4:$A$14,0))*K6*L6*M6 | O6: =INDEX('4_UK_L1_Input'!$D$4:$D$14,MATCH($C6,'4_UK_L1_Input'!$A$4:$A$14,0))*K6*L6*M6 | P6: 217770000 | Q6: 288850000 | R6: 3.17 | S6: =IFERROR(SUMPRODUCT(($E$3:$E$165=E6)*ISNUMBER($P$3:$P$165)*$P$3:$P$165*$F$3:$F$165)/SUMPRODUCT(($E$3:$E$165=E6)*ISNUMBER($P$3:$P$165)*$P$3:$P$165),"") | T6: =IFERROR(SUMPRODUCT(($D$3:$D$165=D6)*ISNUMBER($P$3:$P$165)*$P$3:$P$165*$F$3:$F$165)/SUMPRODUCT(($D$3:$D$165=D6)*ISNUMBER($P$3:$P$165)*$P$3:$P$165),"") | U6: =IFERROR(SUMPRODUCT(($C$3:$C$165=C6)*ISNUMBER($P$3:$P$165)*$P$3:$P$165*$F$3:$F$165)/SUMPRODUCT(($C$3:$C$165=C6)*ISNUMBER($P$3:$P$165)*$P$3:$P$165),"") | V6: =IF(OR(T6="",U6=""),"",T6/U6) | W6: =IF(OR(S6="",T6=""),"",S6/T6) | X6: =IF(S6="","",F6/S6) | Y6: =IF(V6="",N6,INDEX('4_UK_L1_Input'!$C$4:$C$14,MATCH($C6,'4_UK_L1_Input'!$A$4:$A$14,0))*V6*W6*X6) | Z6: =IF(V6="","BETA FALLBACK","REAL (Bloomberg UK)") | AA6: =IFERROR(SUMPRODUCT(($C$3:$C$165=C6)*ISNUMBER($R$3:$R$165)*$Q$3:$Q$165*IF(ISNUMBER($R$3:$R$165),$R$3:$R$165,0))/SUMPRODUCT(($C$3:$C$165=C6)*ISNUMBER($R$3:$R$165)*$Q$3:$Q$165),"") | AB6: =IF(OR(R6="",AA6=""),"",R6/AA6) | AC6: =IF(AB6="",O6,INDEX('4_UK_L1_Input'!$D$4:$D$14,MATCH($C6,'4_UK_L1_Input'!$A$4:$A$14,0))*AB6) | AD6: =IF(AB6="","BETA FALLBACK","REAL (Bloomberg UK)") | AE6: =Y6-N6 | AF6: =AC6-O6
A7: 10102030 | B7: Oil & Gas Refining & Marketing | C7: 10 | D7: 1010 | E7: 101020 | F7: 0.600078 | G7: 1 | H7: =SUMPRODUCT(($E$3:$E$165=E7)*$G$3:$G$165*$F$3:$F$165)/SUMPRODUCT(($E$3:$E$165=E7)*$G$3:$G$165) | I7: =SUMPRODUCT(($D$3:$D$165=D7)*$G$3:$G$165*$F$3:$F$165)/SUMPRODUCT(($D$3:$D$165=D7)*$G$3:$G$165) | J7: =SUMPRODUCT(($C$3:$C$165=C7)*$G$3:$G$165*$F$3:$F$165)/SUMPRODUCT(($C$3:$C$165=C7)*$G$3:$G$165) | K7: =I7/J7 | L7: =H7/I7 | M7: =F7/H7 | N7: =INDEX('4_UK_L1_Input'!$C$4:$C$14,MATCH($C7,'4_UK_L1_Input'!$A$4:$A$14,0))*K7*L7*M7 | O7: =INDEX('4_UK_L1_Input'!$D$4:$D$14,MATCH($C7,'4_UK_L1_Input'!$A$4:$A$14,0))*K7*L7*M7 | P7: 87000 | Q7: 22750000 | S7: =IFERROR(SUMPRODUCT(($E$3:$E$165=E7)*ISNUMBER($P$3:$P$165)*$P$3:$P$165*$F$3:$F$165)/SUMPRODUCT(($E$3:$E$165=E7)*ISNUMBER($P$3:$P$165)*$P$3:$P$165),"") | T7: =IFERROR(SUMPRODUCT(($D$3:$D$165=D7)*ISNUMBER($P$3:$P$165)*$P$3:$P$165*$F$3:$F$165)/SUMPRODUCT(($D$3:$D$165=D7)*ISNUMBER($P$3:$P$165)*$P$3:$P$165),"") | U7: =IFERROR(SUMPRODUCT(($C$3:$C$165=C7)*ISNUMBER($P$3:$P$165)*$P$3:$P$165*$F$3:$F$165)/SUMPRODUCT(($C$3:$C$165=C7)*ISNUMBER($P$3:$P$165)*$P$3:$P$165),"") | V7: =IF(OR(T7="",U7=""),"",T7/U7) | W7: =IF(OR(S7="",T7=""),"",S7/T7) | X7: =IF(S7="","",F7/S7) | Y7: =IF(V7="",N7,INDEX('4_UK_L1_Input'!$C$4:$C$14,MATCH($C7,'4_UK_L1_Input'!$A$4:$A$14,0))*V7*W7*X7) | Z7: =IF(V7="","BETA FALLBACK","REAL (Bloomberg UK)") | AA7: =IFERROR(SUMPRODUCT(($C$3:$C$165=C7)*ISNUMBER($R$3:$R$165)*$Q$3:$Q$165*IF(ISNUMBER($R$3:$R$165),$R$3:$R$165,0))/SUMPRODUCT(($C$3:$C$165=C7)*ISNUMBER($R$3:$R$165)*$Q$3:$Q$165),"") | AB7: =IF(OR(R7="",AA7=""),"",R7/AA7) | AC7: =IF(AB7="",O7,INDEX('4_UK_L1_Input'!$D$4:$D$14,MATCH($C7,'4_UK_L1_Input'!$A$4:$A$14,0))*AB7) | AD7: =IF(AB7="","BETA FALLBACK","REAL (Bloomberg UK)") | AE7: =Y7-N7 | AF7: =AC7-O7
A8: 10102040 | B8: Oil & Gas Storage & Transportation | C8: 10 | D8: 1010 | E8: 101020 | F8: 0.600078 | G8: 1 | H8: =SUMPRODUCT(($E$3:$E$165=E8)*$G$3:$G$165*$F$3:$F$165)/SUMPRODUCT(($E$3:$E$165=E8)*$G$3:$G$165) | I8: =SUMPRODUCT(($D$3:$D$165=D8)*$G$3:$G$165*$F$3:$F$165)/SUMPRODUCT(($D$3:$D$165=D8)*$G$3:$G$165) | J8: =SUMPRODUCT(($C$3:$C$165=C8)*$G$3:$G$165*$F$3:$F$165)/SUMPRODUCT(($C$3:$C$165=C8)*$G$3:$G$165) | K8: =I8/J8 | L8: =H8/I8 | M8: =F8/H8 | N8: =INDEX('4_UK_L1_Input'!$C$4:$C$14,MATCH($C8,'4_UK_L1_Input'!$A$4:$A$14,0))*K8*L8*M8 | O8: =INDEX('4_UK_L1_Input'!$D$4:$D$14,MATCH($C8,'4_UK_L1_Input'!$A$4:$A$14,0))*K8*L8*M8 | P8: 901710000 | Q8: 6580000000 | R8: 3.94 | S8: =IFERROR(SUMPRODUCT(($E$3:$E$165=E8)*ISNUMBER($P$3:$P$165)*$P$3:$P$165*$F$3:$F$165)/SUMPRODUCT(($E$3:$E$165=E8)*ISNUMBER($P$3:$P$165)*$P$3:$P$165),"") | T8: =IFERROR(SUMPRODUCT(($D$3:$D$165=D8)*ISNUMBER($P$3:$P$165)*$P$3:$P$165*$F$3:$F$165)/SUMPRODUCT(($D$3:$D$165=D8)*ISNUMBER($P$3:$P$165)*$P$3:$P$165),"") | U8: =IFERROR(SUMPRODUCT(($C$3:$C$165=C8)*ISNUMBER($P$3:$P$165)*$P$3:$P$165*$F$3:$F$165)/SUMPRODUCT(($C$3:$C$165=C8)*ISNUMBER($P$3:$P$165)*$P$3:$P$165),"") | V8: =IF(OR(T8="",U8=""),"",T8/U8) | W8: =IF(OR(S8="",T8=""),"",S8/T8) | X8: =IF(S8="","",F8/S8) | Y8: =IF(V8="",N8,INDEX('4_UK_L1_Input'!$C$4:$C$14,MATCH($C8,'4_UK_L1_Input'!$A$4:$A$14,0))*V8*W8*X8) | Z8: =IF(V8="","BETA FALLBACK","REAL (Bloomberg UK)") | AA8: =IFERROR(SUMPRODUCT(($C$3:$C$165=C8)*ISNUMBER($R$3:$R$165)*$Q$3:$Q$165*IF(ISNUMBER($R$3:$R$165),$R$3:$R$165,0))/SUMPRODUCT(($C$3:$C$165=C8)*ISNUMBER($R$3:$R$165)*$Q$3:$Q$165),"") | AB8: =IF(OR(R8="",AA8=""),"",R8/AA8) | AC8: =IF(AB8="",O8,INDEX('4_UK_L1_Input'!$D$4:$D$14,MATCH($C8,'4_UK_L1_Input'!$A$4:$A$14,0))*AB8) | AD8: =IF(AB8="","BETA FALLBACK","REAL (Bloomberg UK)") | AE8: =Y8-N8 | AF8: =AC8-O8
A9: 10102050 | B9: Coal & Consumable Fuels | C9: 10 | D9: 1010 | E9: 101020 | F9: 1.07418 | G9: 1 | H9: =SUMPRODUCT(($E$3:$E$165=E9)*$G$3:$G$165*$F$3:$F$165)/SUMPRODUCT(($E$3:$E$165=E9)*$G$3:$G$165) | I9: =SUMPRODUCT(($D$3:$D$165=D9)*$G$3:$G$165*$F$3:$F$165)/SUMPRODUCT(($D$3:$D$165=D9)*$G$3:$G$165) | J9: =SUMPRODUCT(($C$3:$C$165=C9)*$G$3:$G$165*$F$3:$F$165)/SUMPRODUCT(($C$3:$C$165=C9)*$G$3:$G$165) | K9: =I9/J9 | L9: =H9/I9 | M9: =F9/H9 | N9: =INDEX('4_UK_L1_Input'!$C$4:$C$14,MATCH($C9,'4_UK_L1_Input'!$A$4:$A$14,0))*K9*L9*M9 | O9: =INDEX('4_UK_L1_Input'!$D$4:$D$14,MATCH($C9,'4_UK_L1_Input'!$A$4:$A$14,0))*K9*L9*M9 | Q9: 210400000 | R9: 9.47 | S9: =IFERROR(SUMPRODUCT(($E$3:$E$165=E9)*ISNUMBER($P$3:$P$165)*$P$3:$P$165*$F$3:$F$165)/SUMPRODUCT(($E$3:$E$165=E9)*ISNUMBER($P$3:$P$165)*$P$3:$P$165),"") | T9: =IFERROR(SUMPRODUCT(($D$3:$D$165=D9)*ISNUMBER($P$3:$P$165)*$P$3:$P$165*$F$3:$F$165)/SUMPRODUCT(($D$3:$D$165=D9)*ISNUMBER($P$3:$P$165)*$P$3:$P$165),"") | U9: =IFERROR(SUMPRODUCT(($C$3:$C$165=C9)*ISNUMBER($P$3:$P$165)*$P$3:$P$165*$F$3:$F$165)/SUMPRODUCT(($C$3:$C$165=C9)*ISNUMBER($P$3:$P$165)*$P$3:$P$165),"") | V9: =IF(OR(T9="",U9=""),"",T9/U9) | W9: =IF(OR(S9="",T9=""),"",S9/T9) | X9: =IF(S9="","",F9/S9) | Y9: =IF(V9="",N9,INDEX('4_UK_L1_Input'!$C$4:$C$14,MATCH($C9,'4_UK_L1_Input'!$A$4:$A$14,0))*V9*W9*X9) | Z9: =IF(V9="","BETA FALLBACK","REAL (Bloomberg UK)") | AA9: =IFERROR(SUMPRODUCT(($C$3:$C$165=C9)*ISNUMBER($R$3:$R$165)*$Q$3:$Q$165*IF(ISNUMBER($R$3:$R$165),$R$3:$R$165,0))/SUMPRODUCT(($C$3:$C$165=C9)*ISNUMBER($R$3:$R$165)*$Q$3:$Q$165),"") | AB9: =IF(OR(R9="",AA9=""),"",R9/AA9) | AC9: =IF(AB9="",O9,INDEX('4_UK_L1_Input'!$D$4:$D$14,MATCH($C9,'4_UK_L1_Input'!$A$4:$A$14,0))*AB9) | AD9: =IF(AB9="","BETA FALLBACK","REAL (Bloomberg UK)") | AE9: =Y9-N9 | AF9: =AC9-O9
A10: 15101010 | B10: Commodity Chemicals | C10: 15 | D10: 1510 | E10: 151010 | F10: 0.704523 | G10: 1 | H10: =SUMPRODUCT(($E$3:$E$165=E10)*$G$3:$G$165*$F$3:$F$165)/SUMPRODUCT(($E$3:$E$165=E10)*$G$3:$G$165) | I10: =SUMPRODUCT(($D$3:$D$165=D10)*$G$3:$G$165*$F$3:$F$165)/SUMPRODUCT(($D$3:$D$165=D10)*$G$3:$G$165) | J10: =SUMPRODUCT(($C$3:$C$165=C10)*$G$3:$G$165*$F$3:$F$165)/SUMPRODUCT(($C$3:$C$165=C10)*$G$3:$G$165) | K10: =I10/J10 | L10: =H10/I10 | M10: =F10/H10 | N10: =INDEX('4_UK_L1_Input'!$C$4:$C$14,MATCH($C10,'4_UK_L1_Input'!$A$4:$A$14,0))*K10*L10*M10 | O10: =INDEX('4_UK_L1_Input'!$D$4:$D$14,MATCH($C10,'4_UK_L1_Input'!$A$4:$A$14,0))*K10*L10*M10 | P10: 246000000 | Q10: 266070000 | R10: 5.64 | S10: =IFERROR(SUMPRODUCT(($E$3:$E$165=E10)*ISNUMBER($P$3:$P$165)*$P$3:$P$165*$F$3:$F$165)/SUMPRODUCT(($E$3:$E$165=E10)*ISNUMBER($P$3:$P$165)*$P$3:$P$165),"") | T10: =IFERROR(SUMPRODUCT(($D$3:$D$165=D10)*ISNUMBER($P$3:$P$165)*$P$3:$P$165*$F$3:$F$165)/SUMPRODUCT(($D$3:$D$165=D10)*ISNUMBER($P$3:$P$165)*$P$3:$P$165),"") | U10: =IFERROR(SUMPRODUCT(($C$3:$C$165=C10)*ISNUMBER($P$3:$P$165)*$P$3:$P$165*$F$3:$F$165)/SUMPRODUCT(($C$3:$C$165=C10)*ISNUMBER($P$3:$P$165)*$P$3:$P$165),"") | V10: =IF(OR(T10="",U10=""),"",T10/U10) | W10: =IF(OR(S10="",T10=""),"",S10/T10) | X10: =IF(S10="","",F10/S10) | Y10: =IF(V10="",N10,INDEX('4_UK_L1_Input'!$C$4:$C$14,MATCH($C10,'4_UK_L1_Input'!$A$4:$A$14,0))*V10*W10*X10) | Z10: =IF(V10="","BETA FALLBACK","REAL (Bloomberg UK)") | AA10: =IFERROR(SUMPRODUCT(($C$3:$C$165=C10)*ISNUMBER($R$3:$R$165)*$Q$3:$Q$165*IF(ISNUMBER($R$3:$R$165),$R$3:$R$165,0))/SUMPRODUCT(($C$3:$C$165=C10)*ISNUMBER($R$3:$R$165)*$Q$3:$Q$165),"") | AB10: =IF(OR(R10="",AA10=""),"",R10/AA10) | AC10: =IF(AB10="",O10,INDEX('4_UK_L1_Input'!$D$4:$D$14,MATCH($C10,'4_UK_L1_Input'!$A$4:$A$14,0))*AB10) | AD10: =IF(AB10="","BETA FALLBACK","REAL (Bloomberg UK)") | AE10: =Y10-N10 | AF10: =AC10-O10
A11: 15101020 | B11: Diversified Chemicals | C11: 15 | D11: 1510 | E11: 151010 | F11: 0.759589 | G11: 1 | H11: =SUMPRODUCT(($E$3:$E$165=E11)*$G$3:$G$165*$F$3:$F$165)/SUMPRODUCT(($E$3:$E$165=E11)*$G$3:$G$165) | I11: =SUMPRODUCT(($D$3:$D$165=D11)*$G$3:$G$165*$F$3:$F$165)/SUMPRODUCT(($D$3:$D$165=D11)*$G$3:$G$165) | J11: =SUMPRODUCT(($C$3:$C$165=C11)*$G$3:$G$165*$F$3:$F$165)/SUMPRODUCT(($C$3:$C$165=C11)*$G$3:$G$165) | K11: =I11/J11 | L11: =H11/I11 | M11: =F11/H11 | N11: =INDEX('4_UK_L1_Input'!$C$4:$C$14,MATCH($C11,'4_UK_L1_Input'!$A$4:$A$14,0))*K11*L11*M11 | O11: =INDEX('4_UK_L1_Input'!$D$4:$D$14,MATCH($C11,'4_UK_L1_Input'!$A$4:$A$14,0))*K11*L11*M11 | S11: =IFERROR(SUMPRODUCT(($E$3:$E$165=E11)*ISNUMBER($P$3:$P$165)*$P$3:$P$165*$F$3:$F$165)/SUMPRODUCT(($E$3:$E$165=E11)*ISNUMBER($P$3:$P$165)*$P$3:$P$165),"") | T11: =IFERROR(SUMPRODUCT(($D$3:$D$165=D11)*ISNUMBER($P$3:$P$165)*$P$3:$P$165*$F$3:$F$165)/SUMPRODUCT(($D$3:$D$165=D11)*ISNUMBER($P$3:$P$165)*$P$3:$P$165),"") | U11: =IFERROR(SUMPRODUCT(($C$3:$C$165=C11)*ISNUMBER($P$3:$P$165)*$P$3:$P$165*$F$3:$F$165)/SUMPRODUCT(($C$3:$C$165=C11)*ISNUMBER($P$3:$P$165)*$P$3:$P$165),"") | V11: =IF(OR(T11="",U11=""),"",T11/U11) | W11: =IF(OR(S11="",T11=""),"",S11/T11) | X11: =IF(S11="","",F11/S11) | Y11: =IF(V11="",N11,INDEX('4_UK_L1_Input'!$C$4:$C$14,MATCH($C11,'4_UK_L1_Input'!$A$4:$A$14,0))*V11*W11*X11) | Z11: =IF(V11="","BETA FALLBACK","REAL (Bloomberg UK)") | AA11: =IFERROR(SUMPRODUCT(($C$3:$C$165=C11)*ISNUMBER($R$3:$R$165)*$Q$3:$Q$165*IF(ISNUMBER($R$3:$R$165),$R$3:$R$165,0))/SUMPRODUCT(($C$3:$C$165=C11)*ISNUMBER($R$3:$R$165)*$Q$3:$Q$165),"") | AB11: =IF(OR(R11="",AA11=""),"",R11/AA11) | AC11: =IF(AB11="",O11,INDEX('4_UK_L1_Input'!$D$4:$D$14,MATCH($C11,'4_UK_L1_Input'!$A$4:$A$14,0))*AB11) | AD11: =IF(AB11="","BETA FALLBACK","REAL (Bloomberg UK)") | AE11: =Y11-N11 | AF11: =AC11-O11
A12: 15101030 | B12: Fertilizers & Agricultural Chemicals | C12: 15 | D12: 1510 | E12: 151010 | F12: 0.704523 | G12: 1 | H12: =SUMPRODUCT(($E$3:$E$165=E12)*$G$3:$G$165*$F$3:$F$165)/SUMPRODUCT(($E$3:$E$165=E12)*$G$3:$G$165) | I12: =SUMPRODUCT(($D$3:$D$165=D12)*$G$3:$G$165*$F$3:$F$165)/SUMPRODUCT(($D$3:$D$165=D12)*$G$3:$G$165) | J12: =SUMPRODUCT(($C$3:$C$165=C12)*$G$3:$G$165*$F$3:$F$165)/SUMPRODUCT(($C$3:$C$165=C12)*$G$3:$G$165) | K12: =I12/J12 | L12: =H12/I12 | M12: =F12/H12 | N12: =INDEX('4_UK_L1_Input'!$C$4:$C$14,MATCH($C12,'4_UK_L1_Input'!$A$4:$A$14,0))*K12*L12*M12 | O12: =INDEX('4_UK_L1_Input'!$D$4:$D$14,MATCH($C12,'4_UK_L1_Input'!$A$4:$A$14,0))*K12*L12*M12 | P12: 21070000 | Q12: 20780000 | S12: =IFERROR(SUMPRODUCT(($E$3:$E$165=E12)*ISNUMBER($P$3:$P$165)*$P$3:$P$165*$F$3:$F$165)/SUMPRODUCT(($E$3:$E$165=E12)*ISNUMBER($P$3:$P$165)*$P$3:$P$165),"") | T12: =IFERROR(SUMPRODUCT(($D$3:$D$165=D12)*ISNUMBER($P$3:$P$165)*$P$3:$P$165*$F$3:$F$165)/SUMPRODUCT(($D$3:$D$165=D12)*ISNUMBER($P$3:$P$165)*$P$3:$P$165),"") | U12: =IFERROR(SUMPRODUCT(($C$3:$C$165=C12)*ISNUMBER($P$3:$P$165)*$P$3:$P$165*$F$3:$F$165)/SUMPRODUCT(($C$3:$C$165=C12)*ISNUMBER($P$3:$P$165)*$P$3:$P$165),"") | V12: =IF(OR(T12="",U12=""),"",T12/U12) | W12: =IF(OR(S12="",T12=""),"",S12/T12) | X12: =IF(S12="","",F12/S12) | Y12: =IF(V12="",N12,INDEX('4_UK_L1_Input'!$C$4:$C$14,MATCH($C12,'4_UK_L1_Input'!$A$4:$A$14,0))*V12*W12*X12) | Z12: =IF(V12="","BETA FALLBACK","REAL (Bloomberg UK)") | AA12: =IFERROR(SUMPRODUCT(($C$3:$C$165=C12)*ISNUMBER($R$3:$R$165)*$Q$3:$Q$165*IF(ISNUMBER($R$3:$R$165),$R$3:$R$165,0))/SUMPRODUCT(($C$3:$C$165=C12)*ISNUMBER($R$3:$R$165)*$Q$3:$Q$165),"") | AB12: =IF(OR(R12="",AA12=""),"",R12/AA12) | AC12: =IF(AB12="",O12,INDEX('4_UK_L1_Input'!$D$4:$D$14,MATCH($C12,'4_UK_L1_Input'!$A$4:$A$14,0))*AB12) | AD12: =IF(AB12="","BETA FALLBACK","REAL (Bloomberg UK)") | AE12: =Y12-N12 | AF12: =AC12-O12
A13: 15101040 | B13: Industrial Gases | C13: 15 | D13: 1510 | E13: 151010 | F13: 0.835557 | G13: 1 | H13: =SUMPRODUCT(($E$3:$E$165=E13)*$G$3:$G$165*$F$3:$F$165)/SUMPRODUCT(($E$3:$E$165=E13)*$G$3:$G$165) | I13: =SUMPRODUCT(($D$3:$D$165=D13)*$G$3:$G$165*$F$3:$F$165)/SUMPRODUCT(($D$3:$D$165=D13)*$G$3:$G$165) | J13: =SUMPRODUCT(($C$3:$C$165=C13)*$G$3:$G$165*$F$3:$F$165)/SUMPRODUCT(($C$3:$C$165=C13)*$G$3:$G$165) | K13: =I13/J13 | L13: =H13/I13 | M13: =F13/H13 | N13: =INDEX('4_UK_L1_Input'!$C$4:$C$14,MATCH($C13,'4_UK_L1_Input'!$A$4:$A$14,0))*K13*L13*M13 | O13: =INDEX('4_UK_L1_Input'!$D$4:$D$14,MATCH($C13,'4_UK_L1_Input'!$A$4:$A$14,0))*K13*L13*M13 | Q13: 44030000 | S13: =IFERROR(SUMPRODUCT(($E$3:$E$165=E13)*ISNUMBER($P$3:$P$165)*$P$3:$P$165*$F$3:$F$165)/SUMPRODUCT(($E$3:$E$165=E13)*ISNUMBER($P$3:$P$165)*$P$3:$P$165),"") | T13: =IFERROR(SUMPRODUCT(($D$3:$D$165=D13)*ISNUMBER($P$3:$P$165)*$P$3:$P$165*$F$3:$F$165)/SUMPRODUCT(($D$3:$D$165=D13)*ISNUMBER($P$3:$P$165)*$P$3:$P$165),"") | U13: =IFERROR(SUMPRODUCT(($C$3:$C$165=C13)*ISNUMBER($P$3:$P$165)*$P$3:$P$165*$F$3:$F$165)/SUMPRODUCT(($C$3:$C$165=C13)*ISNUMBER($P$3:$P$165)*$P$3:$P$165),"") | V13: =IF(OR(T13="",U13=""),"",T13/U13) | W13: =IF(OR(S13="",T13=""),"",S13/T13) | X13: =IF(S13="","",F13/S13) | Y13: =IF(V13="",N13,INDEX('4_UK_L1_Input'!$C$4:$C$14,MATCH($C13,'4_UK_L1_Input'!$A$4:$A$14,0))*V13*W13*X13) | Z13: =IF(V13="","BETA FALLBACK","REAL (Bloomberg UK)") | AA13: =IFERROR(SUMPRODUCT(($C$3:$C$165=C13)*ISNUMBER($R$3:$R$165)*$Q$3:$Q$165*IF(ISNUMBER($R$3:$R$165),$R$3:$R$165,0))/SUMPRODUCT(($C$3:$C$165=C13)*ISNUMBER($R$3:$R$165)*$Q$3:$Q$165),"") | AB13: =IF(OR(R13="",AA13=""),"",R13/AA13) | AC13: =IF(AB13="",O13,INDEX('4_UK_L1_Input'!$D$4:$D$14,MATCH($C13,'4_UK_L1_Input'!$A$4:$A$14,0))*AB13) | AD13: =IF(AB13="","BETA FALLBACK","REAL (Bloomberg UK)") | AE13: =Y13-N13 | AF13: =AC13-O13
A14: 15101050 | B14: Specialty Chemicals | C14: 15 | D14: 1510 | E14: 151010 | F14: 0.835557 | G14: 1 | H14: =SUMPRODUCT(($E$3:$E$165=E14)*$G$3:$G$165*$F$3:$F$165)/SUMPRODUCT(($E$3:$E$165=E14)*$G$3:$G$165) | I14: =SUMPRODUCT(($D$3:$D$165=D14)*$G$3:$G$165*$F$3:$F$165)/SUMPRODUCT(($D$3:$D$165=D14)*$G$3:$G$165) | J14: =SUMPRODUCT(($C$3:$C$165=C14)*$G$3:$G$165*$F$3:$F$165)/SUMPRODUCT(($C$3:$C$165=C14)*$G$3:$G$165) | K14: =I14/J14 | L14: =H14/I14 | M14: =F14/H14 | N14: =INDEX('4_UK_L1_Input'!$C$4:$C$14,MATCH($C14,'4_UK_L1_Input'!$A$4:$A$14,0))*K14*L14*M14 | O14: =INDEX('4_UK_L1_Input'!$D$4:$D$14,MATCH($C14,'4_UK_L1_Input'!$A$4:$A$14,0))*K14*L14*M14 | P14: 1590000000 | Q14: 876550000 | R14: 8.87 | S14: =IFERROR(SUMPRODUCT(($E$3:$E$165=E14)*ISNUMBER($P$3:$P$165)*$P$3:$P$165*$F$3:$F$165)/SUMPRODUCT(($E$3:$E$165=E14)*ISNUMBER($P$3:$P$165)*$P$3:$P$165),"") | T14: =IFERROR(SUMPRODUCT(($D$3:$D$165=D14)*ISNUMBER($P$3:$P$165)*$P$3:$P$165*$F$3:$F$165)/SUMPRODUCT(($D$3:$D$165=D14)*ISNUMBER($P$3:$P$165)*$P$3:$P$165),"") | U14: =IFERROR(SUMPRODUCT(($C$3:$C$165=C14)*ISNUMBER($P$3:$P$165)*$P$3:$P$165*$F$3:$F$165)/SUMPRODUCT(($C$3:$C$165=C14)*ISNUMBER($P$3:$P$165)*$P$3:$P$165),"") | V14: =IF(OR(T14="",U14=""),"",T14/U14) | W14: =IF(OR(S14="",T14=""),"",S14/T14) | X14: =IF(S14="","",F14/S14) | Y14: =IF(V14="",N14,INDEX('4_UK_L1_Input'!$C$4:$C$14,MATCH($C14,'4_UK_L1_Input'!$A$4:$A$14,0))*V14*W14*X14) | Z14: =IF(V14="","BETA FALLBACK","REAL (Bloomberg UK)") | AA14: =IFERROR(SUMPRODUCT(($C$3:$C$165=C14)*ISNUMBER($R$3:$R$165)*$Q$3:$Q$165*IF(ISNUMBER($R$3:$R$165),$R$3:$R$165,0))/SUMPRODUCT(($C$3:$C$165=C14)*ISNUMBER($R$3:$R$165)*$Q$3:$Q$165),"") | AB14: =IF(OR(R14="",AA14=""),"",R14/AA14) | AC14: =IF(AB14="",O14,INDEX('4_UK_L1_Input'!$D$4:$D$14,MATCH($C14,'4_UK_L1_Input'!$A$4:$A$14,0))*AB14) | AD14: =IF(AB14="","BETA FALLBACK","REAL (Bloomberg UK)") | AE14: =Y14-N14 | AF14: =AC14-O14
A15: 15102010 | B15: Construction Materials | C15: 15 | D15: 1510 | E15: 151020 | F15: 1.017657 | G15: 1 | H15: =SUMPRODUCT(($E$3:$E$165=E15)*$G$3:$G$165*$F$3:$F$165)/SUMPRODUCT(($E$3:$E$165=E15)*$G$3:$G$165) | I15: =SUMPRODUCT(($D$3:$D$165=D15)*$G$3:$G$165*$F$3:$F$165)/SUMPRODUCT(($D$3:$D$165=D15)*$G$3:$G$165) | J15: =SUMPRODUCT(($C$3:$C$165=C15)*$G$3:$G$165*$F$3:$F$165)/SUMPRODUCT(($C$3:$C$165=C15)*$G$3:$G$165) | K15: =I15/J15 | L15: =H15/I15 | M15: =F15/H15 | N15: =INDEX('4_UK_L1_Input'!$C$4:$C$14,MATCH($C15,'4_UK_L1_Input'!$A$4:$A$14,0))*K15*L15*M15 | O15: =INDEX('4_UK_L1_Input'!$D$4:$D$14,MATCH($C15,'4_UK_L1_Input'!$A$4:$A$14,0))*K15*L15*M15 | P15: 699210000 | Q15: 655910000 | R15: 6.57 | S15: =IFERROR(SUMPRODUCT(($E$3:$E$165=E15)*ISNUMBER($P$3:$P$165)*$P$3:$P$165*$F$3:$F$165)/SUMPRODUCT(($E$3:$E$165=E15)*ISNUMBER($P$3:$P$165)*$P$3:$P$165),"") | T15: =IFERROR(SUMPRODUCT(($D$3:$D$165=D15)*ISNUMBER($P$3:$P$165)*$P$3:$P$165*$F$3:$F$165)/SUMPRODUCT(($D$3:$D$165=D15)*ISNUMBER($P$3:$P$165)*$P$3:$P$165),"") | U15: =IFERROR(SUMPRODUCT(($C$3:$C$165=C15)*ISNUMBER($P$3:$P$165)*$P$3:$P$165*$F$3:$F$165)/SUMPRODUCT(($C$3:$C$165=C15)*ISNUMBER($P$3:$P$165)*$P$3:$P$165),"") | V15: =IF(OR(T15="",U15=""),"",T15/U15) | W15: =IF(OR(S15="",T15=""),"",S15/T15) | X15: =IF(S15="","",F15/S15) | Y15: =IF(V15="",N15,INDEX('4_UK_L1_Input'!$C$4:$C$14,MATCH($C15,'4_UK_L1_Input'!$A$4:$A$14,0))*V15*W15*X15) | Z15: =IF(V15="","BETA FALLBACK","REAL (Bloomberg UK)") | AA15: =IFERROR(SUMPRODUCT(($C$3:$C$165=C15)*ISNUMBER($R$3:$R$165)*$Q$3:$Q$165*IF(ISNUMBER($R$3:$R$165),$R$3:$R$165,0))/SUMPRODUCT(($C$3:$C$165=C15)*ISNUMBER($R$3:$R$165)*$Q$3:$Q$165),"") | AB15: =IF(OR(R15="",AA15=""),"",R15/AA15) | AC15: =IF(AB15="",O15,INDEX('4_UK_L1_Input'!$D$4:$D$14,MATCH($C15,'4_UK_L1_Input'!$A$4:$A$14,0))*AB15) | AD15: =IF(AB15="","BETA FALLBACK","REAL (Bloomberg UK)") | AE15: =Y15-N15 | AF15: =AC15-O15
A16: 15103010 | B16: Metal, Glass & Plastic Containers | C16: 15 | D16: 1510 | E16: 151030 | F16: 0.801397 | G16: 1 | H16: =SUMPRODUCT(($E$3:$E$165=E16)*$G$3:$G$165*$F$3:$F$165)/SUMPRODUCT(($E$3:$E$165=E16)*$G$3:$G$165) | I16: =SUMPRODUCT(($D$3:$D$165=D16)*$G$3:$G$165*$F$3:$F$165)/SUMPRODUCT(($D$3:$D$165=D16)*$G$3:$G$165) | J16: =SUMPRODUCT(($C$3:$C$165=C16)*$G$3:$G$165*$F$3:$F$165)/SUMPRODUCT(($C$3:$C$165=C16)*$G$3:$G$165) | K16: =I16/J16 | L16: =H16/I16 | M16: =F16/H16 | N16: =INDEX('4_UK_L1_Input'!$C$4:$C$14,MATCH($C16,'4_UK_L1_Input'!$A$4:$A$14,0))*K16*L16*M16 | O16: =INDEX('4_UK_L1_Input'!$D$4:$D$14,MATCH($C16,'4_UK_L1_Input'!$A$4:$A$14,0))*K16*L16*M16 | P16: 33260000 | Q16: 5110000 | S16: =IFERROR(SUMPRODUCT(($E$3:$E$165=E16)*ISNUMBER($P$3:$P$165)*$P$3:$P$165*$F$3:$F$165)/SUMPRODUCT(($E$3:$E$165=E16)*ISNUMBER($P$3:$P$165)*$P$3:$P$165),"") | T16: =IFERROR(SUMPRODUCT(($D$3:$D$165=D16)*ISNUMBER($P$3:$P$165)*$P$3:$P$165*$F$3:$F$165)/SUMPRODUCT(($D$3:$D$165=D16)*ISNUMBER($P$3:$P$165)*$P$3:$P$165),"") | U16: =IFERROR(SUMPRODUCT(($C$3:$C$165=C16)*ISNUMBER($P$3:$P$165)*$P$3:$P$165*$F$3:$F$165)/SUMPRODUCT(($C$3:$C$165=C16)*ISNUMBER($P$3:$P$165)*$P$3:$P$165),"") | V16: =IF(OR(T16="",U16=""),"",T16/U16) | W16: =IF(OR(S16="",T16=""),"",S16/T16) | X16: =IF(S16="","",F16/S16) | Y16: =IF(V16="",N16,INDEX('4_UK_L1_Input'!$C$4:$C$14,MATCH($C16,'4_UK_L1_Input'!$A$4:$A$14,0))*V16*W16*X16) | Z16: =IF(V16="","BETA FALLBACK","REAL (Bloomberg UK)") | AA16: =IFERROR(SUMPRODUCT(($C$3:$C$165=C16)*ISNUMBER($R$3:$R$165)*$Q$3:$Q$165*IF(ISNUMBER($R$3:$R$165),$R$3:$R$165,0))/SUMPRODUCT(($C$3:$C$165=C16)*ISNUMBER($R$3:$R$165)*$Q$3:$Q$165),"") | AB16: =IF(OR(R16="",AA16=""),"",R16/AA16) | AC16: =IF(AB16="",O16,INDEX('4_UK_L1_Input'!$D$4:$D$14,MATCH($C16,'4_UK_L1_Input'!$A$4:$A$14,0))*AB16) | AD16: =IF(AB16="","BETA FALLBACK","REAL (Bloomberg UK)") | AE16: =Y16-N16 | AF16: =AC16-O16
A17: 15103020 | B17: Paper & Plastic Packaging Products & Materials | C17: 15 | D17: 1510 | E17: 151030 | F17: 0.801397 | G17: 1 | H17: =SUMPRODUCT(($E$3:$E$165=E17)*$G$3:$G$165*$F$3:$F$165)/SUMPRODUCT(($E$3:$E$165=E17)*$G$3:$G$165) | I17: =SUMPRODUCT(($D$3:$D$165=D17)*$G$3:$G$165*$F$3:$F$165)/SUMPRODUCT(($D$3:$D$165=D17)*$G$3:$G$165) | J17: =SUMPRODUCT(($C$3:$C$165=C17)*$G$3:$G$165*$F$3:$F$165)/SUMPRODUCT(($C$3:$C$165=C17)*$G$3:$G$165) | K17: =I17/J17 | L17: =H17/I17 | M17: =F17/H17 | N17: =INDEX('4_UK_L1_Input'!$C$4:$C$14,MATCH($C17,'4_UK_L1_Input'!$A$4:$A$14,0))*K17*L17*M17 | O17: =INDEX('4_UK_L1_Input'!$D$4:$D$14,MATCH($C17,'4_UK_L1_Input'!$A$4:$A$14,0))*K17*L17*M17 | P17: 56210000 | Q17: 20940000 | R17: 3.38 | S17: =IFERROR(SUMPRODUCT(($E$3:$E$165=E17)*ISNUMBER($P$3:$P$165)*$P$3:$P$165*$F$3:$F$165)/SUMPRODUCT(($E$3:$E$165=E17)*ISNUMBER($P$3:$P$165)*$P$3:$P$165),"") | T17: =IFERROR(SUMPRODUCT(($D$3:$D$165=D17)*ISNUMBER($P$3:$P$165)*$P$3:$P$165*$F$3:$F$165)/SUMPRODUCT(($D$3:$D$165=D17)*ISNUMBER($P$3:$P$165)*$P$3:$P$165),"") | U17: =IFERROR(SUMPRODUCT(($C$3:$C$165=C17)*ISNUMBER($P$3:$P$165)*$P$3:$P$165*$F$3:$F$165)/SUMPRODUCT(($C$3:$C$165=C17)*ISNUMBER($P$3:$P$165)*$P$3:$P$165),"") | V17: =IF(OR(T17="",U17=""),"",T17/U17) | W17: =IF(OR(S17="",T17=""),"",S17/T17) | X17: =IF(S17="","",F17/S17) | Y17: =IF(V17="",N17,INDEX('4_UK_L1_Input'!$C$4:$C$14,MATCH($C17,'4_UK_L1_Input'!$A$4:$A$14,0))*V17*W17*X17) | Z17: =IF(V17="","BETA FALLBACK","REAL (Bloomberg UK)") | AA17: =IFERROR(SUMPRODUCT(($C$3:$C$165=C17)*ISNUMBER($R$3:$R$165)*$Q$3:$Q$165*IF(ISNUMBER($R$3:$R$165),$R$3:$R$165,0))/SUMPRODUCT(($C$3:$C$165=C17)*ISNUMBER($R$3:$R$165)*$Q$3:$Q$165),"") | AB17: =IF(OR(R17="",AA17=""),"",R17/AA17) | AC17: =IF(AB17="",O17,INDEX('4_UK_L1_Input'!$D$4:$D$14,MATCH($C17,'4_UK_L1_Input'!$A$4:$A$14,0))*AB17) | AD17: =IF(AB17="","BETA FALLBACK","REAL (Bloomberg UK)") | AE17: =Y17-N17 | AF17: =AC17-O17
A18: 15104010 | B18: Aluminum | C18: 15 | D18: 1510 | E18: 151040 | F18: 0.997259 | G18: 1 | H18: =SUMPRODUCT(($E$3:$E$165=E18)*$G$3:$G$165*$F$3:$F$165)/SUMPRODUCT(($E$3:$E$165=E18)*$G$3:$G$165) | I18: =SUMPRODUCT(($D$3:$D$165=D18)*$G$3:$G$165*$F$3:$F$165)/SUMPRODUCT(($D$3:$D$165=D18)*$G$3:$G$165) | J18: =SUMPRODUCT(($C$3:$C$165=C18)*$G$3:$G$165*$F$3:$F$165)/SUMPRODUCT(($C$3:$C$165=C18)*$G$3:$G$165) | K18: =I18/J18 | L18: =H18/I18 | M18: =F18/H18 | N18: =INDEX('4_UK_L1_Input'!$C$4:$C$14,MATCH($C18,'4_UK_L1_Input'!$A$4:$A$14,0))*K18*L18*M18 | O18: =INDEX('4_UK_L1_Input'!$D$4:$D$14,MATCH($C18,'4_UK_L1_Input'!$A$4:$A$14,0))*K18*L18*M18 | S18: =IFERROR(SUMPRODUCT(($E$3:$E$165=E18)*ISNUMBER($P$3:$P$165)*$P$3:$P$165*$F$3:$F$165)/SUMPRODUCT(($E$3:$E$165=E18)*ISNUMBER($P$3:$P$165)*$P$3:$P$165),"") | T18: =IFERROR(SUMPRODUCT(($D$3:$D$165=D18)*ISNUMBER($P$3:$P$165)*$P$3:$P$165*$F$3:$F$165)/SUMPRODUCT(($D$3:$D$165=D18)*ISNUMBER($P$3:$P$165)*$P$3:$P$165),"") | U18: =IFERROR(SUMPRODUCT(($C$3:$C$165=C18)*ISNUMBER($P$3:$P$165)*$P$3:$P$165*$F$3:$F$165)/SUMPRODUCT(($C$3:$C$165=C18)*ISNUMBER($P$3:$P$165)*$P$3:$P$165),"") | V18: =IF(OR(T18="",U18=""),"",T18/U18) | W18: =IF(OR(S18="",T18=""),"",S18/T18) | X18: =IF(S18="","",F18/S18) | Y18: =IF(V18="",N18,INDEX('4_UK_L1_Input'!$C$4:$C$14,MATCH($C18,'4_UK_L1_Input'!$A$4:$A$14,0))*V18*W18*X18) | Z18: =IF(V18="","BETA FALLBACK","REAL (Bloomberg UK)") | AA18: =IFERROR(SUMPRODUCT(($C$3:$C$165=C18)*ISNUMBER($R$3:$R$165)*$Q$3:$Q$165*IF(ISNUMBER($R$3:$R$165),$R$3:$R$165,0))/SUMPRODUCT(($C$3:$C$165=C18)*ISNUMBER($R$3:$R$165)*$Q$3:$Q$165),"") | AB18: =IF(OR(R18="",AA18=""),"",R18/AA18) | AC18: =IF(AB18="",O18,INDEX('4_UK_L1_Input'!$D$4:$D$14,MATCH($C18,'4_UK_L1_Input'!$A$4:$A$14,0))*AB18) | AD18: =IF(AB18="","BETA FALLBACK","REAL (Bloomberg UK)") | AE18: =Y18-N18 | AF18: =AC18-O18
A19: 15104020 | B19: Diversified Metals & Mining | C19: 15 | D19: 1510 | E19: 151040 | F19: 0.997259 | G19: 1 | H19: =SUMPRODUCT(($E$3:$E$165=E19)*$G$3:$G$165*$F$3:$F$165)/SUMPRODUCT(($E$3:$E$165=E19)*$G$3:$G$165) | I19: =SUMPRODUCT(($D$3:$D$165=D19)*$G$3:$G$165*$F$3:$F$165)/SUMPRODUCT(($D$3:$D$165=D19)*$G$3:$G$165) | J19: =SUMPRODUCT(($C$3:$C$165=C19)*$G$3:$G$165*$F$3:$F$165)/SUMPRODUCT(($C$3:$C$165=C19)*$G$3:$G$165) | K19: =I19/J19 | L19: =H19/I19 | M19: =F19/H19 | N19: =INDEX('4_UK_L1_Input'!$C$4:$C$14,MATCH($C19,'4_UK_L1_Input'!$A$4:$A$14,0))*K19*L19*M19 | O19: =INDEX('4_UK_L1_Input'!$D$4:$D$14,MATCH($C19,'4_UK_L1_Input'!$A$4:$A$14,0))*K19*L19*M19 | P19: 1930000000 | Q19: 3860000000 | R19: 5.94 | S19: =IFERROR(SUMPRODUCT(($E$3:$E$165=E19)*ISNUMBER($P$3:$P$165)*$P$3:$P$165*$F$3:$F$165)/SUMPRODUCT(($E$3:$E$165=E19)*ISNUMBER($P$3:$P$165)*$P$3:$P$165),"") | T19: =IFERROR(SUMPRODUCT(($D$3:$D$165=D19)*ISNUMBER($P$3:$P$165)*$P$3:$P$165*$F$3:$F$165)/SUMPRODUCT(($D$3:$D$165=D19)*ISNUMBER($P$3:$P$165)*$P$3:$P$165),"") | U19: =IFERROR(SUMPRODUCT(($C$3:$C$165=C19)*ISNUMBER($P$3:$P$165)*$P$3:$P$165*$F$3:$F$165)/SUMPRODUCT(($C$3:$C$165=C19)*ISNUMBER($P$3:$P$165)*$P$3:$P$165),"") | V19: =IF(OR(T19="",U19=""),"",T19/U19) | W19: =IF(OR(S19="",T19=""),"",S19/T19) | X19: =IF(S19="","",F19/S19) | Y19: =IF(V19="",N19,INDEX('4_UK_L1_Input'!$C$4:$C$14,MATCH($C19,'4_UK_L1_Input'!$A$4:$A$14,0))*V19*W19*X19) | Z19: =IF(V19="","BETA FALLBACK","REAL (Bloomberg UK)") | AA19: =IFERROR(SUMPRODUCT(($C$3:$C$165=C19)*ISNUMBER($R$3:$R$165)*$Q$3:$Q$165*IF(ISNUMBER($R$3:$R$165),$R$3:$R$165,0))/SUMPRODUCT(($C$3:$C$165=C19)*ISNUMBER($R$3:$R$165)*$Q$3:$Q$165),"") | AB19: =IF(OR(R19="",AA19=""),"",R19/AA19) | AC19: =IF(AB19="",O19,INDEX('4_UK_L1_Input'!$D$4:$D$14,MATCH($C19,'4_UK_L1_Input'!$A$4:$A$14,0))*AB19) | AD19: =IF(AB19="","BETA FALLBACK","REAL (Bloomberg UK)") | AE19: =Y19-N19 | AF19: =AC19-O19
A20: 15104025 | B20: Copper | C20: 15 | D20: 1510 | E20: 151040 | F20: 0.997259 | G20: 1 | H20: =SUMPRODUCT(($E$3:$E$165=E20)*$G$3:$G$165*$F$3:$F$165)/SUMPRODUCT(($E$3:$E$165=E20)*$G$3:$G$165) | I20: =SUMPRODUCT(($D$3:$D$165=D20)*$G$3:$G$165*$F$3:$F$165)/SUMPRODUCT(($D$3:$D$165=D20)*$G$3:$G$165) | J20: =SUMPRODUCT(($C$3:$C$165=C20)*$G$3:$G$165*$F$3:$F$165)/SUMPRODUCT(($C$3:$C$165=C20)*$G$3:$G$165) | K20: =I20/J20 | L20: =H20/I20 | M20: =F20/H20 | N20: =INDEX('4_UK_L1_Input'!$C$4:$C$14,MATCH($C20,'4_UK_L1_Input'!$A$4:$A$14,0))*K20*L20*M20 | O20: =INDEX('4_UK_L1_Input'!$D$4:$D$14,MATCH($C20,'4_UK_L1_Input'!$A$4:$A$14,0))*K20*L20*M20 | P20: 76620000 | Q20: 98500000 | R20: 1.5 | S20: =IFERROR(SUMPRODUCT(($E$3:$E$165=E20)*ISNUMBER($P$3:$P$165)*$P$3:$P$165*$F$3:$F$165)/SUMPRODUCT(($E$3:$E$165=E20)*ISNUMBER($P$3:$P$165)*$P$3:$P$165),"") | T20: =IFERROR(SUMPRODUCT(($D$3:$D$165=D20)*ISNUMBER($P$3:$P$165)*$P$3:$P$165*$F$3:$F$165)/SUMPRODUCT(($D$3:$D$165=D20)*ISNUMBER($P$3:$P$165)*$P$3:$P$165),"") | U20: =IFERROR(SUMPRODUCT(($C$3:$C$165=C20)*ISNUMBER($P$3:$P$165)*$P$3:$P$165*$F$3:$F$165)/SUMPRODUCT(($C$3:$C$165=C20)*ISNUMBER($P$3:$P$165)*$P$3:$P$165),"") | V20: =IF(OR(T20="",U20=""),"",T20/U20) | W20: =IF(OR(S20="",T20=""),"",S20/T20) | X20: =IF(S20="","",F20/S20) | Y20: =IF(V20="",N20,INDEX('4_UK_L1_Input'!$C$4:$C$14,MATCH($C20,'4_UK_L1_Input'!$A$4:$A$14,0))*V20*W20*X20) | Z20: =IF(V20="","BETA FALLBACK","REAL (Bloomberg UK)") | AA20: =IFERROR(SUMPRODUCT(($C$3:$C$165=C20)*ISNUMBER($R$3:$R$165)*$Q$3:$Q$165*IF(ISNUMBER($R$3:$R$165),$R$3:$R$165,0))/SUMPRODUCT(($C$3:$C$165=C20)*ISNUMBER($R$3:$R$165)*$Q$3:$Q$165),"") | AB20: =IF(OR(R20="",AA20=""),"",R20/AA20) | AC20: =IF(AB20="",O20,INDEX('4_UK_L1_Input'!$D$4:$D$14,MATCH($C20,'4_UK_L1_Input'!$A$4:$A$14,0))*AB20) | AD20: =IF(AB20="","BETA FALLBACK","REAL (Bloomberg UK)") | AE20: =Y20-N20 | AF20: =AC20-O20
A21: 15104030 | B21: Gold | C21: 15 | D21: 1510 | E21: 151040 | F21: 0.841513 | G21: 1 | H21: =SUMPRODUCT(($E$3:$E$165=E21)*$G$3:$G$165*$F$3:$F$165)/SUMPRODUCT(($E$3:$E$165=E21)*$G$3:$G$165) | I21: =SUMPRODUCT(($D$3:$D$165=D21)*$G$3:$G$165*$F$3:$F$165)/SUMPRODUCT(($D$3:$D$165=D21)*$G$3:$G$165) | J21: =SUMPRODUCT(($C$3:$C$165=C21)*$G$3:$G$165*$F$3:$F$165)/SUMPRODUCT(($C$3:$C$165=C21)*$G$3:$G$165) | K21: =I21/J21 | L21: =H21/I21 | M21: =F21/H21 | N21: =INDEX('4_UK_L1_Input'!$C$4:$C$14,MATCH($C21,'4_UK_L1_Input'!$A$4:$A$14,0))*K21*L21*M21 | O21: =INDEX('4_UK_L1_Input'!$D$4:$D$14,MATCH($C21,'4_UK_L1_Input'!$A$4:$A$14,0))*K21*L21*M21 | P21: 410600000 | Q21: 1430000000 | R21: 4.23 | S21: =IFERROR(SUMPRODUCT(($E$3:$E$165=E21)*ISNUMBER($P$3:$P$165)*$P$3:$P$165*$F$3:$F$165)/SUMPRODUCT(($E$3:$E$165=E21)*ISNUMBER($P$3:$P$165)*$P$3:$P$165),"") | T21: =IFERROR(SUMPRODUCT(($D$3:$D$165=D21)*ISNUMBER($P$3:$P$165)*$P$3:$P$165*$F$3:$F$165)/SUMPRODUCT(($D$3:$D$165=D21)*ISNUMBER($P$3:$P$165)*$P$3:$P$165),"") | U21: =IFERROR(SUMPRODUCT(($C$3:$C$165=C21)*ISNUMBER($P$3:$P$165)*$P$3:$P$165*$F$3:$F$165)/SUMPRODUCT(($C$3:$C$165=C21)*ISNUMBER($P$3:$P$165)*$P$3:$P$165),"") | V21: =IF(OR(T21="",U21=""),"",T21/U21) | W21: =IF(OR(S21="",T21=""),"",S21/T21) | X21: =IF(S21="","",F21/S21) | Y21: =IF(V21="",N21,INDEX('4_UK_L1_Input'!$C$4:$C$14,MATCH($C21,'4_UK_L1_Input'!$A$4:$A$14,0))*V21*W21*X21) | Z21: =IF(V21="","BETA FALLBACK","REAL (Bloomberg UK)") | AA21: =IFERROR(SUMPRODUCT(($C$3:$C$165=C21)*ISNUMBER($R$3:$R$165)*$Q$3:$Q$165*IF(ISNUMBER($R$3:$R$165),$R$3:$R$165,0))/SUMPRODUCT(($C$3:$C$165=C21)*ISNUMBER($R$3:$R$165)*$Q$3:$Q$165),"") | AB21: =IF(OR(R21="",AA21=""),"",R21/AA21) | AC21: =IF(AB21="",O21,INDEX('4_UK_L1_Input'!$D$4:$D$14,MATCH($C21,'4_UK_L1_Input'!$A$4:$A$14,0))*AB21) | AD21: =IF(AB21="","BETA FALLBACK","REAL (Bloomberg UK)") | AE21: =Y21-N21 | AF21: =AC21-O21
A22: 15104040 | B22: Precious Metals & Minerals | C22: 15 | D22: 1510 | E22: 151040 | F22: 0.841513 | G22: 1 | H22: =SUMPRODUCT(($E$3:$E$165=E22)*$G$3:$G$165*$F$3:$F$165)/SUMPRODUCT(($E$3:$E$165=E22)*$G$3:$G$165) | I22: =SUMPRODUCT(($D$3:$D$165=D22)*$G$3:$G$165*$F$3:$F$165)/SUMPRODUCT(($D$3:$D$165=D22)*$G$3:$G$165) | J22: =SUMPRODUCT(($C$3:$C$165=C22)*$G$3:$G$165*$F$3:$F$165)/SUMPRODUCT(($C$3:$C$165=C22)*$G$3:$G$165) | K22: =I22/J22 | L22: =H22/I22 | M22: =F22/H22 | N22: =INDEX('4_UK_L1_Input'!$C$4:$C$14,MATCH($C22,'4_UK_L1_Input'!$A$4:$A$14,0))*K22*L22*M22 | O22: =INDEX('4_UK_L1_Input'!$D$4:$D$14,MATCH($C22,'4_UK_L1_Input'!$A$4:$A$14,0))*K22*L22*M22 | P22: 20970000 | Q22: 32640000 | S22: =IFERROR(SUMPRODUCT(($E$3:$E$165=E22)*ISNUMBER($P$3:$P$165)*$P$3:$P$165*$F$3:$F$165)/SUMPRODUCT(($E$3:$E$165=E22)*ISNUMBER($P$3:$P$165)*$P$3:$P$165),"") | T22: =IFERROR(SUMPRODUCT(($D$3:$D$165=D22)*ISNUMBER($P$3:$P$165)*$P$3:$P$165*$F$3:$F$165)/SUMPRODUCT(($D$3:$D$165=D22)*ISNUMBER($P$3:$P$165)*$P$3:$P$165),"") | U22: =IFERROR(SUMPRODUCT(($C$3:$C$165=C22)*ISNUMBER($P$3:$P$165)*$P$3:$P$165*$F$3:$F$165)/SUMPRODUCT(($C$3:$C$165=C22)*ISNUMBER($P$3:$P$165)*$P$3:$P$165),"") | V22: =IF(OR(T22="",U22=""),"",T22/U22) | W22: =IF(OR(S22="",T22=""),"",S22/T22) | X22: =IF(S22="","",F22/S22) | Y22: =IF(V22="",N22,INDEX('4_UK_L1_Input'!$C$4:$C$14,MATCH($C22,'4_UK_L1_Input'!$A$4:$A$14,0))*V22*W22*X22) | Z22: =IF(V22="","BETA FALLBACK","REAL (Bloomberg UK)") | AA22: =IFERROR(SUMPRODUCT(($C$3:$C$165=C22)*ISNUMBER($R$3:$R$165)*$Q$3:$Q$165*IF(ISNUMBER($R$3:$R$165),$R$3:$R$165,0))/SUMPRODUCT(($C$3:$C$165=C22)*ISNUMBER($R$3:$R$165)*$Q$3:$Q$165),"") | AB22: =IF(OR(R22="",AA22=""),"",R22/AA22) | AC22: =IF(AB22="",O22,INDEX('4_UK_L1_Input'!$D$4:$D$14,MATCH($C22,'4_UK_L1_Input'!$A$4:$A$14,0))*AB22) | AD22: =IF(AB22="","BETA FALLBACK","REAL (Bloomberg UK)") | AE22: =Y22-N22 | AF22: =AC22-O22
A23: 15104045 | B23: Silver | C23: 15 | D23: 1510 | E23: 151040 | F23: 0.841513 | G23: 1 | H23: =SUMPRODUCT(($E$3:$E$165=E23)*$G$3:$G$165*$F$3:$F$165)/SUMPRODUCT(($E$3:$E$165=E23)*$G$3:$G$165) | I23: =SUMPRODUCT(($D$3:$D$165=D23)*$G$3:$G$165*$F$3:$F$165)/SUMPRODUCT(($D$3:$D$165=D23)*$G$3:$G$165) | J23: =SUMPRODUCT(($C$3:$C$165=C23)*$G$3:$G$165*$F$3:$F$165)/SUMPRODUCT(($C$3:$C$165=C23)*$G$3:$G$165) | K23: =I23/J23 | L23: =H23/I23 | M23: =F23/H23 | N23: =INDEX('4_UK_L1_Input'!$C$4:$C$14,MATCH($C23,'4_UK_L1_Input'!$A$4:$A$14,0))*K23*L23*M23 | O23: =INDEX('4_UK_L1_Input'!$D$4:$D$14,MATCH($C23,'4_UK_L1_Input'!$A$4:$A$14,0))*K23*L23*M23 | S23: =IFERROR(SUMPRODUCT(($E$3:$E$165=E23)*ISNUMBER($P$3:$P$165)*$P$3:$P$165*$F$3:$F$165)/SUMPRODUCT(($E$3:$E$165=E23)*ISNUMBER($P$3:$P$165)*$P$3:$P$165),"") | T23: =IFERROR(SUMPRODUCT(($D$3:$D$165=D23)*ISNUMBER($P$3:$P$165)*$P$3:$P$165*$F$3:$F$165)/SUMPRODUCT(($D$3:$D$165=D23)*ISNUMBER($P$3:$P$165)*$P$3:$P$165),"") | U23: =IFERROR(SUMPRODUCT(($C$3:$C$165=C23)*ISNUMBER($P$3:$P$165)*$P$3:$P$165*$F$3:$F$165)/SUMPRODUCT(($C$3:$C$165=C23)*ISNUMBER($P$3:$P$165)*$P$3:$P$165),"") | V23: =IF(OR(T23="",U23=""),"",T23/U23) | W23: =IF(OR(S23="",T23=""),"",S23/T23) | X23: =IF(S23="","",F23/S23) | Y23: =IF(V23="",N23,INDEX('4_UK_L1_Input'!$C$4:$C$14,MATCH($C23,'4_UK_L1_Input'!$A$4:$A$14,0))*V23*W23*X23) | Z23: =IF(V23="","BETA FALLBACK","REAL (Bloomberg UK)") | AA23: =IFERROR(SUMPRODUCT(($C$3:$C$165=C23)*ISNUMBER($R$3:$R$165)*$Q$3:$Q$165*IF(ISNUMBER($R$3:$R$165),$R$3:$R$165,0))/SUMPRODUCT(($C$3:$C$165=C23)*ISNUMBER($R$3:$R$165)*$Q$3:$Q$165),"") | AB23: =IF(OR(R23="",AA23=""),"",R23/AA23) | AC23: =IF(AB23="",O23,INDEX('4_UK_L1_Input'!$D$4:$D$14,MATCH($C23,'4_UK_L1_Input'!$A$4:$A$14,0))*AB23) | AD23: =IF(AB23="","BETA FALLBACK","REAL (Bloomberg UK)") | AE23: =Y23-N23 | AF23: =AC23-O23
A24: 15104050 | B24: Steel | C24: 15 | D24: 1510 | E24: 151040 | F24: 0.929779 | G24: 1 | H24: =SUMPRODUCT(($E$3:$E$165=E24)*$G$3:$G$165*$F$3:$F$165)/SUMPRODUCT(($E$3:$E$165=E24)*$G$3:$G$165) | I24: =SUMPRODUCT(($D$3:$D$165=D24)*$G$3:$G$165*$F$3:$F$165)/SUMPRODUCT(($D$3:$D$165=D24)*$G$3:$G$165) | J24: =SUMPRODUCT(($C$3:$C$165=C24)*$G$3:$G$165*$F$3:$F$165)/SUMPRODUCT(($C$3:$C$165=C24)*$G$3:$G$165) | K24: =I24/J24 | L24: =H24/I24 | M24: =F24/H24 | N24: =INDEX('4_UK_L1_Input'!$C$4:$C$14,MATCH($C24,'4_UK_L1_Input'!$A$4:$A$14,0))*K24*L24*M24 | O24: =INDEX('4_UK_L1_Input'!$D$4:$D$14,MATCH($C24,'4_UK_L1_Input'!$A$4:$A$14,0))*K24*L24*M24 | P24: 229700000 | Q24: 509320000 | R24: 10.16 | S24: =IFERROR(SUMPRODUCT(($E$3:$E$165=E24)*ISNUMBER($P$3:$P$165)*$P$3:$P$165*$F$3:$F$165)/SUMPRODUCT(($E$3:$E$165=E24)*ISNUMBER($P$3:$P$165)*$P$3:$P$165),"") | T24: =IFERROR(SUMPRODUCT(($D$3:$D$165=D24)*ISNUMBER($P$3:$P$165)*$P$3:$P$165*$F$3:$F$165)/SUMPRODUCT(($D$3:$D$165=D24)*ISNUMBER($P$3:$P$165)*$P$3:$P$165),"") | U24: =IFERROR(SUMPRODUCT(($C$3:$C$165=C24)*ISNUMBER($P$3:$P$165)*$P$3:$P$165*$F$3:$F$165)/SUMPRODUCT(($C$3:$C$165=C24)*ISNUMBER($P$3:$P$165)*$P$3:$P$165),"") | V24: =IF(OR(T24="",U24=""),"",T24/U24) | W24: =IF(OR(S24="",T24=""),"",S24/T24) | X24: =IF(S24="","",F24/S24) | Y24: =IF(V24="",N24,INDEX('4_UK_L1_Input'!$C$4:$C$14,MATCH($C24,'4_UK_L1_Input'!$A$4:$A$14,0))*V24*W24*X24) | Z24: =IF(V24="","BETA FALLBACK","REAL (Bloomberg UK)") | AA24: =IFERROR(SUMPRODUCT(($C$3:$C$165=C24)*ISNUMBER($R$3:$R$165)*$Q$3:$Q$165*IF(ISNUMBER($R$3:$R$165),$R$3:$R$165,0))/SUMPRODUCT(($C$3:$C$165=C24)*ISNUMBER($R$3:$R$165)*$Q$3:$Q$165),"") | AB24: =IF(OR(R24="",AA24=""),"",R24/AA24) | AC24: =IF(AB24="",O24,INDEX('4_UK_L1_Input'!$D$4:$D$14,MATCH($C24,'4_UK_L1_Input'!$A$4:$A$14,0))*AB24) | AD24: =IF(AB24="","BETA FALLBACK","REAL (Bloomberg UK)") | AE24: =Y24-N24 | AF24: =AC24-O24
A25: 15105010 | B25: Forest Products | C25: 15 | D25: 1510 | E25: 151050 | F25: 0.851733 | G25: 1 | H25: =SUMPRODUCT(($E$3:$E$165=E25)*$G$3:$G$165*$F$3:$F$165)/SUMPRODUCT(($E$3:$E$165=E25)*$G$3:$G$165) | I25: =SUMPRODUCT(($D$3:$D$165=D25)*$G$3:$G$165*$F$3:$F$165)/SUMPRODUCT(($D$3:$D$165=D25)*$G$3:$G$165) | J25: =SUMPRODUCT(($C$3:$C$165=C25)*$G$3:$G$165*$F$3:$F$165)/SUMPRODUCT(($C$3:$C$165=C25)*$G$3:$G$165) | K25: =I25/J25 | L25: =H25/I25 | M25: =F25/H25 | N25: =INDEX('4_UK_L1_Input'!$C$4:$C$14,MATCH($C25,'4_UK_L1_Input'!$A$4:$A$14,0))*K25*L25*M25 | O25: =INDEX('4_UK_L1_Input'!$D$4:$D$14,MATCH($C25,'4_UK_L1_Input'!$A$4:$A$14,0))*K25*L25*M25 | P25: 153280000 | Q25: 170210000 | R25: 9.59 | S25: =IFERROR(SUMPRODUCT(($E$3:$E$165=E25)*ISNUMBER($P$3:$P$165)*$P$3:$P$165*$F$3:$F$165)/SUMPRODUCT(($E$3:$E$165=E25)*ISNUMBER($P$3:$P$165)*$P$3:$P$165),"") | T25: =IFERROR(SUMPRODUCT(($D$3:$D$165=D25)*ISNUMBER($P$3:$P$165)*$P$3:$P$165*$F$3:$F$165)/SUMPRODUCT(($D$3:$D$165=D25)*ISNUMBER($P$3:$P$165)*$P$3:$P$165),"") | U25: =IFERROR(SUMPRODUCT(($C$3:$C$165=C25)*ISNUMBER($P$3:$P$165)*$P$3:$P$165*$F$3:$F$165)/SUMPRODUCT(($C$3:$C$165=C25)*ISNUMBER($P$3:$P$165)*$P$3:$P$165),"") | V25: =IF(OR(T25="",U25=""),"",T25/U25) | W25: =IF(OR(S25="",T25=""),"",S25/T25) | X25: =IF(S25="","",F25/S25) | Y25: =IF(V25="",N25,INDEX('4_UK_L1_Input'!$C$4:$C$14,MATCH($C25,'4_UK_L1_Input'!$A$4:$A$14,0))*V25*W25*X25) | Z25: =IF(V25="","BETA FALLBACK","REAL (Bloomberg UK)") | AA25: =IFERROR(SUMPRODUCT(($C$3:$C$165=C25)*ISNUMBER($R$3:$R$165)*$Q$3:$Q$165*IF(ISNUMBER($R$3:$R$165),$R$3:$R$165,0))/SUMPRODUCT(($C$3:$C$165=C25)*ISNUMBER($R$3:$R$165)*$Q$3:$Q$165),"") | AB25: =IF(OR(R25="",AA25=""),"",R25/AA25) | AC25: =IF(AB25="",O25,INDEX('4_UK_L1_Input'!$D$4:$D$14,MATCH($C25,'4_UK_L1_Input'!$A$4:$A$14,0))*AB25) | AD25: =IF(AB25="","BETA FALLBACK","REAL (Bloomberg UK)") | AE25: =Y25-N25 | AF25: =AC25-O25
A26: 15105020 | B26: Paper Products | C26: 15 | D26: 1510 | E26: 151050 | F26: 0.851733 | G26: 1 | H26: =SUMPRODUCT(($E$3:$E$165=E26)*$G$3:$G$165*$F$3:$F$165)/SUMPRODUCT(($E$3:$E$165=E26)*$G$3:$G$165) | I26: =SUMPRODUCT(($D$3:$D$165=D26)*$G$3:$G$165*$F$3:$F$165)/SUMPRODUCT(($D$3:$D$165=D26)*$G$3:$G$165) | J26: =SUMPRODUCT(($C$3:$C$165=C26)*$G$3:$G$165*$F$3:$F$165)/SUMPRODUCT(($C$3:$C$165=C26)*$G$3:$G$165) | K26: =I26/J26 | L26: =H26/I26 | M26: =F26/H26 | N26: =INDEX('4_UK_L1_Input'!$C$4:$C$14,MATCH($C26,'4_UK_L1_Input'!$A$4:$A$14,0))*K26*L26*M26 | O26: =INDEX('4_UK_L1_Input'!$D$4:$D$14,MATCH($C26,'4_UK_L1_Input'!$A$4:$A$14,0))*K26*L26*M26 | P26: 3920000000 | Q26: 2060000000 | R26: 6.56 | S26: =IFERROR(SUMPRODUCT(($E$3:$E$165=E26)*ISNUMBER($P$3:$P$165)*$P$3:$P$165*$F$3:$F$165)/SUMPRODUCT(($E$3:$E$165=E26)*ISNUMBER($P$3:$P$165)*$P$3:$P$165),"") | T26: =IFERROR(SUMPRODUCT(($D$3:$D$165=D26)*ISNUMBER($P$3:$P$165)*$P$3:$P$165*$F$3:$F$165)/SUMPRODUCT(($D$3:$D$165=D26)*ISNUMBER($P$3:$P$165)*$P$3:$P$165),"") | U26: =IFERROR(SUMPRODUCT(($C$3:$C$165=C26)*ISNUMBER($P$3:$P$165)*$P$3:$P$165*$F$3:$F$165)/SUMPRODUCT(($C$3:$C$165=C26)*ISNUMBER($P$3:$P$165)*$P$3:$P$165),"") | V26: =IF(OR(T26="",U26=""),"",T26/U26) | W26: =IF(OR(S26="",T26=""),"",S26/T26) | X26: =IF(S26="","",F26/S26) | Y26: =IF(V26="",N26,INDEX('4_UK_L1_Input'!$C$4:$C$14,MATCH($C26,'4_UK_L1_Input'!$A$4:$A$14,0))*V26*W26*X26) | Z26: =IF(V26="","BETA FALLBACK","REAL (Bloomberg UK)") | AA26: =IFERROR(SUMPRODUCT(($C$3:$C$165=C26)*ISNUMBER($R$3:$R$165)*$Q$3:$Q$165*IF(ISNUMBER($R$3:$R$165),$R$3:$R$165,0))/SUMPRODUCT(($C$3:$C$165=C26)*ISNUMBER($R$3:$R$165)*$Q$3:$Q$165),"") | AB26: =IF(OR(R26="",AA26=""),"",R26/AA26) | AC26: =IF(AB26="",O26,INDEX('4_UK_L1_Input'!$D$4:$D$14,MATCH($C26,'4_UK_L1_Input'!$A$4:$A$14,0))*AB26) | AD26: =IF(AB26="","BETA FALLBACK","REAL (Bloomberg UK)") | AE26: =Y26-N26 | AF26: =AC26-O26
A27: 20101010 | B27: Aerospace & Defense | C27: 20 | D27: 2010 | E27: 201010 | F27: 0.872927 | G27: 1 | H27: =SUMPRODUCT(($E$3:$E$165=E27)*$G$3:$G$165*$F$3:$F$165)/SUMPRODUCT(($E$3:$E$165=E27)*$G$3:$G$165) | I27: =SUMPRODUCT(($D$3:$D$165=D27)*$G$3:$G$165*$F$3:$F$165)/SUMPRODUCT(($D$3:$D$165=D27)*$G$3:$G$165) | J27: =SUMPRODUCT(($C$3:$C$165=C27)*$G$3:$G$165*$F$3:$F$165)/SUMPRODUCT(($C$3:$C$165=C27)*$G$3:$G$165) | K27: =I27/J27 | L27: =H27/I27 | M27: =F27/H27 | N27: =INDEX('4_UK_L1_Input'!$C$4:$C$14,MATCH($C27,'4_UK_L1_Input'!$A$4:$A$14,0))*K27*L27*M27 | O27: =INDEX('4_UK_L1_Input'!$D$4:$D$14,MATCH($C27,'4_UK_L1_Input'!$A$4:$A$14,0))*K27*L27*M27 | P27: 4670000000 | Q27: 15250000000 | R27: 13.03 | S27: =IFERROR(SUMPRODUCT(($E$3:$E$165=E27)*ISNUMBER($P$3:$P$165)*$P$3:$P$165*$F$3:$F$165)/SUMPRODUCT(($E$3:$E$165=E27)*ISNUMBER($P$3:$P$165)*$P$3:$P$165),"") | T27: =IFERROR(SUMPRODUCT(($D$3:$D$165=D27)*ISNUMBER($P$3:$P$165)*$P$3:$P$165*$F$3:$F$165)/SUMPRODUCT(($D$3:$D$165=D27)*ISNUMBER($P$3:$P$165)*$P$3:$P$165),"") | U27: =IFERROR(SUMPRODUCT(($C$3:$C$165=C27)*ISNUMBER($P$3:$P$165)*$P$3:$P$165*$F$3:$F$165)/SUMPRODUCT(($C$3:$C$165=C27)*ISNUMBER($P$3:$P$165)*$P$3:$P$165),"") | V27: =IF(OR(T27="",U27=""),"",T27/U27) | W27: =IF(OR(S27="",T27=""),"",S27/T27) | X27: =IF(S27="","",F27/S27) | Y27: =IF(V27="",N27,INDEX('4_UK_L1_Input'!$C$4:$C$14,MATCH($C27,'4_UK_L1_Input'!$A$4:$A$14,0))*V27*W27*X27) | Z27: =IF(V27="","BETA FALLBACK","REAL (Bloomberg UK)") | AA27: =IFERROR(SUMPRODUCT(($C$3:$C$165=C27)*ISNUMBER($R$3:$R$165)*$Q$3:$Q$165*IF(ISNUMBER($R$3:$R$165),$R$3:$R$165,0))/SUMPRODUCT(($C$3:$C$165=C27)*ISNUMBER($R$3:$R$165)*$Q$3:$Q$165),"") | AB27: =IF(OR(R27="",AA27=""),"",R27/AA27) | AC27: =IF(AB27="",O27,INDEX('4_UK_L1_Input'!$D$4:$D$14,MATCH($C27,'4_UK_L1_Input'!$A$4:$A$14,0))*AB27) | AD27: =IF(AB27="","BETA FALLBACK","REAL (Bloomberg UK)") | AE27: =Y27-N27 | AF27: =AC27-O27
