Workbook

Sheet 0_ReadMe
A1: UK GICS SHOCK PROPAGATION — REAL DATA + BETA CASCADE + SPREAD CASCADE (DUMMY, FORMULA-READY)
A2: Extends UK_Shock_Propagation_RealData_Only.xlsx. All beta/spread values in 4_UK_Beta_Input and 5_UK_DefaultRisk_Input are DUMMY PLACEHOLDERS — overwrite with real data, everything downstream recalculates automatically.
A5: WHAT'S NEW
A6: 4_UK_Beta_Input — a paste zone holding an UNLEVERED beta value at EACH of the four GICS levels
A7: (Sector, Industry Group, Industry, Sub-Industry) independently. This matches how Bloomberg's EQS 'Total by
A8: Group' can aggregate a field at any of these four groupings directly on the terminal — paste in real averages
A9: at whichever level(s) you pull them, no Excel rollup step needed. ALL VALUES ARE DUMMY RIGHT NOW (a varied,
A10: clearly-synthetic placeholder pattern — 0.70/0.85/1.00/1.15/1.30, decorrelated across levels by a hash rather
A11: than a naive mod-cycle, since GICS codes are nested numeric prefixes and a naive cycle would collide across
A12: all four levels for many codes — so the formula chain is verifiable today, not trivially multiplying by 1.0).
A14: 5_UK_DefaultRisk_Input — same structure, one level down: Bloomberg issuer default-risk spread (bps, e.g. a
A15: DRSK-implied CDS-equivalent spread) at all four GICS levels, DUMMY for now. Used as a THIRD EV/EBITDA basis
... A56: 8_Output clean flat table for lookup against a loan tape's GICS sub-industry code

Sheet 1_GICS_Structure
A1: Reference sheet, GICS hierarchy for context/navigation and for the beta-cascade parent lookups on 5_Cascade_Engine.
A2: Sector Code | B2: Sector | C2: IG Code | D2: Industry Group | E2: Industry Code | F2: Industry | G2: Sub-Ind Code | H2: Sub-Industry
A3: 10 | B3: Energy | C3: 1010 | D3: Energy | E3: 101010 | F3: Energy Equipment & Services | G3: 10101010 | H3: Oil & Gas Drilling
A4: 10 | B4: Energy | C4: 1010 | D4: Energy | E4: 101010 | F4: Energy Equipment & Services | G4: 10101020 | H4: Oil & Gas Equipment & Services
A5: 10 | B5: Energy | C5: 1010 | D5: Energy | E5: 101020 | F5: Oil, Gas & Consumable Fuels | G5: 10102010 | H5: Integrated Oil & Gas
A6: 10 | B6: Energy | C6: 1010 | D6: Energy | E6: 101020 | F6: Oil, Gas & Consumable Fuels | G6: 10102020 | H6: Oil & Gas Exploration & Production
A7: 10 | B7: Energy | C7: 1010 | D7: Energy | E7: 101020 | F7: Oil, Gas & Consumable Fuels | G7: 10102030 | H7: Oil & Gas Refining & Marketing
A8: 10 | B8: Energy | C8: 1010 | D8: Energy | E8: 101020 | F8: Oil, Gas & Consumable Fuels | G8: 10102040 | H8: Oil & Gas Storage & Transportation
A9: 10 | B9: Energy | C9: 1010 | D9: Energy | E9: 101020 | F9: Oil, Gas & Consumable Fuels | G9: 10102050 | H9: Coal & Consumable Fuels
A10: 15 | B10: Materials | C10: 1510 | D10: Materials | E10: 151010 | F10: Chemicals | G10: 15101010 | H10: Commodity Chemicals
A11: 15 | B11: Materials | C11: 1510 | D11: Materials | E11: 151010 | F11: Chemicals | G11: 15101020 | H11: Diversified Chemicals
A12: 15 | B12: Materials | C12: 1510 | D12: Materials | E12: 151010 | F12: Chemicals | G12: 15101030 | H12: Fertilizers & Agricultural Chemicals
A13: 15 | B13: Materials | C13: 1510 | D13: Materials | E13: 151010 | F13: Chemicals | G13: 15101040 | H13: Industrial Gases
A14: 15 | B14: Materials | C14: 1510 | D14: Materials | E14: 151010 | F14: Chemicals | G14: 15101050 | H14: Specialty Chemicals
... A165: 60 | B165: Real Estate | C165: 6020 | D165: Real Estate Management & Development | E165: 602010 | F165: Real Estate Management & Development | G165: 60201040 | H165: Real Estate Services

Sheet 2_UK_Bloomberg_Data
A1: REAL DATA, VALUES ONLY. Bloomberg EQS<GO>, UK Refined/Investable Universe (1,298 companies), GICS Sub-Industry level, two independent exports cross-validated: 139/139 names and market caps matched exactly. Read 8 Aug 2026.
A3: Sub-Ind Code | B3: Sub-Industry | C3: N Cos | D3: Sector Code | E3: Market Cap (GBP) | F3: Revenue T12M (GBP) | G3: Current EV/EBITDA | H3: BF EV/EBITDA | I3: Multiple Used (outlier-corrected) | J3: Note
A4: 10101010 | B4: Oil & Gas Drilling | C4: 1 | D4: 10 | E4: 2270000000 | F4: 554970000 | I4: 3.74
A5: 10101020 | B5: Oil & Gas Equipment & Services | C5: 7 | D5: 10 | E5: 18050000000 | F5: 2690000000 | I5: 8.22
A6: 10102010 | B6: Integrated Oil & Gas | C6: 2 | D6: 10 | E6: 131690000000 | F6: 256880000000 | I6: 3.39
A7: 10102020 | B7: Oil & Gas Exploration & Production | C7: 48 | D7: 10 | E7: 288850000 | F7: 217770000 | I7: 3.17
A8: 10102030 | B8: Oil & Gas Refining & Marketing | C8: 1 | D8: 10 | E8: 22750000 | F8: 87000
A9: 10102040 | B9: Oil & Gas Storage & Transportation | C9: 3 | D9: 10 | E9: 6580000000 | F9: 901710000 | I9: 3.94
A10: 10102050 | B10: Coal & Consumable Fuels | C10: 8 | D10: 10 | E10: 210400000 | I10: 9.47 | J10: Revenue 0.00 in source — no-data
A11: 15101010 | B11: Commodity Chemicals | C11: 2 | D11: 15 | E11: 266070000 | F11: 246000000 | I11: 5.64
A12: 15101030 | B12: Fertilizers & Agricultural Chemicals | C12: 3 | D12: 15 | E12: 20780000 | F12: 21070000
A13: 15101040 | B13: Industrial Gases | C13: 2 | D13: 15 | E13: 44030000 | J13: Revenue 0.00 in source — no-data
A14: 15101050 | B14: Specialty Chemicals | C14: 13 | D14: 15 | E14: 876550000 | F14: 1590000000 | I14: 8.87
A15: 15102010 | B15: Construction Materials | C15: 6 | D15: 15 | E15: 655910000 | F15: 699210000 | I15: 6.57
A16: 15103010 | B16: Metal, Glass & Plastic Containers | C16: 1 | D16: 15 | E16: 5110000 | F16: 33260000
A17: 15103020 | B17: Paper & Plastic Packaging Products & Materials | C17: 1 | D17: 15 | E17: 20940000 | F17: 56210000 | I17: 3.38
A18: 15104020 | B18: Diversified Metals & Mining | C18: 47 | D18: 15 | E18: 3860000000 | F18: 1930000000 | I18: 5.94
A19: 15104025 | B19: Copper | C19: 3 | D19: 15 | E19: 98500000 | F19: 76620000 | I19: 1.5
A20: 15104030 | B20: Gold | C20: 14 | D20: 15 | E20: 1430000000 | F20: 410600000 | I20: 4.23
A21: 15104040 | B21: Precious Metals & Minerals | C21: 6 | D21: 15 | E21: 32640000 | F21: 20970000
A22: 15104050 | B22: Steel | C22: 6 | D22: 15 | E22: 509320000 | F22: 229700000 | I22: 10.16
A23: 15105010 | B23: Forest Products | C23: 1 | D23: 15 | E23: 170210000 | F23: 153280000 | I23: 9.59
A24: 15105020 | B24: Paper Products | C24: 2 | D24: 15 | E24: 2060000000 | F24: 3920000000 | I24: 6.56
A25: 20101010 | B25: Aerospace & Defense | C25: 14 | D25: 20 | E25: 15250000000 | F25: 4670000000 | I25: 13.03
A26: 20102010 | B26: Building Products | C26: 9 | D26: 20 | E26: 358510000 | F26: 250880000 | I26: 7.16
A27: 20103010 | B27: Construction & Engineering | C27: 14 | D27: 20 | E27: 850040000 | F27: 1920000000 | I27: 6.91
A28: 20104010 | B28: Electrical Components & Equipment | C28: 16 | D28: 20 | E28: 2040000000 | F28: 480480000 | I28: 9.8 | J28: Outlier-corrected (near-zero-EBITDA artifact) — using BF multiple
A29: 20104020 | B29: Heavy Electrical Equipment | C29: 4 | D29: 20 | E29: 2180000000 | F29: 229090000 | I29: 38.05
A30: 20105010 | B30: Industrial Conglomerates | C30: 2 | D30: 20 | E30: 3980000000 | F30: 1130000000 | I30: 12.91
A31: 20106015 | B31: Agricultural & Farm Machinery | C31: 1 | D31: 20 | E31: 13500000000 | F31: 18180000000 | I31: 27.38
A32: 20106020 | B32: Industrial Machinery & Supplies & Components | C32: 17 | D32: 20 | E32: 2440000000 | F32: 966980000 | I32: 10.77
A33: 20107010 | B33: Trading Companies & Distributors | C33: 18 | D33: 20 | E33: 1790000000 | F33: 1710000000 | I33: 7.57
A34: 20201010 | B34: Commercial Printing | C34: 1 | D34: 20 | E34: 62410000 | F34: 22260000
A35: 20201050 | B35: Environmental & Facilities Services | C35: 6 | D35: 20 | E35: 2410000000 | F35: 2970000000 | I35: 8.34
A36: 20201070 | B36: Diversified Support Services | C36: 10 | D36: 20 | E36: 221420000 | F36: 272250000 | I36: 5.61
A37: 20201080 | B37: Security & Alarm Services | C37: 1 | D37: 20 | E37: 9930000000 | F37: 13500000000 | I37: 8.49
A38: 20202010 | B38: Human Resource & Employment Services | C38: 10 | D38: 20 | E38: 225530000 | F38: 1210000000 | I38: 9.43
A39: 20202020 | B39: Research & Consulting Services | C39: 25 | D39: 20 | E39: 2380000000 | F39: 760740000 | I39: 7.31
A40: 20202030 | B40: Data Processing & Outsourced Services | C40: 1 | D40: 20 | E40: 318990000 | F40: 279910000 | I40: 6.59
A41: 20301010 | B41: Air Freight & Logistics | C41: 1 | D41: 20 | E41: 731310000 | F41: 137040000 | I41: 6.05
...

Sheet 3_UK_L1_Input
A1: STEP 3 — PASTE ZONE. PRA SWES Level-1 (GICS Sector) UK shocks, Year 1, from the BoE annex.
A3: Sector Code | B3: GICS Sector | C3: UK Revenue Shock % | D3: UK EV/EBITDA Shock %
A4: 10 | B4: Energy | C4: 0.08 | D4: 0
A5: 15 | B5: Materials | C5: -0.05 | D5: -0.28
A6: 20 | B6: Industrials | C6: -0.1 | D6: -0.32
A7: 25 | B7: Consumer Discretionary | C7: -0.1 | D7: -0.25
A8: 30 | B8: Consumer Staples | C8: -0.05 | D8: -0.25
A9: 35 | B9: Health Care | C9: -0.05 | D9: -0.25
A10: 40 | B10: Financials | C10: -0.1 | D10: -0.32
A11: 45 | B11: Information Technology | C11: -0.1 | D11: -0.36
A12: 50 | B12: Communication Services | C12: -0.05 | D12: -0.26
A13: 55 | B13: Utilities | C13: 0.02 | D13: -0.01
A14: 60 | B14: Real Estate | C14: -0.1 | D14: -0.36

Sheet 4_UK_Beta_Input
A1: PASTE ZONE — DUMMY VALUES. Unlevered beta at each of the four GICS levels independently. Replace the 'Unlevered Beta (DUMMY)' column with real data (e.g. from Bloomberg EQS 'Total by Group', or your own Hamada delevering of raw beta using each company's effective tax rate and D/E) — every downstream formula recalculates automatically. Dummy values follow a varied, clearly-synthetic pattern (0.70/0.85/1.00/1.15/1.30 cycling by code) so the cascade is verifiable now, not trivially = 1.0.
A3: SECTOR (11)
A4: Code | B4: Name | D4: Unlevered Beta (DUMMY)
A5: 10 | B5: Energy | D5: 0.7
A6: 15 | B6: Materials | D6: 1
A7: 20 | B7: Industrials | D7: 1.3
A8: 25 | B8: Consumer Discretionary | D8: 0.85
A9: 30 | B9: Consumer Staples | D9: 1.15
A10: 35 | B10: Health Care | D10: 0.7
A11: 40 | B11: Financials | D11: 1
A12: 45 | B12: Information Technology | D12: 1.3
A13: 50 | B13: Communication Services | D13: 0.85
A14: 55 | B14: Utilities | D14: 1.15
A15: 60 | B15: Real Estate | D15: 1.3
A18: INDUSTRY GROUP (25)
A19: Code | B19: Name | D19: Unlevered Beta (DUMMY)
A20: 1010 | B20: Energy | D20: 1
A21: 1510 | B21: Materials | D21: 1.15
A22: 2010 | B22: Capital Goods | D22: 1.3
A23: 2020 | B23: Commercial & Professional Services | D23: 1.15
A24: 2030 | B24: Transportation | D24: 1
A25: 2510 | B25: Automobiles & Components | D25: 0.7
A26: 2520 | B26: Consumer Durables & Apparel | D26: 1.3
A27: 2530 | B27: Consumer Services | D27: 1.15
A28: 2550 | B28: Consumer Discretionary Distribution & Retail | D28: 0.85
A29: 3010 | B29: Consumer Staples Distribution & Retail | D29: 0.85
A30: 3020 | B30: Food, Beverage & Tobacco | D30: 0.7
A31: 3030 | B31: Household & Personal Products | D31: 1.3
... A44: 6020 | B44: Real Estate Management & Development | D44: 0.85
A47: INDUSTRY (74)
A48: Code | B48: Name | D48: Unlevered Beta (DUMMY)
A49: 101010 | B49: Energy Equipment & Services | D49: 1.3
A50: 101020 | B50: Oil, Gas & Consumable Fuels | D50: 1.15
A51: 151010 | B51: Chemicals | D51: 1
A52: 151020 | B52: Construction Materials | D52: 0.85
A53: 151030 | B53: Containers & Packaging | D53: 0.7
A54: 151040 | B54: Metals & Mining | D54: 1.3
A55: 151050 | B55: Paper & Forest Products | D55: 1
A56: 201010 | B56: Aerospace & Defense | D56: 0.7
A57: 201020 | B57: Building Products | D57: 1.3
...

Sheet 5_UK_DefaultRisk_Input
A1: PASTE ZONE — DUMMY VALUES. Bloomberg issuer default risk spread (bps, e.g. DRSK-implied CDS-equivalent spread) at each of the four GICS levels independently, same structure as 4_UK_Beta_Input. Replace with real data when available — every downstream formula recalculates automatically. Dummy values follow a varied, clearly-synthetic pattern (120/220/320/420/520bps cycling by code, decorrelated from the beta dummy pattern) so the cascade is verifiable now, not trivially flat.
A3: SECTOR (11)
A4: Code | B4: Name | D4: Default Risk Spread bps (DUMMY)
A5: 10 | B5: Energy | D5: 220
A6: 15 | B6: Materials | D6: 420
A7: 20 | B7: Industrials | D7: 120
A8: 25 | B8: Consumer Discretionary | D8: 320
A9: 30 | B9: Consumer Staples | D9: 520
A10: 35 | B10: Health Care | D10: 220
A11: 40 | B11: Financials | D11: 420
A12: 45 | B12: Information Technology | D12: 120
A13: 50 | B13: Communication Services | D13: 320
A14: 55 | B14: Utilities | D14: 520
A15: 60 | B15: Real Estate | D15: 120
A18: INDUSTRY GROUP (25)
A19: Code | B19: Name | D19: Default Risk Spread bps (DUMMY)
A20: 1010 | B20: Energy | D20: 420
A21: 1510 | B21: Materials | D21: 520
A22: 2010 | B22: Capital Goods | D22: 120
A23: 2020 | B23: Commercial & Professional Services | D23: 520
A24: 2030 | B24: Transportation | D24: 420
A25: 2510 | B25: Automobiles & Components | D25: 220
A26: 2520 | B26: Consumer Durables & Apparel | D26: 120
A27: 2530 | B27: Consumer Services | D27: 520
A28: 2550 | B28: Consumer Discretionary Distribution & Retail | D28: 320
A29: 3010 | B29: Consumer Staples Distribution & Retail | D29: 320
A30: 3020 | B30: Food, Beverage & Tobacco | D30: 220
A31: 3030 | B31: Household & Personal Products | D31: 120
... A44: 6020 | B44: Real Estate Management & Development | D44: 320
A47: INDUSTRY (74)
A48: Code | B48: Name | D48: Default Risk Spread bps (DUMMY)
A49: 101010 | B49: Energy Equipment & Services | D49: 120
A50: 101020 | B50: Oil, Gas & Consumable Fuels | D50: 520
A51: 151010 | B51: Chemicals | D51: 420
A52: 151020 | B52: Construction Materials | D52: 320
A53: 151030 | B53: Containers & Packaging | D53: 220
A54: 151040 | B54: Metals & Mining | D54: 120
A55: 151050 | B55: Paper & Forest Products | D55: 420
A56: 201010 | B56: Aerospace & Defense | D56: 220
A57: 201020 | B57: Building Products | D57: 120
...

Sheet 6_Cascade_Engine
A1: STEP 6 — 163 sub-industries. Columns G-L: real-data EV/EBITDA (both weighting bases). Columns M-P: beta cascade (RelBeta_L2/L3/L4, from 4_UK_Beta_Input — DUMMY until you paste real data), used as the EV/EBITDA fallback and shown as an alternative Revenue differentiator. Columns V-AA: issuer default-risk-spread cascade (from 5_UK_DefaultRisk_Input — DUMMY), a THIRD EV/EBITDA basis — used for EV/EBITDA only, not Revenue, for the same reason levered beta isn't: a credit spread embeds financing/leverage risk, not pure operating cyclicality, so it isn't the right differentiator for a pre-financing metric like revenue.
A2: Sub-Ind Code | B2: Sub-Industry | C2: Sector Code | D2: Industry Code | E2: IG Code | F2: Real UK Revenue | G2: Real UK Multiple Used | H2: Sector Avg Mult (Rev-Wtd) | I2: Sector Avg Mult (Eq-Wtd) | J2: RelMultiple (Rev-Wtd) | K2: RelMultiple (Eq-Wtd) | L2: Sector Beta | M2: IG Beta | N2: Industry Beta | O2: Sub-Ind Beta | P2: RelBeta L2 x L3 x L4 | Q2: EV/EBITDA Shock (Rev-Wtd basis) | R2: EV/EBITDA Shock (Eq-Wtd basis) | S2: EV/EBITDA Source | T2: Revenue Shock (flat pass-through) | U2: Revenue Shock (beta cascade) | V2: Sector Spread bps | W2: IG Spread bps | X2: Industry Spread bps | Y2: Sub-Ind Spread bps | Z2: RelSpread L2 x L3 x L4 | AA2: EV/EBITDA Shock (Spread basis, dummy)
A3: 10101010 | B3: Oil & Gas Drilling | C3: 10 | D3: 101010 | E3: 1010 | F3: 554970000 | G3: 3.74 | H3: =IFERROR(SUMPRODUCT(($C$3:$C$165=C3)*ISNUMBER($G$3:$G$165)*ISNUMBER($F$3:$F$165)*IF(ISNUMBER($F$3:$F$165),$F$3:$F$165,0)*IF(ISNUMBER($G$3:$G$165),$G$3:$G$165,0))/SUMPRODUCT(($C$3:$C$165=C3)*ISNUMBER($G$3:$G$165)*ISNUMBER($F$3:$F$165)*IF(ISNUMBER($F$3:$F$165),$F$3:$F$165,0)),"") | I3: =IFERROR(SUMPRODUCT(($C$3:$C$165=C3)*ISNUMBER($G$3:$G$165)*IF(ISNUMBER($G$3:$G$165),$G$3:$G$165,0))/SUMPRODUCT(($C$3:$C$165=C3)*ISNUMBER($G$3:$G$165)),"") | J3: =IF(OR(G3="",H3=""),"",G3/H3) | K3: =IF(OR(G3="",I3=""),"",G3/I3) | L3: =INDEX('4_UK_Beta_Input'!$D$5:$D$15,MATCH($C3,'4_UK_Beta_Input'!$A$5:$A$15,0)) | M3: =INDEX('4_UK_Beta_Input'!$D$20:$D$44,MATCH($E3,'4_UK_Beta_Input'!$A$20:$A$44,0)) | N3: =INDEX('4_UK_Beta_Input'!$D$49:$D$122,MATCH($D3,'4_UK_Beta_Input'!$A$49:$A$122,0)) | O3: =INDEX('4_UK_Beta_Input'!$D$127:$D$289,MATCH($A3,'4_UK_Beta_Input'!$A$127:$A$289,0)) | P3: =(M3/L3)*(N3/M3)*(O3/N3) | Q3: =IF(J3="",INDEX('3_UK_L1_Input'!$D$4:$D$14,MATCH($C3,'3_UK_L1_Input'!$A$4:$A$14,0))*P3,INDEX('3_UK_L1_Input'!$D$4:$D$14,MATCH($C3,'3_UK_L1_Input'!$A$4:$A$14,0))*J3) | R3: =IF(K3="",INDEX('3_UK_L1_Input'!$D$4:$D$14,MATCH($C3,'3_UK_L1_Input'!$A$4:$A$14,0))*P3,INDEX('3_UK_L1_Input'!$D$4:$D$14,MATCH($C3,'3_UK_L1_Input'!$A$4:$A$14,0))*K3) | S3: =IF(G3="","BETA CASCADE FALLBACK (dummy — replace with real beta)","REAL (Bloomberg UK)") | T3: =INDEX('3_UK_L1_Input'!$C$4:$C$14,MATCH($C3,'3_UK_L1_Input'!$A$4:$A$14,0)) | U3: =INDEX('3_UK_L1_Input'!$C$4:$C$14,MATCH($C3,'3_UK_L1_Input'!$A$4:$A$14,0))*P3 | V3: =INDEX('5_UK_DefaultRisk_Input'!$D$5:$D$15,MATCH($C3,'5_UK_DefaultRisk_Input'!$A$5:$A$15,0)) | W3: =INDEX('5_UK_DefaultRisk_Input'!$D$20:$D$44,MATCH($E3,'5_UK_DefaultRisk_Input'!$A$20:$A$44,0)) | X3: =INDEX('5_UK_DefaultRisk_Input'!$D$49:$D$122,MATCH($D3,'5_UK_DefaultRisk_Input'!$A$49:$A$122,0)) | Y3: =INDEX('5_UK_DefaultRisk_Input'!$D$127:$D$289,MATCH($A3,'5_UK_DefaultRisk_Input'!$A$127:$A$289,0)) | Z3: =(W3/V3)*(X3/W3)*(Y3/X3) | AA3: =INDEX('3_UK_L1_Input'!$D$4:$D$14,MATCH($C3,'3_UK_L1_Input'!$A$4:$A$14,0))*Z3
A4: 10101020 | B4: Oil & Gas Equipment & Services | C4: 10 | D4: 101010 | E4: 1010 | F4: 2690000000 | G4: 8.22 | H4: =IFERROR(SUMPRODUCT(($C$3:$C$165=C4)*ISNUMBER($G$3:$G$165)*ISNUMBER($F$3:$F$165)*IF(ISNUMBER($F$3:$F$165),$F$3:$F$165,0)*IF(ISNUMBER($G$3:$G$165),$G$3:$G$165,0))/SUMPRODUCT(($C$3:$C$165=C4)*ISNUMBER($G$3:$G$165)*ISNUMBER($F$3:$F$165)*IF(ISNUMBER($F$3:$F$165),$F$3:$F$165,0)),"") | I4: =IFERROR(SUMPRODUCT(($C$3:$C$165=C4)*ISNUMBER($G$3:$G$165)*IF(ISNUMBER($G$3:$G$165),$G$3:$G$165,0))/SUMPRODUCT(($C$3:$C$165=C4)*ISNUMBER($G$3:$G$165)),"") | J4: =IF(OR(G4="",H4=""),"",G4/H4) | K4: =IF(OR(G4="",I4=""),"",G4/I4) | L4: =INDEX('4_UK_Beta_Input'!$D$5:$D$15,MATCH($C4,'4_UK_Beta_Input'!$A$5:$A$15,0)) | M4: =INDEX('4_UK_Beta_Input'!$D$20:$D$44,MATCH($E4,'4_UK_Beta_Input'!$A$20:$A$44,0)) | N4: =INDEX('4_UK_Beta_Input'!$D$49:$D$122,MATCH($D4,'4_UK_Beta_Input'!$A$49:$A$122,0)) | O4: =INDEX('4_UK_Beta_Input'!$D$127:$D$289,MATCH($A4,'4_UK_Beta_Input'!$A$127:$A$289,0)) | P4: =(M4/L4)*(N4/M4)*(O4/N4) | Q4: =IF(J4="",INDEX('3_UK_L1_Input'!$D$4:$D$14,MATCH($C4,'3_UK_L1_Input'!$A$4:$A$14,0))*P4,INDEX('3_UK_L1_Input'!$D$4:$D$14,MATCH($C4,'3_UK_L1_Input'!$A$4:$A$14,0))*J4) | R4: =IF(K4="",INDEX('3_UK_L1_Input'!$D$4:$D$14,MATCH($C4,'3_UK_L1_Input'!$A$4:$A$14,0))*P4,INDEX('3_UK_L1_Input'!$D$4:$D$14,MATCH($C4,'3_UK_L1_Input'!$A$4:$A$14,0))*K4) | S4: =IF(G4="","BETA CASCADE FALLBACK (dummy — replace with real beta)","REAL (Bloomberg UK)") | T4: =INDEX('3_UK_L1_Input'!$C$4:$C$14,MATCH($C4,'3_UK_L1_Input'!$A$4:$A$14,0)) | U4: =INDEX('3_UK_L1_Input'!$C$4:$C$14,MATCH($C4,'3_UK_L1_Input'!$A$4:$A$14,0))*P4 | V4: =INDEX('5_UK_DefaultRisk_Input'!$D$5:$D$15,MATCH($C4,'5_UK_DefaultRisk_Input'!$A$5:$A$15,0)) | W4: =INDEX('5_UK_DefaultRisk_Input'!$D$20:$D$44,MATCH($E4,'5_UK_DefaultRisk_Input'!$A$20:$A$44,0)) | X4: =INDEX('5_UK_DefaultRisk_Input'!$D$49:$D$122,MATCH($D4,'5_UK_DefaultRisk_Input'!$A$49:$A$122,0)) | Y4: =INDEX('5_UK_DefaultRisk_Input'!$D$127:$D$289,MATCH($A4,'5_UK_DefaultRisk_Input'!$A$127:$A$289,0)) | Z4: =(W4/V4)*(X4/W4)*(Y4/X4) | AA4: =INDEX('3_UK_L1_Input'!$D$4:$D$14,MATCH($C4,'3_UK_L1_Input'!$A$4:$A$14,0))*Z4
A5: 10102010 | B5: Integrated Oil & Gas | C5: 10 | D5: 101020 | E5: 1010 | F5: 256880000000 | G5: 3.39 | H5: =IFERROR(SUMPRODUCT(($C$3:$C$165=C5)*ISNUMBER($G$3:$G$165)*ISNUMBER($F$3:$F$165)*IF(ISNUMBER($F$3:$F$165),$F$3:$F$165,0)*IF(ISNUMBER($G$3:$G$165),$G$3:$G$165,0))/SUMPRODUCT(($C$3:$C$165=C5)*ISNUMBER($G$3:$G$165)*ISNUMBER($F$3:$F$165)*IF(ISNUMBER($F$3:$F$165),$F$3:$F$165,0)),"") | I5: =IFERROR(SUMPRODUCT(($C$3:$C$165=C5)*ISNUMBER($G$3:$G$165)*IF(ISNUMBER($G$3:$G$165),$G$3:$G$165,0))/SUMPRODUCT(($C$3:$C$165=C5)*ISNUMBER($G$3:$G$165)),"") | J5: =IF(OR(G5="",H5=""),"",G5/H5) | K5: =IF(OR(G5="",I5=""),"",G5/I5) | L5: =INDEX('4_UK_Beta_Input'!$D$5:$D$15,MATCH($C5,'4_UK_Beta_Input'!$A$5:$A$15,0)) | M5: =INDEX('4_UK_Beta_Input'!$D$20:$D$44,MATCH($E5,'4_UK_Beta_Input'!$A$20:$A$44,0)) | N5: =INDEX('4_UK_Beta_Input'!$D$49:$D$122,MATCH($D5,'4_UK_Beta_Input'!$A$49:$A$122,0)) | O5: =INDEX('4_UK_Beta_Input'!$D$127:$D$289,MATCH($A5,'4_UK_Beta_Input'!$A$127:$A$289,0)) | P5: =(M5/L5)*(N5/M5)*(O5/N5) | Q5: =IF(J5="",INDEX('3_UK_L1_Input'!$D$4:$D$14,MATCH($C5,'3_UK_L1_Input'!$A$4:$A$14,0))*P5,INDEX('3_UK_L1_Input'!$D$4:$D$14,MATCH($C5,'3_UK_L1_Input'!$A$4:$A$14,0))*J5) | R5: =IF(K5="",INDEX('3_UK_L1_Input'!$D$4:$D$14,MATCH($C5,'3_UK_L1_Input'!$A$4:$A$14,0))*P5,INDEX('3_UK_L1_Input'!$D$4:$D$14,MATCH($C5,'3_UK_L1_Input'!$A$4:$A$14,0))*K5) | S5: =IF(G5="","BETA CASCADE FALLBACK (dummy — replace with real beta)","REAL (Bloomberg UK)") | T5: =INDEX('3_UK_L1_Input'!$C$4:$C$14,MATCH($C5,'3_UK_L1_Input'!$A$4:$A$14,0)) | U5: =INDEX('3_UK_L1_Input'!$C$4:$C$14,MATCH($C5,'3_UK_L1_Input'!$A$4:$A$14,0))*P5 | V5: =INDEX('5_UK_DefaultRisk_Input'!$D$5:$D$15,MATCH($C5,'5_UK_DefaultRisk_Input'!$A$5:$A$15,0)) | W5: =INDEX('5_UK_DefaultRisk_Input'!$D$20:$D$44,MATCH($E5,'5_UK_DefaultRisk_Input'!$A$20:$A$44,0)) | X5: =INDEX('5_UK_DefaultRisk_Input'!$D$49:$D$122,MATCH($D5,'5_UK_DefaultRisk_Input'!$A$49:$A$122,0)) | Y5: =INDEX('5_UK_DefaultRisk_Input'!$D$127:$D$289,MATCH($A5,'5_UK_DefaultRisk_Input'!$A$127:$A$289,0)) | Z5: =(W5/V5)*(X5/W5)*(Y5/X5) | AA5: =INDEX('3_UK_L1_Input'!$D$4:$D$14,MATCH($C5,'3_UK_L1_Input'!$A$4:$A$14,0))*Z5
A6: 10102020 | B6: Oil & Gas Exploration & Production | C6: 10 | D6: 101020 | E6: 1010 | F6: 217770000 | G6: 3.17 | H6: =IFERROR(SUMPRODUCT(($C$3:$C$165=C6)*ISNUMBER($G$3:$G$165)*ISNUMBER($F$3:$F$165)*IF(ISNUMBER($F$3:$F$165),$F$3:$F$165,0)*IF(ISNUMBER($G$3:$G$165),$G$3:$G$165,0))/SUMPRODUCT(($C$3:$C$165=C6)*ISNUMBER($G$3:$G$165)*ISNUMBER($F$3:$F$165)*IF(ISNUMBER($F$3:$F$165),$F$3:$F$165,0)),"") | I6: =IFERROR(SUMPRODUCT(($C$3:$C$165=C6)*ISNUMBER($G$3:$G$165)*IF(ISNUMBER($G$3:$G$165),$G$3:$G$165,0))/SUMPRODUCT(($C$3:$C$165=C6)*ISNUMBER($G$3:$G$165)),"") | J6: =IF(OR(G6="",H6=""),"",G6/H6) | K6: =IF(OR(G6="",I6=""),"",G6/I6) | L6: =INDEX('4_UK_Beta_Input'!$D$5:$D$15,MATCH($C6,'4_UK_Beta_Input'!$A$5:$A$15,0)) | M6: =INDEX('4_UK_Beta_Input'!$D$20:$D$44,MATCH($E6,'4_UK_Beta_Input'!$A$20:$A$44,0)) | N6: =INDEX('4_UK_Beta_Input'!$D$49:$D$122,MATCH($D6,'4_UK_Beta_Input'!$A$49:$A$122,0)) | O6: =INDEX('4_UK_Beta_Input'!$D$127:$D$289,MATCH($A6,'4_UK_Beta_Input'!$A$127:$A$289,0)) | P6: =(M6/L6)*(N6/M6)*(O6/N6) | Q6: =IF(J6="",INDEX('3_UK_L1_Input'!$D$4:$D$14,MATCH($C6,'3_UK_L1_Input'!$A$4:$A$14,0))*P6,INDEX('3_UK_L1_Input'!$D$4:$D$14,MATCH($C6,'3_UK_L1_Input'!$A$4:$A$14,0))*J6) | R6: =IF(K6="",INDEX('3_UK_L1_Input'!$D$4:$D$14,MATCH($C6,'3_UK_L1_Input'!$A$4:$A$14,0))*P6,INDEX('3_UK_L1_Input'!$D$4:$D$14,MATCH($C6,'3_UK_L1_Input'!$A$4:$A$14,0))*K6) | S6: =IF(G6="","BETA CASCADE FALLBACK (dummy — replace with real beta)","REAL (Bloomberg UK)") | T6: =INDEX('3_UK_L1_Input'!$C$4:$C$14,MATCH($C6,'3_UK_L1_Input'!$A$4:$A$14,0)) | U6: =INDEX('3_UK_L1_Input'!$C$4:$C$14,MATCH($C6,'3_UK_L1_Input'!$A$4:$A$14,0))*P6 | V6: =INDEX('5_UK_DefaultRisk_Input'!$D$5:$D$15,MATCH($C6,'5_UK_DefaultRisk_Input'!$A$5:$A$15,0)) | W6: =INDEX('5_UK_DefaultRisk_Input'!$D$20:$D$44,MATCH($E6,'5_UK_DefaultRisk_Input'!$A$20:$A$44,0)) | X6: =INDEX('5_UK_DefaultRisk_Input'!$D$49:$D$122,MATCH($D6,'5_UK_DefaultRisk_Input'!$A$49:$A$122,0)) | Y6: =INDEX('5_UK_DefaultRisk_Input'!$D$127:$D$289,MATCH($A6,'5_UK_DefaultRisk_Input'!$A$127:$A$289,0)) | Z6: =(W6/V6)*(X6/W6)*(Y6/X6) | AA6: =INDEX('3_UK_L1_Input'!$D$4:$D$14,MATCH($C6,'3_UK_L1_Input'!$A$4:$A$14,0))*Z6
A7: 10102030 | B7: Oil & Gas Refining & Marketing | C7: 10 | D7: 101020 | E7: 1010 | F7: 87000 | H7: =IFERROR(SUMPRODUCT(($C$3:$C$165=C7)*ISNUMBER($G$3:$G$165)*ISNUMBER($F$3:$F$165)*IF(ISNUMBER($F$3:$F$165),$F$3:$F$165,0)*IF(ISNUMBER($G$3:$G$165),$G$3:$G$165,0))/SUMPRODUCT(($C$3:$C$165=C7)*ISNUMBER($G$3:$G$165)*ISNUMBER($F$3:$F$165)*IF(ISNUMBER($F$3:$F$165),$F$3:$F$165,0)),"") | I7: =IFERROR(SUMPRODUCT(($C$3:$C$165=C7)*ISNUMBER($G$3:$G$165)*IF(ISNUMBER($G$3:$G$165),$G$3:$G$165,0))/SUMPRODUCT(($C$3:$C$165=C7)*ISNUMBER($G$3:$G$165)),"") | J7: =IF(OR(G7="",H7=""),"",G7/H7) | K7: =IF(OR(G7="",I7=""),"",G7/I7) | L7: =INDEX('4_UK_Beta_Input'!$D$5:$D$15,MATCH($C7,'4_UK_Beta_Input'!$A$5:$A$15,0)) | M7: =INDEX('4_UK_Beta_Input'!$D$20:$D$44,MATCH($E7,'4_UK_Beta_Input'!$A$20:$A$44,0)) | N7: =INDEX('4_UK_Beta_Input'!$D$49:$D$122,MATCH($D7,'4_UK_Beta_Input'!$A$49:$A$122,0)) | O7: =INDEX('4_UK_Beta_Input'!$D$127:$D$289,MATCH($A7,'4_UK_Beta_Input'!$A$127:$A$289,0)) | P7: =(M7/L7)*(N7/M7)*(O7/N7) | Q7: =IF(J7="",INDEX('3_UK_L1_Input'!$D$4:$D$14,MATCH($C7,'3_UK_L1_Input'!$A$4:$A$14,0))*P7,INDEX('3_UK_L1_Input'!$D$4:$D$14,MATCH($C7,'3_UK_L1_Input'!$A$4:$A$14,0))*J7) | R7: =IF(K7="",INDEX('3_UK_L1_Input'!$D$4:$D$14,MATCH($C7,'3_UK_L1_Input'!$A$4:$A$14,0))*P7,INDEX('3_UK_L1_Input'!$D$4:$D$14,MATCH($C7,'3_UK_L1_Input'!$A$4:$A$14,0))*K7) | S7: =IF(G7="","BETA CASCADE FALLBACK (dummy — replace with real beta)","REAL (Bloomberg UK)") | T7: =INDEX('3_UK_L1_Input'!$C$4:$C$14,MATCH($C7,'3_UK_L1_Input'!$A$4:$A$14,0)) | U7: =INDEX('3_UK_L1_Input'!$C$4:$C$14,MATCH($C7,'3_UK_L1_Input'!$A$4:$A$14,0))*P7 | V7: =INDEX('5_UK_DefaultRisk_Input'!$D$5:$D$15,MATCH($C7,'5_UK_DefaultRisk_Input'!$A$5:$A$15,0)) | W7: =INDEX('5_UK_DefaultRisk_Input'!$D$20:$D$44,MATCH($E7,'5_UK_DefaultRisk_Input'!$A$20:$A$44,0)) | X7: =INDEX('5_UK_DefaultRisk_Input'!$D$49:$D$122,MATCH($D7,'5_UK_DefaultRisk_Input'!$A$49:$A$122,0)) | Y7: =INDEX('5_UK_DefaultRisk_Input'!$D$127:$D$289,MATCH($A7,'5_UK_DefaultRisk_Input'!$A$127:$A$289,0)) | Z7: =(W7/V7)*(X7/W7)*(Y7/X7) | AA7: =INDEX('3_UK_L1_Input'!$D$4:$D$14,MATCH($C7,'3_UK_L1_Input'!$A$4:$A$14,0))*Z7
A8: 10102040 | B8: Oil & Gas Storage & Transportation | C8: 10 | D8: 101020 | E8: 1010 | F8: 901710000 | G8: 3.94 | H8: =IFERROR(SUMPRODUCT(($C$3:$C$165=C8)*ISNUMBER($G$3:$G$165)*ISNUMBER($F$3:$F$165)*IF(ISNUMBER($F$3:$F$165),$F$3:$F$165,0)*IF(ISNUMBER($G$3:$G$165),$G$3:$G$165,0))/SUMPRODUCT(($C$3:$C$165=C8)*ISNUMBER($G$3:$G$165)*ISNUMBER($F$3:$F$165)*IF(ISNUMBER($F$3:$F$165),$F$3:$F$165,0)),"") | I8: =IFERROR(SUMPRODUCT(($C$3:$C$165=C8)*ISNUMBER($G$3:$G$165)*IF(ISNUMBER($G$3:$G$165),$G$3:$G$165,0))/SUMPRODUCT(($C$3:$C$165=C8)*ISNUMBER($G$3:$G$165)),"") | J8: =IF(OR(G8="",H8=""),"",G8/H8) | K8: =IF(OR(G8="",I8=""),"",G8/I8) | L8: =INDEX('4_UK_Beta_Input'!$D$5:$D$15,MATCH($C8,'4_UK_Beta_Input'!$A$5:$A$15,0)) | M8: =INDEX('4_UK_Beta_Input'!$D$20:$D$44,MATCH($E8,'4_UK_Beta_Input'!$A$20:$A$44,0)) | N8: =INDEX('4_UK_Beta_Input'!$D$49:$D$122,MATCH($D8,'4_UK_Beta_Input'!$A$49:$A$122,0)) | O8: =INDEX('4_UK_Beta_Input'!$D$127:$D$289,MATCH($A8,'4_UK_Beta_Input'!$A$127:$A$289,0)) | P8: =(M8/L8)*(N8/M8)*(O8/N8) | Q8: =IF(J8="",INDEX('3_UK_L1_Input'!$D$4:$D$14,MATCH($C8,'3_UK_L1_Input'!$A$4:$A$14,0))*P8,INDEX('3_UK_L1_Input'!$D$4:$D$14,MATCH($C8,'3_UK_L1_Input'!$A$4:$A$14,0))*J8) | R8: =IF(K8="",INDEX('3_UK_L1_Input'!$D$4:$D$14,MATCH($C8,'3_UK_L1_Input'!$A$4:$A$14,0))*P8,INDEX('3_UK_L1_Input'!$D$4:$D$14,MATCH($C8,'3_UK_L1_Input'!$A$4:$A$14,0))*K8) | S8: =IF(G8="","BETA CASCADE FALLBACK (dummy — replace with real beta)","REAL (Bloomberg UK)") | T8: =INDEX('3_UK_L1_Input'!$C$4:$C$14,MATCH($C8,'3_UK_L1_Input'!$A$4:$A$14,0)) | U8: =INDEX('3_UK_L1_Input'!$C$4:$C$14,MATCH($C8,'3_UK_L1_Input'!$A$4:$A$14,0))*P8 | V8: =INDEX('5_UK_DefaultRisk_Input'!$D$5:$D$15,MATCH($C8,'5_UK_DefaultRisk_Input'!$A$5:$A$15,0)) | W8: =INDEX('5_UK_DefaultRisk_Input'!$D$20:$D$44,MATCH($E8,'5_UK_DefaultRisk_Input'!$A$20:$A$44,0)) | X8: =INDEX('5_UK_DefaultRisk_Input'!$D$49:$D$122,MATCH($D8,'5_UK_DefaultRisk_Input'!$A$49:$A$122,0)) | Y8: =INDEX('5_UK_DefaultRisk_Input'!$D$127:$D$289,MATCH($A8,'5_UK_DefaultRisk_Input'!$A$127:$A$289,0)) | Z8: =(W8/V8)*(X8/W8)*(Y8/X8) | AA8: =INDEX('3_UK_L1_Input'!$D$4:$D$14,MATCH($C8,'3_UK_L1_Input'!$A$4:$A$14,0))*Z8
A9: 10102050 | B9: Coal & Consumable Fuels | C9: 10 | D9: 101020 | E9: 1010 | G9: 9.47 | H9: =IFERROR(SUMPRODUCT(($C$3:$C$165=C9)*ISNUMBER($G$3:$G$165)*ISNUMBER($F$3:$F$165)*IF(ISNUMBER($F$3:$F$165),$F$3:$F$165,0)*IF(ISNUMBER($G$3:$G$165),$G$3:$G$165,0))/SUMPRODUCT(($C$3:$C$165=C9)*ISNUMBER($G$3:$G$165)*ISNUMBER($F$3:$F$165)*IF(ISNUMBER($F$3:$F$165),$F$3:$F$165,0)),"") | I9: =IFERROR(SUMPRODUCT(($C$3:$C$165=C9)*ISNUMBER($G$3:$G$165)*IF(ISNUMBER($G$3:$G$165),$G$3:$G$165,0))/SUMPRODUCT(($C$3:$C$165=C9)*ISNUMBER($G$3:$G$165)),"") | J9: =IF(OR(G9="",H9=""),"",G9/H9) | K9: =IF(OR(G9="",I9=""),"",G9/I9) | L9: =INDEX('4_UK_Beta_Input'!$D$5:$D$15,MATCH($C9,'4_UK_Beta_Input'!$A$5:$A$15,0)) | M9: =INDEX('4_UK_Beta_Input'!$D$20:$D$44,MATCH($E9,'4_UK_Beta_Input'!$A$20:$A$44,0)) | N9: =INDEX('4_UK_Beta_Input'!$D$49:$D$122,MATCH($D9,'4_UK_Beta_Input'!$A$49:$A$122,0)) | O9: =INDEX('4_UK_Beta_Input'!$D$127:$D$289,MATCH($A9,'4_UK_Beta_Input'!$A$127:$A$289,0)) | P9: =(M9/L9)*(N9/M9)*(O9/N9) | Q9: =IF(J9="",INDEX('3_UK_L1_Input'!$D$4:$D$14,MATCH($C9,'3_UK_L1_Input'!$A$4:$A$14,0))*P9,INDEX('3_UK_L1_Input'!$D$4:$D$14,MATCH($C9,'3_UK_L1_Input'!$A$4:$A$14,0))*J9) | R9: =IF(K9="",INDEX('3_UK_L1_Input'!$D$4:$D$14,MATCH($C9,'3_UK_L1_Input'!$A$4:$A$14,0))*P9,INDEX('3_UK_L1_Input'!$D$4:$D$14,MATCH($C9,'3_UK_L1_Input'!$A$4:$A$14,0))*K9) | S9: =IF(G9="","BETA CASCADE FALLBACK (dummy — replace with real beta)","REAL (Bloomberg UK)") | T9: =INDEX('3_UK_L1_Input'!$C$4:$C$14,MATCH($C9,'3_UK_L1_Input'!$A$4:$A$14,0)) | U9: =INDEX('3_UK_L1_Input'!$C$4:$C$14,MATCH($C9,'3_UK_L1_Input'!$A$4:$A$14,0))*P9 | V9: =INDEX('5_UK_DefaultRisk_Input'!$D$5:$D$15,MATCH($C9,'5_UK_DefaultRisk_Input'!$A$5:$A$15,0)) | W9: =INDEX('5_UK_DefaultRisk_Input'!$D$20:$D$44,MATCH($E9,'5_UK_DefaultRisk_Input'!$A$20:$A$44,0)) | X9: =INDEX('5_UK_DefaultRisk_Input'!$D$49:$D$122,MATCH($D9,'5_UK_DefaultRisk_Input'!$A$49:$A$122,0)) | Y9: =INDEX('5_UK_DefaultRisk_Input'!$D$127:$D$289,MATCH($A9,'5_UK_DefaultRisk_Input'!$A$127:$A$289,0)) | Z9: =(W9/V9)*(X9/W9)*(Y9/X9) | AA9: =INDEX('3_UK_L1_Input'!$D$4:$D$14,MATCH($C9,'3_UK_L1_Input'!$A$4:$A$14,0))*Z9
A10: 15101010 | B10: Commodity Chemicals | C10: 15 | D10: 151010 | E10: 1510 | F10: 246000000 | G10: 5.64 | H10: =IFERROR(SUMPRODUCT(($C$3:$C$165=C10)*ISNUMBER($G$3:$G$165)*ISNUMBER($F$3:$F$165)*IF(ISNUMBER($F$3:$F$165),$F$3:$F$165,0)*IF(ISNUMBER($G$3:$G$165),$G$3:$G$165,0))/SUMPRODUCT(($C$3:$C$165=C10)*ISNUMBER($G$3:$G$165)*ISNUMBER($F$3:$F$165)*IF(ISNUMBER($F$3:$F$165),$F$3:$F$165,0)),"") | I10: =IFERROR(SUMPRODUCT(($C$3:$C$165=C10)*ISNUMBER($G$3:$G$165)*IF(ISNUMBER($G$3:$G$165),$G$3:$G$165,0))/SUMPRODUCT(($C$3:$C$165=C10)*ISNUMBER($G$3:$G$165)),"") | J10: =IF(OR(G10="",H10=""),"",G10/H10) | K10: =IF(OR(G10="",I10=""),"",G10/I10) | L10: =INDEX('4_UK_Beta_Input'!$D$5:$D$15,MATCH($C10,'4_UK_Beta_Input'!$A$5:$A$15,0)) | M10: =INDEX('4_UK_Beta_Input'!$D$20:$D$44,MATCH($E10,'4_UK_Beta_Input'!$A$20:$A$44,0)) | N10: =INDEX('4_UK_Beta_Input'!$D$49:$D$122,MATCH($D10,'4_UK_Beta_Input'!$A$49:$A$122,0)) | O10: =INDEX('4_UK_Beta_Input'!$D$127:$D$289,MATCH($A10,'4_UK_Beta_Input'!$A$127:$A$289,0)) | P10: =(M10/L10)*(N10/M10)*(O10/N10) | Q10: =IF(J10="",INDEX('3_UK_L1_Input'!$D$4:$D$14,MATCH($C10,'3_UK_L1_Input'!$A$4:$A$14,0))*P10,INDEX('3_UK_L1_Input'!$D$4:$D$14,MATCH($C10,'3_UK_L1_Input'!$A$4:$A$14,0))*J10) | R10: =IF(K10="",INDEX('3_UK_L1_Input'!$D$4:$D$14,MATCH($C10,'3_UK_L1_Input'!$A$4:$A$14,0))*P10,INDEX('3_UK_L1_Input'!$D$4:$D$14,MATCH($C10,'3_UK_L1_Input'!$A$4:$A$14,0))*K10) | S10: =IF(G10="","BETA CASCADE FALLBACK (dummy — replace with real beta)","REAL (Bloomberg UK)") | T10: =INDEX('3_UK_L1_Input'!$C$4:$C$14,MATCH($C10,'3_UK_L1_Input'!$A$4:$A$14,0)) | U10: =INDEX('3_UK_L1_Input'!$C$4:$C$14,MATCH($C10,'3_UK_L1_Input'!$A$4:$A$14,0))*P10 | V10: =INDEX('5_UK_DefaultRisk_Input'!$D$5:$D$15,MATCH($C10,'5_UK_DefaultRisk_Input'!$A$5:$A$15,0)) | W10: =INDEX('5_UK_DefaultRisk_Input'!$D$20:$D$44,MATCH($E10,'5_UK_DefaultRisk_Input'!$A$20:$A$44,0)) | X10: =INDEX('5_UK_DefaultRisk_Input'!$D$49:$D$122,MATCH($D10,'5_UK_DefaultRisk_Input'!$A$49:$A$122,0)) | Y10: =INDEX('5_UK_DefaultRisk_Input'!$D$127:$D$289,MATCH($A10,'5_UK_DefaultRisk_Input'!$A$127:$A$289,0)) | Z10: =(W10/V10)*(X10/W10)*(Y10/X10) | AA10: =INDEX('3_UK_L1_Input'!$D$4:$D$14,MATCH($C10,'3_UK_L1_Input'!$A$4:$A$14,0))*Z10
A11: 15101020 | B11: Diversified Chemicals | C11: 15 | D11: 151010 | E11: 1510 | H11: =IFERROR(SUMPRODUCT(($C$3:$C$165=C11)*ISNUMBER($G$3:$G$165)*ISNUMBER($F$3:$F$165)*IF(ISNUMBER($F$3:$F$165),$F$3:$F$165,0)*IF(ISNUMBER($G$3:$G$165),$G$3:$G$165,0))/SUMPRODUCT(($C$3:$C$165=C11)*ISNUMBER($G$3:$G$165)*ISNUMBER($F$3:$F$165)*IF(ISNUMBER($F$3:$F$165),$F$3:$F$165,0)),"") | I11: =IFERROR(SUMPRODUCT(($C$3:$C$165=C11)*ISNUMBER($G$3:$G$165)*IF(ISNUMBER($G$3:$G$165),$G$3:$G$165,0))/SUMPRODUCT(($C$3:$C$165=C11)*ISNUMBER($G$3:$G$165)),"") | J11: =IF(OR(G11="",H11=""),"",G11/H11) | K11: =IF(OR(G11="",I11=""),"",G11/I11) | L11: =INDEX('4_UK_Beta_Input'!$D$5:$D$15,MATCH($C11,'4_UK_Beta_Input'!$A$5:$A$15,0)) | M11: =INDEX('4_UK_Beta_Input'!$D$20:$D$44,MATCH($E11,'4_UK_Beta_Input'!$A$20:$A$44,0)) | N11: =INDEX('4_UK_Beta_Input'!$D$49:$D$122,MATCH($D11,'4_UK_Beta_Input'!$A$49:$A$122,0)) | O11: =INDEX('4_UK_Beta_Input'!$D$127:$D$289,MATCH($A11,'4_UK_Beta_Input'!$A$127:$A$289,0)) | P11: =(M11/L11)*(N11/M11)*(O11/N11) | Q11: =IF(J11="",INDEX('3_UK_L1_Input'!$D$4:$D$14,MATCH($C11,'3_UK_L1_Input'!$A$4:$A$14,0))*P11,INDEX('3_UK_L1_Input'!$D$4:$D$14,MATCH($C11,'3_UK_L1_Input'!$A$4:$A$14,0))*J11) | R11: =IF(K11="",INDEX('3_UK_L1_Input'!$D$4:$D$14,MATCH($C11,'3_UK_L1_Input'!$A$4:$A$14,0))*P11,INDEX('3_UK_L1_Input'!$D$4:$D$14,MATCH($C11,'3_UK_L1_Input'!$A$4:$A$14,0))*K11) | S11: =IF(G11="","BETA CASCADE FALLBACK (dummy — replace with real beta)","REAL (Bloomberg UK)") | T11: =INDEX('3_UK_L1_Input'!$C$4:$C$14,MATCH($C11,'3_UK_L1_Input'!$A$4:$A$14,0)) | U11: =INDEX('3_UK_L1_Input'!$C$4:$C$14,MATCH($C11,'3_UK_L1_Input'!$A$4:$A$14,0))*P11 | V11: =INDEX('5_UK_DefaultRisk_Input'!$D$5:$D$15,MATCH($C11,'5_UK_DefaultRisk_Input'!$A$5:$A$15,0)) | W11: =INDEX('5_UK_DefaultRisk_Input'!$D$20:$D$44,MATCH($E11,'5_UK_DefaultRisk_Input'!$A$20:$A$44,0)) | X11: =INDEX('5_UK_DefaultRisk_Input'!$D$49:$D$122,MATCH($D11,'5_UK_DefaultRisk_Input'!$A$49:$A$122,0)) | Y11: =INDEX('5_UK_DefaultRisk_Input'!$D$127:$D$289,MATCH($A11,'5_UK_DefaultRisk_Input'!$A$127:$A$289,0)) | Z11: =(W11/V11)*(X11/W11)*(Y11/X11) | AA11: =INDEX('3_UK_L1_Input'!$D$4:$D$14,MATCH($C11,'3_UK_L1_Input'!$A$4:$A$14,0))*Z11
A12: 15101030 | B12: Fertilizers & Agricultural Chemicals | C12: 15 | D12: 151010 | E12: 1510 | F12: 21070000 | H12: =IFERROR(SUMPRODUCT(($C$3:$C$165=C12)*ISNUMBER($G$3:$G$165)*ISNUMBER($F$3:$F$165)*IF(ISNUMBER($F$3:$F$165),$F$3:$F$165,0)*IF(ISNUMBER($G$3:$G$165),$G$3:$G$165,0))/SUMPRODUCT(($C$3:$C$165=C12)*ISNUMBER($G$3:$G$165)*ISNUMBER($F$3:$F$165)*IF(ISNUMBER($F$3:$F$165),$F$3:$F$165,0)),"") | I12: =IFERROR(SUMPRODUCT(($C$3:$C$165=C12)*ISNUMBER($G$3:$G$165)*IF(ISNUMBER($G$3:$G$165),$G$3:$G$165,0))/SUMPRODUCT(($C$3:$C$165=C12)*ISNUMBER($G$3:$G$165)),"") | J12: =IF(OR(G12="",H12=""),"",G12/H12) | K12: =IF(OR(G12="",I12=""),"",G12/I12) | L12: =INDEX('4_UK_Beta_Input'!$D$5:$D$15,MATCH($C12,'4_UK_Beta_Input'!$A$5:$A$15,0)) | M12: =INDEX('4_UK_Beta_Input'!$D$20:$D$44,MATCH($E12,'4_UK_Beta_Input'!$A$20:$A$44,0)) | N12: =INDEX('4_UK_Beta_Input'!$D$49:$D$122,MATCH($D12,'4_UK_Beta_Input'!$A$49:$A$122,0)) | O12: =INDEX('4_UK_Beta_Input'!$D$127:$D$289,MATCH($A12,'4_UK_Beta_Input'!$A$127:$A$289,0)) | P12: =(M12/L12)*(N12/M12)*(O12/N12) | Q12: =IF(J12="",INDEX('3_UK_L1_Input'!$D$4:$D$14,MATCH($C12,'3_UK_L1_Input'!$A$4:$A$14,0))*P12,INDEX('3_UK_L1_Input'!$D$4:$D$14,MATCH($C12,'3_UK_L1_Input'!$A$4:$A$14,0))*J12) | R12: =IF(K12="",INDEX('3_UK_L1_Input'!$D$4:$D$14,MATCH($C12,'3_UK_L1_Input'!$A$4:$A$14,0))*P12,INDEX('3_UK_L1_Input'!$D$4:$D$14,MATCH($C12,'3_UK_L1_Input'!$A$4:$A$14,0))*K12) | S12: =IF(G12="","BETA CASCADE FALLBACK (dummy — replace with real beta)","REAL (Bloomberg UK)") | T12: =INDEX('3_UK_L1_Input'!$C$4:$C$14,MATCH($C12,'3_UK_L1_Input'!$A$4:$A$14,0)) | U12: =INDEX('3_UK_L1_Input'!$C$4:$C$14,MATCH($C12,'3_UK_L1_Input'!$A$4:$A$14,0))*P12 | V12: =INDEX('5_UK_DefaultRisk_Input'!$D$5:$D$15,MATCH($C12,'5_UK_DefaultRisk_Input'!$A$5:$A$15,0)) | W12: =INDEX('5_UK_DefaultRisk_Input'!$D$20:$D$44,MATCH($E12,'5_UK_DefaultRisk_Input'!$A$20:$A$44,0)) | X12: =INDEX('5_UK_DefaultRisk_Input'!$D$49:$D$122,MATCH($D12,'5_UK_DefaultRisk_Input'!$A$49:$A$122,0)) | Y12: =INDEX('5_UK_DefaultRisk_Input'!$D$127:$D$289,MATCH($A12,'5_UK_DefaultRisk_Input'!$A$127:$A$289,0)) | Z12: =(W12/V12)*(X12/W12)*(Y12/X12) | AA12: =INDEX('3_UK_L1_Input'!$D$4:$D$14,MATCH($C12,'3_UK_L1_Input'!$A$4:$A$14,0))*Z12
A13: 15101040 | B13: Industrial Gases | C13: 15 | D13: 151010 | E13: 1510 | H13: =IFERROR(SUMPRODUCT(($C$3:$C$165=C13)*ISNUMBER($G$3:$G$165)*ISNUMBER($F$3:$F$165)*IF(ISNUMBER($F$3:$F$165),$F$3:$F$165,0)*IF(ISNUMBER($G$3:$G$165),$G$3:$G$165,0))/SUMPRODUCT(($C$3:$C$165=C13)*ISNUMBER($G$3:$G$165)*ISNUMBER($F$3:$F$165)*IF(ISNUMBER($F$3:$F$165),$F$3:$F$165,0)),"") | I13: =IFERROR(SUMPRODUCT(($C$3:$C$165=C13)*ISNUMBER($G$3:$G$165)*IF(ISNUMBER($G$3:$G$165),$G$3:$G$165,0))/SUMPRODUCT(($C$3:$C$165=C13)*ISNUMBER($G$3:$G$165)),"") | J13: =IF(OR(G13="",H13=""),"",G13/H13) | K13: =IF(OR(G13="",I13=""),"",G13/I13) | L13: =INDEX('4_UK_Beta_Input'!$D$5:$D$15,MATCH($C13,'4_UK_Beta_Input'!$A$5:$A$15,0)) | M13: =INDEX('4_UK_Beta_Input'!$D$20:$D$44,MATCH($E13,'4_UK_Beta_Input'!$A$20:$A$44,0)) | N13: =INDEX('4_UK_Beta_Input'!$D$49:$D$122,MATCH($D13,'4_UK_Beta_Input'!$A$49:$A$122,0)) | O13: =INDEX('4_UK_Beta_Input'!$D$127:$D$289,MATCH($A13,'4_UK_Beta_Input'!$A$127:$A$289,0)) | P13: =(M13/L13)*(N13/M13)*(O13/N13) | Q13: =IF(J13="",INDEX('3_UK_L1_Input'!$D$4:$D$14,MATCH($C13,'3_UK_L1_Input'!$A$4:$A$14,0))*P13,INDEX('3_UK_L1_Input'!$D$4:$D$14,MATCH($C13,'3_UK_L1_Input'!$A$4:$A$14,0))*J13) | R13: =IF(K13="",INDEX('3_UK_L1_Input'!$D$4:$D$14,MATCH($C13,'3_UK_L1_Input'!$A$4:$A$14,0))*P13,INDEX('3_UK_L1_Input'!$D$4:$D$14,MATCH($C13,'3_UK_L1_Input'!$A$4:$A$14,0))*K13) | S13: =IF(G13="","BETA CASCADE FALLBACK (dummy — replace with real beta)","REAL (Bloomberg UK)") | T13: =INDEX('3_UK_L1_Input'!$C$4:$C$14,MATCH($C13,'3_UK_L1_Input'!$A$4:$A$14,0)) | U13: =INDEX('3_UK_L1_Input'!$C$4:$C$14,MATCH($C13,'3_UK_L1_Input'!$A$4:$A$14,0))*P13 | V13: =INDEX('5_UK_DefaultRisk_Input'!$D$5:$D$15,MATCH($C13,'5_UK_DefaultRisk_Input'!$A$5:$A$15,0)) | W13: =INDEX('5_UK_DefaultRisk_Input'!$D$20:$D$44,MATCH($E13,'5_UK_DefaultRisk_Input'!$A$20:$A$44,0)) | X13: =INDEX('5_UK_DefaultRisk_Input'!$D$49:$D$122,MATCH($D13,'5_UK_DefaultRisk_Input'!$A$49:$A$122,0)) | Y13: =INDEX('5_UK_DefaultRisk_Input'!$D$127:$D$289,MATCH($A13,'5_UK_DefaultRisk_Input'!$A$127:$A$289,0)) | Z13: =(W13/V13)*(X13/W13)*(Y13/X13) | AA13: =INDEX('3_UK_L1_Input'!$D$4:$D$14,MATCH($C13,'3_UK_L1_Input'!$A$4:$A$14,0))*Z13
A14: 15101050 | B14: Specialty Chemicals | C14: 15 | D14: 151010 | E14: 1510 | F14: 1590000000 | G14: 8.87 | H14: =IFERROR(SUMPRODUCT(($C$3:$C$165=C14)*ISNUMBER($G$3:$G$165)*ISNUMBER($F$3:$F$165)*IF(ISNUMBER($F$3:$F$165),$F$3:$F$165,0)*IF(ISNUMBER($G$3:$G$165),$G$3:$G$165,0))/SUMPRODUCT(($C$3:$C$165=C14)*ISNUMBER($G$3:$G$165)*ISNUMBER($F$3:$F$165)*IF(ISNUMBER($F$3:$F$165),$F$3:$F$165,0)),"") | I14: =IFERROR(SUMPRODUCT(($C$3:$C$165=C14)*ISNUMBER($G$3:$G$165)*IF(ISNUMBER($G$3:$G$165),$G$3:$G$165,0))/SUMPRODUCT(($C$3:$C$165=C14)*ISNUMBER($G$3:$G$165)),"") | J14: =IF(OR(G14="",H14=""),"",G14/H14) | K14: =IF(OR(G14="",I14=""),"",G14/I14) | L14: =INDEX('4_UK_Beta_Input'!$D$5:$D$15,MATCH($C14,'4_UK_Beta_Input'!$A$5:$A$15,0)) | M14: =INDEX('4_UK_Beta_Input'!$D$20:$D$44,MATCH($E14,'4_UK_Beta_Input'!$A$20:$A$44,0)) | N14: =INDEX('4_UK_Beta_Input'!$D$49:$D$122,MATCH($D14,'4_UK_Beta_Input'!$A$49:$A$122,0)) | O14: =INDEX('4_UK_Beta_Input'!$D$127:$D$289,MATCH($A14,'4_UK_Beta_Input'!$A$127:$A$289,0)) | P14: =(M14/L14)*(N14/M14)*(O14/N14) | Q14: =IF(J14="",INDEX('3_UK_L1_Input'!$D$4:$D$14,MATCH($C14,'3_UK_L1_Input'!$A$4:$A$14,0))*P14,INDEX('3_UK_L1_Input'!$D$4:$D$14,MATCH($C14,'3_UK_L1_Input'!$A$4:$A$14,0))*J14) | R14: =IF(K14="",INDEX('3_UK_L1_Input'!$D$4:$D$14,MATCH($C14,'3_UK_L1_Input'!$A$4:$A$14,0))*P14,INDEX('3_UK_L1_Input'!$D$4:$D$14,MATCH($C14,'3_UK_L1_Input'!$A$4:$A$14,0))*K14) | S14: =IF(G14="","BETA CASCADE FALLBACK (dummy — replace with real beta)","REAL (Bloomberg UK)") | T14: =INDEX('3_UK_L1_Input'!$C$4:$C$14,MATCH($C14,'3_UK_L1_Input'!$A$4:$A$14,0)) | U14: =INDEX('3_UK_L1_Input'!$C$4:$C$14,MATCH($C14,'3_UK_L1_Input'!$A$4:$A$14,0))*P14 | V14: =INDEX('5_UK_DefaultRisk_Input'!$D$5:$D$15,MATCH($C14,'5_UK_DefaultRisk_Input'!$A$5:$A$15,0)) | W14: =INDEX('5_UK_DefaultRisk_Input'!$D$20:$D$44,MATCH($E14,'5_UK_DefaultRisk_Input'!$A$20:$A$44,0)) | X14: =INDEX('5_UK_DefaultRisk_Input'!$D$49:$D$122,MATCH($D14,'5_UK_DefaultRisk_Input'!$A$49:$A$122,0)) | Y14: =INDEX('5_UK_DefaultRisk_Input'!$D$127:$D$289,MATCH($A14,'5_UK_DefaultRisk_Input'!$A$127:$A$289,0)) | Z14: =(W14/V14)*(X14/W14)*(Y14/X14) | AA14: =INDEX('3_UK_L1_Input'!$D$4:$D$14,MATCH($C14,'3_UK_L1_Input'!$A$4:$A$14,0))*Z14
A15: 15102010 | B15: Construction Materials | C15: 15 | D15: 151020 | E15: 1510 | F15: 699210000 | G15: 6.57 | H15: =IFERROR(SUMPRODUCT(($C$3:$C$165=C15)*ISNUMBER($G$3:$G$165)*ISNUMBER($F$3:$F$165)*IF(ISNUMBER($F$3:$F$165),$F$3:$F$165,0)*IF(ISNUMBER($G$3:$G$165),$G$3:$G$165,0))/SUMPRODUCT(($C$3:$C$165=C15)*ISNUMBER($G$3:$G$165)*ISNUMBER($F$3:$F$165)*IF(ISNUMBER($F$3:$F$165),$F$3:$F$165,0)),"") | I15: =IFERROR(SUMPRODUCT(($C$3:$C$165=C15)*ISNUMBER($G$3:$G$165)*IF(ISNUMBER($G$3:$G$165),$G$3:$G$165,0))/SUMPRODUCT(($C$3:$C$165=C15)*ISNUMBER($G$3:$G$165)),"") | J15: =IF(OR(G15="",H15=""),"",G15/H15) | K15: =IF(OR(G15="",I15=""),"",G15/I15) | L15: =INDEX('4_UK_Beta_Input'!$D$5:$D$15,MATCH($C15,'4_UK_Beta_Input'!$A$5:$A$15,0)) | M15: =INDEX('4_UK_Beta_Input'!$D$20:$D$44,MATCH($E15,'4_UK_Beta_Input'!$A$20:$A$44,0)) | N15: =INDEX('4_UK_Beta_Input'!$D$49:$D$122,MATCH($D15,'4_UK_Beta_Input'!$A$49:$A$122,0)) | O15: =INDEX('4_UK_Beta_Input'!$D$127:$D$289,MATCH($A15,'4_UK_Beta_Input'!$A$127:$A$289,0)) | P15: =(M15/L15)*(N15/M15)*(O15/N15) | Q15: =IF(J15="",INDEX('3_UK_L1_Input'!$D$4:$D$14,MATCH($C15,'3_UK_L1_Input'!$A$4:$A$14,0))*P15,INDEX('3_UK_L1_Input'!$D$4:$D$14,MATCH($C15,'3_UK_L1_Input'!$A$4:$A$14,0))*J15) | R15: =IF(K15="",INDEX('3_UK_L1_Input'!$D$4:$D$14,MATCH($C15,'3_UK_L1_Input'!$A$4:$A$14,0))*P15,INDEX('3_UK_L1_Input'!$D$4:$D$14,MATCH($C15,'3_UK_L1_Input'!$A$4:$A$14,0))*K15) | S15: =IF(G15="","BETA CASCADE FALLBACK (dummy — replace with real beta)","REAL (Bloomberg UK)") | T15: =INDEX('3_UK_L1_Input'!$C$4:$C$14,MATCH($C15,'3_UK_L1_Input'!$A$4:$A$14,0)) | U15: =INDEX('3_UK_L1_Input'!$C$4:$C$14,MATCH($C15,'3_UK_L1_Input'!$A$4:$A$14,0))*P15 | V15: =INDEX('5_UK_DefaultRisk_Input'!$D$5:$D$15,MATCH($C15,'5_UK_DefaultRisk_Input'!$A$5:$A$15,0)) | W15: =INDEX('5_UK_DefaultRisk_Input'!$D$20:$D$44,MATCH($E15,'5_UK_DefaultRisk_Input'!$A$20:$A$44,0)) | X15: =INDEX('5_UK_DefaultRisk_Input'!$D$49:$D$122,MATCH($D15,'5_UK_DefaultRisk_Input'!$A$49:$A$122,0)) | Y15: =INDEX('5_UK_DefaultRisk_Input'!$D$127:$D$289,MATCH($A15,'5_UK_DefaultRisk_Input'!$A$127:$A$289,0)) | Z15: =(W15/V15)*(X15/W15)*(Y15/X15) | AA15: =INDEX('3_UK_L1_Input'!$D$4:$D$14,MATCH($C15,'3_UK_L1_Input'!$A$4:$A$14,0))*Z15
A16: 15103010 | B16: Metal, Glass & Plastic Containers | C16: 15 | D16: 151030 | E16: 1510 | F16: 33260000 | H16: =IFERROR(SUMPRODUCT(($C$3:$C$165=C16)*ISNUMBER($G$3:$G$165)*ISNUMBER($F$3:$F$165)*IF(ISNUMBER($F$3:$F$165),$F$3:$F$165,0)*IF(ISNUMBER($G$3:$G$165),$G$3:$G$165,0))/SUMPRODUCT(($C$3:$C$165=C16)*ISNUMBER($G$3:$G$165)*ISNUMBER($F$3:$F$165)*IF(ISNUMBER($F$3:$F$165),$F$3:$F$165,0)),"") | I16: =IFERROR(SUMPRODUCT(($C$3:$C$165=C16)*ISNUMBER($G$3:$G$165)*IF(ISNUMBER($G$3:$G$165),$G$3:$G$165,0))/SUMPRODUCT(($C$3:$C$165=C16)*ISNUMBER($G$3:$G$165)),"") | J16: =IF(OR(G16="",H16=""),"",G16/H16) | K16: =IF(OR(G16="",I16=""),"",G16/I16) | L16: =INDEX('4_UK_Beta_Input'!$D$5:$D$15,MATCH($C16,'4_UK_Beta_Input'!$A$5:$A$15,0)) | M16: =INDEX('4_UK_Beta_Input'!$D$20:$D$44,MATCH($E16,'4_UK_Beta_Input'!$A$20:$A$44,0)) | N16: =INDEX('4_UK_Beta_Input'!$D$49:$D$122,MATCH($D16,'4_UK_Beta_Input'!$A$49:$A$122,0)) | O16: =INDEX('4_UK_Beta_Input'!$D$127:$D$289,MATCH($A16,'4_UK_Beta_Input'!$A$127:$A$289,0)) | P16: =(M16/L16)*(N16/M16)*(O16/N16) | Q16: =IF(J16="",INDEX('3_UK_L1_Input'!$D$4:$D$14,MATCH($C16,'3_UK_L1_Input'!$A$4:$A$14,0))*P16,INDEX('3_UK_L1_Input'!$D$4:$D$14,MATCH($C16,'3_UK_L1_Input'!$A$4:$A$14,0))*J16) | R16: =IF(K16="",INDEX('3_UK_L1_Input'!$D$4:$D$14,MATCH($C16,'3_UK_L1_Input'!$A$4:$A$14,0))*P16,INDEX('3_UK_L1_Input'!$D$4:$D$14,MATCH($C16,'3_UK_L1_Input'!$A$4:$A$14,0))*K16) | S16: =IF(G16="","BETA CASCADE FALLBACK (dummy — replace with real beta)","REAL (Bloomberg UK)") | T16: =INDEX('3_UK_L1_Input'!$C$4:$C$14,MATCH($C16,'3_UK_L1_Input'!$A$4:$A$14,0)) | U16: =INDEX('3_UK_L1_Input'!$C$4:$C$14,MATCH($C16,'3_UK_L1_Input'!$A$4:$A$14,0))*P16 | V16: =INDEX('5_UK_DefaultRisk_Input'!$D$5:$D$15,MATCH($C16,'5_UK_DefaultRisk_Input'!$A$5:$A$15,0)) | W16: =INDEX('5_UK_DefaultRisk_Input'!$D$20:$D$44,MATCH($E16,'5_UK_DefaultRisk_Input'!$A$20:$A$44,0)) | X16: =INDEX('5_UK_DefaultRisk_Input'!$D$49:$D$122,MATCH($D16,'5_UK_DefaultRisk_Input'!$A$49:$A$122,0)) | Y16: =INDEX('5_UK_DefaultRisk_Input'!$D$127:$D$289,MATCH($A16,'5_UK_DefaultRisk_Input'!$A$127:$A$289,0)) | Z16: =(W16/V16)*(X16/W16)*(Y16/X16) | AA16: =INDEX('3_UK_L1_Input'!$D$4:$D$14,MATCH($C16,'3_UK_L1_Input'!$A$4:$A$14,0))*Z16
A17: 15103020 | B17: Paper & Plastic Packaging Products & Materials | C17: 15 | D17: 151030 | E17: 1510 | F17: 56210000 | G17: 3.38 | H17: =IFERROR(SUMPRODUCT(($C$3:$C$165=C17)*ISNUMBER($G$3:$G$165)*ISNUMBER($F$3:$F$165)*IF(ISNUMBER($F$3:$F$165),$F$3:$F$165,0)*IF(ISNUMBER($G$3:$G$165),$G$3:$G$165,0))/SUMPRODUCT(($C$3:$C$165=C17)*ISNUMBER($G$3:$G$165)*ISNUMBER($F$3:$F$165)*IF(ISNUMBER($F$3:$F$165),$F$3:$F$165,0)),"") | I17: =IFERROR(SUMPRODUCT(($C$3:$C$165=C17)*ISNUMBER($G$3:$G$165)*IF(ISNUMBER($G$3:$G$165),$G$3:$G$165,0))/SUMPRODUCT(($C$3:$C$165=C17)*ISNUMBER($G$3:$G$165)),"") | J17: =IF(OR(G17="",H17=""),"",G17/H17) | K17: =IF(OR(G17="",I17=""),"",G17/I17) | L17: =INDEX('4_UK_Beta_Input'!$D$5:$D$15,MATCH($C17,'4_UK_Beta_Input'!$A$5:$A$15,0)) | M17: =INDEX('4_UK_Beta_Input'!$D$20:$D$44,MATCH($E17,'4_UK_Beta_Input'!$A$20:$A$44,0)) | N17: =INDEX('4_UK_Beta_Input'!$D$49:$D$122,MATCH($D17,'4_UK_Beta_Input'!$A$49:$A$122,0)) | O17: =INDEX('4_UK_Beta_Input'!$D$127:$D$289,MATCH($A17,'4_UK_Beta_Input'!$A$127:$A$289,0)) | P17: =(M17/L17)*(N17/M17)*(O17/N17) | Q17: =IF(J17="",INDEX('3_UK_L1_Input'!$D$4:$D$14,MATCH($C17,'3_UK_L1_Input'!$A$4:$A$14,0))*P17,INDEX('3_UK_L1_Input'!$D$4:$D$14,MATCH($C17,'3_UK_L1_Input'!$A$4:$A$14,0))*J17) | R17: =IF(K17="",INDEX('3_UK_L1_Input'!$D$4:$D$14,MATCH($C17,'3_UK_L1_Input'!$A$4:$A$14,0))*P17,INDEX('3_UK_L1_Input'!$D$4:$D$14,MATCH($C17,'3_UK_L1_Input'!$A$4:$A$14,0))*K17) | S17: =IF(G17="","BETA CASCADE FALLBACK (dummy — replace with real beta)","REAL (Bloomberg UK)") | T17: =INDEX('3_UK_L1_Input'!$C$4:$C$14,MATCH($C17,'3_UK_L1_Input'!$A$4:$A$14,0)) | U17: =INDEX('3_UK_L1_Input'!$C$4:$C$14,MATCH($C17,'3_UK_L1_Input'!$A$4:$A$14,0))*P17 | V17: =INDEX('5_UK_DefaultRisk_Input'!$D$5:$D$15,MATCH($C17,'5_UK_DefaultRisk_Input'!$A$5:$A$15,0)) | W17: =INDEX('5_UK_DefaultRisk_Input'!$D$20:$D$44,MATCH($E17,'5_UK_DefaultRisk_Input'!$A$20:$A$44,0)) | X17: =INDEX('5_UK_DefaultRisk_Input'!$D$49:$D$122,MATCH($D17,'5_UK_DefaultRisk_Input'!$A$49:$A$122,0)) | Y17: =INDEX('5_UK_DefaultRisk_Input'!$D$127:$D$289,MATCH($A17,'5_UK_DefaultRisk_Input'!$A$127:$A$289,0)) | Z17: =(W17/V17)*(X17/W17)*(Y17/X17) | AA17: =INDEX('3_UK_L1_Input'!$D$4:$D$14,MATCH($C17,'3_UK_L1_Input'!$A$4:$A$14,0))*Z17
A18: 15104010 | B18: Aluminum | C18: 15 | D18: 151040 | E18: 1510 | H18: =IFERROR(SUMPRODUCT(($C$3:$C$165=C18)*ISNUMBER($G$3:$G$165)*ISNUMBER($F$3:$F$165)*IF(ISNUMBER($F$3:$F$165),$F$3:$F$165,0)*IF(ISNUMBER($G$3:$G$165),$G$3:$G$165,0))/SUMPRODUCT(($C$3:$C$165=C18)*ISNUMBER($G$3:$G$165)*ISNUMBER($F$3:$F$165)*IF(ISNUMBER($F$3:$F$165),$F$3:$F$165,0)),"") | I18: =IFERROR(SUMPRODUCT(($C$3:$C$165=C18)*ISNUMBER($G$3:$G$165)*IF(ISNUMBER($G$3:$G$165),$G$3:$G$165,0))/SUMPRODUCT(($C$3:$C$165=C18)*ISNUMBER($G$3:$G$165)),"") | J18: =IF(OR(G18="",H18=""),"",G18/H18) | K18: =IF(OR(G18="",I18=""),"",G18/I18) | L18: =INDEX('4_UK_Beta_Input'!$D$5:$D$15,MATCH($C18,'4_UK_Beta_Input'!$A$5:$A$15,0)) | M18: =INDEX('4_UK_Beta_Input'!$D$20:$D$44,MATCH($E18,'4_UK_Beta_Input'!$A$20:$A$44,0)) | N18: =INDEX('4_UK_Beta_Input'!$D$49:$D$122,MATCH($D18,'4_UK_Beta_Input'!$A$49:$A$122,0)) | O18: =INDEX('4_UK_Beta_Input'!$D$127:$D$289,MATCH($A18,'4_UK_Beta_Input'!$A$127:$A$289,0)) | P18: =(M18/L18)*(N18/M18)*(O18/N18) | Q18: =IF(J18="",INDEX('3_UK_L1_Input'!$D$4:$D$14,MATCH($C18,'3_UK_L1_Input'!$A$4:$A$14,0))*P18,INDEX('3_UK_L1_Input'!$D$4:$D$14,MATCH($C18,'3_UK_L1_Input'!$A$4:$A$14,0))*J18) | R18: =IF(K18="",INDEX('3_UK_L1_Input'!$D$4:$D$14,MATCH($C18,'3_UK_L1_Input'!$A$4:$A$14,0))*P18,INDEX('3_UK_L1_Input'!$D$4:$D$14,MATCH($C18,'3_UK_L1_Input'!$A$4:$A$14,0))*K18) | S18: =IF(G18="","BETA CASCADE FALLBACK (dummy — replace with real beta)","REAL (Bloomberg UK)") | T18: =INDEX('3_UK_L1_Input'!$C$4:$C$14,MATCH($C18,'3_UK_L1_Input'!$A$4:$A$14,0)) | U18: =INDEX('3_UK_L1_Input'!$C$4:$C$14,MATCH($C18,'3_UK_L1_Input'!$A$4:$A$14,0))*P18 | V18: =INDEX('5_UK_DefaultRisk_Input'!$D$5:$D$15,MATCH($C18,'5_UK_DefaultRisk_Input'!$A$5:$A$15,0)) | W18: =INDEX('5_UK_DefaultRisk_Input'!$D$20:$D$44,MATCH($E18,'5_UK_DefaultRisk_Input'!$A$20:$A$44,0)) | X18: =INDEX('5_UK_DefaultRisk_Input'!$D$49:$D$122,MATCH($D18,'5_UK_DefaultRisk_Input'!$A$49:$A$122,0)) | Y18: =INDEX('5_UK_DefaultRisk_Input'!$D$127:$D$289,MATCH($A18,'5_UK_DefaultRisk_Input'!$A$127:$A$289,0)) | Z18: =(W18/V18)*(X18/W18)*(Y18/X18) | AA18: =INDEX('3_UK_L1_Input'!$D$4:$D$14,MATCH($C18,'3_UK_L1_Input'!$A$4:$A$14,0))*Z18
A19: 15104020 | B19: Diversified Metals & Mining | C19: 15 | D19: 151040 | E19: 1510 | F19: 1930000000 | G19: 5.94 | H19: =IFERROR(SUMPRODUCT(($C$3:$C$165=C19)*ISNUMBER($G$3:$G$165)*ISNUMBER($F$3:$F$165)*IF(ISNUMBER($F$3:$F$165),$F$3:$F$165,0)*IF(ISNUMBER($G$3:$G$165),$G$3:$G$165,0))/SUMPRODUCT(($C$3:$C$165=C19)*ISNUMBER($G$3:$G$165)*ISNUMBER($F$3:$F$165)*IF(ISNUMBER($F$3:$F$165),$F$3:$F$165,0)),"") | I19: =IFERROR(SUMPRODUCT(($C$3:$C$165=C19)*ISNUMBER($G$3:$G$165)*IF(ISNUMBER($G$3:$G$165),$G$3:$G$165,0))/SUMPRODUCT(($C$3:$C$165=C19)*ISNUMBER($G$3:$G$165)),"") | J19: =IF(OR(G19="",H19=""),"",G19/H19) | K19: =IF(OR(G19="",I19=""),"",G19/I19) | L19: =INDEX('4_UK_Beta_Input'!$D$5:$D$15,MATCH($C19,'4_UK_Beta_Input'!$A$5:$A$15,0)) | M19: =INDEX('4_UK_Beta_Input'!$D$20:$D$44,MATCH($E19,'4_UK_Beta_Input'!$A$20:$A$44,0)) | N19: =INDEX('4_UK_Beta_Input'!$D$49:$D$122,MATCH($D19,'4_UK_Beta_Input'!$A$49:$A$122,0)) | O19: =INDEX('4_UK_Beta_Input'!$D$127:$D$289,MATCH($A19,'4_UK_Beta_Input'!$A$127:$A$289,0)) | P19: =(M19/L19)*(N19/M19)*(O19/N19) | Q19: =IF(J19="",INDEX('3_UK_L1_Input'!$D$4:$D$14,MATCH($C19,'3_UK_L1_Input'!$A$4:$A$14,0))*P19,INDEX('3_UK_L1_Input'!$D$4:$D$14,MATCH($C19,'3_UK_L1_Input'!$A$4:$A$14,0))*J19) | R19: =IF(K19="",INDEX('3_UK_L1_Input'!$D$4:$D$14,MATCH($C19,'3_UK_L1_Input'!$A$4:$A$14,0))*P19,INDEX('3_UK_L1_Input'!$D$4:$D$14,MATCH($C19,'3_UK_L1_Input'!$A$4:$A$14,0))*K19) | S19: =IF(G19="","BETA CASCADE FALLBACK (dummy — replace with real beta)","REAL (Bloomberg UK)") | T19: =INDEX('3_UK_L1_Input'!$C$4:$C$14,MATCH($C19,'3_UK_L1_Input'!$A$4:$A$14,0)) | U19: =INDEX('3_UK_L1_Input'!$C$4:$C$14,MATCH($C19,'3_UK_L1_Input'!$A$4:$A$14,0))*P19 | V19: =INDEX('5_UK_DefaultRisk_Input'!$D$5:$D$15,MATCH($C19,'5_UK_DefaultRisk_Input'!$A$5:$A$15,0)) | W19: =INDEX('5_UK_DefaultRisk_Input'!$D$20:$D$44,MATCH($E19,'5_UK_DefaultRisk_Input'!$A$20:$A$44,0)) | X19: =INDEX('5_UK_DefaultRisk_Input'!$D$49:$D$122,MATCH($D19,'5_UK_DefaultRisk_Input'!$A$49:$A$122,0)) | Y19: =INDEX('5_UK_DefaultRisk_Input'!$D$127:$D$289,MATCH($A19,'5_UK_DefaultRisk_Input'!$A$127:$A$289,0)) | Z19: =(W19/V19)*(X19/W19)*(Y19/X19) | AA19: =INDEX('3_UK_L1_Input'!$D$4:$D$14,MATCH($C19,'3_UK_L1_Input'!$A$4:$A$14,0))*Z19
A20: 15104025 | B20: Copper | C20: 15 | D20: 151040 | E20: 1510 | F20: 76620000 | G20: 1.5 | H20: =IFERROR(SUMPRODUCT(($C$3:$C$165=C20)*ISNUMBER($G$3:$G$165)*ISNUMBER($F$3:$F$165)*IF(ISNUMBER($F$3:$F$165),$F$3:$F$165,0)*IF(ISNUMBER($G$3:$G$165),$G$3:$G$165,0))/SUMPRODUCT(($C$3:$C$165=C20)*ISNUMBER($G$3:$G$165)*ISNUMBER($F$3:$F$165)*IF(ISNUMBER($F$3:$F$165),$F$3:$F$165,0)),"") | I20: =IFERROR(SUMPRODUCT(($C$3:$C$165=C20)*ISNUMBER($G$3:$G$165)*IF(ISNUMBER($G$3:$G$165),$G$3:$G$165,0))/SUMPRODUCT(($C$3:$C$165=C20)*ISNUMBER($G$3:$G$165)),"") | J20: =IF(OR(G20="",H20=""),"",G20/H20) | K20: =IF(OR(G20="",I20=""),"",G20/I20) | L20: =INDEX('4_UK_Beta_Input'!$D$5:$D$15,MATCH($C20,'4_UK_Beta_Input'!$A$5:$A$15,0)) | M20: =INDEX('4_UK_Beta_Input'!$D$20:$D$44,MATCH($E20,'4_UK_Beta_Input'!$A$20:$A$44,0)) | N20: =INDEX('4_UK_Beta_Input'!$D$49:$D$122,MATCH($D20,'4_UK_Beta_Input'!$A$49:$A$122,0)) | O20: =INDEX('4_UK_Beta_Input'!$D$127:$D$289,MATCH($A20,'4_UK_Beta_Input'!$A$127:$A$289,0)) | P20: =(M20/L20)*(N20/M20)*(O20/N20) | Q20: =IF(J20="",INDEX('3_UK_L1_Input'!$D$4:$D$14,MATCH($C20,'3_UK_L1_Input'!$A$4:$A$14,0))*P20,INDEX('3_UK_L1_Input'!$D$4:$D$14,MATCH($C20,'3_UK_L1_Input'!$A$4:$A$14,0))*J20) | R20: =IF(K20="",INDEX('3_UK_L1_Input'!$D$4:$D$14,MATCH($C20,'3_UK_L1_Input'!$A$4:$A$14,0))*P20,INDEX('3_UK_L1_Input'!$D$4:$D$14,MATCH($C20,'3_UK_L1_Input'!$A$4:$A$14,0))*K20) | S20: =IF(G20="","BETA CASCADE FALLBACK (dummy — replace with real beta)","REAL (Bloomberg UK)") | T20: =INDEX('3_UK_L1_Input'!$C$4:$C$14,MATCH($C20,'3_UK_L1_Input'!$A$4:$A$14,0)) | U20: =INDEX('3_UK_L1_Input'!$C$4:$C$14,MATCH($C20,'3_UK_L1_Input'!$A$4:$A$14,0))*P20 | V20: =INDEX('5_UK_DefaultRisk_Input'!$D$5:$D$15,MATCH($C20,'5_UK_DefaultRisk_Input'!$A$5:$A$15,0)) | W20: =INDEX('5_UK_DefaultRisk_Input'!$D$20:$D$44,MATCH($E20,'5_UK_DefaultRisk_Input'!$A$20:$A$44,0)) | X20: =INDEX('5_UK_DefaultRisk_Input'!$D$49:$D$122,MATCH($D20,'5_UK_DefaultRisk_Input'!$A$49:$A$122,0)) | Y20: =INDEX('5_UK_DefaultRisk_Input'!$D$127:$D$289,MATCH($A20,'5_UK_DefaultRisk_Input'!$A$127:$A$289,0)) | Z20: =(W20/V20)*(X20/W20)*(Y20/X20) | AA20: =INDEX('3_UK_L1_Input'!$D$4:$D$14,MATCH($C20,'3_UK_L1_Input'!$A$4:$A$14,0))*Z20
A21: 15104030 | B21: Gold | C21: 15 | D21: 151040 | E21: 1510 | F21: 410600000 | G21: 4.23 | H21: =IFERROR(SUMPRODUCT(($C$3:$C$165=C21)*ISNUMBER($G$3:$G$165)*ISNUMBER($F$3:$F$165)*IF(ISNUMBER($F$3:$F$165),$F$3:$F$165,0)*IF(ISNUMBER($G$3:$G$165),$G$3:$G$165,0))/SUMPRODUCT(($C$3:$C$165=C21)*ISNUMBER($G$3:$G$165)*ISNUMBER($F$3:$F$165)*IF(ISNUMBER($F$3:$F$165),$F$3:$F$165,0)),"") | I21: =IFERROR(SUMPRODUCT(($C$3:$C$165=C21)*ISNUMBER($G$3:$G$165)*IF(ISNUMBER($G$3:$G$165),$G$3:$G$165,0))/SUMPRODUCT(($C$3:$C$165=C21)*ISNUMBER($G$3:$G$165)),"") | J21: =IF(OR(G21="",H21=""),"",G21/H21) | K21: =IF(OR(G21="",I21=""),"",G21/I21) | L21: =INDEX('4_UK_Beta_Input'!$D$5:$D$15,MATCH($C21,'4_UK_Beta_Input'!$A$5:$A$15,0)) | M21: =INDEX('4_UK_Beta_Input'!$D$20:$D$44,MATCH($E21,'4_UK_Beta_Input'!$A$20:$A$44,0)) | N21: =INDEX('4_UK_Beta_Input'!$D$49:$D$122,MATCH($D21,'4_UK_Beta_Input'!$A$49:$A$122,0)) | O21: =INDEX('4_UK_Beta_Input'!$D$127:$D$289,MATCH($A21,'4_UK_Beta_Input'!$A$127:$A$289,0)) | P21: =(M21/L21)*(N21/M21)*(O21/N21) | Q21: =IF(J21="",INDEX('3_UK_L1_Input'!$D$4:$D$14,MATCH($C21,'3_UK_L1_Input'!$A$4:$A$14,0))*P21,INDEX('3_UK_L1_Input'!$D$4:$D$14,MATCH($C21,'3_UK_L1_Input'!$A$4:$A$14,0))*J21) | R21: =IF(K21="",INDEX('3_UK_L1_Input'!$D$4:$D$14,MATCH($C21,'3_UK_L1_Input'!$A$4:$A$14,0))*P21,INDEX('3_UK_L1_Input'!$D$4:$D$14,MATCH($C21,'3_UK_L1_Input'!$A$4:$A$14,0))*K21) | S21: =IF(G21="","BETA CASCADE FALLBACK (dummy — replace with real beta)","REAL (Bloomberg UK)") | T21: =INDEX('3_UK_L1_Input'!$C$4:$C$14,MATCH($C21,'3_UK_L1_Input'!$A$4:$A$14,0)) | U21: =INDEX('3_UK_L1_Input'!$C$4:$C$14,MATCH($C21,'3_UK_L1_Input'!$A$4:$A$14,0))*P21 | V21: =INDEX('5_UK_DefaultRisk_Input'!$D$5:$D$15,MATCH($C21,'5_UK_DefaultRisk_Input'!$A$5:$A$15,0)) | W21: =INDEX('5_UK_DefaultRisk_Input'!$D$20:$D$44,MATCH($E21,'5_UK_DefaultRisk_Input'!$A$20:$A$44,0)) | X21: =INDEX('5_UK_DefaultRisk_Input'!$D$49:$D$122,MATCH($D21,'5_UK_DefaultRisk_Input'!$A$49:$A$122,0)) | Y21: =INDEX('5_UK_DefaultRisk_Input'!$D$127:$D$289,MATCH($A21,'5_UK_DefaultRisk_Input'!$A$127:$A$289,0)) | Z21: =(W21/V21)*(X21/W21)*(Y21/X21) | AA21: =INDEX('3_UK_L1_Input'!$D$4:$D$14,MATCH($C21,'3_UK_L1_Input'!$A$4:$A$14,0))*Z21
A22: 15104040 | B22: Precious Metals & Minerals | C22: 15 | D22: 151040 | E22: 1510 | F22: 20970000 | H22: =IFERROR(SUMPRODUCT(($C$3:$C$165=C22)*ISNUMBER($G$3:$G$165)*ISNUMBER($F$3:$F$165)*IF(ISNUMBER($F$3:$F$165),$F$3:$F$165,0)*IF(ISNUMBER($G$3:$G$165),$G$3:$G$165,0))/SUMPRODUCT(($C$3:$C$165=C22)*ISNUMBER($G$3:$G$165)*ISNUMBER($F$3:$F$165)*IF(ISNUMBER($F$3:$F$165),$F$3:$F$165,0)),"") | I22: =IFERROR(SUMPRODUCT(($C$3:$C$165=C22)*ISNUMBER($G$3:$G$165)*IF(ISNUMBER($G$3:$G$165),$G$3:$G$165,0))/SUMPRODUCT(($C$3:$C$165=C22)*ISNUMBER($G$3:$G$165)),"") | J22: =IF(OR(G22="",H22=""),"",G22/H22) | K22: =IF(OR(G22="",I22=""),"",G22/I22) | L22: =INDEX('4_UK_Beta_Input'!$D$5:$D$15,MATCH($C22,'4_UK_Beta_Input'!$A$5:$A$15,0)) | M22: =INDEX('4_UK_Beta_Input'!$D$20:$D$44,MATCH($E22,'4_UK_Beta_Input'!$A$20:$A$44,0)) | N22: =INDEX('4_UK_Beta_Input'!$D$49:$D$122,MATCH($D22,'4_UK_Beta_Input'!$A$49:$A$122,0)) | O22: =INDEX('4_UK_Beta_Input'!$D$127:$D$289,MATCH($A22,'4_UK_Beta_Input'!$A$127:$A$289,0)) | P22: =(M22/L22)*(N22/M22)*(O22/N22) | Q22: =IF(J22="",INDEX('3_UK_L1_Input'!$D$4:$D$14,MATCH($C22,'3_UK_L1_Input'!$A$4:$A$14,0))*P22,INDEX('3_UK_L1_Input'!$D$4:$D$14,MATCH($C22,'3_UK_L1_Input'!$A$4:$A$14,0))*J22) | R22: =IF(K22="",INDEX('3_UK_L1_Input'!$D$4:$D$14,MATCH($C22,'3_UK_L1_Input'!$A$4:$A$14,0))*P22,INDEX('3_UK_L1_Input'!$D$4:$D$14,MATCH($C22,'3_UK_L1_Input'!$A$4:$A$14,0))*K22) | S22: =IF(G22="","BETA CASCADE FALLBACK (dummy — replace with real beta)","REAL (Bloomberg UK)") | T22: =INDEX('3_UK_L1_Input'!$C$4:$C$14,MATCH($C22,'3_UK_L1_Input'!$A$4:$A$14,0)) | U22: =INDEX('3_UK_L1_Input'!$C$4:$C$14,MATCH($C22,'3_UK_L1_Input'!$A$4:$A$14,0))*P22 | V22: =INDEX('5_UK_DefaultRisk_Input'!$D$5:$D$15,MATCH($C22,'5_UK_DefaultRisk_Input'!$A$5:$A$15,0)) | W22: =INDEX('5_UK_DefaultRisk_Input'!$D$20:$D$44,MATCH($E22,'5_UK_DefaultRisk_Input'!$A$20:$A$44,0)) | X22: =INDEX('5_UK_DefaultRisk_Input'!$D$49:$D$122,MATCH($D22,'5_UK_DefaultRisk_Input'!$A$49:$A$122,0)) | Y22: =INDEX('5_UK_DefaultRisk_Input'!$D$127:$D$289,MATCH($A22,'5_UK_DefaultRisk_Input'!$A$127:$A$289,0)) | Z22: =(W22/V22)*(X22/W22)*(Y22/X22) | AA22: =INDEX('3_UK_L1_Input'!$D$4:$D$14,MATCH($C22,'3_UK_L1_Input'!$A$4:$A$14,0))*Z22
